Workbook
Name _NEW2: [1]吊電B線入出料標準數據!$B$4:$P$4003
Name _XM_XT_THUCTE: '[2]XM.GUI MAIL'!$A$6:$AQ$108
Name _XM_XT_THUCTE: 'SOP HOA NGHIEM'!$B$3:$B$41
Name _XM_XT_THUCTE: 'XM.GUI MAIL'!$A$6:$AW$121
Name AB: #REF!
Name AB: #REF!
Name AB: #REF!
Name AB: #REF!
Name AB: #REF!
Name AB: #REF!
Name AB: #REF!
Name AB: #REF!
Name AB: #REF!
Name AB: #REF!
Name AB: #REF!
Name abcd: #REF!
Name abcd: #REF!
Name abcd: #REF!
Name abcd: #REF!
Name abcd: #REF!
Name abcd: #REF!
Name abcd: #REF!
Name abcd: #REF!
Name abcd: #REF!
Name abcd: #REF!
Name CCC: #REF!
Name CCC: #REF!
Name CCC: #REF!
Name CCC: #REF!
Name CCC: #REF!
Name CCC: #REF!
Name CCC: #REF!
Name CCC: #REF!
Name CCC: #REF!
Name CCC: #REF!
Name CCC: #REF!
Name CXXTA: #REF!
Name CXXTA: #REF!
Name CXXTA: #REF!
Name CXXTA: #REF!
Name CXXTA: #REF!
Name CXXTA: #REF!
Name CXXTA: #REF!
Name CXXTA: #REF!
Name CXXTA: #REF!
Name CXXTA: #REF!
Name CXXTA: #REF!
Name CXXTB: [1]吊電B線入出料標準數據!$B$3:$P$428
Name HUANGHAIDONGA: #REF!
Name HUANGHAIDONGA: #REF!
Name HUANGHAIDONGA: #REF!
Name HUANGHAIDONGA: #REF!
Name HUANGHAIDONGA: #REF!
Name HUANGHAIDONGA: #REF!
Name HUANGHAIDONGA: #REF!
Name HUANGHAIDONGA: #REF!
Name HUANGHAIDONGA: #REF!
Name HUANGHAIDONGA: #REF!
Name HUANGHAIDONGA: #REF!
Name HUANGHAIDONGB: [1]吊電B線入出料標準數據!$A$3:$P$428

Sheet PT TAP CHAT
B1: MẪU GỬI NHÀ CUNG ỨNG
B2: =MENU!AD9 -> 2024/08/01 | G2: 0.29166667 | H2: 0.45833333 | I2: 0.54166667
A3: NCC | B3: Type sample | C3: Test Item | D3: Standards | F3: Unit | G3: Result
A4: JASCO | B4: Akaline Zinc (XL-1E) | C4: Zn2+ | D4: ='XM.GUI MAIL'!E17 -> 8~12 | E4: ='XM.GUI MAIL'!F17 -> (10±2) | F4: g/l | G4: ='XM.GUI MAIL'!I17 -> 0 | H4: ='XM.GUI MAIL'!P17 -> 12.74 | I4: ='XM.GUI MAIL'!W17 -> 12.48
A5: JASCO | C5: NaOH | D5: ='XM.GUI MAIL'!E16 -> 130 - 150 | E5: ='XM.GUI MAIL'!F16 -> (140±7) | F5: g/l | G5: ='XM.GUI MAIL'!I16 -> 0 | H5: ='XM.GUI MAIL'!P16 -> 133.6 | I5: ='XM.GUI MAIL'!W16 -> 140.8
A6: JASCO | C6: Na2CO3 | D6: ＜70g/L | F6: g/l
A7: JASCO | C7: Fe | D7: <5 | F7: ppm
A8: JASCO | C8: Cu | D8: <5 | F8: ppm
A9: JASCO | C9: Cr | D9: <5 | F9: ppm
A10: JASCO | C10: Pb | D10: <5 | F10: ppm
A11: JASCO | B11: Màu (I) (TR173AH) (XL-1E) | C11: Cr2O3 (TR173AH) | D11: ='XM.GUI MAIL'!E18 -> 12~18 | E11: ='XM.GUI MAIL'!F18 -> (14±2) | F11: % | G11: ='XM.GUI MAIL'!I18 -> 0 | H11: ='XM.GUI MAIL'!P18 -> 15.827338 | I11: ='XM.GUI MAIL'!W18 -> 15.827338
A12: JASCO | C12: pH | D12: ='XM.GUI MAIL'!E19 -> 1.5~1.9 | E12: ='XM.GUI MAIL'!F19 -> (1.7±0.1 ) | F12: / | G12: ='XM.GUI MAIL'!I19 -> 0 | H12: ='XM.GUI MAIL'!P19 -> 1.63 | I12: ='XM.GUI MAIL'!W19 -> 1.64
A13: JASCO | C13: Fe | D13: <80 | F13: ppm
A14: JASCO | C14: Cu | D14: ＜5 | F14: ppm
A15: JASCO | C15: Zn | D15: ＜7000 | F15: ppm
A16: JASCO | B16: Màu K (5U109A) (XL-1E) | C16: Màu K (5U109A) | D16: ='XM.GUI MAIL'!E24 -> 5~10 | E16: ='XM.GUI MAIL'!F24 -> (7.5±1) | F16: % | G16: ='XM.GUI MAIL'!I24 | H16: ='XM.GUI MAIL'!I24 | I16: ='XM.GUI MAIL'!W24 -> 7.6923077
A17: JASCO | C17: pH | D17: ='XM.GUI MAIL'!E25 -> 2.0~2.4 | E17: ='XM.GUI MAIL'!F25 -> (2.2±0.1) | F17: / | G17: ='XM.GUI MAIL'!I25 -> 0 | H17: ='XM.GUI MAIL'!I25 -> 0 | I17: ='XM.GUI MAIL'!W25 -> 2.26
A18: JASCO | C18: Fe | D18: <40 | F18: ppm
A19: JASCO | C19: Cu | D19: ＜5 | F19: ppm
A20: JASCO | C20: Zn | D20: ＜6000 | F20: ppm
B22: Type sample | C22: Test Item | D22: Standards | F22: Unit | G22: Result
A23: HALO | B23: Akaline Zinc (XL-1F) | C23: Zn2+ | D23: ='XM.GUI MAIL'!E52 -> 8~12 | E23: ='XM.GUI MAIL'!F52 -> (10±2) | F23: g/l | G23: ='XM.GUI MAIL'!I52 -> 10.01 | H23: ='XM.GUI MAIL'!P52 -> 9.75 | I23: ='XM.GUI MAIL'!W52 -> 9.75
A24: HALO | C24: NaOH | D24: ='XM.GUI MAIL'!E51 -> 130 - 150 | E24: ='XM.GUI MAIL'!F51 -> (140±7) | F24: g/l | G24: ='XM.GUI MAIL'!I51 -> 144.8 | H24: ='XM.GUI MAIL'!P51 -> 144.8 | I24: ='XM.GUI MAIL'!W51 -> 143.2
A25: HALO | C25: Na2CO3 | D25: ＜70 | F25: g/l
A26: HALO | C26: Fe | D26: <5 | F26: ppm
A27: HALO | C27: Cu | D27: <5 | F27: ppm
A28: HALO | C28: Cr | D28: <5 | F28: ppm
A29: HALO | C29: Pb | D29: <5 | F29: ppm
A30: HALO | B30: Màu (I) (Lanthane 318) (XL-1F) | C30: Lanthane 318 | D30: ='XM.GUI MAIL'!E53 -> 6~10 | E30: ='XM.GUI MAIL'!F53 -> (7±1) | F30: % | G30: ='XM.GUI MAIL'!I53 -> 7.21605 | H30: ='XM.GUI MAIL'!P53 -> 7.13131 | I30: ='XM.GUI MAIL'!W53 -> 7.21605
A31: HALO | C31: pH | D31: ='XM.GUI MAIL'!E54 -> 2~2.5 | E31: ='XM.GUI MAIL'!F54 -> (2.3±0.1 ) | F31: / | G31: ='XM.GUI MAIL'!I54 -> 2.23 | H31: ='XM.GUI MAIL'!P54 -> 2.24 | I31: ='XM.GUI MAIL'!W54 -> 2.35
A32: HALO | C32: Fe | D32: <100 | F32: ppm
A33: HALO | C33: Cu | F33: ppm
A34: HALO | C34: Zn | D34: ＜12000 | F34: ppm
A35: HALO | B35: Màu (K) (Finidip 124) (XL-1F) | C35: Finidip 124 | D35: ='XM.GUI MAIL'!E59 -> 5~8 | E35: ='XM.GUI MAIL'!F59 -> (6±0.5) | F35: % | G35: ='XM.GUI MAIL'!I59 -> 7.2 | H35: ='XM.GUI MAIL'!I59 -> 7.2 | I35: ='XM.GUI MAIL'!W59 -> ko sx
A36: HALO | C36: pH | D36: ='XM.GUI MAIL'!E60 -> 1.8~2.4 | E36: ='XM.GUI MAIL'!F60 -> (2.1±0.1 ) | F36: / | G36: ='XM.GUI MAIL'!I60 -> 2.03 | H36: ='XM.GUI MAIL'!I60 -> 2.03 | I36: ='XM.GUI MAIL'!W60 -> ko sx
A37: HALO | C37: Fe | D37: 150 | F37: ppm
A38: HALO | C38: Cu | F38: ppm
A39: HALO | C39: Zn | D39: ＜15000 | F39: ppm
B41: Type sample | C41: Test Item | D41: Standards | F41: Unit | G41: Result
A42: HALO | B42: Akaline Zinc (XT-0C) | C42: Zn2+ | D42: ='XM.GUI MAIL'!E87 -> 7~10 | E42: ='XM.GUI MAIL'!F87 -> (8.5±1) | F42: g/l | G42: ='XM.GUI MAIL'!I87 -> 8.385 | H42: ='XM.GUI MAIL'!P87 -> 8.385 | I42: ='XM.GUI MAIL'!W87 -> 8.45
...

Sheet 1
A1: "BÁO CÁO KẾT QUẢ HÓA NGHIỆM HÀNG NGÀY 表面處理生產製程管控記錄表"
A2: NGAY | B2: Ma__Hang_muc | C2: Nong_Do_01 | E2: 1 | F2: bs | G2: 2 | H2: bs | I2: 3 | J2: bs | K2: 4 | L2: bs | M2: 5 | N2: bs | O2: 6 | P2: bs | Q2: 1
A3: Date | B3: Code | C3: 濃度 g/L-01
A4: 8/1/2024 9:45:00 AM | B4: 1F-XB1 | C4: 71.39 | E4: TRUE | F4: FALSE | G4: FALSE | H4: FALSE | I4: FALSE | J4: FALSE | K4: FALSE | L4: FALSE | M4: FALSE | N4: FALSE | O4: FALSE | P4: FALSE
A5: 8/1/2024 9:45:00 AM | B5: 1F-XB2 | C5: 72.039 | E5: TRUE | F5: FALSE | G5: FALSE | H5: FALSE | I5: FALSE | J5: FALSE | K5: FALSE | L5: FALSE | M5: FALSE | N5: FALSE | O5: FALSE | P5: FALSE
A6: 8/1/2024 9:45:00 AM | B6: 1F-DG1 | C6: 55.209 | E6: TRUE | F6: FALSE | G6: FALSE | H6: FALSE | I6: FALSE | J6: FALSE | K6: FALSE | L6: FALSE | M6: FALSE | N6: FALSE | O6: FALSE | P6: FALSE
A7: 8/1/2024 9:45:00 AM | B7: 1F-DG2 | C7: 58.674 | E7: TRUE | F7: FALSE | G7: FALSE | H7: FALSE | I7: FALSE | J7: FALSE | K7: FALSE | L7: FALSE | M7: FALSE | N7: FALSE | O7: FALSE | P7: FALSE
A8: 8/1/2024 9:45:00 AM | B8: 1F-NAOH | C8: 144.8 | E8: TRUE | F8: FALSE | G8: FALSE | H8: FALSE | I8: FALSE | J8: FALSE | K8: FALSE | L8: FALSE | M8: FALSE | N8: FALSE | O8: FALSE | P8: FALSE
A9: 8/1/2024 9:45:00 AM | B9: 1F-ZN | C9: 10.01 | E9: TRUE | F9: FALSE | G9: FALSE | H9: FALSE | I9: FALSE | J9: FALSE | K9: FALSE | L9: FALSE | M9: FALSE | N9: FALSE | O9: FALSE | P9: FALSE
A10: 8/1/2024 9:45:00 AM | B10: 1F-CR3I | C10: 7.21605 | E10: TRUE | F10: FALSE | G10: FALSE | H10: FALSE | I10: FALSE | J10: FALSE | K10: FALSE | L10: FALSE | M10: FALSE | N10: FALSE | O10: FALSE | P10: FALSE
A11: 8/1/2024 9:45:00 AM | B11: 1F-CR3IPH | C11: 2.23 | E11: TRUE | F11: FALSE | G11: FALSE | H11: FALSE | I11: FALSE | J11: FALSE | K11: FALSE | L11: FALSE | M11: FALSE | N11: FALSE | O11: FALSE | P11: FALSE
A12: 8/1/2024 9:45:00 AM | B12: 1F-HCL1 | C12: 0.46765625 | E12: TRUE | F12: FALSE | G12: FALSE | H12: FALSE | I12: FALSE | J12: FALSE | K12: FALSE | L12: FALSE | M12: FALSE | N12: FALSE | O12: FALSE | P12: FALSE
A13: 8/1/2024 9:45:00 AM | B13: 1F-HCL3 | C13: 0.07984375 | E13: TRUE | F13: FALSE | G13: FALSE | H13: FALSE | I13: FALSE | J13: FALSE | K13: FALSE | L13: FALSE | M13: FALSE | N13: FALSE | O13: FALSE | P13: FALSE
A14: 8/1/2024 9:45:00 AM | B14: 1F-HNO3 | C14: 0.011088 | E14: TRUE | F14: FALSE | G14: FALSE | H14: FALSE | I14: FALSE | J14: FALSE | K14: FALSE | L14: FALSE | M14: FALSE | N14: FALSE | O14: FALSE | P14: FALSE
A15: 8/1/2024 9:45:00 AM | B15: 1F-MEM | C15: 175 | E15: TRUE | F15: FALSE | G15: FALSE | H15: FALSE | I15: FALSE | J15: FALSE | K15: FALSE | L15: FALSE | M15: FALSE | N15: FALSE | O15: FALSE | P15: FALSE
... A59: 8/1/2024 9:45:00 AM | B59: DC-BLACK08 | C59: 5.5 | E59: TRUE | F59: FALSE | G59: FALSE | H59: FALSE | I59: FALSE | J59: FALSE | K59: FALSE | L59: FALSE | M59: FALSE | N59: FALSE | O59: FALSE | P59: FALSE

Sheet 2
A1: "BÁO CÁO KẾT QUẢ HÓA NGHIỆM HÀNG NGÀY 表面處理生產製程管控記錄表"
A2: NGAY | B2: Ma__Hang_muc | C2: Nong_Do_02 | E2: 1 | F2: bs | G2: 2 | H2: bs | I2: 3 | J2: bs | K2: 4 | L2: bs | M2: 5 | N2: bs | O2: 6 | P2: bs | Q2: 2
A3: Date | B3: Code | C3: 濃度 g/L-02
A4: 8/1/2024 11:45:00 AM | B4: 1E-XB1 | C4: 26.6 | E4: FALSE | F4: FALSE | G4: TRUE | H4: FALSE | I4: FALSE | J4: FALSE | K4: FALSE | L4: FALSE | M4: FALSE | N4: FALSE | O4: FALSE | P4: FALSE
A5: 8/1/2024 11:45:00 AM | B5: 1E-XB2 | C5: 31 | E5: FALSE | F5: FALSE | G5: TRUE | H5: FALSE | I5: FALSE | J5: FALSE | K5: FALSE | L5: FALSE | M5: FALSE | N5: FALSE | O5: FALSE | P5: FALSE
A6: 8/1/2024 11:45:00 AM | B6: 1E-DG1 | C6: 77 | E6: FALSE | F6: FALSE | G6: TRUE | H6: FALSE | I6: FALSE | J6: FALSE | K6: FALSE | L6: FALSE | M6: FALSE | N6: FALSE | O6: FALSE | P6: FALSE
A7: 8/1/2024 11:45:00 AM | B7: 1E-DG2 | C7: 72.6 | E7: FALSE | F7: FALSE | G7: TRUE | H7: FALSE | I7: FALSE | J7: FALSE | K7: FALSE | L7: FALSE | M7: FALSE | N7: FALSE | O7: FALSE | P7: FALSE
A8: 8/1/2024 11:45:00 AM | B8: 1E-NAOH | C8: 133.6 | E8: FALSE | F8: FALSE | G8: TRUE | H8: FALSE | I8: FALSE | J8: FALSE | K8: FALSE | L8: FALSE | M8: FALSE | N8: FALSE | O8: FALSE | P8: FALSE
A9: 8/1/2024 11:45:00 AM | B9: 1E-ZN | C9: 12.74 | E9: FALSE | F9: FALSE | G9: TRUE | H9: FALSE | I9: FALSE | J9: FALSE | K9: FALSE | L9: FALSE | M9: FALSE | N9: FALSE | O9: FALSE | P9: FALSE
A10: 8/1/2024 11:45:00 AM | B10: 1E-CR3I | C10: 15.827338 | E10: FALSE | F10: FALSE | G10: TRUE | H10: FALSE | I10: FALSE | J10: FALSE | K10: FALSE | L10: FALSE | M10: FALSE | N10: FALSE | O10: FALSE | P10: FALSE
A11: 8/1/2024 11:45:00 AM | B11: 1E-CR3IPH | C11: 1.63 | E11: FALSE | F11: FALSE | G11: TRUE | H11: FALSE | I11: FALSE | J11: FALSE | K11: FALSE | L11: FALSE | M11: FALSE | N11: FALSE | O11: FALSE | P11: FALSE
A12: 8/1/2024 11:45:00 AM | B12: 1E-HCL1 | C12: 0.4334375 | E12: FALSE | F12: FALSE | G12: TRUE | H12: FALSE | I12: FALSE | J12: FALSE | K12: FALSE | L12: FALSE | M12: FALSE | N12: FALSE | O12: FALSE | P12: FALSE
A13: 8/1/2024 11:45:00 AM | B13: 1E-HCL3 | C13: 0.13459375 | E13: FALSE | F13: FALSE | G13: TRUE | H13: FALSE | I13: FALSE | J13: FALSE | K13: FALSE | L13: FALSE | M13: FALSE | N13: FALSE | O13: FALSE | P13: FALSE
A14: 8/1/2024 11:45:00 AM | B14: 1F-XB1 | C14: 72.688 | E14: FALSE | F14: FALSE | G14: TRUE | H14: FALSE | I14: FALSE | J14: FALSE | K14: FALSE | L14: FALSE | M14: FALSE | N14: FALSE | O14: FALSE | P14: FALSE
A15: 8/1/2024 11:45:00 AM | B15: 1F-XB2 | C15: 74.9595 | E15: FALSE | F15: FALSE | G15: TRUE | H15: FALSE | I15: FALSE | J15: FALSE | K15: FALSE | L15: FALSE | M15: FALSE | N15: FALSE | O15: FALSE | P15: FALSE
... A39: 8/1/2024 11:45:00 AM | B39: XT-MEM | C39: 197 | E39: FALSE | F39: FALSE | G39: TRUE | H39: FALSE | I39: FALSE | J39: FALSE | K39: FALSE | L39: FALSE | M39: FALSE | N39: FALSE | O39: FALSE | P39: FALSE

Sheet 3
A1: "BÁO CÁO KẾT QUẢ HÓA NGHIỆM HÀNG NGÀY 表面處理生產製程管控記錄表"
A2: NGAY | B2: Ma__Hang_muc | C2: Nong_Do_03 | E2: 1 | F2: bs | G2: 2 | H2: bs | I2: 3 | J2: bs | K2: 4 | L2: bs | M2: 5 | N2: bs | O2: 6 | P2: bs | Q2: 3
A3: Date | B3: Code | C3: 濃度 g/03
A4: 8/1/2024 4:30:00 PM | B4: 1E-XB1 | C4: 32.8 | E4: FALSE | F4: FALSE | G4: FALSE | H4: FALSE | I4: TRUE | J4: FALSE | K4: FALSE | L4: FALSE | M4: FALSE | N4: FALSE | O4: FALSE | P4: FALSE
A5: 8/1/2024 4:30:00 PM | B5: 1E-XB2 | C5: 30.2 | E5: FALSE | F5: FALSE | G5: FALSE | H5: FALSE | I5: TRUE | J5: FALSE | K5: FALSE | L5: FALSE | M5: FALSE | N5: FALSE | O5: FALSE | P5: FALSE
A6: 8/1/2024 4:30:00 PM | B6: 1E-DG1 | C6: 78 | E6: FALSE | F6: FALSE | G6: FALSE | H6: FALSE | I6: TRUE | J6: FALSE | K6: FALSE | L6: FALSE | M6: FALSE | N6: FALSE | O6: FALSE | P6: FALSE
A7: 8/1/2024 4:30:00 PM | B7: 1E-DG2 | C7: 72.4 | E7: FALSE | F7: FALSE | G7: FALSE | H7: FALSE | I7: TRUE | J7: FALSE | K7: FALSE | L7: FALSE | M7: FALSE | N7: FALSE | O7: FALSE | P7: FALSE
A8: 8/1/2024 4:30:00 PM | B8: 1E-NAOH | C8: 140.8 | E8: FALSE | F8: FALSE | G8: FALSE | H8: FALSE | I8: TRUE | J8: FALSE | K8: FALSE | L8: FALSE | M8: FALSE | N8: FALSE | O8: FALSE | P8: FALSE
A9: 8/1/2024 4:30:00 PM | B9: 1E-ZN | C9: 12.48 | E9: FALSE | F9: FALSE | G9: FALSE | H9: FALSE | I9: TRUE | J9: FALSE | K9: FALSE | L9: FALSE | M9: FALSE | N9: FALSE | O9: FALSE | P9: FALSE
A10: 8/1/2024 4:30:00 PM | B10: 1E-CR3I | C10: 15.827338 | E10: FALSE | F10: FALSE | G10: FALSE | H10: FALSE | I10: TRUE | J10: FALSE | K10: FALSE | L10: FALSE | M10: FALSE | N10: FALSE | O10: FALSE | P10: FALSE
A11: 8/1/2024 4:30:00 PM | B11: 1E-CR3IPH | C11: 1.64 | E11: FALSE | F11: FALSE | G11: FALSE | H11: FALSE | I11: TRUE | J11: FALSE | K11: FALSE | L11: FALSE | M11: FALSE | N11: FALSE | O11: FALSE | P11: FALSE
A12: 8/1/2024 4:30:00 PM | B12: 1E-HCL1 | C12: 0.4790625 | E12: FALSE | F12: FALSE | G12: FALSE | H12: FALSE | I12: TRUE | J12: FALSE | K12: FALSE | L12: FALSE | M12: FALSE | N12: FALSE | O12: FALSE | P12: FALSE
A13: 8/1/2024 4:30:00 PM | B13: 1E-HCL3 | C13: 0.18478125 | E13: FALSE | F13: FALSE | G13: FALSE | H13: FALSE | I13: TRUE | J13: FALSE | K13: FALSE | L13: FALSE | M13: FALSE | N13: FALSE | O13: FALSE | P13: FALSE
A14: 8/1/2024 4:30:00 PM | B14: 1F-XB1 | C14: 72.3635 | E14: FALSE | F14: FALSE | G14: FALSE | H14: FALSE | I14: TRUE | J14: FALSE | K14: FALSE | L14: FALSE | M14: FALSE | N14: FALSE | O14: FALSE | P14: FALSE
A15: 8/1/2024 4:30:00 PM | B15: 1F-XB2 | C15: 74.635 | E15: FALSE | F15: FALSE | G15: FALSE | H15: FALSE | I15: TRUE | J15: FALSE | K15: FALSE | L15: FALSE | M15: FALSE | N15: FALSE | O15: FALSE | P15: FALSE
... A46: 8/1/2024 4:30:00 PM | B46: RLG-XBPH | C46: 10 | E46: FALSE | F46: FALSE | G46: FALSE | H46: FALSE | I46: TRUE | J46: FALSE | K46: FALSE | L46: FALSE | M46: FALSE | N46: FALSE | O46: FALSE | P46: FALSE

Sheet 4
A1: "BÁO CÁO KẾT QUẢ HÓA NGHIỆM HÀNG NGÀY 表面處理生產製程管控記錄表"
A2: NGAY | B2: Ma__Hang_muc | C2: Nong_Do_03 | E2: 1 | F2: bs | G2: 2 | H2: bs | I2: 3 | J2: bs | K2: 4 | L2: bs | M2: 5 | N2: bs | O2: 6 | P2: bs | Q2: 3
A3: Date | B3: Code | C3: 濃度 g/03
A4: 8/1/2024 6:00:00 PM | B4: RLG-KD | C4: 38 | E4: FALSE | F4: FALSE | G4: FALSE | H4: FALSE | I4: TRUE | J4: FALSE | K4: FALSE | L4: FALSE | M4: FALSE | N4: FALSE | O4: FALSE | P4: FALSE
A5: 8/1/2024 6:00:00 PM | B5: RLG-HCL1 | C5: 9.855 | E5: FALSE | F5: FALSE | G5: FALSE | H5: FALSE | I5: TRUE | J5: FALSE | K5: FALSE | L5: FALSE | M5: FALSE | N5: FALSE | O5: FALSE | P5: FALSE
A6: 8/1/2024 6:00:00 PM | B6: RLG-PPTA | C6: 43 | E6: FALSE | F6: FALSE | G6: FALSE | H6: FALSE | I6: TRUE | J6: FALSE | K6: FALSE | L6: FALSE | M6: FALSE | N6: FALSE | O6: FALSE | P6: FALSE
A7: 8/1/2024 6:00:00 PM | B7: RLG-PPAX | C7: 8.9583333 | E7: FALSE | F7: FALSE | G7: FALSE | H7: FALSE | I7: TRUE | J7: FALSE | K7: FALSE | L7: FALSE | M7: FALSE | N7: FALSE | O7: FALSE | P7: FALSE
A8: 8/1/2024 6:00:00 PM | B8: RLG-PPPL | C8: 0.14 | E8: FALSE | F8: FALSE | G8: FALSE | H8: FALSE | I8: TRUE | J8: FALSE | K8: FALSE | L8: FALSE | M8: FALSE | N8: FALSE | O8: FALSE | P8: FALSE
A9: 8/1/2024 6:00:00 PM | B9: RLG-XB | C9: 0.95 | E9: FALSE | F9: FALSE | G9: FALSE | H9: FALSE | I9: TRUE | J9: FALSE | K9: FALSE | L9: FALSE | M9: FALSE | N9: FALSE | O9: FALSE | P9: FALSE
A10: 8/1/2024 6:00:00 PM | B10: RLG-XBPH | C10: 9.5 | E10: FALSE | F10: FALSE | G10: FALSE | H10: FALSE | I10: TRUE | J10: FALSE | K10: FALSE | L10: FALSE | M10: FALSE | N10: FALSE | O10: FALSE | P10: FALSE

Sheet 5
A1: "BÁO CÁO KẾT QUẢ HÓA NGHIỆM HÀNG NGÀY 表面處理生產製程管控記錄表"
A2: NGAY | B2: Ma__Hang_muc | C2: Nong_Do_04 | E2: 1 | F2: bs | G2: 2 | H2: bs | I2: 3 | J2: bs | K2: 4 | L2: bs | M2: 5 | N2: bs | O2: 6 | P2: bs | Q2: 4
A3: Date | B3: Code | C3: 濃度 g/L_04
A4: 8/1/2024 9:45:00 PM | B4: 1E-XB1 | C4: 33.6 | E4: FALSE | F4: FALSE | G4: FALSE | H4: FALSE | I4: FALSE | J4: FALSE | K4: TRUE | L4: FALSE | M4: FALSE | N4: FALSE | O4: FALSE | P4: FALSE
A5: 8/1/2024 9:45:00 PM | B5: 1E-XB2 | C5: 31.2 | E5: FALSE | F5: FALSE | G5: FALSE | H5: FALSE | I5: FALSE | J5: FALSE | K5: TRUE | L5: FALSE | M5: FALSE | N5: FALSE | O5: FALSE | P5: FALSE
A6: 8/1/2024 9:45:00 PM | B6: 1E-DG1 | C6: 75.2 | E6: FALSE | F6: FALSE | G6: FALSE | H6: FALSE | I6: FALSE | J6: FALSE | K6: TRUE | L6: FALSE | M6: FALSE | N6: FALSE | O6: FALSE | P6: FALSE
A7: 8/1/2024 9:45:00 PM | B7: 1E-DG2 | C7: 69.2 | E7: FALSE | F7: FALSE | G7: FALSE | H7: FALSE | I7: FALSE | J7: FALSE | K7: TRUE | L7: FALSE | M7: FALSE | N7: FALSE | O7: FALSE | P7: FALSE
A8: 8/1/2024 9:45:00 PM | B8: 1E-NAOH | C8: 143.2 | E8: FALSE | F8: FALSE | G8: FALSE | H8: FALSE | I8: FALSE | J8: FALSE | K8: TRUE | L8: FALSE | M8: FALSE | N8: FALSE | O8: FALSE | P8: FALSE
A9: 8/1/2024 9:45:00 PM | B9: 1E-ZN | C9: 11.44 | E9: FALSE | F9: FALSE | G9: FALSE | H9: FALSE | I9: FALSE | J9: FALSE | K9: TRUE | L9: FALSE | M9: FALSE | N9: FALSE | O9: FALSE | P9: FALSE
A10: 8/1/2024 9:45:00 PM | B10: 1E-CR3I | C10: 18.129496 | E10: FALSE | F10: FALSE | G10: FALSE | H10: FALSE | I10: FALSE | J10: FALSE | K10: TRUE | L10: FALSE | M10: FALSE | N10: FALSE | O10: FALSE | P10: FALSE
A11: 8/1/2024 9:45:00 PM | B11: 1E-CR3IPH | C11: 1.8 | E11: FALSE | F11: FALSE | G11: FALSE | H11: FALSE | I11: FALSE | J11: FALSE | K11: TRUE | L11: FALSE | M11: FALSE | N11: FALSE | O11: FALSE | P11: FALSE
A12: 8/1/2024 9:45:00 PM | B12: 1E-HCL1 | C12: 0.49046875 | E12: FALSE | F12: FALSE | G12: FALSE | H12: FALSE | I12: FALSE | J12: FALSE | K12: TRUE | L12: FALSE | M12: FALSE | N12: FALSE | O12: FALSE | P12: FALSE
A13: 8/1/2024 9:45:00 PM | B13: 1E-HCL3 | C13: 0.17109375 | E13: FALSE | F13: FALSE | G13: FALSE | H13: FALSE | I13: FALSE | J13: FALSE | K13: TRUE | L13: FALSE | M13: FALSE | N13: FALSE | O13: FALSE | P13: FALSE
A14: 8/1/2024 9:45:00 PM | B14: 1E-HNO3 | C14: 0.00819 | E14: FALSE | F14: FALSE | G14: FALSE | H14: FALSE | I14: FALSE | J14: FALSE | K14: TRUE | L14: FALSE | M14: FALSE | N14: FALSE | O14: FALSE | P14: FALSE
A15: 8/1/2024 9:45:00 PM | B15: 1E-MEM | C15: 460 | E15: FALSE | F15: FALSE | G15: FALSE | H15: FALSE | I15: FALSE | J15: FALSE | K15: TRUE | L15: FALSE | M15: FALSE | N15: FALSE | O15: FALSE | P15: FALSE
... A35: 8/1/2024 9:45:00 PM | B35: RLG-XBPH | C35: 10 | E35: FALSE | F35: FALSE | G35: FALSE | H35: FALSE | I35: FALSE | J35: FALSE | K35: TRUE | L35: FALSE | M35: FALSE | N35: FALSE | O35: FALSE | P35: FALSE

Sheet 6
A1: "BÁO CÁO KẾT QUẢ HÓA NGHIỆM HÀNG NGÀY 表面處理生產製程管控記錄表"
A2: NGAY | B2: Ma__Hang_muc | C2: Nong_Do_05 | E2: 1 | F2: bs | G2: 2 | H2: bs | I2: 3 | J2: bs | K2: 4 | L2: bs | M2: 5 | N2: bs | O2: 6 | P2: bs | Q2: 5
A3: Date | B3: Code | C3: 濃度 g/L_05
A4: 8/1/2024 11:45:00 PM | B4: 1E-XB1 | C4: 32 | E4: FALSE | F4: FALSE | G4: FALSE | H4: FALSE | I4: FALSE | J4: FALSE | K4: FALSE | L4: FALSE | M4: TRUE | N4: FALSE | O4: FALSE | P4: FALSE
A5: 8/1/2024 11:45:00 PM | B5: 1E-XB2 | C5: 32 | E5: FALSE | F5: FALSE | G5: FALSE | H5: FALSE | I5: FALSE | J5: FALSE | K5: FALSE | L5: FALSE | M5: TRUE | N5: FALSE | O5: FALSE | P5: FALSE
A6: 8/1/2024 11:45:00 PM | B6: 1E-DG1 | C6: 79.2 | E6: FALSE | F6: FALSE | G6: FALSE | H6: FALSE | I6: FALSE | J6: FALSE | K6: FALSE | L6: FALSE | M6: TRUE | N6: FALSE | O6: FALSE | P6: FALSE
A7: 8/1/2024 11:45:00 PM | B7: 1E-DG2 | C7: 68 | E7: FALSE | F7: FALSE | G7: FALSE | H7: FALSE | I7: FALSE | J7: FALSE | K7: FALSE | L7: FALSE | M7: TRUE | N7: FALSE | O7: FALSE | P7: FALSE
A8: 8/1/2024 11:45:00 PM | B8: 1E-NAOH | C8: 142.4 | E8: FALSE | F8: FALSE | G8: FALSE | H8: FALSE | I8: FALSE | J8: FALSE | K8: FALSE | L8: FALSE | M8: TRUE | N8: FALSE | O8: FALSE | P8: FALSE
A9: 8/1/2024 11:45:00 PM | B9: 1E-ZN | C9: 10.79 | E9: FALSE | F9: FALSE | G9: FALSE | H9: FALSE | I9: FALSE | J9: FALSE | K9: FALSE | L9: FALSE | M9: TRUE | N9: FALSE | O9: FALSE | P9: FALSE
A10: 8/1/2024 11:45:00 PM | B10: 1E-CR3I | C10: 15.251799 | E10: FALSE | F10: FALSE | G10: FALSE | H10: FALSE | I10: FALSE | J10: FALSE | K10: FALSE | L10: FALSE | M10: TRUE | N10: FALSE | O10: FALSE | P10: FALSE
A11: 8/1/2024 11:45:00 PM | B11: 1E-CR3IPH | C11: 1.8 | E11: FALSE | F11: FALSE | G11: FALSE | H11: FALSE | I11: FALSE | J11: FALSE | K11: FALSE | L11: FALSE | M11: TRUE | N11: FALSE | O11: FALSE | P11: FALSE
A12: 8/1/2024 11:45:00 PM | B12: 1E-HCL1 | C12: 0.46765625 | E12: FALSE | F12: FALSE | G12: FALSE | H12: FALSE | I12: FALSE | J12: FALSE | K12: FALSE | L12: FALSE | M12: TRUE | N12: FALSE | O12: FALSE | P12: FALSE
A13: 8/1/2024 11:45:00 PM | B13: 1E-HCL3 | C13: 0.15284375 | E13: FALSE | F13: FALSE | G13: FALSE | H13: FALSE | I13: FALSE | J13: FALSE | K13: FALSE | L13: FALSE | M13: TRUE | N13: FALSE | O13: FALSE | P13: FALSE
A14: 8/1/2024 11:45:00 PM | B14: 1E-HNO3 | C14: 0.008946 | E14: FALSE | F14: FALSE | G14: FALSE | H14: FALSE | I14: FALSE | J14: FALSE | K14: FALSE | L14: FALSE | M14: TRUE | N14: FALSE | O14: FALSE | P14: FALSE
A15: 8/1/2024 11:45:00 PM | B15: 1E-MEM | C15: 450 | E15: FALSE | F15: FALSE | G15: FALSE | H15: FALSE | I15: FALSE | J15: FALSE | K15: FALSE | L15: FALSE | M15: TRUE | N15: FALSE | O15: FALSE | P15: FALSE
... A28: 8/1/2024 11:45:00 PM | B28: 1F-BONG | C28: 27 | E28: FALSE | F28: FALSE | G28: FALSE | H28: FALSE | I28: FALSE | J28: FALSE | K28: FALSE | L28: FALSE | M28: TRUE | N28: FALSE | O28: FALSE | P28: FALSE

Sheet 7
A1: "BÁO CÁO KẾT QUẢ HÓA NGHIỆM HÀNG NGÀY 表面處理生產製程管控記錄表"
A2: NGAY | B2: Ma__Hang_muc | C2: Nong_Do_06 | E2: 1 | F2: bs | G2: 2 | H2: bs | I2: 3 | J2: bs | K2: 4 | L2: bs | M2: 5 | N2: bs | O2: 6 | P2: bs | Q2: 6
A3: Date | B3: Code | C3: 濃度 g/L_06
A4: 8/1/2024 4:00:00 AM | B4: 1E-XB1 | C4: 32.8 | E4: FALSE | F4: FALSE | G4: FALSE | H4: FALSE | I4: FALSE | J4: FALSE | K4: FALSE | L4: FALSE | M4: FALSE | N4: FALSE | O4: TRUE | P4: FALSE
A5: 8/1/2024 4:00:00 AM | B5: 1E-XB2 | C5: 32 | E5: FALSE | F5: FALSE | G5: FALSE | H5: FALSE | I5: FALSE | J5: FALSE | K5: FALSE | L5: FALSE | M5: FALSE | N5: FALSE | O5: TRUE | P5: FALSE
A6: 8/1/2024 4:00:00 AM | B6: 1E-DG1 | C6: 78.8 | E6: FALSE | F6: FALSE | G6: FALSE | H6: FALSE | I6: FALSE | J6: FALSE | K6: FALSE | L6: FALSE | M6: FALSE | N6: FALSE | O6: TRUE | P6: FALSE
A7: 8/1/2024 4:00:00 AM | B7: 1E-DG2 | C7: 68 | E7: FALSE | F7: FALSE | G7: FALSE | H7: FALSE | I7: FALSE | J7: FALSE | K7: FALSE | L7: FALSE | M7: FALSE | N7: FALSE | O7: TRUE | P7: FALSE
A8: 8/1/2024 4:00:00 AM | B8: 1E-NAOH | C8: 142.4 | E8: FALSE | F8: FALSE | G8: FALSE | H8: FALSE | I8: FALSE | J8: FALSE | K8: FALSE | L8: FALSE | M8: FALSE | N8: FALSE | O8: TRUE | P8: FALSE
A9: 8/1/2024 4:00:00 AM | B9: 1E-ZN | C9: 10.595 | E9: FALSE | F9: FALSE | G9: FALSE | H9: FALSE | I9: FALSE | J9: FALSE | K9: FALSE | L9: FALSE | M9: FALSE | N9: FALSE | O9: TRUE | P9: FALSE
A10: 8/1/2024 4:00:00 AM | B10: 1E-CR3I | C10: 14.676259 | E10: FALSE | F10: FALSE | G10: FALSE | H10: FALSE | I10: FALSE | J10: FALSE | K10: FALSE | L10: FALSE | M10: FALSE | N10: FALSE | O10: TRUE | P10: FALSE
A11: 8/1/2024 4:00:00 AM | B11: 1E-CR3IPH | C11: 1.76 | E11: FALSE | F11: FALSE | G11: FALSE | H11: FALSE | I11: FALSE | J11: FALSE | K11: FALSE | L11: FALSE | M11: FALSE | N11: FALSE | O11: TRUE | P11: FALSE
A12: 8/1/2024 4:00:00 AM | B12: 1E-HCL1 | C12: 0.46195312 | E12: FALSE | F12: FALSE | G12: FALSE | H12: FALSE | I12: FALSE | J12: FALSE | K12: FALSE | L12: FALSE | M12: FALSE | N12: FALSE | O12: TRUE | P12: FALSE
A13: 8/1/2024 4:00:00 AM | B13: 1E-HCL3 | C13: 0.1140625 | E13: FALSE | F13: FALSE | G13: FALSE | H13: FALSE | I13: FALSE | J13: FALSE | K13: FALSE | L13: FALSE | M13: FALSE | N13: FALSE | O13: TRUE | P13: FALSE
A14: 8/1/2024 4:00:00 AM | B14: 1E-HNO3 | C14: 0.00756 | E14: FALSE | F14: FALSE | G14: FALSE | H14: FALSE | I14: FALSE | J14: FALSE | K14: FALSE | L14: FALSE | M14: FALSE | N14: FALSE | O14: TRUE | P14: FALSE
A15: 8/1/2024 4:00:00 AM | B15: 1E-MEM | C15: 455 | E15: FALSE | F15: FALSE | G15: FALSE | H15: FALSE | I15: FALSE | J15: FALSE | K15: FALSE | L15: FALSE | M15: FALSE | N15: FALSE | O15: TRUE | P15: FALSE
... A35: 8/1/2024 4:00:00 AM | B35: RLG-XBPH | C35: 10 | E35: FALSE | F35: FALSE | G35: FALSE | H35: FALSE | I35: FALSE | J35: FALSE | K35: FALSE | L35: FALSE | M35: FALSE | N35: FALSE | O35: TRUE | P35: FALSE

Sheet 8
A1: "BÁO CÁO KẾT QUẢ HÓA NGHIỆM HÀNG NGÀY 表面處理生產製程管控記錄表"
A2: NGAY | B2: Ma__Hang_muc | C2: Nong_Do_06 | E2: 1 | F2: bs | G2: 2 | H2: bs | I2: 3 | J2: bs | K2: 4 | L2: bs | M2: 5 | N2: bs | O2: 6 | P2: bs | Q2: 6
A3: Date | B3: Code | C3: 濃度 g/L_06
A4: 8/1/2024 6:00:00 AM | B4: RLG-KD | C4: 38 | E4: FALSE | F4: FALSE | G4: FALSE | H4: FALSE | I4: FALSE | J4: FALSE | K4: FALSE | L4: FALSE | M4: FALSE | N4: FALSE | O4: TRUE | P4: FALSE
A5: 8/1/2024 6:00:00 AM | B5: RLG-HCL1 | C5: 8.76 | E5: FALSE | F5: FALSE | G5: FALSE | H5: FALSE | I5: FALSE | J5: FALSE | K5: FALSE | L5: FALSE | M5: FALSE | N5: FALSE | O5: TRUE | P5: FALSE
A6: 8/1/2024 6:00:00 AM | B6: RLG-PPTA | C6: 44 | E6: FALSE | F6: FALSE | G6: FALSE | H6: FALSE | I6: FALSE | J6: FALSE | K6: FALSE | L6: FALSE | M6: FALSE | N6: FALSE | O6: TRUE | P6: FALSE
A7: 8/1/2024 6:00:00 AM | B7: RLG-PPAX | C7: 11 | E7: FALSE | F7: FALSE | G7: FALSE | H7: FALSE | I7: FALSE | J7: FALSE | K7: FALSE | L7: FALSE | M7: FALSE | N7: FALSE | O7: TRUE | P7: FALSE
A8: 8/1/2024 6:00:00 AM | B8: RLG-PPPL | C8: 0.18 | E8: FALSE | F8: FALSE | G8: FALSE | H8: FALSE | I8: FALSE | J8: FALSE | K8: FALSE | L8: FALSE | M8: FALSE | N8: FALSE | O8: TRUE | P8: FALSE
A9: 8/1/2024 6:00:00 AM | B9: RLG-XB | C9: 0.95 | E9: FALSE | F9: FALSE | G9: FALSE | H9: FALSE | I9: FALSE | J9: FALSE | K9: FALSE | L9: FALSE | M9: FALSE | N9: FALSE | O9: TRUE | P9: FALSE
A10: 8/1/2024 6:00:00 AM | B10: RLG-XBPH | C10: 10 | E10: FALSE | F10: FALSE | G10: FALSE | H10: FALSE | I10: FALSE | J10: FALSE | K10: FALSE | L10: FALSE | M10: FALSE | N10: FALSE | O10: TRUE | P10: FALSE

Sheet MENU
B3: XI MẠ, XI TREO | J3: RỬA LIỆU, MÀNG LOA, XI ĐEN | R3: KHÁC | V3: IMPORT | AA3: khoảng thời gian Import | AE3: L.Yen | AF3: Trang
AE4: Trang | AF4: L.Yen
B6: XM.HN | F6: XM.GUI MAIL | J6: ED-XI DEN | N6: R.GUI MAIL | R6: IT.NONG DO | V6: 1 | Y6: =AD9+TIME(9,45,0) -> 45505.406 | AA6: 9:15-9:45 | AD6: CA 1 | AE6: L.Yen
AD7: CA 2 | AE7: Trang
B9: XM.FILE GOC | F9: 1. XL-1E TT(CA1) | J9: R.HN | N9: RL-LINE | R9: IT.NHIET DO | V9: 2 | Y9: =AD9+TIME(11,45,0) -> 45505.49 | AA9: 11:15-11:45 | AC9: Thứ 5, | AD9: 2024/08/01 | AF9: đánh Thứ, 'năm/tháng/ngày vào ô bên
B12: 1. XL-1E kh | F12: 1. XL-1E TT(CA2) | J12: R.FILE GOC | N12: 1.xi den TT | R12: GHI CHU | V12: 3 | Y12: =AD9+TIME(16,30,0) -> 45505.688 | AA12: 16:00-16:30 | AD12: ACID Đ.VAO
B15: 2. XL-1F kh | F15: 2. XL-1F TT(CA1) | J15: 1.xi den | N15: 2.RL E tt | R15: PP HÓA NGHIỆM FILE WORD | V15: 4 | Y15: =AD9+TIME(18,0,0) -> 45505.75 | AA15: 17:30-18:00 | AD15: THỜI GIAN GỬI BC LÊN LINE
B18: 3.XT-C KH | F18: 2. XL-1F TT(CA2) | J18: 2.RL E | N18: 3.RL G tt | R18: QC- E | V18: 5 | Y18: =AD9+TIME(21,45,0) -> 45505.906 | AA18: 21:15-21:45 | AD18: CA 1: | AE18: ĐỢT 1 | AF18: ĐỢT 2 | AG18: ĐỢT 3
AD19: RL | AE19: 0.38541667 | AF19: 0.60416667 | AG19: 0.72916667
AD20: ML | AE20: 0.39583333
B21: 4.Zn Ni.kh | F21: 3.XT-C TT(CA1) | J21: 3.RL G | N21: 4.RL F tt | R21: QC-1F | V21: 6 | Y21: =AD9+TIME(23,45,0) -> 45505.99 | AA21: 23:15-23:45 | AD21: XL | AE21: 0.39583333 | AF21: 0.47569444 | AG21: 0.66666667
AD22: XT | AE22: 0.40277778 | AF22: 0.47569444 | AG22: 0.66666667
AD23: XĐ | AE23: 0.41666667 | AF23: 0.61458333 | AG23: 0.75
B24: 3'.XT-C KH | F24: 3.XT-C TT(CA2) | J24: 4.RL F | N24: 5.ML tt | R24: QC- XT | V24: 7 | Y24: =AD9+TIME(4,0,0) -> 45505.167 | AA24: 3:30-4:00 | AD24: HUCELL | AE24: 0.4375 | AG24: 0.6875
AD26: CA 2: | AE26: ĐỢT 1 | AF26: ĐỢT 2 | AG26: ĐỢT 3
B27: 3''.XT-C KH | F27: 4.ZN-NI tt(CA1) | J27: 5.ML | N27: RL.chart1 | R27: QC-RL | V27: 8 | Y27: =AD9+TIME(6,0,0) -> 45505.25 | AA27: 5:30-6:00 | AD27: RL | AE27: 0.88541667 | AF27: 0.10416667 | AG27: 0.22916667
AD28: ML | AE28: 0.9375
AD29: XL | AE29: 0.91666667 | AG29: 0.1875
B30: XM.chart | F30: 4.ZN-NI tt(CA2) | J30: RL.chart | N30: RL.chart1 | R30: QC-XĐ | Y30: SOP HOA NGHIEM | AA30: tg import | AD30: XT | AE30: 0.91666667 | AG30: 0.1875
AD31: HUCELL | AE31: 0.95833333 | AG31: 0.20833333
F33: BS-XT | R33: QC-ML
F36: XM.chart 1 | R36: QC-NI
R39: PT TAP CHAT
R41: thời gian pha mới bồn màu
U43: 1E | Z43: 1F | AE43: XT
R44: I | U44: Pha mới: 2024/08/01 | Z44: Pha mới: 2024/07/28 | AE44: Pha mới: 2024/06/22
R45: K | U45: Pha mới: 2024/06/27 | Z45: Pha mới: 2024/07/28 | AE45: Pha mới: 2024/06/22
R46: MÀU NI | U46: \ | Z46: \ | AE46: Cr2O3 三價鉻Ni- PH HALO Pha mới: 2024/03/30

Sheet XM.HN
A1: =MENU!AD9 -> 2024/08/01
A2: XL-001E | B2: 07:15 | C2: 11:15 | D2: 15:15 | E2: 19:15 | F2: 23:15 | G2: 03:15 | H2: TIEU CHUAN | J2: 07:15 | K2: 11:15 | L2: 15:15 | M2: 19:15 | N2: 23:15 | O2: 03:15 | P2: NCC | R2: Quy đổi nồng độ acid HCl 32% đậm đặc từ %V/V sang nồng độ %
A3: Xà bông (1)脫脂 | C3: 6.65 | D3: 8.2 | E3: 8.4 | F3: 8 | G3: 8.2 | H3: ='XM.GUI MAIL'!$E$6 -> 20~40 | I3: ='XM.GUI MAIL'!$F$6 -> (30±5) | J3: ='XM.GUI MAIL'!I6 -> 0 | K3: ='XM.GUI MAIL'!P6 -> 26.6 | L3: ='XM.GUI MAIL'!W6 -> 32.8 | M3: ='XM.GUI MAIL'!AD6 -> 33.6 | N3: ='XM.GUI MAIL'!AK6 -> 32 | O3: ='XM.GUI MAIL'!AR6 -> 32.8 | P3: JASCO
H4: 按NaOH添加數據添加 | J4: ='XM.GUI MAIL'!I7 -> 0 | K4: ='XM.GUI MAIL'!P7 -> 0 | L4: ='XM.GUI MAIL'!W7 -> 0 | M4: ='XM.GUI MAIL'!AD7 -> 0 | N4: ='XM.GUI MAIL'!AK7 -> 0 | O4: ='XM.GUI MAIL'!AR7 -> 0
H5: 按NaOH添加數據添加 | J5: ='XM.GUI MAIL'!I8 -> 0 | K5: ='XM.GUI MAIL'!P8 -> 0 | L5: ='XM.GUI MAIL'!W8 -> 0 | M5: ='XM.GUI MAIL'!AD8 -> 0 | N5: ='XM.GUI MAIL'!AK8 -> 0 | O5: ='XM.GUI MAIL'!AR8 -> 0
A6: Xà bông (2)脫脂 | C6: 7.75 | D6: 7.55 | E6: 7.8 | F6: 8 | G6: 8 | H6: ='XM.GUI MAIL'!$E$9 -> 20~40 | I6: ='XM.GUI MAIL'!$F$9 -> (30±5) | J6: ='XM.GUI MAIL'!I9 -> 0 | K6: ='XM.GUI MAIL'!P9 -> 31 | L6: ='XM.GUI MAIL'!W9 -> 30.2 | M6: ='XM.GUI MAIL'!AD9 -> 31.2 | N6: ='XM.GUI MAIL'!AK9 -> 32 | O6: ='XM.GUI MAIL'!AR9 -> 32 | P6: JASCO | R6: 15%V/V | T6: 100%V/V
H7: 按NaOH添加數據添加 | J7: ='XM.GUI MAIL'!I10 -> 0 | K7: ='XM.GUI MAIL'!P10 -> 0 | L7: ='XM.GUI MAIL'!W10 -> 0 | M7: ='XM.GUI MAIL'!AD10 -> 0 | N7: ='XM.GUI MAIL'!AK10 -> 0 | O7: ='XM.GUI MAIL'!AR10 -> 0
H8: 按NaOH添加數據添加 | J8: ='XM.GUI MAIL'!I11 -> 0 | K8: ='XM.GUI MAIL'!P11 -> 0 | L8: ='XM.GUI MAIL'!W11 -> 0 | M8: ='XM.GUI MAIL'!AD11 -> 0 | N8: ='XM.GUI MAIL'!AK11 -> 0 | O8: ='XM.GUI MAIL'!AR11 -> 0
A9: điện giải(1)+電解 | C9: 19.25 | D9: 19.5 | E9: 18.8 | F9: 19.8 | G9: 19.7 | H9: ='XM.GUI MAIL'!$E$12 -> 60~80 | I9: ='XM.GUI MAIL'!$F$12 -> (70±10) | J9: ='XM.GUI MAIL'!I12 -> 0 | K9: ='XM.GUI MAIL'!P12 -> 77 | L9: ='XM.GUI MAIL'!W12 -> 78 | M9: ='XM.GUI MAIL'!AD12 -> 75.2 | N9: ='XM.GUI MAIL'!AK12 -> 79.2 | O9: ='XM.GUI MAIL'!AR12 -> 78.8 | P9: JASCO | R9: 0.048 | T9: 0.32
H10: 按NaOH添加數據添加 | J10: ='XM.GUI MAIL'!I13 -> 0 | K10: ='XM.GUI MAIL'!P13 -> 0 | L10: ='XM.GUI MAIL'!W13 -> 0 | M10: ='XM.GUI MAIL'!AD13 -> 0 | N10: ='XM.GUI MAIL'!AK13 -> 0 | O10: ='XM.GUI MAIL'!AR13 -> 0
A11: điện giải (2)+電解 | C11: 18.15 | D11: 18.1 | E11: 17.3 | F11: 17 | G11: 17 | H11: ='XM.GUI MAIL'!$E$14 -> 60~80 | I11: ='XM.GUI MAIL'!$F$14 -> (70±10) | J11: ='XM.GUI MAIL'!I14 -> 0 | K11: ='XM.GUI MAIL'!P14 -> 72.6 | L11: ='XM.GUI MAIL'!W14 -> 72.4 | M11: ='XM.GUI MAIL'!AD14 -> 69.2 | N11: ='XM.GUI MAIL'!AK14 -> 68 | O11: ='XM.GUI MAIL'!AR14 -> 68 | P11: JASCO
H12: 按NaOH添加數據添加 | J12: ='XM.GUI MAIL'!I15 -> 0 | K12: ='XM.GUI MAIL'!P15 -> 0 | L12: ='XM.GUI MAIL'!W15 -> 0 | M12: ='XM.GUI MAIL'!AD15 -> 0 | N12: ='XM.GUI MAIL'!AK15 -> 0 | O12: ='XM.GUI MAIL'!AR15 -> 0
A13: NaOH氫氧化鈉 | C13: 16.7 | D13: 17.6 | E13: 17.9 | F13: 17.8 | G13: 17.8 | H13: ='XM.GUI MAIL'!$E$16 -> 130 - 150 | I13: ='XM.GUI MAIL'!$F$16 -> (140±7) | J13: ='XM.GUI MAIL'!I16 -> 0 | K13: ='XM.GUI MAIL'!P16 -> 133.6 | L13: ='XM.GUI MAIL'!W16 -> 140.8 | M13: ='XM.GUI MAIL'!AD16 -> 143.2 | N13: ='XM.GUI MAIL'!AK16 -> 142.4 | O13: ='XM.GUI MAIL'!AR16 -> 142.4 | P13: JASCO | R13: 30%V/V | T13: 100%V/V
A14: Zn鋅 | C14: 9.8 | D14: 9.6 | E14: 8.8 | F14: 8.3 | G14: 8.15 | H14: ='XM.GUI MAIL'!$E$17 -> 8~12 | I14: ='XM.GUI MAIL'!$F$17 -> (10±2) | J14: ='XM.GUI MAIL'!I17 -> 0 | K14: ='XM.GUI MAIL'!P17 -> 12.74 | L14: ='XM.GUI MAIL'!W17 -> 12.48 | M14: ='XM.GUI MAIL'!AD17 -> 11.44 | N14: ='XM.GUI MAIL'!AK17 -> 10.79 | O14: ='XM.GUI MAIL'!AR17 -> 10.595 | P14: JASCO | R14: 0.096 | T14: 0.32
A15: Cr3+鈍化劑 (I) | C15: 11 | D15: 11 | E15: 12.6 | F15: 10.6 | G15: 10.2 | H15: ='XM.GUI MAIL'!$E$18 -> 12~18 | I15: ='XM.GUI MAIL'!$F$18 -> (14±2) | J15: ='XM.GUI MAIL'!I18 -> 0 | K15: ='XM.GUI MAIL'!P18 -> 15.827338 | L15: ='XM.GUI MAIL'!W18 -> 15.827338 | M15: ='XM.GUI MAIL'!AD18 -> 18.129496 | N15: ='XM.GUI MAIL'!AK18 -> 15.251799 | O15: ='XM.GUI MAIL'!AR18 -> 14.676259 | P15: JASCO
H16: ='XM.GUI MAIL'!$E$19 -> 1.5~1.9 | I16: ='XM.GUI MAIL'!$F$19 -> (1.7±0.1 ) | J16: ='XM.GUI MAIL'!I19 -> 0 | K16: ='XM.GUI MAIL'!P19 -> 1.63 | L16: ='XM.GUI MAIL'!W19 -> 1.64 | M16: ='XM.GUI MAIL'!AD19 -> 1.8 | N16: ='XM.GUI MAIL'!AK19 -> 1.8 | O16: ='XM.GUI MAIL'!AR19 -> 1.76
A17: HCl Đặc 濃酸洗 | C17: 3.8 | D17: 4.2 | E17: 4.3 | F17: 4.1 | G17: 4.05 | H17: ='XM.GUI MAIL'!$E$20 -> 40~50 | I17: ='XM.GUI MAIL'!$F$20 -> (45±5) | J17: ='XM.GUI MAIL'!I20 -> 0 | K17: ='XM.GUI MAIL'!P20 -> 0.4334375 | L17: ='XM.GUI MAIL'!W20 -> 0.4790625 | M17: ='XM.GUI MAIL'!AD20 -> 0.49046875 | N17: ='XM.GUI MAIL'!AK20 -> 0.46765625 | O17: ='XM.GUI MAIL'!AR20 -> 0.46195312 | R17: 60%V/V | T17: 100%V/V
A18: HCl Loãng弱酸洗 | H18: ='XM.GUI MAIL'!$E$21 -> (22±5) =17~27 | I18: ='XM.GUI MAIL'!$F$21 -> (22±5) | J18: ='XM.GUI MAIL'!I21 -> 0 | K18: ='XM.GUI MAIL'!P21 -> 0 | L18: ='XM.GUI MAIL'!W21 -> 0 | M18: ='XM.GUI MAIL'!AD21 -> 0 | N18: ='XM.GUI MAIL'!AK21 -> 0 | O18: ='XM.GUI MAIL'!AR21 -> 0 | R18: 0.192 | T18: 0.32
A19: HCl hoat hoa | C19: 5.9 | D19: 8.1 | E19: 7.5 | F19: 6.7 | G19: 5 | H19: ='XM.GUI MAIL'!$E$22 -> 5~15 | I19: ='XM.GUI MAIL'!$F$22 -> (10±3) | J19: ='XM.GUI MAIL'!I22 -> 0 | K19: ='XM.GUI MAIL'!P22 -> 0.13459375 | L19: ='XM.GUI MAIL'!W22 -> 0.18478125 | M19: ='XM.GUI MAIL'!AD22 -> 0.17109375 | N19: ='XM.GUI MAIL'!AK22 -> 0.15284375 | O19: ='XM.GUI MAIL'!AR22 -> 0.1140625
A20: HNO3 硝酸中和 | E20: 6.5 | F20: 7.1 | G20: 6 | H20: ='XM.GUI MAIL'!$E$23 -> 0.5~1.0 | I20: ='XM.GUI MAIL'!$F$23 -> (0.7±0.1) | J20: ='XM.GUI MAIL'!I23 -> 0 | K20: ='XM.GUI MAIL'!P23 -> 0 | L20: ='XM.GUI MAIL'!W23 -> 0 | M20: ='XM.GUI MAIL'!AD23 -> 0.00819 | N20: ='XM.GUI MAIL'!AK23 -> 0.008946 | O20: ='XM.GUI MAIL'!AR23 -> 0.00756
A21: Cr3+鈍化劑 (K) | C21: 12 | D21: 12 | E21: 12.3 | H21: ='XM.GUI MAIL'!$E$24 -> 5~10 | I21: ='XM.GUI MAIL'!$F$24 -> (7.5±1) | J21: ='XM.GUI MAIL'!I24 | K21: ='XM.GUI MAIL'!P24 -> 7.6923077 | L21: ='XM.GUI MAIL'!W24 -> 7.6923077 | M21: ='XM.GUI MAIL'!AD24 -> 7.8846154 | N21: ='XM.GUI MAIL'!AK24 -> ko sx | O21: ='XM.GUI MAIL'!AR24 -> ko sx | P21: JASCO
A22: Cr3+鈍化劑 (K) PH | C22: 2.28 | D22: 2.26 | E22: 2.4 | H22: ='XM.GUI MAIL'!$E$25 -> 2.0~2.4 | I22: ='XM.GUI MAIL'!$F$25 -> (2.2±0.1) | J22: ='XM.GUI MAIL'!I25 -> 0 | K22: ='XM.GUI MAIL'!P25 -> 2.28 | L22: ='XM.GUI MAIL'!W25 -> 2.26 | M22: ='XM.GUI MAIL'!AD25 -> 2.4 | N22: ='XM.GUI MAIL'!AK25 -> ko sx | O22: ='XM.GUI MAIL'!AR25 -> ko sx | P22: JASCO
A23: Cr3+鈍化劑 (I) PH | C23: 1.63 | D23: 1.64 | E23: 1.8 | F23: 1.8 | G23: 1.76 | H23: ='XM.GUI MAIL'!$E$19 -> 1.5~1.9 | I23: ='XM.GUI MAIL'!$F$19 -> (1.7±0.1 ) | J23: =B23 -> 0 | K23: =C23 -> 1.63 | L23: =D23 -> 1.64 | M23: =E23 -> 1.8 | N23: =F23 -> 1.8 | O23: =G23 -> 1.76 | P23: JASCO
A25: XL-001F | B25: 07:15 | C25: 11:15 | D25: 15:15 | E25: 19:15 | F25: 23:15 | G25: 03:15 | H25: TIEU CHUAN | J25: 07:15 | K25: 11:15 | L25: 15:15 | M25: 19:15 | N25: 23:15 | O25: 03:15 | P25: NCC
A26: Xà bông (1)脫脂 | B26: 11 | C26: 11.2 | D26: 11.15 | E26: 10.1 | F26: 10.2 | G26: 10.4 | H26: ='XM.GUI MAIL'!$E$43 -> 60~80 | I26: ='XM.GUI MAIL'!$F$43 -> (70±5) | J26: ='XM.GUI MAIL'!I43 -> 71.39 | K26: ='XM.GUI MAIL'!P43 -> 72.688 | L26: ='XM.GUI MAIL'!W43 -> 72.3635 | M26: ='XM.GUI MAIL'!AD43 -> 65.549 | N26: ='XM.GUI MAIL'!AK43 -> 66.198 | O26: ='XM.GUI MAIL'!AR43 -> 67.496 | P26: HALO
H27: CT-21A: 25kg/CT-21B: 5-10Lit | J27: ='XM.GUI MAIL'!I44 -> 0 | K27: ='XM.GUI MAIL'!P44 -> 0 | L27: ='XM.GUI MAIL'!W44 -> 0 | M27: ='XM.GUI MAIL'!AD44 -> 0 | N27: ='XM.GUI MAIL'!AK44 -> 0 | O27: ='XM.GUI MAIL'!AR44 -> 0
A28: Xà bông (2)脫脂 | B28: 11.1 | C28: 11.55 | D28: 11.5 | E28: 11.4 | F28: 11.5 | G28: 11.5 | H28: ='XM.GUI MAIL'!$E$45 -> 60~80 | I28: ='XM.GUI MAIL'!$F$45 -> (70±5) | J28: ='XM.GUI MAIL'!I45 -> 72.039 | K28: ='XM.GUI MAIL'!P45 -> 74.9595 | L28: ='XM.GUI MAIL'!W45 -> 74.635 | M28: ='XM.GUI MAIL'!AD45 -> 73.986 | N28: ='XM.GUI MAIL'!AK45 -> 74.635 | O28: ='XM.GUI MAIL'!AR45 -> 74.635 | P28: HALO | R28: Quy đổi nồng độ acid HCl 32% sang nồng độ g/l
H29: CT-21A: 25kg/CT-21B: 5-10Lit | J29: ='XM.GUI MAIL'!I46 -> 0 | K29: ='XM.GUI MAIL'!P46 -> 0 | L29: ='XM.GUI MAIL'!W46 -> 0 | M29: ='XM.GUI MAIL'!AD46 -> 0 | N29: ='XM.GUI MAIL'!AK46 -> 0 | O29: ='XM.GUI MAIL'!AR46 -> 0
A30: điện giải(1)+電解 | B30: 11.95 | C30: 13 | D30: 13.3 | E30: 13.5 | F30: 13.2 | G30: 12.9 | H30: ='XM.GUI MAIL'!$E$47 -> 50~70 | I30: ='XM.GUI MAIL'!$F$47 -> (60±10) | J30: ='XM.GUI MAIL'!I47 -> 55.209 | K30: ='XM.GUI MAIL'!P47 -> 60.06 | L30: ='XM.GUI MAIL'!W47 -> 61.446 | M30: ='XM.GUI MAIL'!AD47 -> 62.37 | N30: ='XM.GUI MAIL'!AK47 -> 60.984 | O30: ='XM.GUI MAIL'!AR47 -> 59.598 | P30: HALO
H31: EC-508A: 25kg/EC-508B:4-10Lit | J31: ='XM.GUI MAIL'!I48 -> 0 | K31: ='XM.GUI MAIL'!P48 -> 0 | L31: ='XM.GUI MAIL'!W48 -> 0 | M31: ='XM.GUI MAIL'!AD48 -> 0 | N31: ='XM.GUI MAIL'!AK48 -> 0 | O31: ='XM.GUI MAIL'!AR48 -> 0
A32: điện giải (2)+電解 | B32: 12.7 | C32: 13.55 | D32: 13.3 | E32: 12.5 | F32: 14.2 | G32: 14.7 | H32: ='XM.GUI MAIL'!$E$49 -> 50~70 | I32: ='XM.GUI MAIL'!$F$49 -> (60±10) | J32: ='XM.GUI MAIL'!I49 -> 58.674 | K32: ='XM.GUI MAIL'!P49 -> 62.601 | L32: ='XM.GUI MAIL'!W49 -> 61.446 | M32: ='XM.GUI MAIL'!AD49 -> 57.75 | N32: ='XM.GUI MAIL'!AK49 -> 65.604 | O32: ='XM.GUI MAIL'!AR49 -> 67.914 | P32: HALO
H33: EC-508A: 25kg/EC-508B:4-10Lit | J33: ='XM.GUI MAIL'!I50 -> 0 | K33: ='XM.GUI MAIL'!P50 -> 0 | L33: ='XM.GUI MAIL'!W50 -> 0 | M33: ='XM.GUI MAIL'!AD50 -> 0 | N33: ='XM.GUI MAIL'!AK50 -> 0 | O33: ='XM.GUI MAIL'!AR50 -> 0
A34: NaOH氫氧化鈉 | B34: 18.1 | C34: 18.1 | D34: 17.9 | E34: 17.9 | F34: 18 | G34: 18 | H34: ='XM.GUI MAIL'!$E$51 -> 130 - 150 | I34: ='XM.GUI MAIL'!$F$51 -> (140±7) | J34: ='XM.GUI MAIL'!I51 -> 144.8 | K34: ='XM.GUI MAIL'!P51 -> 144.8 | L34: ='XM.GUI MAIL'!W51 -> 143.2 | M34: ='XM.GUI MAIL'!AD51 -> 143.2 | N34: ='XM.GUI MAIL'!AK51 -> 144 | O34: ='XM.GUI MAIL'!AR51 -> 144 | P34: HALO | R34: %*1.162= (g/l)
A35: Zn鋅 | B35: 7.7 | C35: 7.5 | D35: 7.5 | E35: 7.6 | F35: 7.6 | G35: 7.7 | H35: ='XM.GUI MAIL'!$E$52 -> 8~12 | I35: ='XM.GUI MAIL'!$F$52 -> (10±2) | J35: ='XM.GUI MAIL'!I52 -> 10.01 | K35: ='XM.GUI MAIL'!P52 -> 9.75 | L35: ='XM.GUI MAIL'!W52 -> 9.75 | M35: ='XM.GUI MAIL'!AD52 -> 9.88 | N35: ='XM.GUI MAIL'!AK52 -> 9.88 | O35: ='XM.GUI MAIL'!AR52 -> 10.01 | P35: HALO
A36: Cr3+鈍化劑 (I) halo | B36: 19.5 | C36: 19.3 | D36: 19.5 | E36: 19.4 | F36: 19 | G36: 17.8 | H36: ='XM.GUI MAIL'!$E$53 -> 6~10 | I36: ='XM.GUI MAIL'!$F$53 -> (7±1) | J36: ='XM.GUI MAIL'!I53 -> 7.21605 | K36: ='XM.GUI MAIL'!P53 -> 7.13131 | L36: ='XM.GUI MAIL'!W53 -> 7.21605 | M36: ='XM.GUI MAIL'!AD53 -> 7.17368 | N36: ='XM.GUI MAIL'!AK53 -> 7.0042 | O36: ='XM.GUI MAIL'!AR53 -> 6.49576 | P36: HALO | R36: vd:
H37: ='XM.GUI MAIL'!$E$54 -> 2~2.5 | I37: ='XM.GUI MAIL'!$F$54 -> (2.3±0.1 ) | J37: ='XM.GUI MAIL'!I54 -> 2.23 | K37: ='XM.GUI MAIL'!P54 -> 2.24 | L37: ='XM.GUI MAIL'!W54 -> 2.35 | M37: ='XM.GUI MAIL'!AD54 -> 2.4 | N37: ='XM.GUI MAIL'!AK54 -> 2.35 | O37: ='XM.GUI MAIL'!AR54 -> 2.4
A38: HCl Đặc 濃酸洗 | B38: 4.1 | C38: 4.2 | D38: 4 | E38: 4 | F38: 3.9 | G38: 4.1 | H38: ='XM.GUI MAIL'!$E$55 -> 40~50 | I38: ='XM.GUI MAIL'!$F$55 -> (45±5) | J38: ='XM.GUI MAIL'!I55 -> 0.46765625 | K38: ='XM.GUI MAIL'!P55 -> 0.4790625 | L38: ='XM.GUI MAIL'!W55 -> 0.45625 | M38: ='XM.GUI MAIL'!AD55 -> 0.45625 | N38: ='XM.GUI MAIL'!AK55 -> 0.44484375 | O38: ='XM.GUI MAIL'!AR55 -> 0.46765625 | R38: =5*1.162 -> 5.81 | S38: (g/l)
A39: HCl Loãng弱酸洗 | H39: ='XM.GUI MAIL'!$E$56 -> (22±5) =17~27 | I39: ='XM.GUI MAIL'!$F$56 -> (22±5) | J39: ='XM.GUI MAIL'!I56 -> 0 | K39: ='XM.GUI MAIL'!P56 -> 0 | L39: ='XM.GUI MAIL'!W56 -> 0 | M39: ='XM.GUI MAIL'!AD56 -> 0 | N39: ='XM.GUI MAIL'!AK56 -> 0 | O39: ='XM.GUI MAIL'!AR56 -> 0 | R39: =R38*1000 -> 5810 | S39: (g/ml)
A40: HCl hoat hoa | B40: 3.5 | C40: 3.6 | D40: 3.85 | E40: 3 | F40: 5 | G40: 4.5 | H40: ='XM.GUI MAIL'!$E$57 -> 5~15 | I40: ='XM.GUI MAIL'!$F$57 -> (10±3) | J40: ='XM.GUI MAIL'!I57 -> 0.07984375 | K40: ='XM.GUI MAIL'!P57 -> 0.082125 | L40: ='XM.GUI MAIL'!W57 -> 0.087828125 | M40: ='XM.GUI MAIL'!AD57 -> 0.0684375 | N40: ='XM.GUI MAIL'!AK57 -> 0.1140625 | O40: ='XM.GUI MAIL'!AR57 -> 0.10265625
A41: HNO3 硝酸中和 | B41: 8.8 | C41: 10.5 | D41: 8.8 | E41: 8.5 | F41: 10 | G41: 8 | H41: ='XM.GUI MAIL'!$E$58 -> 0.5~1.5 | I41: ='XM.GUI MAIL'!$F$58 -> (1±0.4) | J41: ='XM.GUI MAIL'!I58 -> 0.011088 | K41: ='XM.GUI MAIL'!P58 -> 0.01323 | L41: ='XM.GUI MAIL'!W58 -> 0.011088 | M41: ='XM.GUI MAIL'!AD58 -> 0.01071 | N41: ='XM.GUI MAIL'!AK58 -> 0.0126 | O41: ='XM.GUI MAIL'!AR58 -> 0.01008
...

Sheet XM.FILE GOC
C1: BÁO CÁO KẾT QUẢ HÓA NGHIỆM HÀNG NGÀY 报告每日化学测试结果
A2: =MENU!$AC$9 -> Thứ 5, | C2: =MENU!$AD$9 -> 2024/08/01
A3: 生產線別：無氰鹼滾電E線 (XL-001E) | F3: =MENU!$AC$9 -> Thứ 5, | I3: =MENU!$AD$9 -> 2024/08/01 | AX3: =A2 -> Thứ 5,
G4: tiêu chuẩn khống chế để bổ sung | I4: 7:15 | P4: 11:15 | W4: 15:15 | AD4: 19:15 | AK4: 23:15 | AR4: 03:15 | AX4: =C2 -> 2024/08/01 | AZ4: =AX4-1 -> 45504 | BF4: =AZ4 -> 45504
A5: MÃ | B5: MÃ MÁY | C5: Hạng mục kiểm tra nồng độ 化驗檢查項目 | D5: Đơn vị 單位 | E5: Phạm vi kiểm soát 範圍值 | F5: Giới hạn kiểm soát 管控值 | I5: 濃度 | J5: 補充 BS | K5: 補充 BS | P5: 濃度 | Q5: 補充 BS | R5: 補充 BS | W5: 濃度 | X5: 補充 BS | Y5: 補充 BS | AD5: 濃度 | AE5: 補充 BS | AF5: 補充 BS | AK5: 濃度 | AL5: 補充 BS | AM5: 補充 BS | AR5: 濃度 | AS5: 補充 BS | AT5: 補充 BS | AX5: XI ĐEN 15:00 | AY5: XI ĐEN 03:00 | AZ5: XM | BF5: XI ĐEN 15:00 | BG5: XI ĐEN 03:00
A6: 1E-XB1 | B6: XL-001E | C6: Xà bông (1)脫脂 | D6: g/L | E6: ='XM.GUI MAIL'!E6 -> 20~40 | F6: ='XM.GUI MAIL'!F6 -> (30±5) | G6: ='XM.GUI MAIL'!G6 -> 30 | H6: =XM.HN!B3 -> 0 | I6: =H6*4 -> 0 | J6: =($G$6-I6)*2693/1000 -> 80.79 | K6: + | L6: =IF(J6<0,0,J6) -> 80.79 | N6: kg | O6: =XM.HN!C3 -> 6.65 | P6: =O6*4 -> 26.6 | Q6: =($G$6-P6)*2693/1000 -> 9.1562 | R6: + | S6: =IF(Q6<0,0,Q6) -> 9.1562 | U6: kg | V6: =XM.HN!D3 -> 8.2 | W6: =V6*4 -> 32.8 | X6: =($G$6-W6)*2693/1000 -> -7.5404 | Y6: + | Z6: =IF(X6<0,0,X6) -> 0 | AB6: kg | AC6: =XM.HN!E3 -> 8.4 | AD6: =AC6*4 -> 33.6 | AE6: =($G$6-AD6)*2693/1000 -> -9.6948 | AF6: + | AG6: =IF(AE6<0,0,AE6) -> 0 | AI6: kg | AJ6: =XM.HN!F3 -> 8 | AK6: =AJ6*4 -> 32 | AL6: =($G$6-AK6)*2693/1000 -> -5.386 | AM6: + | AN6: =IF(AL6<0,0,AL6) -> 0 | AP6: kg | AQ6: =XM.HN!G3 -> 8.2 | AR6: =AQ6*4 -> 32.8 | AS6: =($G$6-AR6)*2693/1000 -> -7.5404 | AT6: + | AU6: =IF(AS6<0,0,AS6) -> 0 | AW6: kg | AX6: ='R.FILE GOC'!AI57 -> 15.3 | AY6: ='R.FILE GOC'!AJ57 -> 0 | AZ6: 0 | BA6: 80.79 | BB6: + | BC6: 80.79 | BE6: kg | BF6: 15.5 | BG6: 0
C7: CleanA 840ml/NaOH 25kg | E7: 按NaOH添加數據添加 | K7: + | L7: =L6/25*840/1000 -> 2.714544 | M7: =IF('1. XL-1E TT'!AB7="","",'1. XL-1E TT'!AB7) | N7: L | R7: + | S7: =S6/25*840/1000 -> 0.30764832 | T7: =IF('1. XL-1E TT'!AF7="","",'1. XL-1E TT'!AF7) | U7: L | Y7: + | Z7: =Z6/25*840/1000 -> 0 | AA7: =IF('1. XL-1E TT'!AJ7="","",'1. XL-1E TT'!AJ7) | AB7: L | AF7: + | AG7: =AG6/25*840/1000 -> 0 | AH7: =IF('1. XL-1E TT(CA2)'!AB7="","",'1. XL-1E TT(CA2)'!AB7) | AI7: L | AM7: + | AN7: =AN6/25*840/1000 -> 0 | AO7: =IF('1. XL-1E TT(CA2)'!AF7="","",'1. XL-1E TT(CA2)'!AF7) | AP7: L | AT7: + | AU7: =AU6/25*840/1000 -> 0 | AV7: =IF('1. XL-1E TT(CA2)'!AJ7="","",'1. XL-1E TT(CA2)'!AJ7) | AW7: L | AX7: ='R.FILE GOC'!AI58 -> 15 | AY7: ='R.FILE GOC'!AJ58 -> 0 | BB7: + | BC7: 2.714544 | BE7: L | BF7: 15.3 | BG7: 0
C8: CleanB 8400ml/NaOH 25kg | E8: 按NaOH添加數據添加 | K8: + | L8: =L7*10 -> 27.14544 | M8: =IF('1. XL-1E TT'!AB8="","",'1. XL-1E TT'!AB8) | N8: L | R8: + | S8: =S7*10 -> 3.0764832 | T8: =IF('1. XL-1E TT'!AF8="","",'1. XL-1E TT'!AF8) | U8: L | Y8: + | Z8: =Z7*10 -> 0 | AA8: =IF('1. XL-1E TT'!AJ8="","",'1. XL-1E TT'!AJ8) | AB8: L | AF8: + | AG8: =AG7*10 -> 0 | AH8: =IF('1. XL-1E TT(CA2)'!AB8="","",'1. XL-1E TT(CA2)'!AB8) | AI8: L | AM8: + | AN8: =AN7*10 -> 0 | AO8: =IF('1. XL-1E TT(CA2)'!AF8="","",'1. XL-1E TT(CA2)'!AF8) | AP8: L | AT8: + | AU8: =AU7*10 -> 0 | AV8: =IF('1. XL-1E TT(CA2)'!AJ8="","",'1. XL-1E TT(CA2)'!AJ8) | AW8: L | AX8: ='R.FILE GOC'!AI59 -> 15 | AY8: ='R.FILE GOC'!AJ59 -> 0 | BB8: + | BC8: 27.14544 | BE8: L | BF8: 15.3 | BG8: 0
A9: 1E-XB2 | B9: XL-001E | C9: Xà bông (2)脫脂 | D9: g/L | E9: ='XM.GUI MAIL'!E9 -> 20~40 | F9: ='XM.GUI MAIL'!F9 -> (30±5) | G9: ='XM.GUI MAIL'!G9 -> 30 | H9: =XM.HN!B6 -> 0 | I9: =H9*4 -> 0 | J9: =($G$9-I9)*3305/1000 -> 99.15 | K9: + | L9: =IF(J9<0,0,J9) -> 99.15 | N9: kg | O9: =XM.HN!C6 -> 7.75 | P9: =O9*4 -> 31 | Q9: =($G$9-P9)*3305/1000 -> -3.305 | R9: + | S9: =IF(Q9<0,0,Q9) -> 0 | U9: kg | V9: =XM.HN!D6 -> 7.55 | W9: =V9*4 -> 30.2 | X9: =($G$9-W9)*3305/1000 -> -0.661 | Y9: + | Z9: =IF(X9<0,0,X9) -> 0 | AB9: kg | AC9: =XM.HN!E6 -> 7.8 | AD9: =AC9*4 -> 31.2 | AE9: =($G$9-AD9)*3305/1000 -> -3.966 | AF9: + | AG9: =IF(AE9<0,0,AE9) -> 0 | AI9: kg | AJ9: =XM.HN!F6 -> 8 | AK9: =AJ9*4 -> 32 | AL9: =($G$9-AK9)*3305/1000 -> -6.61 | AM9: + | AN9: =IF(AL9<0,0,AL9) -> 0 | AP9: kg | AQ9: =XM.HN!G6 -> 8 | AR9: =AQ9*4 -> 32 | AS9: =($G$9-AR9)*3305/1000 -> -6.61 | AT9: + | AU9: =IF(AS9<0,0,AS9) -> 0 | AW9: kg | AX9: ='R.FILE GOC'!AI60 -> 10.1 | AY9: ='R.FILE GOC'!AJ60 -> 0 | AZ9: 0 | BA9: 99.15 | BB9: + | BC9: 99.15 | BE9: kg | BF9: 10.3 | BG9: 0
C10: CleanA 840ml/NaOH 25kg | E10: 按NaOH添加數據添加 | K10: + | L10: =L9/25*840/1000 -> 3.33144 | M10: =IF('1. XL-1E TT'!AB10="","",'1. XL-1E TT'!AB10) | N10: L | R10: + | S10: =S9/25*840/1000 -> 0 | T10: =IF('1. XL-1E TT'!AF10="","",'1. XL-1E TT'!AF10) | U10: L | Y10: + | Z10: =Z9/25*840/1000 -> 0 | AA10: =IF('1. XL-1E TT'!AJ10="","",'1. XL-1E TT'!AJ10) | AB10: L | AF10: + | AG10: =AG9/25*840/1000 -> 0 | AH10: =IF('1. XL-1E TT(CA2)'!AB10="","",'1. XL-1E TT(CA2)'!AB10) | AI10: L | AM10: + | AN10: =AN9/25*840/1000 -> 0 | AO10: =IF('1. XL-1E TT(CA2)'!AF10="","",'1. XL-1E TT(CA2)'!AF10) | AP10: L | AT10: + | AU10: =AU9/25*840/1000 -> 0 | AV10: =IF('1. XL-1E TT(CA2)'!AJ10="","",'1. XL-1E TT(CA2)'!AJ10) | AW10: L | AX10: ='R.FILE GOC'!AI61 -> 1.2 | AY10: ='R.FILE GOC'!AJ61 -> 0 | BB10: + | BC10: 3.33144 | BE10: L | BF10: 1 | BG10: 0
C11: CleanB 8400ml/NaOH 25kg | E11: 按NaOH添加數據添加 | K11: + | L11: =L10*10 -> 33.3144 | M11: =IF('1. XL-1E TT'!AB11="","",'1. XL-1E TT'!AB11) | N11: L | R11: + | S11: =S10*10 -> 0 | T11: =IF('1. XL-1E TT'!AF11="","",'1. XL-1E TT'!AF11) | U11: L | Y11: + | Z11: =Z10*10 -> 0 | AA11: =IF('1. XL-1E TT'!AJ11="","",'1. XL-1E TT'!AJ11) | AB11: L | AF11: + | AG11: =AG10*10 -> 0 | AH11: =IF('1. XL-1E TT(CA2)'!AB11="","",'1. XL-1E TT(CA2)'!AB11) | AI11: L | AM11: + | AN11: =AN10*10 -> 0 | AO11: =IF('1. XL-1E TT(CA2)'!AF11="","",'1. XL-1E TT(CA2)'!AF11) | AP11: L | AT11: + | AU11: =AU10*10 -> 0 | AV11: =IF('1. XL-1E TT(CA2)'!AJ11="","",'1. XL-1E TT(CA2)'!AJ11) | AW11: L | AX11: ='R.FILE GOC'!AI62 -> 23.5 | AY11: ='R.FILE GOC'!AJ62 -> 0 | BB11: + | BC11: 33.3144 | BE11: L | BF11: 23 | BG11: 0
A12: 1E-DG1 | B12: XL-001E | C12: điện giải(1)+電解 | D12: g/L | E12: ='XM.GUI MAIL'!E12 -> 60~80 | F12: ='XM.GUI MAIL'!F12 -> (70±10) | G12: ='XM.GUI MAIL'!G12 -> 70 | H12: =XM.HN!B9 -> 0 | I12: =H12*4 -> 0 | J12: =($G$12-I12)*1156/1000 -> 80.92 | K12: + | L12: =IF(J12<0,0,J12) -> 80.92 | N12: kg | O12: =XM.HN!C9 -> 19.25 | P12: =O12*4 -> 77 | Q12: =($G$12-P12)*1156/1000 -> -8.092 | R12: + | S12: =IF(Q12<0,0,Q12) -> 0 | U12: kg | V12: =XM.HN!D9 -> 19.5 | W12: =V12*4 -> 78 | X12: =($G$12-W12)*1156/1000 -> -9.248 | Y12: + | Z12: =IF(X12<0,0,X12) -> 0 | AB12: kg | AC12: =XM.HN!E9 -> 18.8 | AD12: =AC12*4 -> 75.2 | AE12: =($G$12-AD12)*1156/1000 -> -6.0112 | AF12: + | AG12: =IF(AE12<0,0,AE12) -> 0 | AI12: kg | AJ12: =XM.HN!F9 -> 19.8 | AK12: 74.5 | AL12: =($G$12-AK12)*1156/1000 -> -5.202 | AM12: + | AN12: =IF(AL12<0,0,AL12) -> 0 | AP12: kg | AQ12: =XM.HN!G9 -> 19.7 | AR12: 74 | AS12: =($G$12-AR12)*1156/1000 -> -4.624 | AT12: + | AU12: =IF(AS12<0,0,AS12) -> 0 | AW12: kg | AX12: ='R.FILE GOC'!AI63 -> 7.5 | AY12: ='R.FILE GOC'!AJ63 -> 0 | AZ12: 0 | BA12: 80.92 | BB12: + | BC12: 80.92 | BE12: kg | BF12: 7.5 | BG12: 0
C13: CleanB 7.5L/NaOH 25kg | E13: 按NaOH添加數據添加 | K13: + | L13: =L12/25*7.5 -> 24.276 | M13: =IF('1. XL-1E TT'!AB13="","",'1. XL-1E TT'!AB13) | N13: L | R13: + | S13: =S12/25*7.5 -> 0 | T13: =IF('1. XL-1E TT'!AF13="","",'1. XL-1E TT'!AF13) | U13: L | Y13: + | Z13: =Z12/25*7.5 -> 0 | AA13: =IF('1. XL-1E TT'!AJ13="","",'1. XL-1E TT'!AJ13) | AB13: L | AF13: + | AG13: =AG12/25*7.5 -> 0 | AH13: =IF('1. XL-1E TT(CA2)'!AB13="","",'1. XL-1E TT(CA2)'!AB13) | AI13: L | AM13: + | AN13: =AN12/25*7.5 -> 0 | AO13: =IF('1. XL-1E TT(CA2)'!AF13="","",'1. XL-1E TT(CA2)'!AF13) | AP13: L | AT13: + | AU13: =AU12/25*7.5 -> 0 | AV13: =IF('1. XL-1E TT(CA2)'!AJ13="","",'1. XL-1E TT(CA2)'!AJ13) | AW13: L | AX13: ='R.FILE GOC'!AI64 -> 7.3 | AY13: ='R.FILE GOC'!AJ64 -> 0 | BB13: + | BC13: 24.276 | BE13: L | BF13: 7.3 | BG13: 0
A14: 1E-DG2 | B14: XL-001E | C14: điện giải (2)+電解 | D14: g/L | E14: ='XM.GUI MAIL'!E14 -> 60~80 | F14: ='XM.GUI MAIL'!F14 -> (70±10) | G14: ='XM.GUI MAIL'!G14 -> 70 | H14: =XM.HN!B11 -> 0 | I14: =H14*4 -> 0 | J14: =($G$14-I14)*1459/1000 -> 102.13 | K14: + | L14: =IF(J14<0,0,J14) -> 102.13 | N14: kg | O14: =XM.HN!C11 -> 18.15 | P14: =O14*4 -> 72.6 | Q14: =($G$14-P14)*1459/1000 -> -3.7934 | R14: + | S14: =IF(Q14<0,0,Q14) -> 0 | U14: kg | V14: =XM.HN!D11 -> 18.1 | W14: =V14*4 -> 72.4 | X14: =($G$14-W14)*1459/1000 -> -3.5016 | Y14: + | Z14: =IF(X14<0,0,X14) -> 0 | AB14: kg | AC14: =XM.HN!E11 -> 17.3 | AD14: 72 | AE14: =($G$14-AD14)*1459/1000 -> -2.918 | AF14: + | AG14: =IF(AE14<0,0,AE14) -> 0 | AI14: kg | AJ14: =XM.HN!F11 -> 17 | AK14: 71 | AL14: =($G$14-AK14)*1459/1000 -> -1.459 | AM14: + | AN14: =IF(AL14<0,0,AL14) -> 0 | AP14: kg | AQ14: =XM.HN!G11 -> 17 | AR14: =AQ14*4 -> 68 | AS14: =($G$14-AR14)*1459/1000 -> 2.918 | AT14: + | AU14: =IF(AS14<0,0,AS14) -> 2.918 | AW14: kg | AX14: ='R.FILE GOC'!AI65 -> 5.4 | AY14: ='R.FILE GOC'!AJ65 -> 0 | AZ14: 0 | BA14: 102.13 | BB14: + | BC14: 102.13 | BE14: kg | BF14: 5.4 | BG14: 0
C15: CleanB 7.5L/NaOH 25kg | E15: 按NaOH添加數據添加 | K15: + | L15: =L14/25*7.5 -> 30.639 | M15: =IF('1. XL-1E TT'!AB15="","",'1. XL-1E TT'!AB15) | N15: L | R15: + | S15: =S14/25*7.5 -> 0 | T15: =IF('1. XL-1E TT'!AF15="","",'1. XL-1E TT'!AF15) | U15: L | Y15: + | Z15: =Z14/25*7.5 -> 0 | AA15: =IF('1. XL-1E TT'!AJ15="","",'1. XL-1E TT'!AJ15) | AB15: L | AF15: + | AG15: =AG14/25*7.5 -> 0 | AH15: =IF('1. XL-1E TT(CA2)'!AB15="","",'1. XL-1E TT(CA2)'!AB15) | AI15: L | AM15: + | AN15: =AN14/25*7.5 -> 0 | AO15: =IF('1. XL-1E TT(CA2)'!AF15="","",'1. XL-1E TT(CA2)'!AF15) | AP15: L | AT15: + | AU15: =AU14/25*7.5 -> 0.8754 | AV15: =IF('1. XL-1E TT(CA2)'!AJ15="","",'1. XL-1E TT(CA2)'!AJ15) | AW15: L | AX15: ='R.FILE GOC'!AI66 -> 0 | AY15: ='R.FILE GOC'!AJ66 -> 0 | BB15: + | BC15: 30.639 | BE15: L | BF15: 0 | BG15: 0
A16: 1E-NAOH | B16: XL-001E | C16: Nồng độ NaOH 氫氧化鈉 | D16: g/L | E16: ='XM.GUI MAIL'!E16 -> 130 - 150 | F16: (140±7) | G16: ='XM.GUI MAIL'!G16 -> 140 | H16: =XM.HN!B13 -> 0 | I16: =H16*8 -> 0 | J16: =($G$16-I16)*19951/1000 -> 2793.14 | K16: + | L16: =IF(J16<0,0,J16) -> 2793.14 | N16: kg | O16: =XM.HN!C13 -> 16.7 | P16: =O16*8 -> 133.6 | Q16: =($G$16-P16)*19951/1000 -> 127.6864 | R16: + | S16: =IF(Q16<0,0,Q16) -> 127.6864 | U16: kg | V16: =XM.HN!D13 -> 17.6 | W16: =V16*8 -> 140.8 | X16: =($G$16-W16)*19951/1000 -> -15.9608 | Y16: + | Z16: =IF(X16<0,0,X16) -> 0 | AB16: kg | AC16: =XM.HN!E13 -> 17.9 | AD16: =AC16*8 -> 143.2 | AE16: =($G$16-AD16)*19951/1000 -> -63.8432 | AF16: + | AG16: =IF(AE16<0,0,AE16) -> 0 | AI16: kg | AJ16: =XM.HN!F13 -> 17.8 | AK16: =AJ16*8 -> 142.4 | AL16: =($G$16-AK16)*19951/1000 -> -47.8824 | AM16: + | AN16: =IF(AL16<0,0,AL16) -> 0 | AP16: kg | AQ16: =XM.HN!G13 -> 17.8 | AR16: =AQ16*8 -> 142.4 | AS16: =($G$16-AR16)*19951/1000 -> -47.8824 | AT16: + | AU16: =IF(AS16<0,0,AS16) -> 0 | AW16: kg | AX16: ='R.FILE GOC'!AI67 -> 15.035954 | AY16: ='R.FILE GOC'!AJ67 -> 0 | AZ16: 136 | BA16: 79.804 | BB16: + | BC16: 79.804 | BE16: kg | BF16: 15.048232 | BG16: 0
A17: 1E-ZN | B17: XL-001E | C17: Nồng độ Zn 鋅 (1 pcs Zn=25kg) | D17: g/L | E17: ='XM.GUI MAIL'!E17 -> 8~12 | F17: (10±2) | G17: ='XM.GUI MAIL'!G17 -> 10 | H17: =XM.HN!B14 -> 0 | I17: =H17*1.3 -> 0 | J17: =($G$17-I17)*19951/1000 -> 199.51 | K17: + | L17: =IF(J17<0,0,J17) -> 199.51 | N17: kg | O17: =XM.HN!C14 -> 9.8 | P17: =O17*1.3 -> 12.74 | Q17: =($G$17-P17)*19951/1000 -> -54.66574 | R17: + | S17: =IF(Q17<0,0,Q17) -> 0 | U17: kg | V17: =XM.HN!D14 -> 9.6 | W17: =V17*1.3 -> 12.48 | X17: =($G$17-W17)*19951/1000 -> -49.47848 | Y17: + | Z17: =IF(X17<0,0,X17) -> 0 | AB17: kg | AC17: =XM.HN!E14 -> 8.8 | AD17: =AC17*1.3 -> 11.44 | AE17: =($G$17-AD17)*19951/1000 -> -28.72944 | AF17: + | AG17: =IF(AE17<0,0,AE17) -> 0 | AI17: kg | AJ17: =XM.HN!F14 -> 8.3 | AK17: =AJ17*1.3 -> 10.79 | AL17: =($G$17-AK17)*19951/1000 -> -15.76129 | AM17: + | AN17: =IF(AL17<0,0,AL17) -> 0 | AP17: kg | AQ17: =XM.HN!G14 -> 8.15 | AR17: =AQ17*1.3 -> 10.595 | AS17: =($G$17-AR17)*19951/1000 -> -11.870845 | AT17: + | AU17: =IF(AS17<0,0,AS17) -> 0 | AW17: kg | AX17: ='R.FILE GOC'!AI68 -> 12.3 | AY17: ='R.FILE GOC'!AJ68 -> 0 | AZ17: 13.78 | BA17: -75.41478 | BB17: + | BC17: 0 | BE17: kg | BF17: 12.1 | BG17: 0
A18: 1E-CR3I | B18: XL-001E | C18: Nồng độ Cr2O3 三價鉻 | D18: % | E18: ='XM.GUI MAIL'!E18 -> 12~18 | F18: ='XM.GUI MAIL'!F18 -> (14±2) | G18: ='XM.GUI MAIL'!G18 -> 14 | H18: =XM.HN!B15 -> 0 | I18: =H18*100/6.95/10 -> 0 | J18: =($G$18-I18)*575/100 -> 80.5 | K18: + | L18: =IF(J18<0,0,J18) -> 80.5 | N18: L | O18: =XM.HN!C15 -> 11 | P18: =O18*100/6.95/10 -> 15.827338 | Q18: =($G$18-P18)*575/100 -> -10.507194 | R18: + | S18: =IF(Q18<0,0,Q18) -> 0 | U18: L | V18: =XM.HN!D15 -> 11 | W18: =V18*100/6.95/10 -> 15.827338 | X18: =($G$18-W18)*575/100 -> -10.507194 | Y18: + | Z18: =IF(X18<0,0,X18) -> 0 | AB18: L | AC18: =XM.HN!E15 -> 12.6 | AD18: 15.8 | AE18: =($G$18-AD18)*575/100 -> -10.35 | AF18: + | AG18: =IF(AE18<0,0,AE18) -> 0 | AI18: L | AJ18: =XM.HN!F15 -> 10.6 | AK18: =AJ18*100/6.95/10 -> 15.251799 | AL18: =($G$18-AK18)*575/100 -> -7.1978417 | AM18: + | AN18: =IF(AL18<0,0,AL18) -> 0 | AP18: L | AQ18: =XM.HN!G15 -> 10.2 | AR18: =AQ18*100/6.95/10 -> 14.676259 | AS18: =($G$18-AR18)*575/100 -> -3.8884892 | AT18: + | AU18: =IF(AS18<0,0,AS18) -> 0 | AW18: L | AX18: ='R.FILE GOC'!AI69 | AY18: ='R.FILE GOC'!AJ69 -> 0 | AZ18: 0 | BA18: 80.5 | BB18: + | BC18: 80.5 | BE18: L | BG18: 0
A19: 1E-CR3IPH | B19: XL-001E | D19: pH | E19: ='XM.GUI MAIL'!E19 -> 1.5~1.9 | F19: ='XM.GUI MAIL'!F19 -> (1.7±0.1 ) | G19: ='XM.GUI MAIL'!G19 -> 0 | I19: =XM.HN!B23 -> 0 | P19: =XM.HN!C23 -> 1.63 | W19: =XM.HN!D23 -> 1.64 | AD19: =XM.HN!E23 -> 1.8 | AK19: =XM.HN!F23 -> 1.8 | AR19: =XM.HN!G23 -> 1.76 | AX19: ='R.FILE GOC'!AI70 | AY19: ='R.FILE GOC'!AJ70 -> 0 | AZ19: 0 | BG19: 0
A20: 1E-HCL1 | B20: XL-001E | C20: Nồng độ acid đặc 鹽酸 濃度 | D20: %V/V | E20: ='XM.GUI MAIL'!E20 -> 40~50 | F20: ='XM.GUI MAIL'!F20 -> (45±5) | G20: ='XM.GUI MAIL'!G20 -> 0.45 | H20: =XM.HN!B17 -> 0 | I20: =(1*H20*36.5)/(1*10)/32%/100 -> 0 | J20: =($G$20-I20)*2122 -> 954.9 | K20: + | L20: =IF(J20<0,0,J20) -> 954.9 | N20: L | O20: =XM.HN!C17 -> 3.8 | P20: =(1*O20*36.5)/(1*10)/32%/100 -> 0.4334375 | Q20: =($G$20-P20)*2122 -> 35.145625 | R20: + | S20: =IF(Q20<0,0,Q20) -> 35.145625 | U20: L | V20: =XM.HN!D17 -> 4.2 | W20: =(1*V20*36.5)/(1*10)/32%/100 -> 0.4790625 | X20: =($G$20-W20)*2122 -> -61.670625 | Y20: + | Z20: =IF(X20<0,0,X20) -> 0 | AB20: L | AC20: =XM.HN!E17 -> 4.3 | AD20: =(1*AC20*36.5)/(1*10)/32%/100 -> 0.49046875 | AE20: =($G$20-AD20)*2122 -> -85.874687 | AF20: + | AG20: =IF(AE20<0,0,AE20) -> 0 | AI20: L | AJ20: =XM.HN!F17 -> 4.1 | AK20: =(1*AJ20*36.5)/(1*10)/32%/100 -> 0.46765625 | AL20: =($G$20-AK20)*2122 -> -37.466562 | AM20: + | AN20: =IF(AL20<0,0,AL20) -> 0 | AP20: L | AQ20: =XM.HN!G17 -> 4.05 | AR20: =(1*AQ20*36.5)/(1*10)/32%/100 -> 0.46195312 | AS20: =($G$20-AR20)*2122 -> -25.364531 | AT20: + | AU20: =IF(AS20<0,0,AS20) -> 0 | AW20: L | AX20: ='R.FILE GOC'!AI71 -> 0.43407043 | AY20: ='R.FILE GOC'!AJ71 -> 0 | AZ20: 0 | BA20: 954.9 | BB20: + | BC20: 954.9 | BE20: L | BF20: 0.57232913 | BG20: 0
A21: 1E-HCL2 | B21: XL-001E | C21: Nồng độ acid loãng 稀酸 濃度 | D21: %V/V | E21: ='XM.GUI MAIL'!E21 -> (22±5) =17~27 | F21: ='XM.GUI MAIL'!F21 -> (22±5) | G21: ='XM.GUI MAIL'!G21 -> 0.22 | H21: =XM.HN!B18 -> 0 | I21: =(1*H21*36.5)/(1*10)/32%/100 -> 0 | J21: =($G$21-I21)*612 -> 134.64 | K21: + | L21: =IF(J21<0,0,J21) -> 134.64 | N21: L | O21: =XM.HN!C18 -> 0 | P21: =(1*O21*36.5)/(1*10)/32%/100 -> 0 | Q21: =($G$21-P21)*612 -> 134.64 | R21: + | S21: =IF(Q21<0,0,Q21) -> 134.64 | U21: L | V21: =XM.HN!D18 -> 0 | W21: =(1*V21*36.5)/(1*10)/32%/100 -> 0 | X21: =($G$21-W21)*612 -> 134.64 | Y21: + | Z21: =IF(X21<0,0,X21) -> 134.64 | AB21: L | AC21: =XM.HN!E18 -> 0 | AD21: =(1*AC21*36.5)/(1*10)/32%/100 -> 0 | AE21: =($G$21-AD21)*612 -> 134.64 | AF21: + | AG21: =IF(AE21<0,0,AE21) -> 134.64 | AI21: L | AJ21: =XM.HN!F18 -> 0 | AK21: =(1*AJ21*36.5)/(1*10)/32%/100 -> 0 | AL21: =($G$21-AK21)*612 -> 134.64 | AM21: + | AN21: =IF(AL21<0,0,AL21) -> 134.64 | AP21: L | AQ21: =XM.HN!G18 -> 0 | AR21: =(1*AQ21*36.5)/(1*10)/32%/100 -> 0 | AS21: =($G$21-AR21)*612 -> 134.64 | AT21: + | AU21: =IF(AS21<0,0,AS21) -> 134.64 | AW21: L | AX21: ='R.FILE GOC'!AI72 -> 0.26837996 | AY21: ='R.FILE GOC'!AJ72 -> 0 | AZ21: 0 | BA21: 134.64 | BB21: + | BC21: 134.64 | BE21: L | BF21: 0.36169209 | BG21: 0
A22: 1E-HCL3 | B22: XL-001E | C22: Nồng độ HCl hoạt hóa 稀酸活化 濃度 | D22: %V/V | E22: ='XM.GUI MAIL'!E22 -> 5~15 | F22: ='XM.GUI MAIL'!F22 -> (10±3) | G22: ='XM.GUI MAIL'!G22 -> 0.1 | H22: =XM.HN!B19 -> 0 | I22: =(1*H22*36.5)/(5*10)/32%/100 -> 0 | J22: =($G$22-I22)*575 -> 57.5 | K22: + | L22: =IF(J22<0,0,J22) -> 57.5 | N22: L | O22: =XM.HN!C19 -> 5.9 | P22: =(1*O22*36.5)/(5*10)/32%/100 -> 0.13459375 | Q22: =($G$22-P22)*575 -> -19.891406 | R22: + | S22: =IF(Q22<0,0,Q22) -> 0 | U22: L | V22: =XM.HN!D19 -> 8.1 | W22: =(1*V22*36.5)/(5*10)/32%/100 -> 0.18478125 | X22: =($G$22-W22)*575 -> -48.749219 | Y22: + | Z22: =IF(X22<0,0,X22) -> 0 | AB22: L | AC22: =XM.HN!E19 -> 7.5 | AD22: =(1*AC22*36.5)/(5*10)/32%/100 -> 0.17109375 | AE22: =($G$22-AD22)*575 -> -40.878906 | AF22: + | AG22: =IF(AE22<0,0,AE22) -> 0 | AI22: L | AJ22: =XM.HN!F19 -> 6.7 | AK22: =(1*AJ22*36.5)/(5*10)/32%/100 -> 0.15284375 | AL22: =($G$22-AK22)*575 -> -30.385156 | AM22: + | AN22: =IF(AL22<0,0,AL22) -> 0 | AP22: L | AQ22: =XM.HN!G19 -> 5 | AR22: =(1*AQ22*36.5)/(5*10)/32%/100 -> 0.1140625 | AS22: =($G$22-AR22)*575 -> -8.0859375 | AT22: + | AU22: =IF(AS22<0,0,AS22) -> 0 | AW22: L | AY22: ='R.FILE GOC'!AJ73 -> 0 | AZ22: 0 | BA22: 57.5 | BB22: + | BC22: 57.5 | BE22: L | BG22: 0
