Workbook
Name _NEW2: [1]吊電B線入出料標準數據!$B$4:$P$4003
Name _XM_XT_THUCTE: '[2]XM.GUI MAIL'!$A$6:$AQ$108
Name _XM_XT_THUCTE: 'XM.GUI MAIL'!$A$6:$AQ$108
Name AB: #REF!
Name AB: #REF!
Name AB: #REF!
Name AB: #REF!
Name AB: #REF!
Name AB: #REF!
Name AB: #REF!
Name abcd: #REF!
Name abcd: #REF!
Name abcd: #REF!
Name abcd: #REF!
Name abcd: #REF!
Name abcd: #REF!
Name abcd: #REF!
Name abcd: #REF!
Name abcd: #REF!
Name abcd: #REF!
Name abcd: #REF!
Name abcd: #REF!
Name CCC: #REF!
Name CCC: #REF!
Name CCC: #REF!
Name CCC: #REF!
Name CCC: #REF!
Name CCC: #REF!
Name CCC: #REF!
Name CXXTA: #REF!
Name CXXTA: #REF!
Name CXXTA: #REF!
Name CXXTA: #REF!
Name CXXTA: #REF!
Name CXXTA: #REF!
Name CXXTA: #REF!
Name CXXTB: [1]吊電B線入出料標準數據!$B$3:$P$428
Name HUANGHAIDONGA: #REF!
Name HUANGHAIDONGA: #REF!
Name HUANGHAIDONGA: #REF!
Name HUANGHAIDONGA: #REF!
Name HUANGHAIDONGA: #REF!
Name HUANGHAIDONGA: #REF!
Name HUANGHAIDONGA: #REF!
Name HUANGHAIDONGB: [1]吊電B線入出料標準數據!$A$3:$P$428
Name PartNo: [3]All!$B$5:$Q$65536
Name RLMLXD: '[2]R.GUI MAIL'!$A$6:$AQ$114
Name RLMLXD: 'R.GUI MAIL'!$A$6:$AQ$114
Name sss: '[4]附表-01'!$A$2:$L$1662
Name WUJIWEI: #REF!
Name WUJIWEI: #REF!
Name WUJIWEI: #REF!
Name WUJIWEI: #REF!
Name WUJIWEI: #REF!
Name WUJIWEI: #REF!
Name WUJIWEI: #REF!
Name XTB123: [5]輸入!#REF!
Name XTB123: [5]輸入!#REF!
Name XTB123: [5]輸入!#REF!
Name XTB123: [5]輸入!#REF!

Sheet PT TAP CHAT
B1: MẪU GỬI NHÀ CUNG ỨNG
B2: =MENU!AC9 -> 2023/03/21
A3: NCC | B3: Type sample | C3: Test Item | D3: Standards | F3: Unit | G3: Result | H3: KQ NCC | I3: ±5%
A4: JASCO | B4: Akaline Zinc (XL-1E) | C4: Zn2+ | D4: ='XM.GUI MAIL'!E11 -> 7~12 | E4: ='XM.GUI MAIL'!F11 -> (9g±1) | F4: g/l | G4: ='XM.GUI MAIL'!I11 -> 0 | I4: =IF(H4="","",(G4-H4)/G4)
A5: JASCO | C5: NaOH | D5: ='XM.GUI MAIL'!E10 -> 130 - 150 | E5: ='XM.GUI MAIL'!F12 -> (14±2) | F5: g/l | G5: ='XM.GUI MAIL'!I10 -> 0 | I5: =IF(H5="","",(G5-H5)/G5)
A6: JASCO | C6: Na2CO3 | D6: ＜70g/L | E6: ='XM.GUI MAIL'!F13 -> (1.8±0.1 ) | F6: g/l | G6: =XM.HN!E60 -> 0 | I6: =IF(H6="","",(G6-H6)/G6)
A7: JASCO | C7: Fe | D7: <5 | E7: ='XM.GUI MAIL'!F14 -> (45±5) | F7: ppm | I7: =IF(H7="","",(G7-H7)/G7)
A8: JASCO | C8: Cu | D8: <5 | E8: ='XM.GUI MAIL'!F15 -> (22±5) | F8: ppm | I8: =IF(H8="","",(G8-H8)/G8)
A9: JASCO | C9: Cr | D9: <5 | E9: ='XM.GUI MAIL'!F16 -> (10±3) | F9: ppm | I9: =IF(H9="","",(G9-H9)/G9)
A10: JASCO | C10: Pb | D10: <5 | E10: ='XM.GUI MAIL'!F17 -> (1±0.4) | F10: ppm | I10: =IF(H10="","",(G10-H10)/G10)
A11: JASCO | B11: Màu (I) (TR173AH) (XL-1E) | C11: Cr2O3 (TR173AH) | D11: ='XM.GUI MAIL'!E12 -> 12~18 | E11: ='XM.GUI MAIL'!F18 -> (7.5±1) | F11: % | G11: ='XM.GUI MAIL'!I12 -> 0 | I11: =IF(H11="","",(G11-H11)/G11)
A12: JASCO | C12: pH | D12: ='XM.GUI MAIL'!E13 -> 1.6~2.2 | E12: ='XM.GUI MAIL'!F19 -> (1.8±0.1) | F12: / | G12: ='XM.GUI MAIL'!I13 -> 0 | I12: =IF(H12="","",(G12-H12)/G12)
A13: JASCO | C13: Fe | D13: <80 | E13: ='XM.GUI MAIL'!F20 -> 0 | F13: ppm | I13: =IF(H13="","",(G13-H13)/G13)
A14: JASCO | C14: Cu | D14: ＜5 | E14: ='XM.GUI MAIL'!F21 -> Giới hạn kiểm soát 管控值 | F14: ppm | I14: =IF(H14="","",(G14-H14)/G14)
A15: JASCO | C15: Zn | D15: ＜7000ppm | E15: ='XM.GUI MAIL'!F22 -> (70±3) | F15: ppm | I15: =IF(H15="","",(G15-H15)/G15)
A16: JASCO | B16: Màu K (5U109A) (XL-1E) | C16: Màu K (5U109A) | D16: ='XM.GUI MAIL'!E18 -> 5~10 | E16: ='XM.GUI MAIL'!F23 -> (70±3) | F16: % | G16: ='XM.GUI MAIL'!I18 | I16: =IF(H16="","",(G16-H16)/G16)
A17: JASCO | C17: pH | D17: ='XM.GUI MAIL'!E19 -> 1.6~2.0 | E17: ='XM.GUI MAIL'!F24 -> (55±3) | F17: / | G17: ='XM.GUI MAIL'!I19 -> 0 | I17: =IF(H17="","",(G17-H17)/G17)
A18: JASCO | C18: Fe | D18: <40ppm | F18: ppm | I18: =(G18-H18)/G18 -> #DIV/0!
A19: JASCO | C19: Cu | D19: ＜5ppm | F19: ppm | I19: =(G19-H19)/G19 -> #DIV/0!
A20: JASCO | C20: Zn | D20: ＜6000ppm | F20: ppm | I20: =(G20-H20)/G20 -> #DIV/0!
B22: Type sample | C22: Test Item | D22: Standards | F22: Unit | G22: Result
A23: HALO | B23: Akaline Zinc (XL-1F) | C23: Zn2+ | D23: ='XM.GUI MAIL'!E42 -> 8~12 | E23: ='XM.GUI MAIL'!F42 -> (10±1) | F23: g/l | G23: ='XM.GUI MAIL'!I42 -> 0 | I23: =IF(H23="","",(G23-H23)/G23)
A24: HALO | C24: NaOH | D24: ='XM.GUI MAIL'!E41 -> 130 - 150 | E24: ='XM.GUI MAIL'!F41 -> (140±10) | F24: g/l | G24: ='XM.GUI MAIL'!I41 -> 0 | I24: =IF(H24="","",(G24-H24)/G24)
A25: HALO | C25: Na2CO3 | D25: ＜70g/L | E25: ＜70g/L | F25: g/l | G25: =XM.HN!E61 -> 0 | I25: =IF(H25="","",(G25-H25)/G25)
A26: HALO | C26: Fe | D26: <5 | E26: <5 | F26: ppm | I26: =IF(H26="","",(G26-H26)/G26)
A27: HALO | C27: Cu | D27: <5 | E27: <5 | F27: ppm | I27: =IF(H27="","",(G27-H27)/G27)
A28: HALO | C28: Cr | D28: <5 | E28: <5 | F28: ppm | I28: =IF(H28="","",(G28-H28)/G28)
A29: HALO | C29: Pb | D29: <5 | E29: <5 | F29: ppm | I29: =IF(H29="","",(G29-H29)/G29)
A30: HALO | B30: Màu (I) (Lanthane 318) (XL-1F) | C30: Lanthane 318 | D30: ='XM.GUI MAIL'!E43 -> 6~10 | E30: ='XM.GUI MAIL'!F43 -> (8±0.5) | F30: % | G30: ='XM.GUI MAIL'!I43 -> -1.0461 | I30: =IF(H30="","",(G30-H30)/G30)
A31: HALO | C31: pH | D31: ='XM.GUI MAIL'!E44 -> 2~2.5 | E31: ='XM.GUI MAIL'!F44 -> (2.3±0.1 ) | F31: / | G31: ='XM.GUI MAIL'!I44 -> 0 | I31: =IF(H31="","",(G31-H31)/G31)
A32: HALO | C32: Fe | D32: <80 | E32: <80 | F32: ppm | I32: =IF(H32="","",(G32-H32)/G32)
A33: HALO | C33: Cu | D33: ＜5 | E33: ＜5 | F33: ppm | I33: =IF(H33="","",(G33-H33)/G33)
A34: HALO | C34: Zn | D34: ＜7000ppm | E34: ＜7000ppm | F34: ppm | I34: =IF(H34="","",(G34-H34)/G34)
A35: HALO | B35: Màu (K) (Finidip 124) (XL-1F) | C35: Finidip 124 | D35: ='XM.GUI MAIL'!E49 -> 5~8 | E35: ='XM.GUI MAIL'!F49 -> (6%±0.5) | F35: % | G35: ='XM.GUI MAIL'!I49 | I35: =IF(H35="","",(G35-H35)/G35)
A36: HALO | C36: pH | D36: ='XM.GUI MAIL'!E50 -> 1.8~2.4 | E36: ='XM.GUI MAIL'!F50 -> (2.1±0.1 ) | F36: / | G36: ='XM.GUI MAIL'!I50 -> 0 | I36: =IF(H36="","",(G36-H36)/G36)
A37: HALO | C37: Fe | D37: (2.1±0.1 ) | F37: ppm | I37: =(G37-H37)/G37 -> #DIV/0!
A38: HALO | C38: Cu | D38: ＜5ppm | F38: ppm | I38: =(G38-H38)/G38 -> #DIV/0!
A39: HALO | C39: Zn | D39: ＜7000ppm | F39: ppm | I39: =(G39-H39)/G39 -> #DIV/0!
B41: Type sample | C41: Test Item | D41: Standards | F41: Unit | G41: Result
A42: HALO | B42: Akaline Zinc (XT-0C) | C42: Zn2+ | D42: ='XM.GUI MAIL'!E73 -> 6~8 | E42: ='XM.GUI MAIL'!F73 -> (7±0.5) | F42: g/l | G42: ='XM.GUI MAIL'!I73 -> 5.85 | I42: =IF(H42="","",(G42-H42)/G42)
...

Sheet MENU
B3: XI MẠ, XI TREO | J3: RỬA LIỆU, MÀNG LOA, XI ĐEN | R3: KHÁC | V3: IMPORT | AA3: khoảng thời gian Import
B6: XM.HN | F6: XM.GUI MAIL | J6: ED-XI DEN | N6: R.GUI MAIL | R6: IT.NONG DO | V6: 1 | Y6: =AC9+TIME(8,45,0) -> 45006.365 | AA6: 8:15-8:45 | AC6: CA 1 | AD6: Trang
AC7: CA 2 | AD7: L.Yen
B9: XM.FILE GOC | F9: 1. XL-1E TT(CA1) | J9: R.HN | N9: RL-LINE | R9: IT.NHIET DO | V9: 2 | Y9: =AC9+TIME(10,45,0) -> 45006.448 | AA9: 10:15-10:45 | AC9: 2023/03/21 | AE9: đánh năm/tháng/ngày vào ô bên
B12: 1. XL-1E kh | F12: 1. XL-1E TT(CA2) | J12: R.FILE GOC | N12: 1.xi den TT | R12: GHI CHU | V12: 3 | Y12: =AC9+TIME(15,30,0) -> 45006.646 | AA12: 15:00-15:30
B15: 2. XL-1F kh | F15: 2. XL-1F TT(CA1) | J15: 1.xi den | N15: 2.RL E tt | R15: PP HÓA NGHIỆM FILE WORD | V15: 4 | Y15: =AC9+TIME(17,0,0) -> 45006.708 | AA15: 16:30-17:00 | AC15: ACID Đ.VAO
B18: 3.XT-C kh | F18: 2. XL-1F TT(CA2) | J18: 2.RL E | N18: 3.RL G tt | R18: QC- E | V18: 5 | Y18: =AC9+TIME(20,45,0) -> 45006.865 | AA18: 20:15-20:45
B21: 4.Zn Ni.kh | F21: 3.XT-C TT(CA1) | J21: 3.RL G | N21: 4.RL F tt | R21: QC-1F | V21: 6 | Y21: =AC9+TIME(22,45,0) -> 45006.948 | AA21: 22:15-22:45
F24: 3.XT-C TT(CA2) | J24: 4.RL F | N24: 5.ML tt | R24: QC- XT | V24: 7 | Y24: =AC9+TIME(3,0,0) -> 45006.125 | AA24: 2:30-3:00
F27: 4.Zn Ni TT | J27: 5.ML | R27: QC-RL | V27: 8 | Y27: =AC9+TIME(5,0,0) -> 45006.208 | AA27: 4:30-5:00
B30: XM.chart | F30: XM.chart 1 | J30: RL.chart | N30: RL.chart1 | R30: QC-NI | AA30: tg import
F33: 4.ZN-NI tt(CA1) | R33: PT TAP CHAT
F36: 4.ZN-NI tt(CA2)
F39: BS-XT

Sheet 1
A1: "BÁO CÁO KẾT QUẢ HÓA NGHIỆM HÀNG NGÀY 表面處理生產製程管控記錄表"
A2: NGAY | B2: Ma__Hang_muc | C2: Nong_Do_01 | E2: 1 | F2: bs | G2: 2 | H2: bs | I2: 3 | J2: bs | K2: 4 | L2: bs | M2: 5 | N2: bs | O2: 6 | P2: bs | Q2: 1
A3: Date | B3: Code | C3: 濃度 g/L-01
A4: =MENU!Y6 -> 45006.365 | B4: 1E-XB1 | C4: =IFERROR(VLOOKUP($B4,_XM_XT_THUCTE,9,0),"") -> 0 | E4: =ISNUMBER(C4) -> TRUE | F4: =ISNUMBER(#REF!) -> FALSE | G4: =ISNUMBER(#REF!) -> FALSE | H4: =ISNUMBER(#REF!) -> FALSE | I4: =ISNUMBER(#REF!) -> FALSE | J4: =ISNUMBER(#REF!) -> FALSE | K4: =ISNUMBER(#REF!) -> FALSE | L4: =ISNUMBER(#REF!) -> FALSE | M4: =ISNUMBER(#REF!) -> FALSE | ... P4: =ISNUMBER(#REF!) -> FALSE | Q4: =IF(E4=TRUE,"",1)
A5: =$A$4 -> 45006.365 | B5: 1E-XB2 | C5: =IFERROR(VLOOKUP($B5,_XM_XT_THUCTE,9,0),"") -> 0 | E5: =ISNUMBER(C5) -> TRUE | F5: =ISNUMBER(#REF!) -> FALSE | G5: =ISNUMBER(#REF!) -> FALSE | H5: =ISNUMBER(#REF!) -> FALSE | I5: =ISNUMBER(#REF!) -> FALSE | J5: =ISNUMBER(#REF!) -> FALSE | K5: =ISNUMBER(#REF!) -> FALSE | L5: =ISNUMBER(#REF!) -> FALSE | M5: =ISNUMBER(#REF!) -> FALSE | ... P5: =ISNUMBER(#REF!) -> FALSE | Q5: =IF(E5=TRUE,"",1)
A6: =$A$4 -> 45006.365 | B6: 1E-DG1 | C6: =IFERROR(VLOOKUP($B6,_XM_XT_THUCTE,9,0),"") -> 0 | E6: =ISNUMBER(C6) -> TRUE | F6: =ISNUMBER(#REF!) -> FALSE | G6: =ISNUMBER(#REF!) -> FALSE | H6: =ISNUMBER(#REF!) -> FALSE | I6: =ISNUMBER(#REF!) -> FALSE | J6: =ISNUMBER(#REF!) -> FALSE | K6: =ISNUMBER(#REF!) -> FALSE | L6: =ISNUMBER(#REF!) -> FALSE | M6: =ISNUMBER(#REF!) -> FALSE | ... P6: =ISNUMBER(#REF!) -> FALSE | Q6: =IF(E6=TRUE,"",1)
A7: =$A$4 -> 45006.365 | B7: 1E-DG2 | C7: =IFERROR(VLOOKUP($B7,_XM_XT_THUCTE,9,0),"") -> 0 | E7: =ISNUMBER(C7) -> TRUE | F7: =ISNUMBER(#REF!) -> FALSE | G7: =ISNUMBER(#REF!) -> FALSE | H7: =ISNUMBER(#REF!) -> FALSE | I7: =ISNUMBER(#REF!) -> FALSE | J7: =ISNUMBER(#REF!) -> FALSE | K7: =ISNUMBER(#REF!) -> FALSE | L7: =ISNUMBER(#REF!) -> FALSE | M7: =ISNUMBER(#REF!) -> FALSE | ... P7: =ISNUMBER(#REF!) -> FALSE | Q7: =IF(E7=TRUE,"",1)
A8: =$A$4 -> 45006.365 | B8: 1E-NAOH | C8: =IFERROR(VLOOKUP($B8,_XM_XT_THUCTE,9,0),"") -> 0 | E8: =ISNUMBER(C8) -> TRUE | F8: =ISNUMBER(#REF!) -> FALSE | G8: =ISNUMBER(#REF!) -> FALSE | H8: =ISNUMBER(#REF!) -> FALSE | I8: =ISNUMBER(#REF!) -> FALSE | J8: =ISNUMBER(#REF!) -> FALSE | K8: =ISNUMBER(#REF!) -> FALSE | L8: =ISNUMBER(#REF!) -> FALSE | M8: =ISNUMBER(#REF!) -> FALSE | ... P8: =ISNUMBER(#REF!) -> FALSE | Q8: =IF(E8=TRUE,"",1)
A9: =$A$4 -> 45006.365 | B9: 1E-ZN | C9: =IFERROR(VLOOKUP($B9,_XM_XT_THUCTE,9,0),"") -> 0 | E9: =ISNUMBER(C9) -> TRUE | F9: =ISNUMBER(#REF!) -> FALSE | G9: =ISNUMBER(#REF!) -> FALSE | H9: =ISNUMBER(#REF!) -> FALSE | I9: =ISNUMBER(#REF!) -> FALSE | J9: =ISNUMBER(#REF!) -> FALSE | K9: =ISNUMBER(#REF!) -> FALSE | L9: =ISNUMBER(#REF!) -> FALSE | M9: =ISNUMBER(#REF!) -> FALSE | ... P9: =ISNUMBER(#REF!) -> FALSE | Q9: =IF(E9=TRUE,"",1)
A10: =$A$4 -> 45006.365 | B10: 1E-CR3I | C10: =IFERROR(VLOOKUP($B10,_XM_XT_THUCTE,9,0),"") -> 0 | E10: =ISNUMBER(C10) -> TRUE | F10: =ISNUMBER(#REF!) -> FALSE | G10: =ISNUMBER(#REF!) -> FALSE | H10: =ISNUMBER(#REF!) -> FALSE | I10: =ISNUMBER(#REF!) -> FALSE | J10: =ISNUMBER(#REF!) -> FALSE | K10: =ISNUMBER(#REF!) -> FALSE | L10: =ISNUMBER(#REF!) -> FALSE | M10: =ISNUMBER(#REF!) -> FALSE | ... P10: =ISNUMBER(#REF!) -> FALSE | Q10: =IF(E10=TRUE,"",1)
A11: =$A$4 -> 45006.365 | B11: 1E-CR3IPH | C11: =IFERROR(VLOOKUP($B11,_XM_XT_THUCTE,9,0),"") -> 0 | E11: =ISNUMBER(C11) -> TRUE | F11: =ISNUMBER(#REF!) -> FALSE | G11: =ISNUMBER(#REF!) -> FALSE | H11: =ISNUMBER(#REF!) -> FALSE | I11: =ISNUMBER(#REF!) -> FALSE | J11: =ISNUMBER(#REF!) -> FALSE | K11: =ISNUMBER(#REF!) -> FALSE | L11: =ISNUMBER(#REF!) -> FALSE | M11: =ISNUMBER(#REF!) -> FALSE | ... P11: =ISNUMBER(#REF!) -> FALSE | Q11: =IF(E11=TRUE,"",1)
A12: =$A$4 -> 45006.365 | B12: 1E-HCL1 | C12: =IFERROR(VLOOKUP($B12,_XM_XT_THUCTE,9,0),"") -> 0 | E12: =ISNUMBER(C12) -> TRUE | F12: =ISNUMBER(#REF!) -> FALSE | G12: =ISNUMBER(#REF!) -> FALSE | H12: =ISNUMBER(#REF!) -> FALSE | I12: =ISNUMBER(#REF!) -> FALSE | J12: =ISNUMBER(#REF!) -> FALSE | K12: =ISNUMBER(#REF!) -> FALSE | L12: =ISNUMBER(#REF!) -> FALSE | M12: =ISNUMBER(#REF!) -> FALSE | ... P12: =ISNUMBER(#REF!) -> FALSE | Q12: =IF(E12=TRUE,"",1)
A13: =$A$4 -> 45006.365 | B13: 1E-HCL2 | C13: =IFERROR(VLOOKUP($B13,_XM_XT_THUCTE,9,0),"") -> 0 | E13: =ISNUMBER(C13) -> TRUE | F13: =ISNUMBER(#REF!) -> FALSE | G13: =ISNUMBER(#REF!) -> FALSE | H13: =ISNUMBER(#REF!) -> FALSE | I13: =ISNUMBER(#REF!) -> FALSE | J13: =ISNUMBER(#REF!) -> FALSE | K13: =ISNUMBER(#REF!) -> FALSE | L13: =ISNUMBER(#REF!) -> FALSE | M13: =ISNUMBER(#REF!) -> FALSE | ... P13: =ISNUMBER(#REF!) -> FALSE | Q13: =IF(E13=TRUE,"",1)
A14: =$A$4 -> 45006.365 | B14: 1E-HCL3 | C14: =IFERROR(VLOOKUP($B14,_XM_XT_THUCTE,9,0),"") -> 0 | E14: =ISNUMBER(C14) -> TRUE | F14: =ISNUMBER(#REF!) -> FALSE | G14: =ISNUMBER(#REF!) -> FALSE | H14: =ISNUMBER(#REF!) -> FALSE | I14: =ISNUMBER(#REF!) -> FALSE | J14: =ISNUMBER(#REF!) -> FALSE | K14: =ISNUMBER(#REF!) -> FALSE | L14: =ISNUMBER(#REF!) -> FALSE | M14: =ISNUMBER(#REF!) -> FALSE | ... P14: =ISNUMBER(#REF!) -> FALSE | Q14: =IF(E14=TRUE,"",1)
A15: =$A$4 -> 45006.365 | B15: 1E-HNO3 | C15: =IFERROR(VLOOKUP($B15,_XM_XT_THUCTE,9,0),"") -> 0 | E15: =ISNUMBER(C15) -> TRUE | F15: =ISNUMBER(#REF!) -> FALSE | G15: =ISNUMBER(#REF!) -> FALSE | H15: =ISNUMBER(#REF!) -> FALSE | I15: =ISNUMBER(#REF!) -> FALSE | J15: =ISNUMBER(#REF!) -> FALSE | K15: =ISNUMBER(#REF!) -> FALSE | L15: =ISNUMBER(#REF!) -> FALSE | M15: =ISNUMBER(#REF!) -> FALSE | ... P15: =ISNUMBER(#REF!) -> FALSE | Q15: =IF(E15=TRUE,"",1)
A16: =$A$4 -> 45006.365 | B16: 1E-MEM | C16: =IFERROR(VLOOKUP($B16,_XM_XT_THUCTE,9,0),"") -> 0 | E16: =ISNUMBER(C16) -> TRUE | F16: =ISNUMBER(#REF!) -> FALSE | G16: =ISNUMBER(#REF!) -> FALSE | H16: =ISNUMBER(#REF!) -> FALSE | I16: =ISNUMBER(#REF!) -> FALSE | J16: =ISNUMBER(#REF!) -> FALSE | K16: =ISNUMBER(#REF!) -> FALSE | L16: =ISNUMBER(#REF!) -> FALSE | M16: =ISNUMBER(#REF!) -> FALSE | ... P16: =ISNUMBER(#REF!) -> FALSE | Q16: =IF(E16=TRUE,"",1)
... A45: =$A$4 -> 45006.365 | B45: XT-MEM | C45: =IFERROR(VLOOKUP($B45,_XM_XT_THUCTE,9,0),"") -> 0 | E45: =ISNUMBER(C45) -> TRUE | F45: =ISNUMBER(#REF!) -> FALSE | G45: =ISNUMBER(#REF!) -> FALSE | H45: =ISNUMBER(#REF!) -> FALSE | I45: =ISNUMBER(#REF!) -> FALSE | J45: =ISNUMBER(#REF!) -> FALSE | K45: =ISNUMBER(#REF!) -> FALSE | L45: =ISNUMBER(#REF!) -> FALSE | M45: =ISNUMBER(#REF!) -> FALSE | ... P45: =ISNUMBER(#REF!) -> FALSE | Q45: =IF(E45=TRUE,"",1)
A46: =$A$4 -> 45006.365 | B46: RLE-HCL1 | C46: =IFERROR(VLOOKUP($B46,RLMLXD,8,0),"") -> 0 | E46: =ISNUMBER(C46) -> TRUE | F46: =ISNUMBER(#REF!) -> FALSE | G46: =ISNUMBER(#REF!) -> FALSE | H46: =ISNUMBER(#REF!) -> FALSE | I46: =ISNUMBER(#REF!) -> FALSE | J46: =ISNUMBER(#REF!) -> FALSE | K46: =ISNUMBER(#REF!) -> FALSE | L46: =ISNUMBER(#REF!) -> FALSE | M46: =ISNUMBER(#REF!) -> FALSE | ... P46: =ISNUMBER(#REF!) -> FALSE | Q46: =IF(E46=TRUE,"",1)
A47: =$A$4 -> 45006.365 | B47: RLE-HCL2 | C47: =IFERROR(VLOOKUP($B47,RLMLXD,8,0),"") -> 0 | E47: =ISNUMBER(C47) -> TRUE | F47: =ISNUMBER(#REF!) -> FALSE | G47: =ISNUMBER(#REF!) -> FALSE | H47: =ISNUMBER(#REF!) -> FALSE | I47: =ISNUMBER(#REF!) -> FALSE | J47: =ISNUMBER(#REF!) -> FALSE | K47: =ISNUMBER(#REF!) -> FALSE | L47: =ISNUMBER(#REF!) -> FALSE | M47: =ISNUMBER(#REF!) -> FALSE | ... P47: =ISNUMBER(#REF!) -> FALSE | Q47: =IF(E47=TRUE,"",1)
A48: =$A$4 -> 45006.365 | B48: RLE-PP1TA | C48: =IFERROR(VLOOKUP($B48,RLMLXD,8,0),"") -> 0 | E48: =ISNUMBER(C48) -> TRUE | F48: =ISNUMBER(#REF!) -> FALSE | G48: =ISNUMBER(#REF!) -> FALSE | H48: =ISNUMBER(#REF!) -> FALSE | I48: =ISNUMBER(#REF!) -> FALSE | J48: =ISNUMBER(#REF!) -> FALSE | K48: =ISNUMBER(#REF!) -> FALSE | L48: =ISNUMBER(#REF!) -> FALSE | M48: =ISNUMBER(#REF!) -> FALSE | ... P48: =ISNUMBER(#REF!) -> FALSE | Q48: =IF(E48=TRUE,"",1)
A49: =$A$4 -> 45006.365 | B49: RLE-PP1AX | C49: =IFERROR(VLOOKUP($B49,RLMLXD,8,0),"") -> 0 | E49: =ISNUMBER(C49) -> TRUE | F49: =ISNUMBER(#REF!) -> FALSE | G49: =ISNUMBER(#REF!) -> FALSE | H49: =ISNUMBER(#REF!) -> FALSE | I49: =ISNUMBER(#REF!) -> FALSE | J49: =ISNUMBER(#REF!) -> FALSE | K49: =ISNUMBER(#REF!) -> FALSE | L49: =ISNUMBER(#REF!) -> FALSE | M49: =ISNUMBER(#REF!) -> FALSE | ... P49: =ISNUMBER(#REF!) -> FALSE | Q49: =IF(E49=TRUE,"",1)
A50: =$A$4 -> 45006.365 | B50: RLE-PP1PL | C50: =IFERROR(VLOOKUP($B50,RLMLXD,8,0),"") -> 0 | E50: =ISNUMBER(C50) -> TRUE | F50: =ISNUMBER(#REF!) -> FALSE | G50: =ISNUMBER(#REF!) -> FALSE | H50: =ISNUMBER(#REF!) -> FALSE | I50: =ISNUMBER(#REF!) -> FALSE | J50: =ISNUMBER(#REF!) -> FALSE | K50: =ISNUMBER(#REF!) -> FALSE | L50: =ISNUMBER(#REF!) -> FALSE | M50: =ISNUMBER(#REF!) -> FALSE | ... P50: =ISNUMBER(#REF!) -> FALSE | Q50: =IF(E50=TRUE,"",1)
A51: =$A$4 -> 45006.365 | B51: RLE-PP2TA | C51: =IFERROR(VLOOKUP($B51,RLMLXD,8,0),"") -> 0 | E51: =ISNUMBER(C51) -> TRUE | F51: =ISNUMBER(#REF!) -> FALSE | G51: =ISNUMBER(#REF!) -> FALSE | H51: =ISNUMBER(#REF!) -> FALSE | I51: =ISNUMBER(#REF!) -> FALSE | J51: =ISNUMBER(#REF!) -> FALSE | K51: =ISNUMBER(#REF!) -> FALSE | L51: =ISNUMBER(#REF!) -> FALSE | M51: =ISNUMBER(#REF!) -> FALSE | ... P51: =ISNUMBER(#REF!) -> FALSE | Q51: =IF(E51=TRUE,"",1)
A52: =$A$4 -> 45006.365 | B52: RLE-PP2AX | C52: =IFERROR(VLOOKUP($B52,RLMLXD,8,0),"") -> 0 | E52: =ISNUMBER(C52) -> TRUE | F52: =ISNUMBER(#REF!) -> FALSE | G52: =ISNUMBER(#REF!) -> FALSE | H52: =ISNUMBER(#REF!) -> FALSE | I52: =ISNUMBER(#REF!) -> FALSE | J52: =ISNUMBER(#REF!) -> FALSE | K52: =ISNUMBER(#REF!) -> FALSE | L52: =ISNUMBER(#REF!) -> FALSE | M52: =ISNUMBER(#REF!) -> FALSE | ... P52: =ISNUMBER(#REF!) -> FALSE | Q52: =IF(E52=TRUE,"",1)
A53: =$A$4 -> 45006.365 | B53: RLE-PP2PL | C53: =IFERROR(VLOOKUP($B53,RLMLXD,8,0),"") -> 0 | E53: =ISNUMBER(C53) -> TRUE | F53: =ISNUMBER(#REF!) -> FALSE | G53: =ISNUMBER(#REF!) -> FALSE | H53: =ISNUMBER(#REF!) -> FALSE | I53: =ISNUMBER(#REF!) -> FALSE | J53: =ISNUMBER(#REF!) -> FALSE | K53: =ISNUMBER(#REF!) -> FALSE | L53: =ISNUMBER(#REF!) -> FALSE | M53: =ISNUMBER(#REF!) -> FALSE | ... P53: =ISNUMBER(#REF!) -> FALSE | Q53: =IF(E53=TRUE,"",1)
A54: =$A$4 -> 45006.365 | B54: RLE-XB | C54: =IFERROR(VLOOKUP($B54,RLMLXD,8,0),"") -> 0 | E54: =ISNUMBER(C54) -> TRUE | F54: =ISNUMBER(#REF!) -> FALSE | G54: =ISNUMBER(#REF!) -> FALSE | H54: =ISNUMBER(#REF!) -> FALSE | I54: =ISNUMBER(#REF!) -> FALSE | J54: =ISNUMBER(#REF!) -> FALSE | K54: =ISNUMBER(#REF!) -> FALSE | L54: =ISNUMBER(#REF!) -> FALSE | M54: =ISNUMBER(#REF!) -> FALSE | ... P54: =ISNUMBER(#REF!) -> FALSE | Q54: =IF(E54=TRUE,"",1)
A55: =$A$4 -> 45006.365 | B55: RLE-XBPH | C55: =IFERROR(VLOOKUP($B55,RLMLXD,8,0),"") -> 0 | E55: =ISNUMBER(C55) -> TRUE | F55: =ISNUMBER(#REF!) -> FALSE | G55: =ISNUMBER(#REF!) -> FALSE | H55: =ISNUMBER(#REF!) -> FALSE | I55: =ISNUMBER(#REF!) -> FALSE | J55: =ISNUMBER(#REF!) -> FALSE | K55: =ISNUMBER(#REF!) -> FALSE | L55: =ISNUMBER(#REF!) -> FALSE | M55: =ISNUMBER(#REF!) -> FALSE | ... P55: =ISNUMBER(#REF!) -> FALSE | Q55: =IF(E55=TRUE,"",1)
A56: =$A$4 -> 45006.365 | B56: RLG-KD | C56: =IFERROR(VLOOKUP($B56,RLMLXD,8,0),"") -> 0 | E56: =ISNUMBER(C56) -> TRUE | F56: =ISNUMBER(#REF!) -> FALSE | G56: =ISNUMBER(#REF!) -> FALSE | H56: =ISNUMBER(#REF!) -> FALSE | I56: =ISNUMBER(#REF!) -> FALSE | J56: =ISNUMBER(#REF!) -> FALSE | K56: =ISNUMBER(#REF!) -> FALSE | L56: =ISNUMBER(#REF!) -> FALSE | M56: =ISNUMBER(#REF!) -> FALSE | ... P56: =ISNUMBER(#REF!) -> FALSE | Q56: =IF(E56=TRUE,"",1)
A57: =$A$4 -> 45006.365 | B57: RLG-HCL1 | C57: =IFERROR(VLOOKUP($B57,RLMLXD,8,0),"") -> 0 | E57: =ISNUMBER(C57) -> TRUE | F57: =ISNUMBER(#REF!) -> FALSE | G57: =ISNUMBER(#REF!) -> FALSE | H57: =ISNUMBER(#REF!) -> FALSE | I57: =ISNUMBER(#REF!) -> FALSE | J57: =ISNUMBER(#REF!) -> FALSE | K57: =ISNUMBER(#REF!) -> FALSE | L57: =ISNUMBER(#REF!) -> FALSE | M57: =ISNUMBER(#REF!) -> FALSE | ... P57: =ISNUMBER(#REF!) -> FALSE | Q57: =IF(E57=TRUE,"",1)
... A96: =$A$4 -> 45006.365 | B96: DC-BLACK08 | C96: =IFERROR(VLOOKUP($B96,RLMLXD,8,0),"") -> 0 | E96: =ISNUMBER(C96) -> TRUE | F96: =ISNUMBER(#REF!) -> FALSE | G96: =ISNUMBER(#REF!) -> FALSE | H96: =ISNUMBER(#REF!) -> FALSE | I96: =ISNUMBER(#REF!) -> FALSE | J96: =ISNUMBER(#REF!) -> FALSE | K96: =ISNUMBER(#REF!) -> FALSE | L96: =ISNUMBER(#REF!) -> FALSE | M96: =ISNUMBER(#REF!) -> FALSE | ... P96: =ISNUMBER(#REF!) -> FALSE | Q96: =IF(E96=TRUE,"",1)

Sheet 2
A1: "BÁO CÁO KẾT QUẢ HÓA NGHIỆM HÀNG NGÀY 表面處理生產製程管控記錄表"
A2: NGAY | B2: Ma__Hang_muc | C2: Nong_Do_02 | E2: 1 | F2: bs | G2: 2 | H2: bs | I2: 3 | J2: bs | K2: 4 | L2: bs | M2: 5 | N2: bs | O2: 6 | P2: bs | Q2: 2
A3: Date | B3: Code | C3: 濃度 g/L-02
A4: =MENU!Y9 -> 45006.448 | B4: 1E-XB1 | C4: =IFERROR(VLOOKUP($B4,_XM_XT_THUCTE,15,0),"") -> 0 | E4: =ISNUMBER(#REF!) -> FALSE | F4: =ISNUMBER(#REF!) -> FALSE | G4: =ISNUMBER(C4) -> TRUE | H4: =ISNUMBER(#REF!) -> FALSE | I4: =ISNUMBER(#REF!) -> FALSE | J4: =ISNUMBER(#REF!) -> FALSE | K4: =ISNUMBER(#REF!) -> FALSE | L4: =ISNUMBER(#REF!) -> FALSE | M4: =ISNUMBER(#REF!) -> FALSE | N4: =ISNUMBER(#REF!) -> FALSE | O4: =ISNUMBER(#REF!) -> FALSE | P4: =ISNUMBER(#REF!) -> FALSE | Q4: =IF(G4=TRUE,"",1)
A5: =$A$4 -> 45006.448 | B5: 1E-XB2 | C5: =IFERROR(VLOOKUP($B5,_XM_XT_THUCTE,15,0),"") -> 0 | E5: =ISNUMBER(#REF!) -> FALSE | F5: =ISNUMBER(#REF!) -> FALSE | G5: =ISNUMBER(C5) -> TRUE | H5: =ISNUMBER(#REF!) -> FALSE | I5: =ISNUMBER(#REF!) -> FALSE | J5: =ISNUMBER(#REF!) -> FALSE | K5: =ISNUMBER(#REF!) -> FALSE | L5: =ISNUMBER(#REF!) -> FALSE | M5: =ISNUMBER(#REF!) -> FALSE | N5: =ISNUMBER(#REF!) -> FALSE | O5: =ISNUMBER(#REF!) -> FALSE | P5: =ISNUMBER(#REF!) -> FALSE | Q5: =IF(G5=TRUE,"",1)
A6: =$A$4 -> 45006.448 | B6: 1E-DG1 | C6: =IFERROR(VLOOKUP($B6,_XM_XT_THUCTE,15,0),"") -> 0 | E6: =ISNUMBER(#REF!) -> FALSE | F6: =ISNUMBER(#REF!) -> FALSE | G6: =ISNUMBER(C6) -> TRUE | H6: =ISNUMBER(#REF!) -> FALSE | I6: =ISNUMBER(#REF!) -> FALSE | J6: =ISNUMBER(#REF!) -> FALSE | K6: =ISNUMBER(#REF!) -> FALSE | L6: =ISNUMBER(#REF!) -> FALSE | M6: =ISNUMBER(#REF!) -> FALSE | N6: =ISNUMBER(#REF!) -> FALSE | O6: =ISNUMBER(#REF!) -> FALSE | P6: =ISNUMBER(#REF!) -> FALSE | Q6: =IF(G6=TRUE,"",1)
A7: =$A$4 -> 45006.448 | B7: 1E-DG2 | C7: =IFERROR(VLOOKUP($B7,_XM_XT_THUCTE,15,0),"") -> 0 | E7: =ISNUMBER(#REF!) -> FALSE | F7: =ISNUMBER(#REF!) -> FALSE | G7: =ISNUMBER(C7) -> TRUE | H7: =ISNUMBER(#REF!) -> FALSE | I7: =ISNUMBER(#REF!) -> FALSE | J7: =ISNUMBER(#REF!) -> FALSE | K7: =ISNUMBER(#REF!) -> FALSE | L7: =ISNUMBER(#REF!) -> FALSE | M7: =ISNUMBER(#REF!) -> FALSE | N7: =ISNUMBER(#REF!) -> FALSE | O7: =ISNUMBER(#REF!) -> FALSE | P7: =ISNUMBER(#REF!) -> FALSE | Q7: =IF(G7=TRUE,"",1)
A8: =$A$4 -> 45006.448 | B8: 1E-NAOH | C8: =IFERROR(VLOOKUP($B8,_XM_XT_THUCTE,15,0),"") -> 0 | E8: =ISNUMBER(#REF!) -> FALSE | F8: =ISNUMBER(#REF!) -> FALSE | G8: =ISNUMBER(C8) -> TRUE | H8: =ISNUMBER(#REF!) -> FALSE | I8: =ISNUMBER(#REF!) -> FALSE | J8: =ISNUMBER(#REF!) -> FALSE | K8: =ISNUMBER(#REF!) -> FALSE | L8: =ISNUMBER(#REF!) -> FALSE | M8: =ISNUMBER(#REF!) -> FALSE | N8: =ISNUMBER(#REF!) -> FALSE | O8: =ISNUMBER(#REF!) -> FALSE | P8: =ISNUMBER(#REF!) -> FALSE | Q8: =IF(G8=TRUE,"",1)
A9: =$A$4 -> 45006.448 | B9: 1E-ZN | C9: =IFERROR(VLOOKUP($B9,_XM_XT_THUCTE,15,0),"") -> 0 | E9: =ISNUMBER(#REF!) -> FALSE | F9: =ISNUMBER(#REF!) -> FALSE | G9: =ISNUMBER(C9) -> TRUE | H9: =ISNUMBER(#REF!) -> FALSE | I9: =ISNUMBER(#REF!) -> FALSE | J9: =ISNUMBER(#REF!) -> FALSE | K9: =ISNUMBER(#REF!) -> FALSE | L9: =ISNUMBER(#REF!) -> FALSE | M9: =ISNUMBER(#REF!) -> FALSE | N9: =ISNUMBER(#REF!) -> FALSE | O9: =ISNUMBER(#REF!) -> FALSE | P9: =ISNUMBER(#REF!) -> FALSE | Q9: =IF(G9=TRUE,"",1)
A10: =$A$4 -> 45006.448 | B10: 1E-CR3I | C10: =IFERROR(VLOOKUP($B10,_XM_XT_THUCTE,15,0),"") -> 0 | E10: =ISNUMBER(#REF!) -> FALSE | F10: =ISNUMBER(#REF!) -> FALSE | G10: =ISNUMBER(C10) -> TRUE | H10: =ISNUMBER(#REF!) -> FALSE | I10: =ISNUMBER(#REF!) -> FALSE | J10: =ISNUMBER(#REF!) -> FALSE | K10: =ISNUMBER(#REF!) -> FALSE | L10: =ISNUMBER(#REF!) -> FALSE | M10: =ISNUMBER(#REF!) -> FALSE | N10: =ISNUMBER(#REF!) -> FALSE | O10: =ISNUMBER(#REF!) -> FALSE | P10: =ISNUMBER(#REF!) -> FALSE | Q10: =IF(G10=TRUE,"",1)
A11: =$A$4 -> 45006.448 | B11: 1E-CR3IPH | C11: =IFERROR(VLOOKUP($B11,_XM_XT_THUCTE,15,0),"") -> 0 | E11: =ISNUMBER(#REF!) -> FALSE | F11: =ISNUMBER(#REF!) -> FALSE | G11: =ISNUMBER(C11) -> TRUE | H11: =ISNUMBER(#REF!) -> FALSE | I11: =ISNUMBER(#REF!) -> FALSE | J11: =ISNUMBER(#REF!) -> FALSE | K11: =ISNUMBER(#REF!) -> FALSE | L11: =ISNUMBER(#REF!) -> FALSE | M11: =ISNUMBER(#REF!) -> FALSE | N11: =ISNUMBER(#REF!) -> FALSE | O11: =ISNUMBER(#REF!) -> FALSE | P11: =ISNUMBER(#REF!) -> FALSE | Q11: =IF(G11=TRUE,"",1)
A12: =$A$4 -> 45006.448 | B12: 1E-HCL1 | C12: =IFERROR(VLOOKUP($B12,_XM_XT_THUCTE,15,0),"") -> 0 | E12: =ISNUMBER(#REF!) -> FALSE | F12: =ISNUMBER(#REF!) -> FALSE | G12: =ISNUMBER(C12) -> TRUE | H12: =ISNUMBER(#REF!) -> FALSE | I12: =ISNUMBER(#REF!) -> FALSE | J12: =ISNUMBER(#REF!) -> FALSE | K12: =ISNUMBER(#REF!) -> FALSE | L12: =ISNUMBER(#REF!) -> FALSE | M12: =ISNUMBER(#REF!) -> FALSE | N12: =ISNUMBER(#REF!) -> FALSE | O12: =ISNUMBER(#REF!) -> FALSE | P12: =ISNUMBER(#REF!) -> FALSE | Q12: =IF(G12=TRUE,"",1)
A13: =$A$4 -> 45006.448 | B13: 1E-HCL2 | C13: =IFERROR(VLOOKUP($B13,_XM_XT_THUCTE,15,0),"") -> 0 | E13: =ISNUMBER(#REF!) -> FALSE | F13: =ISNUMBER(#REF!) -> FALSE | G13: =ISNUMBER(C13) -> TRUE | H13: =ISNUMBER(#REF!) -> FALSE | I13: =ISNUMBER(#REF!) -> FALSE | J13: =ISNUMBER(#REF!) -> FALSE | K13: =ISNUMBER(#REF!) -> FALSE | L13: =ISNUMBER(#REF!) -> FALSE | M13: =ISNUMBER(#REF!) -> FALSE | N13: =ISNUMBER(#REF!) -> FALSE | O13: =ISNUMBER(#REF!) -> FALSE | P13: =ISNUMBER(#REF!) -> FALSE | Q13: =IF(G13=TRUE,"",1)
A14: =$A$4 -> 45006.448 | B14: 1E-HCL3 | C14: =IFERROR(VLOOKUP($B14,_XM_XT_THUCTE,15,0),"") -> 0 | E14: =ISNUMBER(#REF!) -> FALSE | F14: =ISNUMBER(#REF!) -> FALSE | G14: =ISNUMBER(C14) -> TRUE | H14: =ISNUMBER(#REF!) -> FALSE | I14: =ISNUMBER(#REF!) -> FALSE | J14: =ISNUMBER(#REF!) -> FALSE | K14: =ISNUMBER(#REF!) -> FALSE | L14: =ISNUMBER(#REF!) -> FALSE | M14: =ISNUMBER(#REF!) -> FALSE | N14: =ISNUMBER(#REF!) -> FALSE | O14: =ISNUMBER(#REF!) -> FALSE | P14: =ISNUMBER(#REF!) -> FALSE | Q14: =IF(G14=TRUE,"",1)
A15: =$A$4 -> 45006.448 | B15: 1E-HNO3 | C15: =IFERROR(VLOOKUP($B15,_XM_XT_THUCTE,15,0),"") -> 0 | E15: =ISNUMBER(#REF!) -> FALSE | F15: =ISNUMBER(#REF!) -> FALSE | G15: =ISNUMBER(C15) -> TRUE | H15: =ISNUMBER(#REF!) -> FALSE | I15: =ISNUMBER(#REF!) -> FALSE | J15: =ISNUMBER(#REF!) -> FALSE | K15: =ISNUMBER(#REF!) -> FALSE | L15: =ISNUMBER(#REF!) -> FALSE | M15: =ISNUMBER(#REF!) -> FALSE | N15: =ISNUMBER(#REF!) -> FALSE | O15: =ISNUMBER(#REF!) -> FALSE | P15: =ISNUMBER(#REF!) -> FALSE | Q15: =IF(G15=TRUE,"",1)
A16: =$A$4 -> 45006.448 | B16: 1E-MEM | C16: =IFERROR(VLOOKUP($B16,_XM_XT_THUCTE,15,0),"") -> 0 | E16: =ISNUMBER(#REF!) -> FALSE | F16: =ISNUMBER(#REF!) -> FALSE | G16: =ISNUMBER(C16) -> TRUE | H16: =ISNUMBER(#REF!) -> FALSE | I16: =ISNUMBER(#REF!) -> FALSE | J16: =ISNUMBER(#REF!) -> FALSE | K16: =ISNUMBER(#REF!) -> FALSE | L16: =ISNUMBER(#REF!) -> FALSE | M16: =ISNUMBER(#REF!) -> FALSE | N16: =ISNUMBER(#REF!) -> FALSE | O16: =ISNUMBER(#REF!) -> FALSE | P16: =ISNUMBER(#REF!) -> FALSE | Q16: =IF(G16=TRUE,"",1)
... A45: =$A$4 -> 45006.448 | B45: XT-MEM | C45: =IFERROR(VLOOKUP($B45,_XM_XT_THUCTE,15,0),"") -> 0 | E45: =ISNUMBER(#REF!) -> FALSE | F45: =ISNUMBER(#REF!) -> FALSE | G45: =ISNUMBER(C45) -> TRUE | H45: =ISNUMBER(#REF!) -> FALSE | I45: =ISNUMBER(#REF!) -> FALSE | J45: =ISNUMBER(#REF!) -> FALSE | K45: =ISNUMBER(#REF!) -> FALSE | L45: =ISNUMBER(#REF!) -> FALSE | M45: =ISNUMBER(#REF!) -> FALSE | N45: =ISNUMBER(#REF!) -> FALSE | O45: =ISNUMBER(#REF!) -> FALSE | P45: =ISNUMBER(#REF!) -> FALSE | Q45: =IF(G45=TRUE,"",1)

Sheet 3
A1: "BÁO CÁO KẾT QUẢ HÓA NGHIỆM HÀNG NGÀY 表面處理生產製程管控記錄表"
A2: NGAY | B2: Ma__Hang_muc | C2: Nong_Do_03 | E2: 1 | F2: bs | G2: 2 | H2: bs | I2: 3 | J2: bs | K2: 4 | L2: bs | M2: 5 | N2: bs | O2: 6 | P2: bs | Q2: 3
A3: Date | B3: Code | C3: 濃度 g/03
A4: =MENU!Y12 -> 45006.646 | B4: 1E-XB1 | C4: =IFERROR(VLOOKUP($B4,_XM_XT_THUCTE,21,0),"") -> 0 | E4: =ISNUMBER(#REF!) -> FALSE | F4: =ISNUMBER(#REF!) -> FALSE | G4: =ISNUMBER(#REF!) -> FALSE | H4: =ISNUMBER(#REF!) -> FALSE | I4: =ISNUMBER(C4) -> TRUE | J4: =ISNUMBER(#REF!) -> FALSE | K4: =ISNUMBER(#REF!) -> FALSE | L4: =ISNUMBER(#REF!) -> FALSE | M4: =ISNUMBER(#REF!) -> FALSE | N4: =ISNUMBER(#REF!) -> FALSE | O4: =ISNUMBER(#REF!) -> FALSE | P4: =ISNUMBER(#REF!) -> FALSE | Q4: =IF(I4=TRUE,"",1)
A5: =IF(B5="","",$A$4) -> 45006.646 | B5: 1E-XB2 | C5: =IFERROR(VLOOKUP($B5,_XM_XT_THUCTE,21,0),"") -> 0 | E5: =ISNUMBER(#REF!) -> FALSE | F5: =ISNUMBER(#REF!) -> FALSE | G5: =ISNUMBER(#REF!) -> FALSE | H5: =ISNUMBER(#REF!) -> FALSE | I5: =ISNUMBER(C5) -> TRUE | J5: =ISNUMBER(#REF!) -> FALSE | K5: =ISNUMBER(#REF!) -> FALSE | L5: =ISNUMBER(#REF!) -> FALSE | M5: =ISNUMBER(#REF!) -> FALSE | N5: =ISNUMBER(#REF!) -> FALSE | O5: =ISNUMBER(#REF!) -> FALSE | P5: =ISNUMBER(#REF!) -> FALSE | Q5: =IF(I5=TRUE,"",1)
A6: =IF(B6="","",$A$4) -> 45006.646 | B6: 1E-DG1 | C6: =IFERROR(VLOOKUP($B6,_XM_XT_THUCTE,21,0),"") -> 0 | E6: =ISNUMBER(#REF!) -> FALSE | F6: =ISNUMBER(#REF!) -> FALSE | G6: =ISNUMBER(#REF!) -> FALSE | H6: =ISNUMBER(#REF!) -> FALSE | I6: =ISNUMBER(C6) -> TRUE | J6: =ISNUMBER(#REF!) -> FALSE | K6: =ISNUMBER(#REF!) -> FALSE | L6: =ISNUMBER(#REF!) -> FALSE | M6: =ISNUMBER(#REF!) -> FALSE | N6: =ISNUMBER(#REF!) -> FALSE | O6: =ISNUMBER(#REF!) -> FALSE | P6: =ISNUMBER(#REF!) -> FALSE | Q6: =IF(I6=TRUE,"",1)
A7: =IF(B7="","",$A$4) -> 45006.646 | B7: 1E-DG2 | C7: =IFERROR(VLOOKUP($B7,_XM_XT_THUCTE,21,0),"") -> 0 | E7: =ISNUMBER(#REF!) -> FALSE | F7: =ISNUMBER(#REF!) -> FALSE | G7: =ISNUMBER(#REF!) -> FALSE | H7: =ISNUMBER(#REF!) -> FALSE | I7: =ISNUMBER(C7) -> TRUE | J7: =ISNUMBER(#REF!) -> FALSE | K7: =ISNUMBER(#REF!) -> FALSE | L7: =ISNUMBER(#REF!) -> FALSE | M7: =ISNUMBER(#REF!) -> FALSE | N7: =ISNUMBER(#REF!) -> FALSE | O7: =ISNUMBER(#REF!) -> FALSE | P7: =ISNUMBER(#REF!) -> FALSE | Q7: =IF(I7=TRUE,"",1)
A8: =IF(B8="","",$A$4) -> 45006.646 | B8: 1E-NAOH | C8: =IFERROR(VLOOKUP($B8,_XM_XT_THUCTE,21,0),"") -> 0 | E8: =ISNUMBER(#REF!) -> FALSE | F8: =ISNUMBER(#REF!) -> FALSE | G8: =ISNUMBER(#REF!) -> FALSE | H8: =ISNUMBER(#REF!) -> FALSE | I8: =ISNUMBER(C8) -> TRUE | J8: =ISNUMBER(#REF!) -> FALSE | K8: =ISNUMBER(#REF!) -> FALSE | L8: =ISNUMBER(#REF!) -> FALSE | M8: =ISNUMBER(#REF!) -> FALSE | N8: =ISNUMBER(#REF!) -> FALSE | O8: =ISNUMBER(#REF!) -> FALSE | P8: =ISNUMBER(#REF!) -> FALSE | Q8: =IF(I8=TRUE,"",1)
A9: =IF(B9="","",$A$4) -> 45006.646 | B9: 1E-ZN | C9: =IFERROR(VLOOKUP($B9,_XM_XT_THUCTE,21,0),"") -> 0 | E9: =ISNUMBER(#REF!) -> FALSE | F9: =ISNUMBER(#REF!) -> FALSE | G9: =ISNUMBER(#REF!) -> FALSE | H9: =ISNUMBER(#REF!) -> FALSE | I9: =ISNUMBER(C9) -> TRUE | J9: =ISNUMBER(#REF!) -> FALSE | K9: =ISNUMBER(#REF!) -> FALSE | L9: =ISNUMBER(#REF!) -> FALSE | M9: =ISNUMBER(#REF!) -> FALSE | N9: =ISNUMBER(#REF!) -> FALSE | O9: =ISNUMBER(#REF!) -> FALSE | P9: =ISNUMBER(#REF!) -> FALSE | Q9: =IF(I9=TRUE,"",1)
A10: =IF(B10="","",$A$4) -> 45006.646 | B10: 1E-CR3I | C10: =IFERROR(VLOOKUP($B10,_XM_XT_THUCTE,21,0),"") -> 0 | E10: =ISNUMBER(#REF!) -> FALSE | F10: =ISNUMBER(#REF!) -> FALSE | G10: =ISNUMBER(#REF!) -> FALSE | H10: =ISNUMBER(#REF!) -> FALSE | I10: =ISNUMBER(C10) -> TRUE | J10: =ISNUMBER(#REF!) -> FALSE | K10: =ISNUMBER(#REF!) -> FALSE | L10: =ISNUMBER(#REF!) -> FALSE | M10: =ISNUMBER(#REF!) -> FALSE | N10: =ISNUMBER(#REF!) -> FALSE | O10: =ISNUMBER(#REF!) -> FALSE | P10: =ISNUMBER(#REF!) -> FALSE | Q10: =IF(I10=TRUE,"",1)
A11: =IF(B11="","",$A$4) -> 45006.646 | B11: 1E-CR3IPH | C11: =IFERROR(VLOOKUP($B11,_XM_XT_THUCTE,21,0),"") -> 0 | E11: =ISNUMBER(#REF!) -> FALSE | F11: =ISNUMBER(#REF!) -> FALSE | G11: =ISNUMBER(#REF!) -> FALSE | H11: =ISNUMBER(#REF!) -> FALSE | I11: =ISNUMBER(C11) -> TRUE | J11: =ISNUMBER(#REF!) -> FALSE | K11: =ISNUMBER(#REF!) -> FALSE | L11: =ISNUMBER(#REF!) -> FALSE | M11: =ISNUMBER(#REF!) -> FALSE | N11: =ISNUMBER(#REF!) -> FALSE | O11: =ISNUMBER(#REF!) -> FALSE | P11: =ISNUMBER(#REF!) -> FALSE | Q11: =IF(I11=TRUE,"",1)
A12: =IF(B12="","",$A$4) -> 45006.646 | B12: 1E-HCL1 | C12: =IFERROR(VLOOKUP($B12,_XM_XT_THUCTE,21,0),"") -> 0 | E12: =ISNUMBER(#REF!) -> FALSE | F12: =ISNUMBER(#REF!) -> FALSE | G12: =ISNUMBER(#REF!) -> FALSE | H12: =ISNUMBER(#REF!) -> FALSE | I12: =ISNUMBER(C12) -> TRUE | J12: =ISNUMBER(#REF!) -> FALSE | K12: =ISNUMBER(#REF!) -> FALSE | L12: =ISNUMBER(#REF!) -> FALSE | M12: =ISNUMBER(#REF!) -> FALSE | N12: =ISNUMBER(#REF!) -> FALSE | O12: =ISNUMBER(#REF!) -> FALSE | P12: =ISNUMBER(#REF!) -> FALSE | Q12: =IF(I12=TRUE,"",1)
A13: =IF(B13="","",$A$4) -> 45006.646 | B13: 1E-HCL2 | C13: =IFERROR(VLOOKUP($B13,_XM_XT_THUCTE,21,0),"") -> 0 | E13: =ISNUMBER(#REF!) -> FALSE | F13: =ISNUMBER(#REF!) -> FALSE | G13: =ISNUMBER(#REF!) -> FALSE | H13: =ISNUMBER(#REF!) -> FALSE | I13: =ISNUMBER(C13) -> TRUE | J13: =ISNUMBER(#REF!) -> FALSE | K13: =ISNUMBER(#REF!) -> FALSE | L13: =ISNUMBER(#REF!) -> FALSE | M13: =ISNUMBER(#REF!) -> FALSE | N13: =ISNUMBER(#REF!) -> FALSE | O13: =ISNUMBER(#REF!) -> FALSE | P13: =ISNUMBER(#REF!) -> FALSE | Q13: =IF(I13=TRUE,"",1)
A14: =IF(B14="","",$A$4) -> 45006.646 | B14: 1E-HCL3 | C14: =IFERROR(VLOOKUP($B14,_XM_XT_THUCTE,21,0),"") -> 0 | E14: =ISNUMBER(#REF!) -> FALSE | F14: =ISNUMBER(#REF!) -> FALSE | G14: =ISNUMBER(#REF!) -> FALSE | H14: =ISNUMBER(#REF!) -> FALSE | I14: =ISNUMBER(C14) -> TRUE | J14: =ISNUMBER(#REF!) -> FALSE | K14: =ISNUMBER(#REF!) -> FALSE | L14: =ISNUMBER(#REF!) -> FALSE | M14: =ISNUMBER(#REF!) -> FALSE | N14: =ISNUMBER(#REF!) -> FALSE | O14: =ISNUMBER(#REF!) -> FALSE | P14: =ISNUMBER(#REF!) -> FALSE | Q14: =IF(I14=TRUE,"",1)
A15: =IF(B15="","",$A$4) -> 45006.646 | B15: 1E-HNO3 | C15: =IFERROR(VLOOKUP($B15,_XM_XT_THUCTE,21,0),"") -> 0 | E15: =ISNUMBER(#REF!) -> FALSE | F15: =ISNUMBER(#REF!) -> FALSE | G15: =ISNUMBER(#REF!) -> FALSE | H15: =ISNUMBER(#REF!) -> FALSE | I15: =ISNUMBER(C15) -> TRUE | J15: =ISNUMBER(#REF!) -> FALSE | K15: =ISNUMBER(#REF!) -> FALSE | L15: =ISNUMBER(#REF!) -> FALSE | M15: =ISNUMBER(#REF!) -> FALSE | N15: =ISNUMBER(#REF!) -> FALSE | O15: =ISNUMBER(#REF!) -> FALSE | P15: =ISNUMBER(#REF!) -> FALSE | Q15: =IF(I15=TRUE,"",1)
A16: =IF(B16="","",$A$4) -> 45006.646 | B16: 1E-MEM | C16: =IFERROR(VLOOKUP($B16,_XM_XT_THUCTE,21,0),"") -> 0 | E16: =ISNUMBER(#REF!) -> FALSE | F16: =ISNUMBER(#REF!) -> FALSE | G16: =ISNUMBER(#REF!) -> FALSE | H16: =ISNUMBER(#REF!) -> FALSE | I16: =ISNUMBER(C16) -> TRUE | J16: =ISNUMBER(#REF!) -> FALSE | K16: =ISNUMBER(#REF!) -> FALSE | L16: =ISNUMBER(#REF!) -> FALSE | M16: =ISNUMBER(#REF!) -> FALSE | N16: =ISNUMBER(#REF!) -> FALSE | O16: =ISNUMBER(#REF!) -> FALSE | P16: =ISNUMBER(#REF!) -> FALSE | Q16: =IF(I16=TRUE,"",1)
... A45: =IF(B45="","",$A$4) -> 45006.646 | B45: XT-MEM | C45: =IFERROR(VLOOKUP($B45,_XM_XT_THUCTE,21,0),"") -> 0 | E45: =ISNUMBER(#REF!) -> FALSE | F45: =ISNUMBER(#REF!) -> FALSE | G45: =ISNUMBER(#REF!) -> FALSE | H45: =ISNUMBER(#REF!) -> FALSE | I45: =ISNUMBER(C45) -> TRUE | J45: =ISNUMBER(#REF!) -> FALSE | K45: =ISNUMBER(#REF!) -> FALSE | L45: =ISNUMBER(#REF!) -> FALSE | M45: =ISNUMBER(#REF!) -> FALSE | N45: =ISNUMBER(#REF!) -> FALSE | O45: =ISNUMBER(#REF!) -> FALSE | P45: =ISNUMBER(#REF!) -> FALSE | Q45: =IF(I45=TRUE,"",1)
A46: =IF(B46="","",$A$4) -> 45006.646 | B46: RLE-HCL1 | C46: =IFERROR(VLOOKUP($B46,RLMLXD,14,0),"") -> 0 | E46: =ISNUMBER(#REF!) -> FALSE | F46: =ISNUMBER(#REF!) -> FALSE | G46: =ISNUMBER(#REF!) -> FALSE | H46: =ISNUMBER(#REF!) -> FALSE | I46: =ISNUMBER(C46) -> TRUE | J46: =ISNUMBER(#REF!) -> FALSE | K46: =ISNUMBER(#REF!) -> FALSE | L46: =ISNUMBER(#REF!) -> FALSE | M46: =ISNUMBER(#REF!) -> FALSE | N46: =ISNUMBER(#REF!) -> FALSE | O46: =ISNUMBER(#REF!) -> FALSE | P46: =ISNUMBER(#REF!) -> FALSE | Q46: =IF(I46=TRUE,"",1)
A47: =IF(B47="","",$A$4) -> 45006.646 | B47: RLE-HCL2 | C47: =IFERROR(VLOOKUP($B47,RLMLXD,14,0),"") -> 0 | E47: =ISNUMBER(#REF!) -> FALSE | F47: =ISNUMBER(#REF!) -> FALSE | G47: =ISNUMBER(#REF!) -> FALSE | H47: =ISNUMBER(#REF!) -> FALSE | I47: =ISNUMBER(C47) -> TRUE | J47: =ISNUMBER(#REF!) -> FALSE | K47: =ISNUMBER(#REF!) -> FALSE | L47: =ISNUMBER(#REF!) -> FALSE | M47: =ISNUMBER(#REF!) -> FALSE | N47: =ISNUMBER(#REF!) -> FALSE | O47: =ISNUMBER(#REF!) -> FALSE | P47: =ISNUMBER(#REF!) -> FALSE | Q47: =IF(I47=TRUE,"",1)
A48: =IF(B48="","",$A$4) -> 45006.646 | B48: RLE-PP1TA | C48: =IFERROR(VLOOKUP($B48,RLMLXD,14,0),"") -> 0 | E48: =ISNUMBER(#REF!) -> FALSE | F48: =ISNUMBER(#REF!) -> FALSE | G48: =ISNUMBER(#REF!) -> FALSE | H48: =ISNUMBER(#REF!) -> FALSE | I48: =ISNUMBER(C48) -> TRUE | J48: =ISNUMBER(#REF!) -> FALSE | K48: =ISNUMBER(#REF!) -> FALSE | L48: =ISNUMBER(#REF!) -> FALSE | M48: =ISNUMBER(#REF!) -> FALSE | N48: =ISNUMBER(#REF!) -> FALSE | O48: =ISNUMBER(#REF!) -> FALSE | P48: =ISNUMBER(#REF!) -> FALSE | Q48: =IF(I48=TRUE,"",1)
A49: =IF(B49="","",$A$4) -> 45006.646 | B49: RLE-PP1AX | C49: =IFERROR(VLOOKUP($B49,RLMLXD,14,0),"") -> 0 | E49: =ISNUMBER(#REF!) -> FALSE | F49: =ISNUMBER(#REF!) -> FALSE | G49: =ISNUMBER(#REF!) -> FALSE | H49: =ISNUMBER(#REF!) -> FALSE | I49: =ISNUMBER(C49) -> TRUE | J49: =ISNUMBER(#REF!) -> FALSE | K49: =ISNUMBER(#REF!) -> FALSE | L49: =ISNUMBER(#REF!) -> FALSE | M49: =ISNUMBER(#REF!) -> FALSE | N49: =ISNUMBER(#REF!) -> FALSE | O49: =ISNUMBER(#REF!) -> FALSE | P49: =ISNUMBER(#REF!) -> FALSE | Q49: =IF(I49=TRUE,"",1)
A50: =IF(B50="","",$A$4) -> 45006.646 | B50: RLE-PP1PL | C50: =IFERROR(VLOOKUP($B50,RLMLXD,14,0),"") -> 0 | E50: =ISNUMBER(#REF!) -> FALSE | F50: =ISNUMBER(#REF!) -> FALSE | G50: =ISNUMBER(#REF!) -> FALSE | H50: =ISNUMBER(#REF!) -> FALSE | I50: =ISNUMBER(C50) -> TRUE | J50: =ISNUMBER(#REF!) -> FALSE | K50: =ISNUMBER(#REF!) -> FALSE | L50: =ISNUMBER(#REF!) -> FALSE | M50: =ISNUMBER(#REF!) -> FALSE | N50: =ISNUMBER(#REF!) -> FALSE | O50: =ISNUMBER(#REF!) -> FALSE | P50: =ISNUMBER(#REF!) -> FALSE | Q50: =IF(I50=TRUE,"",1)
A51: =IF(B51="","",$A$4) -> 45006.646 | B51: RLE-PP2TA | C51: =IFERROR(VLOOKUP($B51,RLMLXD,14,0),"") -> 0 | E51: =ISNUMBER(#REF!) -> FALSE | F51: =ISNUMBER(#REF!) -> FALSE | G51: =ISNUMBER(#REF!) -> FALSE | H51: =ISNUMBER(#REF!) -> FALSE | I51: =ISNUMBER(C51) -> TRUE | J51: =ISNUMBER(#REF!) -> FALSE | K51: =ISNUMBER(#REF!) -> FALSE | L51: =ISNUMBER(#REF!) -> FALSE | M51: =ISNUMBER(#REF!) -> FALSE | N51: =ISNUMBER(#REF!) -> FALSE | O51: =ISNUMBER(#REF!) -> FALSE | P51: =ISNUMBER(#REF!) -> FALSE | Q51: =IF(I51=TRUE,"",1)
A52: =IF(B52="","",$A$4) -> 45006.646 | B52: RLE-PP2AX | C52: =IFERROR(VLOOKUP($B52,RLMLXD,14,0),"") -> 0 | E52: =ISNUMBER(#REF!) -> FALSE | F52: =ISNUMBER(#REF!) -> FALSE | G52: =ISNUMBER(#REF!) -> FALSE | H52: =ISNUMBER(#REF!) -> FALSE | I52: =ISNUMBER(C52) -> TRUE | J52: =ISNUMBER(#REF!) -> FALSE | K52: =ISNUMBER(#REF!) -> FALSE | L52: =ISNUMBER(#REF!) -> FALSE | M52: =ISNUMBER(#REF!) -> FALSE | N52: =ISNUMBER(#REF!) -> FALSE | O52: =ISNUMBER(#REF!) -> FALSE | P52: =ISNUMBER(#REF!) -> FALSE | Q52: =IF(I52=TRUE,"",1)
A53: =IF(B53="","",$A$4) -> 45006.646 | B53: RLE-PP2PL | C53: =IFERROR(VLOOKUP($B53,RLMLXD,14,0),"") -> 0 | E53: =ISNUMBER(#REF!) -> FALSE | F53: =ISNUMBER(#REF!) -> FALSE | G53: =ISNUMBER(#REF!) -> FALSE | H53: =ISNUMBER(#REF!) -> FALSE | I53: =ISNUMBER(C53) -> TRUE | J53: =ISNUMBER(#REF!) -> FALSE | K53: =ISNUMBER(#REF!) -> FALSE | L53: =ISNUMBER(#REF!) -> FALSE | M53: =ISNUMBER(#REF!) -> FALSE | N53: =ISNUMBER(#REF!) -> FALSE | O53: =ISNUMBER(#REF!) -> FALSE | P53: =ISNUMBER(#REF!) -> FALSE | Q53: =IF(I53=TRUE,"",1)
A54: =IF(B54="","",$A$4) -> 45006.646 | B54: RLE-XB | C54: =IFERROR(VLOOKUP($B54,RLMLXD,14,0),"") -> 0 | E54: =ISNUMBER(#REF!) -> FALSE | F54: =ISNUMBER(#REF!) -> FALSE | G54: =ISNUMBER(#REF!) -> FALSE | H54: =ISNUMBER(#REF!) -> FALSE | I54: =ISNUMBER(C54) -> TRUE | J54: =ISNUMBER(#REF!) -> FALSE | K54: =ISNUMBER(#REF!) -> FALSE | L54: =ISNUMBER(#REF!) -> FALSE | M54: =ISNUMBER(#REF!) -> FALSE | N54: =ISNUMBER(#REF!) -> FALSE | O54: =ISNUMBER(#REF!) -> FALSE | P54: =ISNUMBER(#REF!) -> FALSE | Q54: =IF(I54=TRUE,"",1)
A55: =IF(B55="","",$A$4) -> 45006.646 | B55: RLE-XBPH | C55: =IFERROR(VLOOKUP($B55,RLMLXD,14,0),"") -> 0 | E55: =ISNUMBER(#REF!) -> FALSE | F55: =ISNUMBER(#REF!) -> FALSE | G55: =ISNUMBER(#REF!) -> FALSE | H55: =ISNUMBER(#REF!) -> FALSE | I55: =ISNUMBER(C55) -> TRUE | J55: =ISNUMBER(#REF!) -> FALSE | K55: =ISNUMBER(#REF!) -> FALSE | L55: =ISNUMBER(#REF!) -> FALSE | M55: =ISNUMBER(#REF!) -> FALSE | N55: =ISNUMBER(#REF!) -> FALSE | O55: =ISNUMBER(#REF!) -> FALSE | P55: =ISNUMBER(#REF!) -> FALSE | Q55: =IF(I55=TRUE,"",1)
A56: =IF(B56="","",$A$4) -> 45006.646 | B56: RLG-KD | C56: =IFERROR(VLOOKUP($B56,RLMLXD,14,0),"") -> 0 | E56: =ISNUMBER(#REF!) -> FALSE | F56: =ISNUMBER(#REF!) -> FALSE | G56: =ISNUMBER(#REF!) -> FALSE | H56: =ISNUMBER(#REF!) -> FALSE | I56: =ISNUMBER(C56) -> TRUE | J56: =ISNUMBER(#REF!) -> FALSE | K56: =ISNUMBER(#REF!) -> FALSE | L56: =ISNUMBER(#REF!) -> FALSE | M56: =ISNUMBER(#REF!) -> FALSE | N56: =ISNUMBER(#REF!) -> FALSE | O56: =ISNUMBER(#REF!) -> FALSE | P56: =ISNUMBER(#REF!) -> FALSE | Q56: =IF(I56=TRUE,"",1)
A57: =IF(B57="","",$A$4) -> 45006.646 | B57: RLG-HCL1 | C57: =IFERROR(VLOOKUP($B57,RLMLXD,14,0),"") -> 0 | E57: =ISNUMBER(#REF!) -> FALSE | F57: =ISNUMBER(#REF!) -> FALSE | G57: =ISNUMBER(#REF!) -> FALSE | H57: =ISNUMBER(#REF!) -> FALSE | I57: =ISNUMBER(C57) -> TRUE | J57: =ISNUMBER(#REF!) -> FALSE | K57: =ISNUMBER(#REF!) -> FALSE | L57: =ISNUMBER(#REF!) -> FALSE | M57: =ISNUMBER(#REF!) -> FALSE | N57: =ISNUMBER(#REF!) -> FALSE | O57: =ISNUMBER(#REF!) -> FALSE | P57: =ISNUMBER(#REF!) -> FALSE | Q57: =IF(I57=TRUE,"",1)
... A69: =IF(B69="","",$A$4) -> 45006.646 | B69: RLF-XBPH | C69: =IFERROR(VLOOKUP($B69,RLMLXD,14,0),"") -> 0 | E69: =ISNUMBER(#REF!) -> FALSE | F69: =ISNUMBER(#REF!) -> FALSE | G69: =ISNUMBER(#REF!) -> FALSE | H69: =ISNUMBER(#REF!) -> FALSE | I69: =ISNUMBER(C69) -> TRUE | J69: =ISNUMBER(#REF!) -> FALSE | K69: =ISNUMBER(#REF!) -> FALSE | L69: =ISNUMBER(#REF!) -> FALSE | M69: =ISNUMBER(#REF!) -> FALSE | N69: =ISNUMBER(#REF!) -> FALSE | O69: =ISNUMBER(#REF!) -> FALSE | P69: =ISNUMBER(#REF!) -> FALSE | Q69: =IF(I69=TRUE,"",1)
A70: =IF(B70="","",$A$4) -> 45006.646 | B70: DC-XB1 | C70: =IFERROR(VLOOKUP($B70,RLMLXD,20,0),"") -> 0 | E70: =ISNUMBER(#REF!) -> FALSE | F70: =ISNUMBER(#REF!) -> FALSE | G70: =ISNUMBER(#REF!) -> FALSE | H70: =ISNUMBER(#REF!) -> FALSE | I70: =ISNUMBER(C70) -> TRUE | J70: =ISNUMBER(#REF!) -> FALSE | K70: =ISNUMBER(#REF!) -> FALSE | L70: =ISNUMBER(#REF!) -> FALSE | M70: =ISNUMBER(#REF!) -> FALSE | N70: =ISNUMBER(#REF!) -> FALSE | O70: =ISNUMBER(#REF!) -> FALSE | P70: =ISNUMBER(#REF!) -> FALSE | Q70: =IF(I70=TRUE,"",1)
A71: =IF(B71="","",$A$4) -> 45006.646 | B71: DC-XB2 | C71: =IFERROR(VLOOKUP($B71,RLMLXD,20,0),"") -> 0 | E71: =ISNUMBER(#REF!) -> FALSE | F71: =ISNUMBER(#REF!) -> FALSE | G71: =ISNUMBER(#REF!) -> FALSE | H71: =ISNUMBER(#REF!) -> FALSE | I71: =ISNUMBER(C71) -> TRUE | J71: =ISNUMBER(#REF!) -> FALSE | K71: =ISNUMBER(#REF!) -> FALSE | L71: =ISNUMBER(#REF!) -> FALSE | M71: =ISNUMBER(#REF!) -> FALSE | N71: =ISNUMBER(#REF!) -> FALSE | O71: =ISNUMBER(#REF!) -> FALSE | P71: =ISNUMBER(#REF!) -> FALSE | Q71: =IF(I71=TRUE,"",1)
A72: =IF(B72="","",$A$4) -> 45006.646 | B72: DC-HNO3 | C72: =IFERROR(VLOOKUP($B72,RLMLXD,20,0),"") -> 0 | E72: =ISNUMBER(#REF!) -> FALSE | F72: =ISNUMBER(#REF!) -> FALSE | G72: =ISNUMBER(#REF!) -> FALSE | H72: =ISNUMBER(#REF!) -> FALSE | I72: =ISNUMBER(C72) -> TRUE | J72: =ISNUMBER(#REF!) -> FALSE | K72: =ISNUMBER(#REF!) -> FALSE | L72: =ISNUMBER(#REF!) -> FALSE | M72: =ISNUMBER(#REF!) -> FALSE | N72: =ISNUMBER(#REF!) -> FALSE | O72: =ISNUMBER(#REF!) -> FALSE | P72: =ISNUMBER(#REF!) -> FALSE | Q72: =IF(I72=TRUE,"",1)
A73: =IF(B73="","",$A$4) -> 45006.646 | B73: DC1-H2SO4 | C73: =IFERROR(VLOOKUP($B73,RLMLXD,20,0),"") -> 0 | E73: =ISNUMBER(#REF!) -> FALSE | F73: =ISNUMBER(#REF!) -> FALSE | G73: =ISNUMBER(#REF!) -> FALSE | H73: =ISNUMBER(#REF!) -> FALSE | I73: =ISNUMBER(C73) -> TRUE | J73: =ISNUMBER(#REF!) -> FALSE | K73: =ISNUMBER(#REF!) -> FALSE | L73: =ISNUMBER(#REF!) -> FALSE | M73: =ISNUMBER(#REF!) -> FALSE | N73: =ISNUMBER(#REF!) -> FALSE | O73: =ISNUMBER(#REF!) -> FALSE | P73: =ISNUMBER(#REF!) -> FALSE | Q73: =IF(I73=TRUE,"",1)
A74: =IF(B74="","",$A$4) -> 45006.646 | B74: DC1-AL | C74: =IFERROR(VLOOKUP($B74,RLMLXD,20,0),"") -> 0 | E74: =ISNUMBER(#REF!) -> FALSE | F74: =ISNUMBER(#REF!) -> FALSE | G74: =ISNUMBER(#REF!) -> FALSE | H74: =ISNUMBER(#REF!) -> FALSE | I74: =ISNUMBER(C74) -> TRUE | J74: =ISNUMBER(#REF!) -> FALSE | K74: =ISNUMBER(#REF!) -> FALSE | L74: =ISNUMBER(#REF!) -> FALSE | M74: =ISNUMBER(#REF!) -> FALSE | N74: =ISNUMBER(#REF!) -> FALSE | O74: =ISNUMBER(#REF!) -> FALSE | P74: =ISNUMBER(#REF!) -> FALSE | Q74: =IF(I74=TRUE,"",1)
A75: =IF(B75="","",$A$4) -> 45006.646 | B75: DC2-H2SO4 | C75: =IFERROR(VLOOKUP($B75,RLMLXD,20,0),"") -> 0 | E75: =ISNUMBER(#REF!) -> FALSE | F75: =ISNUMBER(#REF!) -> FALSE | G75: =ISNUMBER(#REF!) -> FALSE | H75: =ISNUMBER(#REF!) -> FALSE | I75: =ISNUMBER(C75) -> TRUE | J75: =ISNUMBER(#REF!) -> FALSE | K75: =ISNUMBER(#REF!) -> FALSE | L75: =ISNUMBER(#REF!) -> FALSE | M75: =ISNUMBER(#REF!) -> FALSE | N75: =ISNUMBER(#REF!) -> FALSE | O75: =ISNUMBER(#REF!) -> FALSE | P75: =ISNUMBER(#REF!) -> FALSE | Q75: =IF(I75=TRUE,"",1)
A76: =IF(B76="","",$A$4) -> 45006.646 | B76: DC2-AL | C76: =IFERROR(VLOOKUP($B76,RLMLXD,20,0),"") -> 0 | E76: =ISNUMBER(#REF!) -> FALSE | F76: =ISNUMBER(#REF!) -> FALSE | G76: =ISNUMBER(#REF!) -> FALSE | H76: =ISNUMBER(#REF!) -> FALSE | I76: =ISNUMBER(C76) -> TRUE | J76: =ISNUMBER(#REF!) -> FALSE | K76: =ISNUMBER(#REF!) -> FALSE | L76: =ISNUMBER(#REF!) -> FALSE | M76: =ISNUMBER(#REF!) -> FALSE | N76: =ISNUMBER(#REF!) -> FALSE | O76: =ISNUMBER(#REF!) -> FALSE | P76: =ISNUMBER(#REF!) -> FALSE | Q76: =IF(I76=TRUE,"",1)
A77: =IF(B77="","",$A$4) -> 45006.646 | B77: DC3-H2SO4 | C77: =IFERROR(VLOOKUP($B77,RLMLXD,20,0),"") -> 0 | E77: =ISNUMBER(#REF!) -> FALSE | F77: =ISNUMBER(#REF!) -> FALSE | G77: =ISNUMBER(#REF!) -> FALSE | H77: =ISNUMBER(#REF!) -> FALSE | I77: =ISNUMBER(C77) -> TRUE | J77: =ISNUMBER(#REF!) -> FALSE | K77: =ISNUMBER(#REF!) -> FALSE | L77: =ISNUMBER(#REF!) -> FALSE | M77: =ISNUMBER(#REF!) -> FALSE | N77: =ISNUMBER(#REF!) -> FALSE | O77: =ISNUMBER(#REF!) -> FALSE | P77: =ISNUMBER(#REF!) -> FALSE | Q77: =IF(I77=TRUE,"",1)
A78: =IF(B78="","",$A$4) -> 45006.646 | B78: DC3-AL | C78: =IFERROR(VLOOKUP($B78,RLMLXD,20,0),"") -> 0 | E78: =ISNUMBER(#REF!) -> FALSE | F78: =ISNUMBER(#REF!) -> FALSE | G78: =ISNUMBER(#REF!) -> FALSE | H78: =ISNUMBER(#REF!) -> FALSE | I78: =ISNUMBER(C78) -> TRUE | J78: =ISNUMBER(#REF!) -> FALSE | K78: =ISNUMBER(#REF!) -> FALSE | L78: =ISNUMBER(#REF!) -> FALSE | M78: =ISNUMBER(#REF!) -> FALSE | N78: =ISNUMBER(#REF!) -> FALSE | O78: =ISNUMBER(#REF!) -> FALSE | P78: =ISNUMBER(#REF!) -> FALSE | Q78: =IF(I78=TRUE,"",1)
A79: =IF(B79="","",$A$4) -> 45006.646 | B79: DC-DL | C79: =IFERROR(VLOOKUP($B79,RLMLXD,20,0),"") -> 0 | E79: =ISNUMBER(#REF!) -> FALSE | F79: =ISNUMBER(#REF!) -> FALSE | G79: =ISNUMBER(#REF!) -> FALSE | H79: =ISNUMBER(#REF!) -> FALSE | I79: =ISNUMBER(C79) -> TRUE | J79: =ISNUMBER(#REF!) -> FALSE | K79: =ISNUMBER(#REF!) -> FALSE | L79: =ISNUMBER(#REF!) -> FALSE | M79: =ISNUMBER(#REF!) -> FALSE | N79: =ISNUMBER(#REF!) -> FALSE | O79: =ISNUMBER(#REF!) -> FALSE | P79: =ISNUMBER(#REF!) -> FALSE | Q79: =IF(I79=TRUE,"",1)
...

Sheet 4
A1: "BÁO CÁO KẾT QUẢ HÓA NGHIỆM HÀNG NGÀY 表面處理生產製程管控記錄表"
A2: NGAY | B2: Ma__Hang_muc | C2: Nong_Do_03 | E2: 1 | F2: bs | G2: 2 | H2: bs | I2: 3 | J2: bs | K2: 4 | L2: bs | M2: 5 | N2: bs | O2: 6 | P2: bs | Q2: 3
A3: Date | B3: Code | C3: 濃度 g/03
A4: =MENU!Y15 -> 45006.708 | B4: 1E-XB1 | E4: =ISNUMBER(#REF!) -> FALSE | F4: =ISNUMBER(#REF!) -> FALSE | G4: =ISNUMBER(#REF!) -> FALSE | H4: =ISNUMBER(#REF!) -> FALSE | I4: =ISNUMBER(C4) -> FALSE | J4: =ISNUMBER(#REF!) -> FALSE | K4: =ISNUMBER(#REF!) -> FALSE | L4: =ISNUMBER(#REF!) -> FALSE | M4: =ISNUMBER(#REF!) -> FALSE | N4: =ISNUMBER(#REF!) -> FALSE | O4: =ISNUMBER(#REF!) -> FALSE | P4: =ISNUMBER(#REF!) -> FALSE | Q4: =IF(I4=TRUE,"",1) -> 1
A5: =IF(B5="","",$A$4) -> 45006.708 | B5: RLE-HCL1 | C5: =IFERROR(VLOOKUP($B5,RLMLXD,20,0),"") -> 0 | E5: =ISNUMBER(#REF!) -> FALSE | F5: =ISNUMBER(#REF!) -> FALSE | G5: =ISNUMBER(#REF!) -> FALSE | H5: =ISNUMBER(#REF!) -> FALSE | I5: =ISNUMBER(C5) -> TRUE | J5: =ISNUMBER(#REF!) -> FALSE | K5: =ISNUMBER(#REF!) -> FALSE | L5: =ISNUMBER(#REF!) -> FALSE | M5: =ISNUMBER(#REF!) -> FALSE | N5: =ISNUMBER(#REF!) -> FALSE | O5: =ISNUMBER(#REF!) -> FALSE | P5: =ISNUMBER(#REF!) -> FALSE | Q5: =IF(I5=TRUE,"",1)
A6: =IF(B6="","",$A$4) -> 45006.708 | B6: RLE-HCL2 | C6: =IFERROR(VLOOKUP($B6,RLMLXD,20,0),"") -> 0 | E6: =ISNUMBER(#REF!) -> FALSE | F6: =ISNUMBER(#REF!) -> FALSE | G6: =ISNUMBER(#REF!) -> FALSE | H6: =ISNUMBER(#REF!) -> FALSE | I6: =ISNUMBER(C6) -> TRUE | J6: =ISNUMBER(#REF!) -> FALSE | K6: =ISNUMBER(#REF!) -> FALSE | L6: =ISNUMBER(#REF!) -> FALSE | M6: =ISNUMBER(#REF!) -> FALSE | N6: =ISNUMBER(#REF!) -> FALSE | O6: =ISNUMBER(#REF!) -> FALSE | P6: =ISNUMBER(#REF!) -> FALSE | Q6: =IF(I6=TRUE,"",1)
A7: =IF(B7="","",$A$4) -> 45006.708 | B7: RLE-PP1TA | C7: =IFERROR(VLOOKUP($B7,RLMLXD,20,0),"") -> 0 | E7: =ISNUMBER(#REF!) -> FALSE | F7: =ISNUMBER(#REF!) -> FALSE | G7: =ISNUMBER(#REF!) -> FALSE | H7: =ISNUMBER(#REF!) -> FALSE | I7: =ISNUMBER(C7) -> TRUE | J7: =ISNUMBER(#REF!) -> FALSE | K7: =ISNUMBER(#REF!) -> FALSE | L7: =ISNUMBER(#REF!) -> FALSE | M7: =ISNUMBER(#REF!) -> FALSE | N7: =ISNUMBER(#REF!) -> FALSE | O7: =ISNUMBER(#REF!) -> FALSE | P7: =ISNUMBER(#REF!) -> FALSE | Q7: =IF(I7=TRUE,"",1)
A8: =IF(B8="","",$A$4) -> 45006.708 | B8: RLE-PP1AX | C8: =IFERROR(VLOOKUP($B8,RLMLXD,20,0),"") -> 0 | E8: =ISNUMBER(#REF!) -> FALSE | F8: =ISNUMBER(#REF!) -> FALSE | G8: =ISNUMBER(#REF!) -> FALSE | H8: =ISNUMBER(#REF!) -> FALSE | I8: =ISNUMBER(C8) -> TRUE | J8: =ISNUMBER(#REF!) -> FALSE | K8: =ISNUMBER(#REF!) -> FALSE | L8: =ISNUMBER(#REF!) -> FALSE | M8: =ISNUMBER(#REF!) -> FALSE | N8: =ISNUMBER(#REF!) -> FALSE | O8: =ISNUMBER(#REF!) -> FALSE | P8: =ISNUMBER(#REF!) -> FALSE | Q8: =IF(I8=TRUE,"",1)
A9: =IF(B9="","",$A$4) -> 45006.708 | B9: RLE-PP1PL | C9: =IFERROR(VLOOKUP($B9,RLMLXD,20,0),"") -> 0 | E9: =ISNUMBER(#REF!) -> FALSE | F9: =ISNUMBER(#REF!) -> FALSE | G9: =ISNUMBER(#REF!) -> FALSE | H9: =ISNUMBER(#REF!) -> FALSE | I9: =ISNUMBER(C9) -> TRUE | J9: =ISNUMBER(#REF!) -> FALSE | K9: =ISNUMBER(#REF!) -> FALSE | L9: =ISNUMBER(#REF!) -> FALSE | M9: =ISNUMBER(#REF!) -> FALSE | N9: =ISNUMBER(#REF!) -> FALSE | O9: =ISNUMBER(#REF!) -> FALSE | P9: =ISNUMBER(#REF!) -> FALSE | Q9: =IF(I9=TRUE,"",1)
A10: =IF(B10="","",$A$4) -> 45006.708 | B10: RLE-PP2TA | C10: =IFERROR(VLOOKUP($B10,RLMLXD,20,0),"") -> 0 | E10: =ISNUMBER(#REF!) -> FALSE | F10: =ISNUMBER(#REF!) -> FALSE | G10: =ISNUMBER(#REF!) -> FALSE | H10: =ISNUMBER(#REF!) -> FALSE | I10: =ISNUMBER(C10) -> TRUE | J10: =ISNUMBER(#REF!) -> FALSE | K10: =ISNUMBER(#REF!) -> FALSE | L10: =ISNUMBER(#REF!) -> FALSE | M10: =ISNUMBER(#REF!) -> FALSE | N10: =ISNUMBER(#REF!) -> FALSE | O10: =ISNUMBER(#REF!) -> FALSE | P10: =ISNUMBER(#REF!) -> FALSE | Q10: =IF(I10=TRUE,"",1)
A11: =IF(B11="","",$A$4) -> 45006.708 | B11: RLE-PP2AX | C11: =IFERROR(VLOOKUP($B11,RLMLXD,20,0),"") -> 0 | E11: =ISNUMBER(#REF!) -> FALSE | F11: =ISNUMBER(#REF!) -> FALSE | G11: =ISNUMBER(#REF!) -> FALSE | H11: =ISNUMBER(#REF!) -> FALSE | I11: =ISNUMBER(C11) -> TRUE | J11: =ISNUMBER(#REF!) -> FALSE | K11: =ISNUMBER(#REF!) -> FALSE | L11: =ISNUMBER(#REF!) -> FALSE | M11: =ISNUMBER(#REF!) -> FALSE | N11: =ISNUMBER(#REF!) -> FALSE | O11: =ISNUMBER(#REF!) -> FALSE | P11: =ISNUMBER(#REF!) -> FALSE | Q11: =IF(I11=TRUE,"",1)
A12: =IF(B12="","",$A$4) -> 45006.708 | B12: RLE-PP2PL | C12: =IFERROR(VLOOKUP($B12,RLMLXD,20,0),"") -> 0 | E12: =ISNUMBER(#REF!) -> FALSE | F12: =ISNUMBER(#REF!) -> FALSE | G12: =ISNUMBER(#REF!) -> FALSE | H12: =ISNUMBER(#REF!) -> FALSE | I12: =ISNUMBER(C12) -> TRUE | J12: =ISNUMBER(#REF!) -> FALSE | K12: =ISNUMBER(#REF!) -> FALSE | L12: =ISNUMBER(#REF!) -> FALSE | M12: =ISNUMBER(#REF!) -> FALSE | N12: =ISNUMBER(#REF!) -> FALSE | O12: =ISNUMBER(#REF!) -> FALSE | P12: =ISNUMBER(#REF!) -> FALSE | Q12: =IF(I12=TRUE,"",1)
A13: =IF(B13="","",$A$4) -> 45006.708 | B13: RLE-XB | C13: =IFERROR(VLOOKUP($B13,RLMLXD,20,0),"") -> 0 | E13: =ISNUMBER(#REF!) -> FALSE | F13: =ISNUMBER(#REF!) -> FALSE | G13: =ISNUMBER(#REF!) -> FALSE | H13: =ISNUMBER(#REF!) -> FALSE | I13: =ISNUMBER(C13) -> TRUE | J13: =ISNUMBER(#REF!) -> FALSE | K13: =ISNUMBER(#REF!) -> FALSE | L13: =ISNUMBER(#REF!) -> FALSE | M13: =ISNUMBER(#REF!) -> FALSE | N13: =ISNUMBER(#REF!) -> FALSE | O13: =ISNUMBER(#REF!) -> FALSE | P13: =ISNUMBER(#REF!) -> FALSE | Q13: =IF(I13=TRUE,"",1)
A14: =IF(B14="","",$A$4) -> 45006.708 | B14: RLE-XBPH | C14: =IFERROR(VLOOKUP($B14,RLMLXD,20,0),"") -> 0 | E14: =ISNUMBER(#REF!) -> FALSE | F14: =ISNUMBER(#REF!) -> FALSE | G14: =ISNUMBER(#REF!) -> FALSE | H14: =ISNUMBER(#REF!) -> FALSE | I14: =ISNUMBER(C14) -> TRUE | J14: =ISNUMBER(#REF!) -> FALSE | K14: =ISNUMBER(#REF!) -> FALSE | L14: =ISNUMBER(#REF!) -> FALSE | M14: =ISNUMBER(#REF!) -> FALSE | N14: =ISNUMBER(#REF!) -> FALSE | O14: =ISNUMBER(#REF!) -> FALSE | P14: =ISNUMBER(#REF!) -> FALSE | Q14: =IF(I14=TRUE,"",1)
A15: =IF(B15="","",$A$4) -> 45006.708 | B15: RLG-KD | C15: =IFERROR(VLOOKUP($B15,RLMLXD,20,0),"") -> 0 | E15: =ISNUMBER(#REF!) -> FALSE | F15: =ISNUMBER(#REF!) -> FALSE | G15: =ISNUMBER(#REF!) -> FALSE | H15: =ISNUMBER(#REF!) -> FALSE | I15: =ISNUMBER(C15) -> TRUE | J15: =ISNUMBER(#REF!) -> FALSE | K15: =ISNUMBER(#REF!) -> FALSE | L15: =ISNUMBER(#REF!) -> FALSE | M15: =ISNUMBER(#REF!) -> FALSE | N15: =ISNUMBER(#REF!) -> FALSE | O15: =ISNUMBER(#REF!) -> FALSE | P15: =ISNUMBER(#REF!) -> FALSE | Q15: =IF(I15=TRUE,"",1)
A16: =IF(B16="","",$A$4) -> 45006.708 | B16: RLG-HCL1 | C16: =IFERROR(VLOOKUP($B16,RLMLXD,20,0),"") -> 0 | E16: =ISNUMBER(#REF!) -> FALSE | F16: =ISNUMBER(#REF!) -> FALSE | G16: =ISNUMBER(#REF!) -> FALSE | H16: =ISNUMBER(#REF!) -> FALSE | I16: =ISNUMBER(C16) -> TRUE | J16: =ISNUMBER(#REF!) -> FALSE | K16: =ISNUMBER(#REF!) -> FALSE | L16: =ISNUMBER(#REF!) -> FALSE | M16: =ISNUMBER(#REF!) -> FALSE | N16: =ISNUMBER(#REF!) -> FALSE | O16: =ISNUMBER(#REF!) -> FALSE | P16: =ISNUMBER(#REF!) -> FALSE | Q16: =IF(I16=TRUE,"",1)
... A33: =IF(B33="","",$A$4) -> 45006.708 | B33: XD-8 | C33: =IFERROR(VLOOKUP($B33,RLMLXD,20,0),"") | E33: =ISNUMBER(#REF!) -> FALSE | F33: =ISNUMBER(#REF!) -> FALSE | G33: =ISNUMBER(#REF!) -> FALSE | H33: =ISNUMBER(#REF!) -> FALSE | I33: =ISNUMBER(C33) -> FALSE | J33: =ISNUMBER(#REF!) -> FALSE | K33: =ISNUMBER(#REF!) -> FALSE | L33: =ISNUMBER(#REF!) -> FALSE | M33: =ISNUMBER(#REF!) -> FALSE | N33: =ISNUMBER(#REF!) -> FALSE | O33: =ISNUMBER(#REF!) -> FALSE | P33: =ISNUMBER(#REF!) -> FALSE | Q33: =IF(I33=TRUE,"",1) -> 1

Sheet 5
A1: "BÁO CÁO KẾT QUẢ HÓA NGHIỆM HÀNG NGÀY 表面處理生產製程管控記錄表"
A2: NGAY | B2: Ma__Hang_muc | C2: Nong_Do_04 | E2: 1 | F2: bs | G2: 2 | H2: bs | I2: 3 | J2: bs | K2: 4 | L2: bs | M2: 5 | N2: bs | O2: 6 | P2: bs | Q2: 4
A3: Date | B3: Code | C3: 濃度 g/L_04
A4: =MENU!Y18 -> 45006.865 | B4: 1E-XB1 | C4: =IFERROR(VLOOKUP($B4,_XM_XT_THUCTE,27,0),"") -> 0 | E4: =ISNUMBER(#REF!) -> FALSE | F4: =ISNUMBER(#REF!) -> FALSE | G4: =ISNUMBER(#REF!) -> FALSE | H4: =ISNUMBER(#REF!) -> FALSE | I4: =ISNUMBER(#REF!) -> FALSE | J4: =ISNUMBER(#REF!) -> FALSE | K4: =ISNUMBER(C4) -> TRUE | L4: =ISNUMBER(#REF!) -> FALSE | M4: =ISNUMBER(#REF!) -> FALSE | N4: =ISNUMBER(#REF!) -> FALSE | O4: =ISNUMBER(#REF!) -> FALSE | P4: =ISNUMBER(#REF!) -> FALSE | Q4: =IF(K4=TRUE,"",1)
A5: =$A$4 -> 45006.865 | B5: 1E-XB2 | C5: =IFERROR(VLOOKUP($B5,_XM_XT_THUCTE,27,0),"") -> 0 | E5: =ISNUMBER(#REF!) -> FALSE | F5: =ISNUMBER(#REF!) -> FALSE | G5: =ISNUMBER(#REF!) -> FALSE | H5: =ISNUMBER(#REF!) -> FALSE | I5: =ISNUMBER(#REF!) -> FALSE | J5: =ISNUMBER(#REF!) -> FALSE | K5: =ISNUMBER(C5) -> TRUE | L5: =ISNUMBER(#REF!) -> FALSE | M5: =ISNUMBER(#REF!) -> FALSE | N5: =ISNUMBER(#REF!) -> FALSE | O5: =ISNUMBER(#REF!) -> FALSE | P5: =ISNUMBER(#REF!) -> FALSE | Q5: =IF(K5=TRUE,"",1)
A6: =$A$4 -> 45006.865 | B6: 1E-DG1 | C6: =IFERROR(VLOOKUP($B6,_XM_XT_THUCTE,27,0),"") -> 0 | E6: =ISNUMBER(#REF!) -> FALSE | F6: =ISNUMBER(#REF!) -> FALSE | G6: =ISNUMBER(#REF!) -> FALSE | H6: =ISNUMBER(#REF!) -> FALSE | I6: =ISNUMBER(#REF!) -> FALSE | J6: =ISNUMBER(#REF!) -> FALSE | K6: =ISNUMBER(C6) -> TRUE | L6: =ISNUMBER(#REF!) -> FALSE | M6: =ISNUMBER(#REF!) -> FALSE | N6: =ISNUMBER(#REF!) -> FALSE | O6: =ISNUMBER(#REF!) -> FALSE | P6: =ISNUMBER(#REF!) -> FALSE | Q6: =IF(K6=TRUE,"",1)
A7: =$A$4 -> 45006.865 | B7: 1E-DG2 | C7: =IFERROR(VLOOKUP($B7,_XM_XT_THUCTE,27,0),"") -> 0 | E7: =ISNUMBER(#REF!) -> FALSE | F7: =ISNUMBER(#REF!) -> FALSE | G7: =ISNUMBER(#REF!) -> FALSE | H7: =ISNUMBER(#REF!) -> FALSE | I7: =ISNUMBER(#REF!) -> FALSE | J7: =ISNUMBER(#REF!) -> FALSE | K7: =ISNUMBER(C7) -> TRUE | L7: =ISNUMBER(#REF!) -> FALSE | M7: =ISNUMBER(#REF!) -> FALSE | N7: =ISNUMBER(#REF!) -> FALSE | O7: =ISNUMBER(#REF!) -> FALSE | P7: =ISNUMBER(#REF!) -> FALSE | Q7: =IF(K7=TRUE,"",1)
A8: =$A$4 -> 45006.865 | B8: 1E-NAOH | C8: =IFERROR(VLOOKUP($B8,_XM_XT_THUCTE,27,0),"") -> 0 | E8: =ISNUMBER(#REF!) -> FALSE | F8: =ISNUMBER(#REF!) -> FALSE | G8: =ISNUMBER(#REF!) -> FALSE | H8: =ISNUMBER(#REF!) -> FALSE | I8: =ISNUMBER(#REF!) -> FALSE | J8: =ISNUMBER(#REF!) -> FALSE | K8: =ISNUMBER(C8) -> TRUE | L8: =ISNUMBER(#REF!) -> FALSE | M8: =ISNUMBER(#REF!) -> FALSE | N8: =ISNUMBER(#REF!) -> FALSE | O8: =ISNUMBER(#REF!) -> FALSE | P8: =ISNUMBER(#REF!) -> FALSE | Q8: =IF(K8=TRUE,"",1)
A9: =$A$4 -> 45006.865 | B9: 1E-ZN | C9: =IFERROR(VLOOKUP($B9,_XM_XT_THUCTE,27,0),"") -> 0 | E9: =ISNUMBER(#REF!) -> FALSE | F9: =ISNUMBER(#REF!) -> FALSE | G9: =ISNUMBER(#REF!) -> FALSE | H9: =ISNUMBER(#REF!) -> FALSE | I9: =ISNUMBER(#REF!) -> FALSE | J9: =ISNUMBER(#REF!) -> FALSE | K9: =ISNUMBER(C9) -> TRUE | L9: =ISNUMBER(#REF!) -> FALSE | M9: =ISNUMBER(#REF!) -> FALSE | N9: =ISNUMBER(#REF!) -> FALSE | O9: =ISNUMBER(#REF!) -> FALSE | P9: =ISNUMBER(#REF!) -> FALSE | Q9: =IF(K9=TRUE,"",1)
A10: =$A$4 -> 45006.865 | B10: 1E-CR3I | C10: =IFERROR(VLOOKUP($B10,_XM_XT_THUCTE,27,0),"") -> 0 | E10: =ISNUMBER(#REF!) -> FALSE | F10: =ISNUMBER(#REF!) -> FALSE | G10: =ISNUMBER(#REF!) -> FALSE | H10: =ISNUMBER(#REF!) -> FALSE | I10: =ISNUMBER(#REF!) -> FALSE | J10: =ISNUMBER(#REF!) -> FALSE | K10: =ISNUMBER(C10) -> TRUE | L10: =ISNUMBER(#REF!) -> FALSE | M10: =ISNUMBER(#REF!) -> FALSE | N10: =ISNUMBER(#REF!) -> FALSE | O10: =ISNUMBER(#REF!) -> FALSE | P10: =ISNUMBER(#REF!) -> FALSE | Q10: =IF(K10=TRUE,"",1)
A11: =$A$4 -> 45006.865 | B11: 1E-CR3IPH | C11: =IFERROR(VLOOKUP($B11,_XM_XT_THUCTE,27,0),"") -> 0 | E11: =ISNUMBER(#REF!) -> FALSE | F11: =ISNUMBER(#REF!) -> FALSE | G11: =ISNUMBER(#REF!) -> FALSE | H11: =ISNUMBER(#REF!) -> FALSE | I11: =ISNUMBER(#REF!) -> FALSE | J11: =ISNUMBER(#REF!) -> FALSE | K11: =ISNUMBER(C11) -> TRUE | L11: =ISNUMBER(#REF!) -> FALSE | M11: =ISNUMBER(#REF!) -> FALSE | N11: =ISNUMBER(#REF!) -> FALSE | O11: =ISNUMBER(#REF!) -> FALSE | P11: =ISNUMBER(#REF!) -> FALSE | Q11: =IF(K11=TRUE,"",1)
A12: =$A$4 -> 45006.865 | B12: 1E-HCL1 | C12: =IFERROR(VLOOKUP($B12,_XM_XT_THUCTE,27,0),"") -> 0 | E12: =ISNUMBER(#REF!) -> FALSE | F12: =ISNUMBER(#REF!) -> FALSE | G12: =ISNUMBER(#REF!) -> FALSE | H12: =ISNUMBER(#REF!) -> FALSE | I12: =ISNUMBER(#REF!) -> FALSE | J12: =ISNUMBER(#REF!) -> FALSE | K12: =ISNUMBER(C12) -> TRUE | L12: =ISNUMBER(#REF!) -> FALSE | M12: =ISNUMBER(#REF!) -> FALSE | N12: =ISNUMBER(#REF!) -> FALSE | O12: =ISNUMBER(#REF!) -> FALSE | P12: =ISNUMBER(#REF!) -> FALSE | Q12: =IF(K12=TRUE,"",1)
A13: =$A$4 -> 45006.865 | B13: 1E-HCL2 | C13: =IFERROR(VLOOKUP($B13,_XM_XT_THUCTE,27,0),"") -> 0 | E13: =ISNUMBER(#REF!) -> FALSE | F13: =ISNUMBER(#REF!) -> FALSE | G13: =ISNUMBER(#REF!) -> FALSE | H13: =ISNUMBER(#REF!) -> FALSE | I13: =ISNUMBER(#REF!) -> FALSE | J13: =ISNUMBER(#REF!) -> FALSE | K13: =ISNUMBER(C13) -> TRUE | L13: =ISNUMBER(#REF!) -> FALSE | M13: =ISNUMBER(#REF!) -> FALSE | N13: =ISNUMBER(#REF!) -> FALSE | O13: =ISNUMBER(#REF!) -> FALSE | P13: =ISNUMBER(#REF!) -> FALSE | Q13: =IF(K13=TRUE,"",1)
