Workbook
Name _NEW2: [1]吊電B線入出料標準數據!$B$4:$P$4003
Name _XM_XT_THUCTE: '[2]XM.GUI MAIL'!$A$6:$AQ$108
Name _XM_XT_THUCTE: 'XM.GUI MAIL'!$A$6:$AW$120
Name AB: #REF!
Name AB: #REF!
Name AB: #REF!
Name AB: #REF!
Name AB: #REF!
Name AB: #REF!
Name AB: #REF!
Name AB: #REF!
Name AB: #REF!
Name abcd: #REF!
Name abcd: #REF!
Name abcd: #REF!
Name abcd: #REF!
Name abcd: #REF!
Name abcd: #REF!
Name abcd: #REF!
Name abcd: #REF!
Name abcd: #REF!
Name abcd: #REF!
Name CCC: #REF!
Name CCC: #REF!
Name CCC: #REF!
Name CCC: #REF!
Name CCC: #REF!
Name CCC: #REF!
Name CCC: #REF!
Name CCC: #REF!
Name CCC: #REF!
Name CXXTA: #REF!
Name CXXTA: #REF!
Name CXXTA: #REF!
Name CXXTA: #REF!
Name CXXTA: #REF!
Name CXXTA: #REF!
Name CXXTA: #REF!
Name CXXTA: #REF!
Name CXXTA: #REF!
Name CXXTB: [1]吊電B線入出料標準數據!$B$3:$P$428
Name HUANGHAIDONGA: #REF!
Name HUANGHAIDONGA: #REF!
Name HUANGHAIDONGA: #REF!
Name HUANGHAIDONGA: #REF!
Name HUANGHAIDONGA: #REF!
Name HUANGHAIDONGA: #REF!
Name HUANGHAIDONGA: #REF!
Name HUANGHAIDONGA: #REF!
Name HUANGHAIDONGA: #REF!
Name HUANGHAIDONGB: [1]吊電B線入出料標準數據!$A$3:$P$428
Name PartNo: [3]All!$B$5:$Q$65536
Name RLMLXD: '[2]R.GUI MAIL'!$A$6:$AQ$114
Name RLMLXD: 'R.GUI MAIL'!$A$6:$AQ$114
Name sss: '[4]附表-01'!$A$2:$L$1662
Name WUJIWEI: #REF!
Name WUJIWEI: #REF!
Name WUJIWEI: #REF!
Name WUJIWEI: #REF!
Name WUJIWEI: #REF!

Sheet PT TAP CHAT
B1: MẪU GỬI NHÀ CUNG ỨNG
B2: =MENU!AD9 -> 2024/01/09 | G2: 0.29166667 | H2: 0.45833333 | I2: 0.54166667
A3: NCC | B3: Type sample | C3: Test Item | D3: Standards | F3: Unit | G3: Result
A4: JASCO | B4: Akaline Zinc (XL-1E) | C4: Zn2+ | D4: ='XM.GUI MAIL'!E17 -> 8~12 | E4: ='XM.GUI MAIL'!F17 -> (10±2) | F4: g/l | G4: ='XM.GUI MAIL'!I17 -> 0 | H4: ='XM.GUI MAIL'!P17 -> 0 | I4: ='XM.GUI MAIL'!W17 -> 0
A5: JASCO | C5: NaOH | D5: ='XM.GUI MAIL'!E16 -> 130 - 150 | E5: ='XM.GUI MAIL'!F18 -> (14±2) | F5: g/l | G5: ='XM.GUI MAIL'!I16 -> 0 | H5: ='XM.GUI MAIL'!P16 -> 0 | I5: ='XM.GUI MAIL'!W16 -> 0
A6: JASCO | C6: Na2CO3 | D6: ＜70g/L | E6: ='XM.GUI MAIL'!F19 -> (2±0.2 ) | F6: g/l
A7: JASCO | C7: Fe | D7: <5 | F7: ppm
A8: JASCO | C8: Cu | D8: <5 | F8: ppm
A9: JASCO | C9: Cr | D9: <5 | F9: ppm
A10: JASCO | C10: Pb | D10: <5 | F10: ppm
A11: JASCO | B11: Màu (I) (TR173AH) (XL-1E) | C11: Cr2O3 (TR173AH) | D11: ='XM.GUI MAIL'!E18 -> 12~18 | E11: ='XM.GUI MAIL'!F24 -> (7.5±1) | F11: % | G11: ='XM.GUI MAIL'!I18 -> 0 | H11: ='XM.GUI MAIL'!P18 -> 0 | I11: ='XM.GUI MAIL'!W18 -> 0
A12: JASCO | C12: pH | D12: ='XM.GUI MAIL'!E19 -> 1.6~2.2 | E12: ='XM.GUI MAIL'!F25 -> (2±0.1) | F12: / | G12: ='XM.GUI MAIL'!I19 -> 0 | H12: ='XM.GUI MAIL'!P19 -> 0 | I12: ='XM.GUI MAIL'!W19 -> 0
A13: JASCO | C13: Fe | D13: <80 | F13: ppm
A14: JASCO | C14: Cu | D14: ＜5 | F14: ppm
A15: JASCO | C15: Zn | D15: ＜7000 | F15: ppm
A16: JASCO | B16: Màu K (5U109A) (XL-1E) | C16: Màu K (5U109A) | D16: ='XM.GUI MAIL'!E24 -> 5~10 | E16: ='XM.GUI MAIL'!F29 -> (60±5) | F16: % | G16: ='XM.GUI MAIL'!I24 | H16: ='XM.GUI MAIL'!I24 | I16: ='XM.GUI MAIL'!W24
A17: JASCO | C17: pH | D17: ='XM.GUI MAIL'!E25 -> 1.8~2.2 | E17: ='XM.GUI MAIL'!F30 -> (50±5) | F17: / | G17: ='XM.GUI MAIL'!I25 -> 0 | H17: ='XM.GUI MAIL'!I25 -> 0 | I17: ='XM.GUI MAIL'!W25 -> 0
A18: JASCO | C18: Fe | D18: <40 | F18: ppm
A19: JASCO | C19: Cu | D19: ＜5 | F19: ppm
A20: JASCO | C20: Zn | D20: ＜6000 | F20: ppm
B22: Type sample | C22: Test Item | D22: Standards | F22: Unit | G22: Result
A23: HALO | B23: Akaline Zinc (XL-1F) | C23: Zn2+ | D23: ='XM.GUI MAIL'!E52 -> 8~12 | E23: ='XM.GUI MAIL'!F52 -> (10±2) | F23: g/l | G23: ='XM.GUI MAIL'!I52 -> 11.57 | H23: ='XM.GUI MAIL'!P52 -> 11.18 | I23: ='XM.GUI MAIL'!W52 -> 11.18
A24: HALO | C24: NaOH | D24: ='XM.GUI MAIL'!E51 -> 130 - 150 | E24: ='XM.GUI MAIL'!F51 -> (140±7) | F24: g/l | G24: ='XM.GUI MAIL'!I51 -> 144.4 | H24: ='XM.GUI MAIL'!P51 -> 145.6 | I24: ='XM.GUI MAIL'!W51 -> 145.6
A25: HALO | C25: Na2CO3 | D25: ＜70 | F25: g/l
A26: HALO | C26: Fe | D26: <5 | F26: ppm
A27: HALO | C27: Cu | D27: <5 | F27: ppm
A28: HALO | C28: Cr | D28: <5 | F28: ppm
A29: HALO | C29: Pb | D29: <5 | F29: ppm
A30: HALO | B30: Màu (I) (Lanthane 318) (XL-1F) | C30: Lanthane 318 | D30: ='XM.GUI MAIL'!E53 -> 6~10 | E30: ='XM.GUI MAIL'!F53 -> (7±1) | F30: % | G30: ='XM.GUI MAIL'!I53 -> 6.96183 | H30: ='XM.GUI MAIL'!P53 -> 7.0042 | I30: ='XM.GUI MAIL'!W53 -> 6.66524
A31: HALO | C31: pH | D31: ='XM.GUI MAIL'!E54 -> 2~2.5 | E31: ='XM.GUI MAIL'!F54 -> (2.3±0.1 ) | F31: / | G31: ='XM.GUI MAIL'!I54 -> 2.5 | H31: ='XM.GUI MAIL'!P54 -> 2.3 | I31: ='XM.GUI MAIL'!W54 -> 2.3
A32: HALO | C32: Fe | D32: <100 | F32: ppm
A33: HALO | C33: Cu | F33: ppm
A34: HALO | C34: Zn | D34: ＜12000 | F34: ppm
A35: HALO | B35: Màu (K) (Finidip 124) (XL-1F) | C35: Finidip 124 | D35: ='XM.GUI MAIL'!E59 -> 5~8 | E35: ='XM.GUI MAIL'!F59 -> (6±0.5) | F35: % | G35: ='XM.GUI MAIL'!I59 -> 6.12 | H35: ='XM.GUI MAIL'!I59 -> 6.12 | I35: ='XM.GUI MAIL'!W59 -> KO SX
A36: HALO | C36: pH | D36: ='XM.GUI MAIL'!E60 -> 1.8~2.4 | E36: ='XM.GUI MAIL'!F60 -> (2.1±0.1 ) | F36: / | G36: ='XM.GUI MAIL'!I60 -> 2.2 | H36: ='XM.GUI MAIL'!I60 -> 2.2 | I36: ='XM.GUI MAIL'!W60 -> KO SX
A37: HALO | C37: Fe | D37: 150 | F37: ppm
A38: HALO | C38: Cu | F38: ppm
A39: HALO | C39: Zn | D39: ＜15000 | F39: ppm
B41: Type sample | C41: Test Item | D41: Standards | F41: Unit | G41: Result
A42: HALO | B42: Akaline Zinc (XT-0C) | C42: Zn2+ | D42: ='XM.GUI MAIL'!E87 -> 7~10 | E42: ='XM.GUI MAIL'!F87 -> (8.5±1) | F42: g/l | G42: ='XM.GUI MAIL'!I87 -> 8.58 | H42: ='XM.GUI MAIL'!P87 -> 8.32 | I42: ='XM.GUI MAIL'!W87 -> 8.385
...

Sheet 1
A1: "BÁO CÁO KẾT QUẢ HÓA NGHIỆM HÀNG NGÀY 表面處理生產製程管控記錄表"
A2: NGAY | B2: Ma__Hang_muc | C2: Nong_Do_01 | E2: 1 | F2: bs | G2: 2 | H2: bs | I2: 3 | J2: bs | K2: 4 | L2: bs | M2: 5 | N2: bs | O2: 6 | P2: bs | Q2: 1
A3: Date | B3: Code | C3: 濃度 g/L-01
A4: 1/9/2024 9:45:00 AM | B4: 1F-XB1 | C4: 70.092 | E4: TRUE | F4: FALSE | G4: FALSE | H4: FALSE | I4: FALSE | J4: FALSE | K4: FALSE | L4: FALSE | M4: FALSE | N4: FALSE | O4: FALSE | P4: FALSE
A5: 1/9/2024 9:45:00 AM | B5: 1F-XB2 | C5: 74.3105 | E5: TRUE | F5: FALSE | G5: FALSE | H5: FALSE | I5: FALSE | J5: FALSE | K5: FALSE | L5: FALSE | M5: FALSE | N5: FALSE | O5: FALSE | P5: FALSE
A6: 1/9/2024 9:45:00 AM | B6: 1F-DG1 | C6: 56.595 | E6: TRUE | F6: FALSE | G6: FALSE | H6: FALSE | I6: FALSE | J6: FALSE | K6: FALSE | L6: FALSE | M6: FALSE | N6: FALSE | O6: FALSE | P6: FALSE
A7: 1/9/2024 9:45:00 AM | B7: 1F-DG2 | C7: 56.826 | E7: TRUE | F7: FALSE | G7: FALSE | H7: FALSE | I7: FALSE | J7: FALSE | K7: FALSE | L7: FALSE | M7: FALSE | N7: FALSE | O7: FALSE | P7: FALSE
A8: 1/9/2024 9:45:00 AM | B8: 1F-NAOH | C8: 144.4 | E8: TRUE | F8: FALSE | G8: FALSE | H8: FALSE | I8: FALSE | J8: FALSE | K8: FALSE | L8: FALSE | M8: FALSE | N8: FALSE | O8: FALSE | P8: FALSE
A9: 1/9/2024 9:45:00 AM | B9: 1F-ZN | C9: 11.57 | E9: TRUE | F9: FALSE | G9: FALSE | H9: FALSE | I9: FALSE | J9: FALSE | K9: FALSE | L9: FALSE | M9: FALSE | N9: FALSE | O9: FALSE | P9: FALSE
A10: 1/9/2024 9:45:00 AM | B10: 1F-CR3I | C10: 6.96183 | E10: TRUE | F10: FALSE | G10: FALSE | H10: FALSE | I10: FALSE | J10: FALSE | K10: FALSE | L10: FALSE | M10: FALSE | N10: FALSE | O10: FALSE | P10: FALSE
A11: 1/9/2024 9:45:00 AM | B11: 1F-CR3IPH | C11: 2.5 | E11: TRUE | F11: FALSE | G11: FALSE | H11: FALSE | I11: FALSE | J11: FALSE | K11: FALSE | L11: FALSE | M11: FALSE | N11: FALSE | O11: FALSE | P11: FALSE
A12: 1/9/2024 9:45:00 AM | B12: 1F-HCL1 | C12: 0.4334375 | E12: TRUE | F12: FALSE | G12: FALSE | H12: FALSE | I12: FALSE | J12: FALSE | K12: FALSE | L12: FALSE | M12: FALSE | N12: FALSE | O12: FALSE | P12: FALSE
A13: 1/9/2024 9:45:00 AM | B13: 1F-HNO3 | C13: 0.011844 | E13: TRUE | F13: FALSE | G13: FALSE | H13: FALSE | I13: FALSE | J13: FALSE | K13: FALSE | L13: FALSE | M13: FALSE | N13: FALSE | O13: FALSE | P13: FALSE
A14: 1/9/2024 9:45:00 AM | B14: 1F-MEM | C14: 120 | E14: TRUE | F14: FALSE | G14: FALSE | H14: FALSE | I14: FALSE | J14: FALSE | K14: FALSE | L14: FALSE | M14: FALSE | N14: FALSE | O14: FALSE | P14: FALSE
A15: 1/9/2024 9:45:00 AM | B15: 1F-BONG | C15: 38 | E15: TRUE | F15: FALSE | G15: FALSE | H15: FALSE | I15: FALSE | J15: FALSE | K15: FALSE | L15: FALSE | M15: FALSE | N15: FALSE | O15: FALSE | P15: FALSE
... A55: 1/9/2024 9:45:00 AM | B55: DC-BLACK08 | C55: 5.6 | E55: TRUE | F55: FALSE | G55: FALSE | H55: FALSE | I55: FALSE | J55: FALSE | K55: FALSE | L55: FALSE | M55: FALSE | N55: FALSE | O55: FALSE | P55: FALSE

Sheet 2
A1: "BÁO CÁO KẾT QUẢ HÓA NGHIỆM HÀNG NGÀY 表面處理生產製程管控記錄表"
A2: NGAY | B2: Ma__Hang_muc | C2: Nong_Do_02 | E2: 1 | F2: bs | G2: 2 | H2: bs | I2: 3 | J2: bs | K2: 4 | L2: bs | M2: 5 | N2: bs | O2: 6 | P2: bs | Q2: 2
A3: Date | B3: Code | C3: 濃度 g/L-02
A4: 1/9/2024 11:45:00 AM | B4: 1F-XB1 | C4: 70.741 | E4: FALSE | F4: FALSE | G4: TRUE | H4: FALSE | I4: FALSE | J4: FALSE | K4: FALSE | L4: FALSE | M4: FALSE | N4: FALSE | O4: FALSE | P4: FALSE
A5: 1/9/2024 11:45:00 AM | B5: 1F-XB2 | C5: 73.986 | E5: FALSE | F5: FALSE | G5: TRUE | H5: FALSE | I5: FALSE | J5: FALSE | K5: FALSE | L5: FALSE | M5: FALSE | N5: FALSE | O5: FALSE | P5: FALSE
A6: 1/9/2024 11:45:00 AM | B6: 1F-DG1 | C6: 56.364 | E6: FALSE | F6: FALSE | G6: TRUE | H6: FALSE | I6: FALSE | J6: FALSE | K6: FALSE | L6: FALSE | M6: FALSE | N6: FALSE | O6: FALSE | P6: FALSE
A7: 1/9/2024 11:45:00 AM | B7: 1F-DG2 | C7: 58.212 | E7: FALSE | F7: FALSE | G7: TRUE | H7: FALSE | I7: FALSE | J7: FALSE | K7: FALSE | L7: FALSE | M7: FALSE | N7: FALSE | O7: FALSE | P7: FALSE
A8: 1/9/2024 11:45:00 AM | B8: 1F-NAOH | C8: 145.6 | E8: FALSE | F8: FALSE | G8: TRUE | H8: FALSE | I8: FALSE | J8: FALSE | K8: FALSE | L8: FALSE | M8: FALSE | N8: FALSE | O8: FALSE | P8: FALSE
A9: 1/9/2024 11:45:00 AM | B9: 1F-ZN | C9: 11.18 | E9: FALSE | F9: FALSE | G9: TRUE | H9: FALSE | I9: FALSE | J9: FALSE | K9: FALSE | L9: FALSE | M9: FALSE | N9: FALSE | O9: FALSE | P9: FALSE
A10: 1/9/2024 11:45:00 AM | B10: 1F-CR3I | C10: 7.0042 | E10: FALSE | F10: FALSE | G10: TRUE | H10: FALSE | I10: FALSE | J10: FALSE | K10: FALSE | L10: FALSE | M10: FALSE | N10: FALSE | O10: FALSE | P10: FALSE
A11: 1/9/2024 11:45:00 AM | B11: 1F-CR3IPH | C11: 2.3 | E11: FALSE | F11: FALSE | G11: TRUE | H11: FALSE | I11: FALSE | J11: FALSE | K11: FALSE | L11: FALSE | M11: FALSE | N11: FALSE | O11: FALSE | P11: FALSE
A12: 1/9/2024 11:45:00 AM | B12: 1F-HCL1 | C12: 0.45625 | E12: FALSE | F12: FALSE | G12: TRUE | H12: FALSE | I12: FALSE | J12: FALSE | K12: FALSE | L12: FALSE | M12: FALSE | N12: FALSE | O12: FALSE | P12: FALSE
A13: 1/9/2024 11:45:00 AM | B13: 1F-HNO3 | C13: 0.010584 | E13: FALSE | F13: FALSE | G13: TRUE | H13: FALSE | I13: FALSE | J13: FALSE | K13: FALSE | L13: FALSE | M13: FALSE | N13: FALSE | O13: FALSE | P13: FALSE
A14: 1/9/2024 11:45:00 AM | B14: 1F-MEM | C14: 122 | E14: FALSE | F14: FALSE | G14: TRUE | H14: FALSE | I14: FALSE | J14: FALSE | K14: FALSE | L14: FALSE | M14: FALSE | N14: FALSE | O14: FALSE | P14: FALSE
A15: 1/9/2024 11:45:00 AM | B15: 1F-BONG | C15: 40 | E15: FALSE | F15: FALSE | G15: TRUE | H15: FALSE | I15: FALSE | J15: FALSE | K15: FALSE | L15: FALSE | M15: FALSE | N15: FALSE | O15: FALSE | P15: FALSE
... A29: 1/9/2024 11:45:00 AM | B29: XT-MEM | C29: 178 | E29: FALSE | F29: FALSE | G29: TRUE | H29: FALSE | I29: FALSE | J29: FALSE | K29: FALSE | L29: FALSE | M29: FALSE | N29: FALSE | O29: FALSE | P29: FALSE

Sheet 3
A1: "BÁO CÁO KẾT QUẢ HÓA NGHIỆM HÀNG NGÀY 表面處理生產製程管控記錄表"
A2: NGAY | B2: Ma__Hang_muc | C2: Nong_Do_03 | E2: 1 | F2: bs | G2: 2 | H2: bs | I2: 3 | J2: bs | K2: 4 | L2: bs | M2: 5 | N2: bs | O2: 6 | P2: bs | Q2: 3
A3: Date | B3: Code | C3: 濃度 g/03
A4: 1/9/2024 4:30:00 PM | B4: 1F-XB1 | C4: 73.986 | E4: FALSE | F4: FALSE | G4: FALSE | H4: FALSE | I4: TRUE | J4: FALSE | K4: FALSE | L4: FALSE | M4: FALSE | N4: FALSE | O4: FALSE | P4: FALSE
A5: 1/9/2024 4:30:00 PM | B5: 1F-XB2 | C5: 72.039 | E5: FALSE | F5: FALSE | G5: FALSE | H5: FALSE | I5: TRUE | J5: FALSE | K5: FALSE | L5: FALSE | M5: FALSE | N5: FALSE | O5: FALSE | P5: FALSE
A6: 1/9/2024 4:30:00 PM | B6: 1F-DG1 | C6: 61.215 | E6: FALSE | F6: FALSE | G6: FALSE | H6: FALSE | I6: TRUE | J6: FALSE | K6: FALSE | L6: FALSE | M6: FALSE | N6: FALSE | O6: FALSE | P6: FALSE
A7: 1/9/2024 4:30:00 PM | B7: 1F-DG2 | C7: 64.218 | E7: FALSE | F7: FALSE | G7: FALSE | H7: FALSE | I7: TRUE | J7: FALSE | K7: FALSE | L7: FALSE | M7: FALSE | N7: FALSE | O7: FALSE | P7: FALSE
A8: 1/9/2024 4:30:00 PM | B8: 1F-NAOH | C8: 145.6 | E8: FALSE | F8: FALSE | G8: FALSE | H8: FALSE | I8: TRUE | J8: FALSE | K8: FALSE | L8: FALSE | M8: FALSE | N8: FALSE | O8: FALSE | P8: FALSE
A9: 1/9/2024 4:30:00 PM | B9: 1F-ZN | C9: 11.18 | E9: FALSE | F9: FALSE | G9: FALSE | H9: FALSE | I9: TRUE | J9: FALSE | K9: FALSE | L9: FALSE | M9: FALSE | N9: FALSE | O9: FALSE | P9: FALSE
A10: 1/9/2024 4:30:00 PM | B10: 1F-CR3I | C10: 6.66524 | E10: FALSE | F10: FALSE | G10: FALSE | H10: FALSE | I10: TRUE | J10: FALSE | K10: FALSE | L10: FALSE | M10: FALSE | N10: FALSE | O10: FALSE | P10: FALSE
A11: 1/9/2024 4:30:00 PM | B11: 1F-CR3IPH | C11: 2.3 | E11: FALSE | F11: FALSE | G11: FALSE | H11: FALSE | I11: TRUE | J11: FALSE | K11: FALSE | L11: FALSE | M11: FALSE | N11: FALSE | O11: FALSE | P11: FALSE
A12: 1/9/2024 4:30:00 PM | B12: 1F-HCL1 | C12: 0.47335938 | E12: FALSE | F12: FALSE | G12: FALSE | H12: FALSE | I12: TRUE | J12: FALSE | K12: FALSE | L12: FALSE | M12: FALSE | N12: FALSE | O12: FALSE | P12: FALSE
A13: 1/9/2024 4:30:00 PM | B13: 1F-HNO3 | C13: 0.010332 | E13: FALSE | F13: FALSE | G13: FALSE | H13: FALSE | I13: TRUE | J13: FALSE | K13: FALSE | L13: FALSE | M13: FALSE | N13: FALSE | O13: FALSE | P13: FALSE
A14: 1/9/2024 4:30:00 PM | B14: 1F-MEM | C14: 115 | E14: FALSE | F14: FALSE | G14: FALSE | H14: FALSE | I14: TRUE | J14: FALSE | K14: FALSE | L14: FALSE | M14: FALSE | N14: FALSE | O14: FALSE | P14: FALSE
A15: 1/9/2024 4:30:00 PM | B15: 1F-BONG | C15: 40 | E15: FALSE | F15: FALSE | G15: FALSE | H15: FALSE | I15: TRUE | J15: FALSE | K15: FALSE | L15: FALSE | M15: FALSE | N15: FALSE | O15: FALSE | P15: FALSE
... A36: 1/9/2024 4:30:00 PM | B36: RLF-XBPH | C36: 10 | E36: FALSE | F36: FALSE | G36: FALSE | H36: FALSE | I36: TRUE | J36: FALSE | K36: FALSE | L36: FALSE | M36: FALSE | N36: FALSE | O36: FALSE | P36: FALSE

Sheet 4
A1: "BÁO CÁO KẾT QUẢ HÓA NGHIỆM HÀNG NGÀY 表面處理生產製程管控記錄表"
A2: NGAY | B2: Ma__Hang_muc | C2: Nong_Do_03 | E2: 1 | F2: bs | G2: 2 | H2: bs | I2: 3 | J2: bs | K2: 4 | L2: bs | M2: 5 | N2: bs | O2: 6 | P2: bs | Q2: 3
A3: Date | B3: Code | C3: 濃度 g/03
A4: 1/9/2024 6:00:00 PM | B4: RLF-KD | C4: 46 | E4: FALSE | F4: FALSE | G4: FALSE | H4: FALSE | I4: TRUE | J4: FALSE | K4: FALSE | L4: FALSE | M4: FALSE | N4: FALSE | O4: FALSE | P4: FALSE
A5: 1/9/2024 6:00:00 PM | B5: RLF-HCL1 | C5: 10.22 | E5: FALSE | F5: FALSE | G5: FALSE | H5: FALSE | I5: TRUE | J5: FALSE | K5: FALSE | L5: FALSE | M5: FALSE | N5: FALSE | O5: FALSE | P5: FALSE
A6: 1/9/2024 6:00:00 PM | B6: RLF-PP1TA | C6: 51 | E6: FALSE | F6: FALSE | G6: FALSE | H6: FALSE | I6: TRUE | J6: FALSE | K6: FALSE | L6: FALSE | M6: FALSE | N6: FALSE | O6: FALSE | P6: FALSE
A7: 1/9/2024 6:00:00 PM | B7: RLF-PP1AX | C7: 10.2 | E7: FALSE | F7: FALSE | G7: FALSE | H7: FALSE | I7: TRUE | J7: FALSE | K7: FALSE | L7: FALSE | M7: FALSE | N7: FALSE | O7: FALSE | P7: FALSE
A8: 1/9/2024 6:00:00 PM | B8: RLF-PP1PL | C8: 0.72 | E8: FALSE | F8: FALSE | G8: FALSE | H8: FALSE | I8: TRUE | J8: FALSE | K8: FALSE | L8: FALSE | M8: FALSE | N8: FALSE | O8: FALSE | P8: FALSE
A9: 1/9/2024 6:00:00 PM | B9: RLF-XB | C9: 0.9 | E9: FALSE | F9: FALSE | G9: FALSE | H9: FALSE | I9: TRUE | J9: FALSE | K9: FALSE | L9: FALSE | M9: FALSE | N9: FALSE | O9: FALSE | P9: FALSE
A10: 1/9/2024 6:00:00 PM | B10: RLF-XBPH | C10: 10 | E10: FALSE | F10: FALSE | G10: FALSE | H10: FALSE | I10: TRUE | J10: FALSE | K10: FALSE | L10: FALSE | M10: FALSE | N10: FALSE | O10: FALSE | P10: FALSE
A11: 1/9/2024 6:00:00 PM | B11: XD-1 | C11: 5.6 | E11: FALSE | F11: FALSE | G11: FALSE | H11: FALSE | I11: TRUE | J11: FALSE | K11: FALSE | L11: FALSE | M11: FALSE | N11: FALSE | O11: FALSE | P11: FALSE

Sheet 5
A1: "BÁO CÁO KẾT QUẢ HÓA NGHIỆM HÀNG NGÀY 表面處理生產製程管控記錄表"
A2: NGAY | B2: Ma__Hang_muc | C2: Nong_Do_04 | E2: 1 | F2: bs | G2: 2 | H2: bs | I2: 3 | J2: bs | K2: 4 | L2: bs | M2: 5 | N2: bs | O2: 6 | P2: bs | Q2: 4
A3: Date | B3: Code | C3: 濃度 g/L_04
A4: 1/9/2024 9:45:00 PM | B4: 1F-XB1 | C4: 74.635 | E4: FALSE | F4: FALSE | G4: FALSE | H4: FALSE | I4: FALSE | J4: FALSE | K4: TRUE | L4: FALSE | M4: FALSE | N4: FALSE | O4: FALSE | P4: FALSE
A5: 1/9/2024 9:45:00 PM | B5: 1F-XB2 | C5: 71.39 | E5: FALSE | F5: FALSE | G5: FALSE | H5: FALSE | I5: FALSE | J5: FALSE | K5: TRUE | L5: FALSE | M5: FALSE | N5: FALSE | O5: FALSE | P5: FALSE
A6: 1/9/2024 9:45:00 PM | B6: 1F-DG1 | C6: 62.832 | E6: FALSE | F6: FALSE | G6: FALSE | H6: FALSE | I6: FALSE | J6: FALSE | K6: TRUE | L6: FALSE | M6: FALSE | N6: FALSE | O6: FALSE | P6: FALSE
A7: 1/9/2024 9:45:00 PM | B7: 1F-DG2 | C7: 61.908 | E7: FALSE | F7: FALSE | G7: FALSE | H7: FALSE | I7: FALSE | J7: FALSE | K7: TRUE | L7: FALSE | M7: FALSE | N7: FALSE | O7: FALSE | P7: FALSE
A8: 1/9/2024 9:45:00 PM | B8: 1F-NAOH | C8: 145.6 | E8: FALSE | F8: FALSE | G8: FALSE | H8: FALSE | I8: FALSE | J8: FALSE | K8: TRUE | L8: FALSE | M8: FALSE | N8: FALSE | O8: FALSE | P8: FALSE
A9: 1/9/2024 9:45:00 PM | B9: 1F-ZN | C9: 11.18 | E9: FALSE | F9: FALSE | G9: FALSE | H9: FALSE | I9: FALSE | J9: FALSE | K9: TRUE | L9: FALSE | M9: FALSE | N9: FALSE | O9: FALSE | P9: FALSE
A10: 1/9/2024 9:45:00 PM | B10: 1F-CR3I | C10: 6.91946 | E10: FALSE | F10: FALSE | G10: FALSE | H10: FALSE | I10: FALSE | J10: FALSE | K10: TRUE | L10: FALSE | M10: FALSE | N10: FALSE | O10: FALSE | P10: FALSE
A11: 1/9/2024 9:45:00 PM | B11: 1F-CR3IPH | C11: 2.2 | E11: FALSE | F11: FALSE | G11: FALSE | H11: FALSE | I11: FALSE | J11: FALSE | K11: TRUE | L11: FALSE | M11: FALSE | N11: FALSE | O11: FALSE | P11: FALSE
A12: 1/9/2024 9:45:00 PM | B12: 1F-HCL1 | C12: 0.45625 | E12: FALSE | F12: FALSE | G12: FALSE | H12: FALSE | I12: FALSE | J12: FALSE | K12: TRUE | L12: FALSE | M12: FALSE | N12: FALSE | O12: FALSE | P12: FALSE
A13: 1/9/2024 9:45:00 PM | B13: 1F-MEM | C13: 115 | E13: FALSE | F13: FALSE | G13: FALSE | H13: FALSE | I13: FALSE | J13: FALSE | K13: TRUE | L13: FALSE | M13: FALSE | N13: FALSE | O13: FALSE | P13: FALSE
A14: 1/9/2024 9:45:00 PM | B14: 1F-BONG | C14: 42 | E14: FALSE | F14: FALSE | G14: FALSE | H14: FALSE | I14: FALSE | J14: FALSE | K14: TRUE | L14: FALSE | M14: FALSE | N14: FALSE | O14: FALSE | P14: FALSE
A15: 1/9/2024 9:45:00 PM | B15: XT-XB1 | C15: 51.92 | E15: FALSE | F15: FALSE | G15: FALSE | H15: FALSE | I15: FALSE | J15: FALSE | K15: TRUE | L15: FALSE | M15: FALSE | N15: FALSE | O15: FALSE | P15: FALSE
... A35: 1/9/2024 9:45:00 PM | B35: RLF-XBPH | C35: 9.5 | E35: FALSE | F35: FALSE | G35: FALSE | H35: FALSE | I35: FALSE | J35: FALSE | K35: TRUE | L35: FALSE | M35: FALSE | N35: FALSE | O35: FALSE | P35: FALSE

Sheet 6
A1: "BÁO CÁO KẾT QUẢ HÓA NGHIỆM HÀNG NGÀY 表面處理生產製程管控記錄表"
A2: NGAY | B2: Ma__Hang_muc | C2: Nong_Do_05 | E2: 1 | F2: bs | G2: 2 | H2: bs | I2: 3 | J2: bs | K2: 4 | L2: bs | M2: 5 | N2: bs | O2: 6 | P2: bs | Q2: 5
A3: Date | B3: Code | C3: 濃度 g/L_05
A4: =MENU!Y21 -> 45300.99 | B4: 1E-XB1 | C4: =IFERROR(VLOOKUP($B4,_XM_XT_THUCTE,37,0),"") -> 0 | E4: =ISNUMBER(#REF!) -> FALSE | F4: =ISNUMBER(#REF!) -> FALSE | G4: =ISNUMBER(#REF!) -> FALSE | H4: =ISNUMBER(#REF!) -> FALSE | I4: =ISNUMBER(#REF!) -> FALSE | J4: =ISNUMBER(#REF!) -> FALSE | K4: =ISNUMBER(#REF!) -> FALSE | L4: =ISNUMBER(#REF!) -> FALSE | M4: =ISNUMBER(C4) -> TRUE | N4: =ISNUMBER(#REF!) -> FALSE | O4: =ISNUMBER(#REF!) -> FALSE | P4: =ISNUMBER(#REF!) -> FALSE | Q4: =IF(M4=TRUE,"",1)
A5: =IF(B5="","",$A$4) -> 45300.99 | B5: 1E-XB2 | C5: =IFERROR(VLOOKUP($B5,_XM_XT_THUCTE,37,0),"") -> 0 | E5: =ISNUMBER(#REF!) -> FALSE | F5: =ISNUMBER(#REF!) -> FALSE | G5: =ISNUMBER(#REF!) -> FALSE | H5: =ISNUMBER(#REF!) -> FALSE | I5: =ISNUMBER(#REF!) -> FALSE | J5: =ISNUMBER(#REF!) -> FALSE | K5: =ISNUMBER(#REF!) -> FALSE | L5: =ISNUMBER(#REF!) -> FALSE | M5: =ISNUMBER(C5) -> TRUE | N5: =ISNUMBER(#REF!) -> FALSE | O5: =ISNUMBER(#REF!) -> FALSE | P5: =ISNUMBER(#REF!) -> FALSE | Q5: =IF(M5=TRUE,"",1)
A6: =IF(B6="","",$A$4) -> 45300.99 | B6: 1E-DG1 | C6: =IFERROR(VLOOKUP($B6,_XM_XT_THUCTE,37,0),"") -> 0 | E6: =ISNUMBER(#REF!) -> FALSE | F6: =ISNUMBER(#REF!) -> FALSE | G6: =ISNUMBER(#REF!) -> FALSE | H6: =ISNUMBER(#REF!) -> FALSE | I6: =ISNUMBER(#REF!) -> FALSE | J6: =ISNUMBER(#REF!) -> FALSE | K6: =ISNUMBER(#REF!) -> FALSE | L6: =ISNUMBER(#REF!) -> FALSE | M6: =ISNUMBER(C6) -> TRUE | N6: =ISNUMBER(#REF!) -> FALSE | O6: =ISNUMBER(#REF!) -> FALSE | P6: =ISNUMBER(#REF!) -> FALSE | Q6: =IF(M6=TRUE,"",1)
A7: =IF(B7="","",$A$4) -> 45300.99 | B7: 1E-DG2 | C7: =IFERROR(VLOOKUP($B7,_XM_XT_THUCTE,37,0),"") -> 0 | E7: =ISNUMBER(#REF!) -> FALSE | F7: =ISNUMBER(#REF!) -> FALSE | G7: =ISNUMBER(#REF!) -> FALSE | H7: =ISNUMBER(#REF!) -> FALSE | I7: =ISNUMBER(#REF!) -> FALSE | J7: =ISNUMBER(#REF!) -> FALSE | K7: =ISNUMBER(#REF!) -> FALSE | L7: =ISNUMBER(#REF!) -> FALSE | M7: =ISNUMBER(C7) -> TRUE | N7: =ISNUMBER(#REF!) -> FALSE | O7: =ISNUMBER(#REF!) -> FALSE | P7: =ISNUMBER(#REF!) -> FALSE | Q7: =IF(M7=TRUE,"",1)
A8: =IF(B8="","",$A$4) -> 45300.99 | B8: 1E-NAOH | C8: =IFERROR(VLOOKUP($B8,_XM_XT_THUCTE,37,0),"") -> 0 | E8: =ISNUMBER(#REF!) -> FALSE | F8: =ISNUMBER(#REF!) -> FALSE | G8: =ISNUMBER(#REF!) -> FALSE | H8: =ISNUMBER(#REF!) -> FALSE | I8: =ISNUMBER(#REF!) -> FALSE | J8: =ISNUMBER(#REF!) -> FALSE | K8: =ISNUMBER(#REF!) -> FALSE | L8: =ISNUMBER(#REF!) -> FALSE | M8: =ISNUMBER(C8) -> TRUE | N8: =ISNUMBER(#REF!) -> FALSE | O8: =ISNUMBER(#REF!) -> FALSE | P8: =ISNUMBER(#REF!) -> FALSE | Q8: =IF(M8=TRUE,"",1)
A9: =IF(B9="","",$A$4) -> 45300.99 | B9: 1E-ZN | C9: =IFERROR(VLOOKUP($B9,_XM_XT_THUCTE,37,0),"") -> 0 | E9: =ISNUMBER(#REF!) -> FALSE | F9: =ISNUMBER(#REF!) -> FALSE | G9: =ISNUMBER(#REF!) -> FALSE | H9: =ISNUMBER(#REF!) -> FALSE | I9: =ISNUMBER(#REF!) -> FALSE | J9: =ISNUMBER(#REF!) -> FALSE | K9: =ISNUMBER(#REF!) -> FALSE | L9: =ISNUMBER(#REF!) -> FALSE | M9: =ISNUMBER(C9) -> TRUE | N9: =ISNUMBER(#REF!) -> FALSE | O9: =ISNUMBER(#REF!) -> FALSE | P9: =ISNUMBER(#REF!) -> FALSE | Q9: =IF(M9=TRUE,"",1)
A10: =IF(B10="","",$A$4) -> 45300.99 | B10: 1E-CR3I | C10: =IFERROR(VLOOKUP($B10,_XM_XT_THUCTE,37,0),"") -> 0 | E10: =ISNUMBER(#REF!) -> FALSE | F10: =ISNUMBER(#REF!) -> FALSE | G10: =ISNUMBER(#REF!) -> FALSE | H10: =ISNUMBER(#REF!) -> FALSE | I10: =ISNUMBER(#REF!) -> FALSE | J10: =ISNUMBER(#REF!) -> FALSE | K10: =ISNUMBER(#REF!) -> FALSE | L10: =ISNUMBER(#REF!) -> FALSE | M10: =ISNUMBER(C10) -> TRUE | N10: =ISNUMBER(#REF!) -> FALSE | O10: =ISNUMBER(#REF!) -> FALSE | P10: =ISNUMBER(#REF!) -> FALSE | Q10: =IF(M10=TRUE,"",1)
A11: =IF(B11="","",$A$4) -> 45300.99 | B11: 1E-CR3IPH | C11: =IFERROR(VLOOKUP($B11,_XM_XT_THUCTE,37,0),"") -> 0 | E11: =ISNUMBER(#REF!) -> FALSE | F11: =ISNUMBER(#REF!) -> FALSE | G11: =ISNUMBER(#REF!) -> FALSE | H11: =ISNUMBER(#REF!) -> FALSE | I11: =ISNUMBER(#REF!) -> FALSE | J11: =ISNUMBER(#REF!) -> FALSE | K11: =ISNUMBER(#REF!) -> FALSE | L11: =ISNUMBER(#REF!) -> FALSE | M11: =ISNUMBER(C11) -> TRUE | N11: =ISNUMBER(#REF!) -> FALSE | O11: =ISNUMBER(#REF!) -> FALSE | P11: =ISNUMBER(#REF!) -> FALSE | Q11: =IF(M11=TRUE,"",1)
A12: =IF(B12="","",$A$4) -> 45300.99 | B12: 1E-HCL1 | C12: =IFERROR(VLOOKUP($B12,_XM_XT_THUCTE,37,0),"") -> 0 | E12: =ISNUMBER(#REF!) -> FALSE | F12: =ISNUMBER(#REF!) -> FALSE | G12: =ISNUMBER(#REF!) -> FALSE | H12: =ISNUMBER(#REF!) -> FALSE | I12: =ISNUMBER(#REF!) -> FALSE | J12: =ISNUMBER(#REF!) -> FALSE | K12: =ISNUMBER(#REF!) -> FALSE | L12: =ISNUMBER(#REF!) -> FALSE | M12: =ISNUMBER(C12) -> TRUE | N12: =ISNUMBER(#REF!) -> FALSE | O12: =ISNUMBER(#REF!) -> FALSE | P12: =ISNUMBER(#REF!) -> FALSE | Q12: =IF(M12=TRUE,"",1)
A13: =IF(B13="","",$A$4) -> 45300.99 | B13: 1E-HCL2 | C13: =IFERROR(VLOOKUP($B13,_XM_XT_THUCTE,37,0),"") -> 0 | E13: =ISNUMBER(#REF!) -> FALSE | F13: =ISNUMBER(#REF!) -> FALSE | G13: =ISNUMBER(#REF!) -> FALSE | H13: =ISNUMBER(#REF!) -> FALSE | I13: =ISNUMBER(#REF!) -> FALSE | J13: =ISNUMBER(#REF!) -> FALSE | K13: =ISNUMBER(#REF!) -> FALSE | L13: =ISNUMBER(#REF!) -> FALSE | M13: =ISNUMBER(C13) -> TRUE | N13: =ISNUMBER(#REF!) -> FALSE | O13: =ISNUMBER(#REF!) -> FALSE | P13: =ISNUMBER(#REF!) -> FALSE | Q13: =IF(M13=TRUE,"",1)
A14: =IF(B14="","",$A$4) -> 45300.99 | B14: 1E-HCL3 | C14: =IFERROR(VLOOKUP($B14,_XM_XT_THUCTE,37,0),"") -> 0 | E14: =ISNUMBER(#REF!) -> FALSE | F14: =ISNUMBER(#REF!) -> FALSE | G14: =ISNUMBER(#REF!) -> FALSE | H14: =ISNUMBER(#REF!) -> FALSE | I14: =ISNUMBER(#REF!) -> FALSE | J14: =ISNUMBER(#REF!) -> FALSE | K14: =ISNUMBER(#REF!) -> FALSE | L14: =ISNUMBER(#REF!) -> FALSE | M14: =ISNUMBER(C14) -> TRUE | N14: =ISNUMBER(#REF!) -> FALSE | O14: =ISNUMBER(#REF!) -> FALSE | P14: =ISNUMBER(#REF!) -> FALSE | Q14: =IF(M14=TRUE,"",1)
A15: =IF(B15="","",$A$4) -> 45300.99 | B15: 1E-HNO3 | C15: =IFERROR(VLOOKUP($B15,_XM_XT_THUCTE,37,0),"") -> 0 | E15: =ISNUMBER(#REF!) -> FALSE | F15: =ISNUMBER(#REF!) -> FALSE | G15: =ISNUMBER(#REF!) -> FALSE | H15: =ISNUMBER(#REF!) -> FALSE | I15: =ISNUMBER(#REF!) -> FALSE | J15: =ISNUMBER(#REF!) -> FALSE | K15: =ISNUMBER(#REF!) -> FALSE | L15: =ISNUMBER(#REF!) -> FALSE | M15: =ISNUMBER(C15) -> TRUE | N15: =ISNUMBER(#REF!) -> FALSE | O15: =ISNUMBER(#REF!) -> FALSE | P15: =ISNUMBER(#REF!) -> FALSE | Q15: =IF(M15=TRUE,"",1)
A16: =IF(B16="","",$A$4) -> 45300.99 | B16: 1E-MEM | C16: =IFERROR(VLOOKUP($B16,_XM_XT_THUCTE,37,0),"") -> 0 | E16: =ISNUMBER(#REF!) -> FALSE | F16: =ISNUMBER(#REF!) -> FALSE | G16: =ISNUMBER(#REF!) -> FALSE | H16: =ISNUMBER(#REF!) -> FALSE | I16: =ISNUMBER(#REF!) -> FALSE | J16: =ISNUMBER(#REF!) -> FALSE | K16: =ISNUMBER(#REF!) -> FALSE | L16: =ISNUMBER(#REF!) -> FALSE | M16: =ISNUMBER(C16) -> TRUE | N16: =ISNUMBER(#REF!) -> FALSE | O16: =ISNUMBER(#REF!) -> FALSE | P16: =ISNUMBER(#REF!) -> FALSE | Q16: =IF(M16=TRUE,"",1)
... A45: =IF(B45="","",$A$4) -> 45300.99 | B45: XT-MEM | C45: =IFERROR(VLOOKUP($B45,_XM_XT_THUCTE,37,0),"") -> 0 | E45: =ISNUMBER(#REF!) -> FALSE | F45: =ISNUMBER(#REF!) -> FALSE | G45: =ISNUMBER(#REF!) -> FALSE | H45: =ISNUMBER(#REF!) -> FALSE | I45: =ISNUMBER(#REF!) -> FALSE | J45: =ISNUMBER(#REF!) -> FALSE | K45: =ISNUMBER(#REF!) -> FALSE | L45: =ISNUMBER(#REF!) -> FALSE | M45: =ISNUMBER(C45) -> TRUE | N45: =ISNUMBER(#REF!) -> FALSE | O45: =ISNUMBER(#REF!) -> FALSE | P45: =ISNUMBER(#REF!) -> FALSE | Q45: =IF(M45=TRUE,"",1)

Sheet 7
A1: "BÁO CÁO KẾT QUẢ HÓA NGHIỆM HÀNG NGÀY 表面處理生產製程管控記錄表"
A2: NGAY | B2: Ma__Hang_muc | C2: Nong_Do_06 | E2: 1 | F2: bs | G2: 2 | H2: bs | I2: 3 | J2: bs | K2: 4 | L2: bs | M2: 5 | N2: bs | O2: 6 | P2: bs | Q2: 6
A3: Date | B3: Code | C3: 濃度 g/L_06
A4: 1/9/2024 4:00:00 AM | B4: 1F-XB1 | C4: 72.688 | E4: FALSE | F4: FALSE | G4: FALSE | H4: FALSE | I4: FALSE | J4: FALSE | K4: FALSE | L4: FALSE | M4: FALSE | N4: FALSE | O4: TRUE | P4: FALSE
A5: 1/9/2024 4:00:00 AM | B5: 1F-XB2 | C5: 71.39 | E5: FALSE | F5: FALSE | G5: FALSE | H5: FALSE | I5: FALSE | J5: FALSE | K5: FALSE | L5: FALSE | M5: FALSE | N5: FALSE | O5: TRUE | P5: FALSE
A6: 1/9/2024 4:00:00 AM | B6: 1F-DG1 | C6: 60.522 | E6: FALSE | F6: FALSE | G6: FALSE | H6: FALSE | I6: FALSE | J6: FALSE | K6: FALSE | L6: FALSE | M6: FALSE | N6: FALSE | O6: TRUE | P6: FALSE
A7: 1/9/2024 4:00:00 AM | B7: 1F-DG2 | C7: 58.674 | E7: FALSE | F7: FALSE | G7: FALSE | H7: FALSE | I7: FALSE | J7: FALSE | K7: FALSE | L7: FALSE | M7: FALSE | N7: FALSE | O7: TRUE | P7: FALSE
A8: 1/9/2024 4:00:00 AM | B8: 1F-NAOH | C8: 146.4 | E8: FALSE | F8: FALSE | G8: FALSE | H8: FALSE | I8: FALSE | J8: FALSE | K8: FALSE | L8: FALSE | M8: FALSE | N8: FALSE | O8: TRUE | P8: FALSE
A9: 1/9/2024 4:00:00 AM | B9: 1F-ZN | C9: 10.92 | E9: FALSE | F9: FALSE | G9: FALSE | H9: FALSE | I9: FALSE | J9: FALSE | K9: FALSE | L9: FALSE | M9: FALSE | N9: FALSE | O9: TRUE | P9: FALSE
A10: 1/9/2024 4:00:00 AM | B10: 1F-CR3I | C10: 7.51264 | E10: FALSE | F10: FALSE | G10: FALSE | H10: FALSE | I10: FALSE | J10: FALSE | K10: FALSE | L10: FALSE | M10: FALSE | N10: FALSE | O10: TRUE | P10: FALSE
A11: 1/9/2024 4:00:00 AM | B11: 1F-CR3IPH | C11: 2.2 | E11: FALSE | F11: FALSE | G11: FALSE | H11: FALSE | I11: FALSE | J11: FALSE | K11: FALSE | L11: FALSE | M11: FALSE | N11: FALSE | O11: TRUE | P11: FALSE
A12: 1/9/2024 4:00:00 AM | B12: 1F-HCL1 | C12: 0.4334375 | E12: FALSE | F12: FALSE | G12: FALSE | H12: FALSE | I12: FALSE | J12: FALSE | K12: FALSE | L12: FALSE | M12: FALSE | N12: FALSE | O12: TRUE | P12: FALSE
A13: 1/9/2024 4:00:00 AM | B13: 1F-MEM | C13: 115 | E13: FALSE | F13: FALSE | G13: FALSE | H13: FALSE | I13: FALSE | J13: FALSE | K13: FALSE | L13: FALSE | M13: FALSE | N13: FALSE | O13: TRUE | P13: FALSE
A14: 1/9/2024 4:00:00 AM | B14: 1F-BONG | C14: 40 | E14: FALSE | F14: FALSE | G14: FALSE | H14: FALSE | I14: FALSE | J14: FALSE | K14: FALSE | L14: FALSE | M14: FALSE | N14: FALSE | O14: TRUE | P14: FALSE
A15: 1/9/2024 4:00:00 AM | B15: XT-XB1 | C15: 51.92 | E15: FALSE | F15: FALSE | G15: FALSE | H15: FALSE | I15: FALSE | J15: FALSE | K15: FALSE | L15: FALSE | M15: FALSE | N15: FALSE | O15: TRUE | P15: FALSE
... A35: 1/9/2024 4:00:00 AM | B35: RLF-XBPH | C35: 10 | E35: FALSE | F35: FALSE | G35: FALSE | H35: FALSE | I35: FALSE | J35: FALSE | K35: FALSE | L35: FALSE | M35: FALSE | N35: FALSE | O35: TRUE | P35: FALSE

Sheet 8
A1: "BÁO CÁO KẾT QUẢ HÓA NGHIỆM HÀNG NGÀY 表面處理生產製程管控記錄表"
A2: NGAY | B2: Ma__Hang_muc | C2: Nong_Do_06 | E2: 1 | F2: bs | G2: 2 | H2: bs | I2: 3 | J2: bs | K2: 4 | L2: bs | M2: 5 | N2: bs | O2: 6 | P2: bs | Q2: 6
A3: Date | B3: Code | C3: 濃度 g/L_06
A4: 1/9/2024 6:00:00 AM | B4: RLF-KD | C4: 37 | E4: FALSE | F4: FALSE | G4: FALSE | H4: FALSE | I4: FALSE | J4: FALSE | K4: FALSE | L4: FALSE | M4: FALSE | N4: FALSE | O4: TRUE | P4: FALSE
A5: 1/9/2024 6:00:00 AM | B5: RLF-HCL1 | C5: 10.585 | E5: FALSE | F5: FALSE | G5: FALSE | H5: FALSE | I5: FALSE | J5: FALSE | K5: FALSE | L5: FALSE | M5: FALSE | N5: FALSE | O5: TRUE | P5: FALSE
A6: 1/9/2024 6:00:00 AM | B6: RLF-PP1TA | C6: 45 | E6: FALSE | F6: FALSE | G6: FALSE | H6: FALSE | I6: FALSE | J6: FALSE | K6: FALSE | L6: FALSE | M6: FALSE | N6: FALSE | O6: TRUE | P6: FALSE
A7: 1/9/2024 6:00:00 AM | B7: RLF-PP1AX | C7: 8.490566 | E7: FALSE | F7: FALSE | G7: FALSE | H7: FALSE | I7: FALSE | J7: FALSE | K7: FALSE | L7: FALSE | M7: FALSE | N7: FALSE | O7: TRUE | P7: FALSE
A8: 1/9/2024 6:00:00 AM | B8: RLF-PP1PL | C8: 0.64 | E8: FALSE | F8: FALSE | G8: FALSE | H8: FALSE | I8: FALSE | J8: FALSE | K8: FALSE | L8: FALSE | M8: FALSE | N8: FALSE | O8: TRUE | P8: FALSE
A9: 1/9/2024 6:00:00 AM | B9: RLF-XB | C9: 0.9 | E9: FALSE | F9: FALSE | G9: FALSE | H9: FALSE | I9: FALSE | J9: FALSE | K9: FALSE | L9: FALSE | M9: FALSE | N9: FALSE | O9: TRUE | P9: FALSE
A10: 1/9/2024 6:00:00 AM | B10: RLF-XBPH | C10: 9 | E10: FALSE | F10: FALSE | G10: FALSE | H10: FALSE | I10: FALSE | J10: FALSE | K10: FALSE | L10: FALSE | M10: FALSE | N10: FALSE | O10: TRUE | P10: FALSE

Sheet MENU
B3: XI MẠ, XI TREO | J3: RỬA LIỆU, MÀNG LOA, XI ĐEN | R3: KHÁC | V3: IMPORT | AA3: khoảng thời gian Import | AE3: L.Yen | AF3: Trang
AE4: Trang | AF4: L.Yen
B6: XM.HN | F6: XM.GUI MAIL | J6: ED-XI DEN | N6: R.GUI MAIL | R6: IT.NONG DO | V6: 1 | Y6: =AD9+TIME(9,45,0) -> 45300.406 | AA6: 9:15-9:45 | AD6: CA 1 | AE6: Trang
AD7: CA 2 | AE7: L.Yen
B9: XM.FILE GOC | F9: 1. XL-1E TT(CA1) | J9: R.HN | N9: RL-LINE | R9: IT.NHIET DO | V9: 2 | Y9: =AD9+TIME(11,45,0) -> 45300.49 | AA9: 11:15-11:45 | AC9: Thứ 3, | AD9: 2024/01/09 | AF9: đánh Thứ, 'năm/tháng/ngày vào ô bên
B12: 1. XL-1E kh | F12: 1. XL-1E TT(CA2) | J12: R.FILE GOC | N12: 1.xi den TT | R12: GHI CHU | V12: 3 | Y12: =AD9+TIME(16,30,0) -> 45300.688 | AA12: 16:00-16:30 | AD12: ACID Đ.VAO
B15: 2. XL-1F kh | F15: 2. XL-1F TT(CA1) | J15: 1.xi den | N15: 2.RL E tt | R15: PP HÓA NGHIỆM FILE WORD | V15: 4 | Y15: =AD9+TIME(18,0,0) -> 45300.75 | AA15: 17:30-18:00 | AD15: THỜI GIAN GỬI BC LÊN LINE
B18: 3.XT-C kh.mau JASCO | F18: 2. XL-1F TT(CA2) | J18: 2.RL E | N18: 3.RL G tt | R18: QC- E | V18: 5 | Y18: =AD9+TIME(21,45,0) -> 45300.906 | AA18: 21:15-21:45 | AD18: CA 1: | AE18: ĐỢT 1 | AF18: ĐỢT 2 | AG18: ĐỢT 3
AD19: RL | AE19: 0.38541667 | AF19: 0.60416667 | AG19: 0.72916667
AD20: ML | AE20: 0.39583333
B21: 3.XT-C kh.mau HALO | F21: 3.XT-C TT(CA1) | J21: 3.RL G | N21: 4.RL F tt | R21: QC-1F | V21: 6 | Y21: =AD9+TIME(23,45,0) -> 45300.99 | AA21: 23:15-23:45 | AD21: XL | AE21: 0.39583333 | AF21: 0.47569444 | AG21: 0.66666667
AD22: XT | AE22: 0.40277778 | AF22: 0.47569444 | AG22: 0.66666667
AD23: XĐ | AE23: 0.41666667 | AF23: 0.61458333 | AG23: 0.75
B24: 4.Zn Ni.kh | F24: 3.XT-C TT(CA2) | J24: 4.RL F | N24: 5.ML tt | R24: QC- XT | V24: 7 | Y24: =AD9+TIME(4,0,0) -> 45300.167 | AA24: 3:30-4:00 | AD24: HUCELL | AE24: 0.4375 | AG24: 0.6875
AD26: CA 2: | AE26: ĐỢT 1 | AF26: ĐỢT 2 | AG26: ĐỢT 3
B27: XM.chart | F27: 4.ZN-NI tt(CA1) | J27: 5.ML | N27: RL.chart1 | R27: QC-RL | V27: 8 | Y27: =AD9+TIME(6,0,0) -> 45300.25 | AA27: 5:30-6:00 | AD27: RL | AE27: 0.88541667 | AF27: 0.10416667 | AG27: 0.22916667
AD28: ML | AE28: 0.9375
AD29: XL | AE29: 0.91666667 | AG29: 0.1875
F30: 4.ZN-NI tt(CA2) | J30: RL.chart | N30: RL.chart1 | R30: QC-XĐ | AA30: tg import | AD30: XT | AE30: 0.91666667 | AG30: 0.1875
AD31: HUCELL | AE31: 0.95833333 | AG31: 0.20833333
F33: BS-XT | R33: QC-ML
F36: XM.chart 1 | R36: QC-NI
R39: PT TAP CHAT
R41: thời gian pha mới bồn màu
U43: 1E | Z43: 1F | AE43: XT
R44: I | U44: Pha mới: 2024/01/02 | Z44: Pha mới: 2024/01/07 | AE44: Pha mới: 2023/12/08
R45: K | U45: Pha mới: 2024/01/02 | Z45: Pha mới: 2023/12/24 | AE45: Pha mới: 2023/12/02
R46: MÀU NI | U46: \ | Z46: \ | AE46: Cr2O3 三價鉻Ni- PH Pha mới: 2023/02/07

Sheet XM.HN
A1: =MENU!AD9 -> 2024/01/09
A2: XL-001E | B2: 07:15 | C2: 11:15 | D2: 15:15 | E2: 19:15 | F2: 23:15 | G2: 03:15 | H2: TIEU CHUAN | J2: 07:15 | K2: 11:15 | L2: 15:15 | M2: 19:15 | N2: 23:15 | O2: 03:15 | P2: NCC | R2: Quy đổi nồng độ acid HCl 32% đậm đặc từ %V/V sang nồng độ %
A3: Xà bông (1)脫脂 | H3: ='XM.GUI MAIL'!$E$6 -> 20~40 | I3: ='XM.GUI MAIL'!$F$6 -> (30±5) | J3: ='XM.GUI MAIL'!I6 -> 0 | K3: ='XM.GUI MAIL'!P6 -> 0 | L3: ='XM.GUI MAIL'!W6 -> 0 | M3: ='XM.GUI MAIL'!AD6 -> 0 | N3: ='XM.GUI MAIL'!AK6 -> 0 | O3: ='XM.GUI MAIL'!AR6 -> 0 | P3: JASCO
H4: 按NaOH添加數據添加 | J4: ='XM.GUI MAIL'!I7 -> 0 | K4: ='XM.GUI MAIL'!P7 -> 0 | L4: ='XM.GUI MAIL'!W7 -> 0 | M4: ='XM.GUI MAIL'!AD7 -> 0 | N4: ='XM.GUI MAIL'!AK7 -> 0 | O4: ='XM.GUI MAIL'!AR7 -> 0
H5: 按NaOH添加數據添加 | J5: ='XM.GUI MAIL'!I8 -> 0 | K5: ='XM.GUI MAIL'!P8 -> 0 | L5: ='XM.GUI MAIL'!W8 -> 0 | M5: ='XM.GUI MAIL'!AD8 -> 0 | N5: ='XM.GUI MAIL'!AK8 -> 0 | O5: ='XM.GUI MAIL'!AR8 -> 0
A6: Xà bông (2)脫脂 | H6: ='XM.GUI MAIL'!$E$9 -> 20~40 | I6: ='XM.GUI MAIL'!$F$9 -> (30±5) | J6: ='XM.GUI MAIL'!I9 -> 0 | K6: ='XM.GUI MAIL'!P9 -> 0 | L6: ='XM.GUI MAIL'!W9 -> 0 | M6: ='XM.GUI MAIL'!AD9 -> 0 | N6: ='XM.GUI MAIL'!AK9 -> 0 | O6: ='XM.GUI MAIL'!AR9 -> 0 | P6: JASCO | R6: 15%V/V | T6: 100%V/V
H7: 按NaOH添加數據添加 | J7: ='XM.GUI MAIL'!I10 -> 0 | K7: ='XM.GUI MAIL'!P10 -> 0 | L7: ='XM.GUI MAIL'!W10 -> 0 | M7: ='XM.GUI MAIL'!AD10 -> 0 | N7: ='XM.GUI MAIL'!AK10 -> 0 | O7: ='XM.GUI MAIL'!AR10 -> 0
H8: 按NaOH添加數據添加 | J8: ='XM.GUI MAIL'!I11 -> 0 | K8: ='XM.GUI MAIL'!P11 -> 0 | L8: ='XM.GUI MAIL'!W11 -> 0 | M8: ='XM.GUI MAIL'!AD11 -> 0 | N8: ='XM.GUI MAIL'!AK11 -> 0 | O8: ='XM.GUI MAIL'!AR11 -> 0
A9: điện giải(1)+電解 | H9: ='XM.GUI MAIL'!$E$12 -> 60~80 | I9: ='XM.GUI MAIL'!$F$12 -> (70±10) | J9: ='XM.GUI MAIL'!I12 -> 0 | K9: ='XM.GUI MAIL'!P12 -> 0 | L9: ='XM.GUI MAIL'!W12 -> 0 | M9: ='XM.GUI MAIL'!AD12 -> 0 | N9: ='XM.GUI MAIL'!AK12 -> 0 | O9: ='XM.GUI MAIL'!AR12 -> 0 | P9: JASCO | R9: 0.048 | T9: 0.32
H10: 按NaOH添加數據添加 | J10: ='XM.GUI MAIL'!I13 -> 0 | K10: ='XM.GUI MAIL'!P13 -> 0 | L10: ='XM.GUI MAIL'!W13 -> 0 | M10: ='XM.GUI MAIL'!AD13 -> 0 | N10: ='XM.GUI MAIL'!AK13 -> 0 | O10: ='XM.GUI MAIL'!AR13 -> 0
A11: điện giải (2)+電解 | H11: ='XM.GUI MAIL'!$E$14 -> 60~80 | I11: ='XM.GUI MAIL'!$F$14 -> (70±10) | J11: ='XM.GUI MAIL'!I14 -> 0 | K11: ='XM.GUI MAIL'!P14 -> 0 | L11: ='XM.GUI MAIL'!W14 -> 0 | M11: ='XM.GUI MAIL'!AD14 -> 0 | N11: ='XM.GUI MAIL'!AK14 -> 0 | O11: ='XM.GUI MAIL'!AR14 -> 0 | P11: JASCO
H12: 按NaOH添加數據添加 | J12: ='XM.GUI MAIL'!I15 -> 0 | K12: ='XM.GUI MAIL'!P15 -> 0 | L12: ='XM.GUI MAIL'!W15 -> 0 | M12: ='XM.GUI MAIL'!AD15 -> 0 | N12: ='XM.GUI MAIL'!AK15 -> 0 | O12: ='XM.GUI MAIL'!AR15 -> 0
A13: NaOH氫氧化鈉 | H13: ='XM.GUI MAIL'!$E$16 -> 130 - 150 | I13: ='XM.GUI MAIL'!$F$16 -> (140±7) | J13: ='XM.GUI MAIL'!I16 -> 0 | K13: ='XM.GUI MAIL'!P16 -> 0 | L13: ='XM.GUI MAIL'!W16 -> 0 | M13: ='XM.GUI MAIL'!AD16 -> 0 | N13: ='XM.GUI MAIL'!AK16 -> 0 | O13: ='XM.GUI MAIL'!AR16 -> 0 | P13: JASCO | R13: 30%V/V | T13: 100%V/V
A14: Zn鋅 | H14: ='XM.GUI MAIL'!$E$17 -> 8~12 | I14: ='XM.GUI MAIL'!$F$17 -> (10±2) | J14: ='XM.GUI MAIL'!I17 -> 0 | K14: ='XM.GUI MAIL'!P17 -> 0 | L14: ='XM.GUI MAIL'!W17 -> 0 | M14: ='XM.GUI MAIL'!AD17 -> 0 | N14: ='XM.GUI MAIL'!AK17 -> 0 | O14: ='XM.GUI MAIL'!AR17 -> 0 | P14: JASCO | R14: 0.096 | T14: 0.32
A15: Cr3+鈍化劑 (I) | H15: ='XM.GUI MAIL'!$E$18 -> 12~18 | I15: ='XM.GUI MAIL'!$F$18 -> (14±2) | J15: ='XM.GUI MAIL'!I18 -> 0 | K15: ='XM.GUI MAIL'!P18 -> 0 | L15: ='XM.GUI MAIL'!W18 -> 0 | M15: ='XM.GUI MAIL'!AD18 -> 0 | N15: ='XM.GUI MAIL'!AK18 -> 0 | O15: ='XM.GUI MAIL'!AR18 -> 0 | P15: JASCO
H16: ='XM.GUI MAIL'!$E$19 -> 1.6~2.2 | I16: ='XM.GUI MAIL'!$F$19 -> (2±0.2 ) | J16: ='XM.GUI MAIL'!I19 -> 0 | K16: ='XM.GUI MAIL'!P19 -> 0 | L16: ='XM.GUI MAIL'!W19 -> 0 | M16: ='XM.GUI MAIL'!AD19 -> 0 | N16: ='XM.GUI MAIL'!AK19 -> 0 | O16: ='XM.GUI MAIL'!AR19 -> 0
A17: HCl Đặc 濃酸洗 | H17: ='XM.GUI MAIL'!$E$20 -> 40~50 | I17: ='XM.GUI MAIL'!$F$20 -> (45±5) | J17: ='XM.GUI MAIL'!I20 -> 0 | K17: ='XM.GUI MAIL'!P20 -> 0 | L17: ='XM.GUI MAIL'!W20 -> 0 | M17: ='XM.GUI MAIL'!AD20 -> 0 | N17: ='XM.GUI MAIL'!AK20 -> 0 | O17: ='XM.GUI MAIL'!AR20 -> 0 | R17: 60%V/V | T17: 100%V/V
A18: HCl Loãng弱酸洗 | H18: ='XM.GUI MAIL'!$E$21 -> (22±5) =17~27 | I18: ='XM.GUI MAIL'!$F$21 -> (22±5) | J18: ='XM.GUI MAIL'!I21 -> 0 | K18: ='XM.GUI MAIL'!P21 -> 0 | L18: ='XM.GUI MAIL'!W21 -> 0 | M18: ='XM.GUI MAIL'!AD21 -> 0 | N18: ='XM.GUI MAIL'!AK21 -> 0 | O18: ='XM.GUI MAIL'!AR21 -> 0 | R18: 0.192 | T18: 0.32
A19: HCl hoat hoa | H19: ='XM.GUI MAIL'!$E$22 -> 5~15 | I19: ='XM.GUI MAIL'!$F$22 -> (30±4) | J19: ='XM.GUI MAIL'!I22 -> 0 | K19: ='XM.GUI MAIL'!P22 -> 0 | L19: ='XM.GUI MAIL'!W22 -> 0 | M19: ='XM.GUI MAIL'!AD22 -> 0 | N19: ='XM.GUI MAIL'!AK22 -> 0 | O19: ='XM.GUI MAIL'!AR22 -> 0
A20: HNO3 硝酸中和 | H20: ='XM.GUI MAIL'!$E$23 -> 0.5~1.5 | I20: ='XM.GUI MAIL'!$F$23 -> (1±0.4) | J20: ='XM.GUI MAIL'!I23 -> 0 | K20: ='XM.GUI MAIL'!P23 -> 0 | L20: ='XM.GUI MAIL'!W23 -> 0 | M20: ='XM.GUI MAIL'!AD23 -> 0 | N20: ='XM.GUI MAIL'!AK23 -> 0 | O20: ='XM.GUI MAIL'!AR23 -> 0
A21: Cr3+鈍化劑 (K) | H21: ='XM.GUI MAIL'!$E$24 -> 5~10 | I21: ='XM.GUI MAIL'!$F$24 -> (7.5±1) | J21: ='XM.GUI MAIL'!I24 | K21: ='XM.GUI MAIL'!P24 | L21: ='XM.GUI MAIL'!W24 | M21: ='XM.GUI MAIL'!AD24 | N21: ='XM.GUI MAIL'!AK24 | O21: ='XM.GUI MAIL'!AR24 | P21: JASCO
A22: Cr3+鈍化劑 (K) PH | H22: ='XM.GUI MAIL'!$E$25 -> 1.8~2.2 | I22: ='XM.GUI MAIL'!$F$25 -> (2±0.1) | J22: ='XM.GUI MAIL'!I25 -> 0 | K22: ='XM.GUI MAIL'!P25 -> 0 | L22: ='XM.GUI MAIL'!W25 -> 0 | M22: ='XM.GUI MAIL'!AD25 -> 0 | N22: ='XM.GUI MAIL'!AK25 -> 0 | O22: ='XM.GUI MAIL'!AR25 -> 0 | P22: JASCO
A23: Cr3+鈍化劑 (I) PH | H23: 1.6~2.1 | I23: (1.8±0.1) | J23: =B23 -> 0 | K23: =C23 -> 0 | L23: =D23 -> 0 | M23: =E23 -> 0 | N23: =F23 -> 0 | O23: =G23 -> 0 | P23: JASCO
A25: XL-001F | B25: 07:15 | C25: 11:15 | D25: 15:15 | E25: 19:15 | F25: 23:15 | G25: 03:15 | H25: TIEU CHUAN | J25: 07:15 | K25: 11:15 | L25: 15:15 | M25: 19:15 | N25: 23:15 | O25: 03:15 | P25: NCC
A26: Xà bông (1)脫脂 | B26: 10.8 | C26: 10.9 | D26: 11.4 | E26: 11.5 | G26: 11.2 | H26: ='XM.GUI MAIL'!$E$43 -> 60~80 | I26: ='XM.GUI MAIL'!$F$43 -> (70±5) | J26: ='XM.GUI MAIL'!I43 -> 70.092 | K26: ='XM.GUI MAIL'!P43 -> 70.741 | L26: ='XM.GUI MAIL'!W43 -> 73.986 | M26: ='XM.GUI MAIL'!AD43 -> 74.635 | N26: ='XM.GUI MAIL'!AK43 -> 0 | O26: ='XM.GUI MAIL'!AR43 -> 72.688 | P26: HALO
H27: CT-21A: 25kg/CT-21B: 5-10Lit | J27: ='XM.GUI MAIL'!I44 -> 0 | K27: ='XM.GUI MAIL'!P44 -> 0 | L27: ='XM.GUI MAIL'!W44 -> 0 | M27: ='XM.GUI MAIL'!AD44 -> 0 | N27: ='XM.GUI MAIL'!AK44 -> 0 | O27: ='XM.GUI MAIL'!AR44 -> 0
A28: Xà bông (2)脫脂 | B28: 11.45 | C28: 11.4 | D28: 11.1 | E28: 11 | G28: 11 | H28: ='XM.GUI MAIL'!$E$45 -> 60~80 | I28: ='XM.GUI MAIL'!$F$45 -> (70±5) | J28: ='XM.GUI MAIL'!I45 -> 74.3105 | K28: ='XM.GUI MAIL'!P45 -> 73.986 | L28: ='XM.GUI MAIL'!W45 -> 72.039 | M28: ='XM.GUI MAIL'!AD45 -> 71.39 | N28: ='XM.GUI MAIL'!AK45 -> 0 | O28: ='XM.GUI MAIL'!AR45 -> 71.39 | P28: HALO | R28: Quy đổi nồng độ acid HCl 32% sang nồng độ g/l
H29: CT-21A: 25kg/CT-21B: 5-10Lit | J29: ='XM.GUI MAIL'!I46 -> 0 | K29: ='XM.GUI MAIL'!P46 -> 0 | L29: ='XM.GUI MAIL'!W46 -> 0 | M29: ='XM.GUI MAIL'!AD46 -> 0 | N29: ='XM.GUI MAIL'!AK46 -> 0 | O29: ='XM.GUI MAIL'!AR46 -> 0
A30: điện giải(1)+電解 | B30: 12.25 | C30: 12.2 | D30: 13.25 | E30: 13.6 | G30: 13.1 | H30: ='XM.GUI MAIL'!$E$47 -> 50~70 | I30: ='XM.GUI MAIL'!$F$47 -> (60±10) | J30: ='XM.GUI MAIL'!I47 -> 56.595 | K30: ='XM.GUI MAIL'!P47 -> 56.364 | L30: ='XM.GUI MAIL'!W47 -> 61.215 | M30: ='XM.GUI MAIL'!AD47 -> 62.832 | N30: ='XM.GUI MAIL'!AK47 -> 0 | O30: ='XM.GUI MAIL'!AR47 -> 60.522 | P30: HALO
H31: EC-508A: 25kg/EC-508B:4-10Lit | J31: ='XM.GUI MAIL'!I48 -> 0 | K31: ='XM.GUI MAIL'!P48 -> 0 | L31: ='XM.GUI MAIL'!W48 -> 0 | M31: ='XM.GUI MAIL'!AD48 -> 0 | N31: ='XM.GUI MAIL'!AK48 -> 0 | O31: ='XM.GUI MAIL'!AR48 -> 0
A32: điện giải (2)+電解 | B32: 12.3 | C32: 12.6 | D32: 13.9 | E32: 13.4 | G32: 12.7 | H32: ='XM.GUI MAIL'!$E$49 -> 50~70 | I32: ='XM.GUI MAIL'!$F$49 -> (60±10) | J32: ='XM.GUI MAIL'!I49 -> 56.826 | K32: ='XM.GUI MAIL'!P49 -> 58.212 | L32: ='XM.GUI MAIL'!W49 -> 64.218 | M32: ='XM.GUI MAIL'!AD49 -> 61.908 | N32: ='XM.GUI MAIL'!AK49 -> 0 | O32: ='XM.GUI MAIL'!AR49 -> 58.674 | P32: HALO
H33: EC-508A: 25kg/EC-508B:4-10Lit | J33: ='XM.GUI MAIL'!I50 -> 0 | K33: ='XM.GUI MAIL'!P50 -> 0 | L33: ='XM.GUI MAIL'!W50 -> 0 | M33: ='XM.GUI MAIL'!AD50 -> 0 | N33: ='XM.GUI MAIL'!AK50 -> 0 | O33: ='XM.GUI MAIL'!AR50 -> 0
A34: NaOH氫氧化鈉 | B34: 18.05 | C34: 18.2 | D34: 18.2 | E34: 18.2 | G34: 18.3 | H34: ='XM.GUI MAIL'!$E$51 -> 130 - 150 | I34: ='XM.GUI MAIL'!$F$51 -> (140±7) | J34: ='XM.GUI MAIL'!I51 -> 144.4 | K34: ='XM.GUI MAIL'!P51 -> 145.6 | L34: ='XM.GUI MAIL'!W51 -> 145.6 | M34: ='XM.GUI MAIL'!AD51 -> 145.6 | N34: ='XM.GUI MAIL'!AK51 -> 0 | O34: ='XM.GUI MAIL'!AR51 -> 146.4 | P34: HALO | R34: %*1.162= (g/l)
A35: Zn鋅 | B35: 8.9 | C35: 8.6 | D35: 8.6 | E35: 8.6 | G35: 8.4 | H35: ='XM.GUI MAIL'!$E$52 -> 8~12 | I35: ='XM.GUI MAIL'!$F$52 -> (10±2) | J35: ='XM.GUI MAIL'!I52 -> 11.57 | K35: ='XM.GUI MAIL'!P52 -> 11.18 | L35: ='XM.GUI MAIL'!W52 -> 11.18 | M35: ='XM.GUI MAIL'!AD52 -> 11.18 | N35: ='XM.GUI MAIL'!AK52 -> 0 | O35: ='XM.GUI MAIL'!AR52 -> 10.92 | P35: HALO
A36: Cr3+鈍化劑 (I) halo | B36: 18.9 | C36: 19 | D36: 18.2 | E36: 18.8 | G36: 20.2 | H36: ='XM.GUI MAIL'!$E$53 -> 6~10 | I36: ='XM.GUI MAIL'!$F$53 -> (7±1) | J36: ='XM.GUI MAIL'!I53 -> 6.96183 | K36: ='XM.GUI MAIL'!P53 -> 7.0042 | L36: ='XM.GUI MAIL'!W53 -> 6.66524 | M36: ='XM.GUI MAIL'!AD53 -> 6.91946 | N36: ='XM.GUI MAIL'!AK53 -> -1.0461 | O36: ='XM.GUI MAIL'!AR53 -> 7.51264 | P36: HALO | R36: vd:
H37: ='XM.GUI MAIL'!$E$54 -> 2~2.5 | I37: ='XM.GUI MAIL'!$F$54 -> (2.3±0.1 ) | J37: ='XM.GUI MAIL'!I54 -> 2.5 | K37: ='XM.GUI MAIL'!P54 -> 2.3 | L37: ='XM.GUI MAIL'!W54 -> 2.3 | M37: ='XM.GUI MAIL'!AD54 -> 2.2 | N37: ='XM.GUI MAIL'!AK54 -> 0 | O37: ='XM.GUI MAIL'!AR54 -> 2.2
A38: HCl Đặc 濃酸洗 | B38: 3.8 | C38: 4 | D38: 4.15 | E38: 4 | G38: 3.8 | H38: ='XM.GUI MAIL'!$E$55 -> 40~50 | I38: ='XM.GUI MAIL'!$F$55 -> (45±5) | J38: ='XM.GUI MAIL'!I55 -> 0.4334375 | K38: ='XM.GUI MAIL'!P55 -> 0.45625 | L38: ='XM.GUI MAIL'!W55 -> 0.47335938 | M38: ='XM.GUI MAIL'!AD55 -> 0.45625 | N38: ='XM.GUI MAIL'!AK55 -> 0 | O38: ='XM.GUI MAIL'!AR55 -> 0.4334375 | R38: =5*1.162 -> 5.81 | S38: (g/l)
A39: HCl Loãng弱酸洗 | H39: ='XM.GUI MAIL'!$E$56 -> (22±5) =17~27 | I39: ='XM.GUI MAIL'!$F$56 -> (22±5) | J39: ='XM.GUI MAIL'!I56 -> 0 | K39: ='XM.GUI MAIL'!P56 -> 0 | L39: ='XM.GUI MAIL'!W56 -> 0 | M39: ='XM.GUI MAIL'!AD56 -> 0 | N39: ='XM.GUI MAIL'!AK56 -> 0 | O39: ='XM.GUI MAIL'!AR56 -> 0 | R39: =R38*1000 -> 5810 | S39: (g/ml)
A40: HCl hoat hoa | H40: ='XM.GUI MAIL'!$E$57 -> 5~15 | I40: ='XM.GUI MAIL'!$F$57 -> (10±3) | J40: ='XM.GUI MAIL'!I57 -> 0 | K40: ='XM.GUI MAIL'!P57 -> 0 | L40: ='XM.GUI MAIL'!W57 -> 0 | M40: ='XM.GUI MAIL'!AD57 -> 0 | N40: ='XM.GUI MAIL'!AK57 -> 0 | O40: ='XM.GUI MAIL'!AR57 -> 0
A41: HNO3 硝酸中和 | B41: 9.4 | C41: 8.4 | D41: 8.2 | E41: 9.8 | G41: 7.5 | H41: ='XM.GUI MAIL'!$E$58 -> 0.5~1.5 | I41: ='XM.GUI MAIL'!$F$58 -> (1±0.4) | J41: ='XM.GUI MAIL'!I58 -> 0.011844 | K41: ='XM.GUI MAIL'!P58 -> 0.010584 | L41: ='XM.GUI MAIL'!W58 -> 0.010332 | M41: ='XM.GUI MAIL'!AD58 -> 0.012348 | N41: ='XM.GUI MAIL'!AK58 -> 0 | O41: ='XM.GUI MAIL'!AR58 -> 0.00945
...

Sheet XM.FILE GOC
C1: BÁO CÁO KẾT QUẢ HÓA NGHIỆM HÀNG NGÀY 报告每日化学测试结果
A2: =MENU!$AC$9 -> Thứ 3, | C2: =MENU!$AD$9 -> 2024/01/09
A3: 生產線別：無氰鹼滾電E線 (XL-001E) | F3: =MENU!$AC$9 -> Thứ 3, | I3: =MENU!$AD$9 -> 2024/01/09 | AX3: =A2 -> Thứ 3,
G4: tiêu chuẩn khống chế để bổ sung | I4: 7:15 | P4: 11:15 | W4: 15:15 | AD4: 19:15 | AK4: 23:15 | AR4: 03:15 | AX4: =C2 -> 2024/01/09 | AY4: =AX4-1 -> 45299 | BE4: =AY4 -> 45299
A5: MÃ | B5: MÃ MÁY | C5: Hạng mục kiểm tra nồng độ 化驗檢查項目 | D5: Đơn vị 單位 | E5: Phạm vi kiểm soát 範圍值 | F5: Giới hạn kiểm soát 管控值 | I5: 濃度 | J5: 補充 BS | K5: 補充 BS | P5: 濃度 | Q5: 補充 BS | R5: 補充 BS | W5: 濃度 | X5: 補充 BS | Y5: 補充 BS | AD5: 濃度 | AE5: 補充 BS | AF5: 補充 BS | AK5: 濃度 | AL5: 補充 BS | AM5: 補充 BS | AR5: 濃度 | AS5: 補充 BS | AT5: 補充 BS | AX5: XI ĐEN | AY5: XM | BE5: XI ĐEN
A6: 1E-XB1 | B6: XL-001E | C6: Xà bông (1)脫脂 | D6: g/L | E6: ='XM.GUI MAIL'!E6 -> 20~40 | F6: ='XM.GUI MAIL'!F6 -> (30±5) | G6: ='XM.GUI MAIL'!G6 -> 30 | H6: =XM.HN!B3 -> 0 | I6: =H6*4 -> 0 | J6: =($G$6-I6)*2693/1000 -> 80.79 | K6: + | L6: =IF(J6<0,0,J6) -> 80.79 | N6: kg | O6: =XM.HN!C3 -> 0 | P6: =O6*4 -> 0 | Q6: =($G$6-P6)*2693/1000 -> 80.79 | R6: + | S6: =IF(Q6<0,0,Q6) -> 80.79 | U6: kg | V6: =XM.HN!D3 -> 0 | W6: =V6*4 -> 0 | X6: =($G$6-W6)*2693/1000 -> 80.79 | Y6: + | Z6: =IF(X6<0,0,X6) -> 80.79 | AB6: kg | AC6: =XM.HN!E3 -> 0 | AD6: =AC6*4 -> 0 | AE6: =($G$6-AD6)*2693/1000 -> 80.79 | AF6: + | AG6: =IF(AE6<0,0,AE6) -> 80.79 | AI6: kg | AJ6: =XM.HN!F3 -> 0 | AK6: =AJ6*4 -> 0 | AL6: =($G$6-AK6)*2693/1000 -> 80.79 | AM6: + | AN6: =IF(AL6<0,0,AL6) -> 80.79 | AP6: kg | AQ6: =XM.HN!G3 -> 0 | AR6: =AQ6*4 -> 0 | AS6: =($G$6-AR6)*2693/1000 -> 80.79 | AT6: + | AU6: =IF(AS6<0,0,AS6) -> 80.79 | AW6: kg | AX6: ='R.FILE GOC'!W57 -> 15 | AY6: 0 | AZ6: 80.79 | BA6: + | BB6: 80.79 | BD6: kg | BE6: 15.2
C7: CleanA 840ml/NaOH 25kg | E7: 按NaOH添加數據添加 | K7: + | L7: =L6/25*840/1000 -> 2.714544 | M7: =IF('1. XL-1E TT'!AB7="","",'1. XL-1E TT'!AB7) | N7: L | R7: + | S7: =S6/25*840/1000 -> 2.714544 | T7: =IF('1. XL-1E TT'!AF7="","",'1. XL-1E TT'!AF7) | U7: L | Y7: + | Z7: =Z6/25*840/1000 -> 2.714544 | AA7: =IF('1. XL-1E TT'!AJ7="","",'1. XL-1E TT'!AJ7) | AB7: L | AF7: + | AG7: =AG6/25*840/1000 -> 2.714544 | AH7: =IF('1. XL-1E TT(CA2)'!AB7="","",'1. XL-1E TT(CA2)'!AB7) | AI7: L | AM7: + | AN7: =AN6/25*840/1000 -> 2.714544 | AO7: =IF('1. XL-1E TT(CA2)'!AF7="","",'1. XL-1E TT(CA2)'!AF7) | AP7: L | AT7: + | AU7: =AU6/25*840/1000 -> 2.714544 | AV7: =IF('1. XL-1E TT(CA2)'!AJ7="","",'1. XL-1E TT(CA2)'!AJ7) | AW7: L | AX7: ='R.FILE GOC'!W58 -> 15 | BA7: + | BB7: 2.714544 | BD7: L | BE7: 15.3
C8: CleanB 8400ml/NaOH 25kg | E8: 按NaOH添加數據添加 | K8: + | L8: =L7*10 -> 27.14544 | M8: =IF('1. XL-1E TT'!AB8="","",'1. XL-1E TT'!AB8) | N8: L | R8: + | S8: =S7*10 -> 27.14544 | T8: =IF('1. XL-1E TT'!AF8="","",'1. XL-1E TT'!AF8) | U8: L | Y8: + | Z8: =Z7*10 -> 27.14544 | AA8: =IF('1. XL-1E TT'!AJ8="","",'1. XL-1E TT'!AJ8) | AB8: L | AF8: + | AG8: =AG7*10 -> 27.14544 | AH8: =IF('1. XL-1E TT(CA2)'!AB8="","",'1. XL-1E TT(CA2)'!AB8) | AI8: L | AM8: + | AN8: =AN7*10 -> 27.14544 | AO8: =IF('1. XL-1E TT(CA2)'!AF8="","",'1. XL-1E TT(CA2)'!AF8) | AP8: L | AT8: + | AU8: =AU7*10 -> 27.14544 | AV8: =IF('1. XL-1E TT(CA2)'!AJ8="","",'1. XL-1E TT(CA2)'!AJ8) | AW8: L | AX8: ='R.FILE GOC'!W59 -> 15 | BA8: + | BB8: 27.14544 | BD8: L | BE8: 15
A9: 1E-XB2 | B9: XL-001E | C9: Xà bông (2)脫脂 | D9: g/L | E9: ='XM.GUI MAIL'!E9 -> 20~40 | F9: ='XM.GUI MAIL'!F9 -> (30±5) | G9: ='XM.GUI MAIL'!G9 -> 30 | H9: =XM.HN!B6 -> 0 | I9: =H9*4 -> 0 | J9: =($G$9-I9)*3305/1000 -> 99.15 | K9: + | L9: =IF(J9<0,0,J9) -> 99.15 | N9: kg | O9: =XM.HN!C6 -> 0 | P9: =O9*4 -> 0 | Q9: =($G$9-P9)*3305/1000 -> 99.15 | R9: + | S9: =IF(Q9<0,0,Q9) -> 99.15 | U9: kg | V9: =XM.HN!D6 -> 0 | W9: =V9*4 -> 0 | X9: =($G$9-W9)*3305/1000 -> 99.15 | Y9: + | Z9: =IF(X9<0,0,X9) -> 99.15 | AB9: kg | AC9: =XM.HN!E6 -> 0 | AD9: =AC9*4 -> 0 | AE9: =($G$9-AD9)*3305/1000 -> 99.15 | AF9: + | AG9: =IF(AE9<0,0,AE9) -> 99.15 | AI9: kg | AJ9: =XM.HN!F6 -> 0 | AK9: =AJ9*4 -> 0 | AL9: =($G$9-AK9)*3305/1000 -> 99.15 | AM9: + | AN9: =IF(AL9<0,0,AL9) -> 99.15 | AP9: kg | AQ9: =XM.HN!G6 -> 0 | AR9: =AQ9*4 -> 0 | AS9: =($G$9-AR9)*3305/1000 -> 99.15 | AT9: + | AU9: =IF(AS9<0,0,AS9) -> 99.15 | AW9: kg | AX9: ='R.FILE GOC'!W60 -> 9.9 | AY9: 0 | AZ9: 99.15 | BA9: + | BB9: 99.15 | BD9: kg | BE9: 10.1
C10: CleanA 840ml/NaOH 25kg | E10: 按NaOH添加數據添加 | K10: + | L10: =L9/25*840/1000 -> 3.33144 | M10: =IF('1. XL-1E TT'!AB10="","",'1. XL-1E TT'!AB10) | N10: L | R10: + | S10: =S9/25*840/1000 -> 3.33144 | T10: =IF('1. XL-1E TT'!AF10="","",'1. XL-1E TT'!AF10) | U10: L | Y10: + | Z10: =Z9/25*840/1000 -> 3.33144 | AA10: =IF('1. XL-1E TT'!AJ10="","",'1. XL-1E TT'!AJ10) | AB10: L | AF10: + | AG10: =AG9/25*840/1000 -> 3.33144 | AH10: =IF('1. XL-1E TT(CA2)'!AB10="","",'1. XL-1E TT(CA2)'!AB10) | AI10: L | AM10: + | AN10: =AN9/25*840/1000 -> 3.33144 | AO10: =IF('1. XL-1E TT(CA2)'!AF10="","",'1. XL-1E TT(CA2)'!AF10) | AP10: L | AT10: + | AU10: =AU9/25*840/1000 -> 3.33144 | AV10: =IF('1. XL-1E TT(CA2)'!AJ10="","",'1. XL-1E TT(CA2)'!AJ10) | AW10: L | AX10: ='R.FILE GOC'!W61 -> 0.96 | BA10: + | BB10: 3.33144 | BD10: L | BE10: 1.34
C11: CleanB 8400ml/NaOH 25kg | E11: 按NaOH添加數據添加 | K11: + | L11: =L10*10 -> 33.3144 | M11: =IF('1. XL-1E TT'!AB11="","",'1. XL-1E TT'!AB11) | N11: L | R11: + | S11: =S10*10 -> 33.3144 | T11: =IF('1. XL-1E TT'!AF11="","",'1. XL-1E TT'!AF11) | U11: L | Y11: + | Z11: =Z10*10 -> 33.3144 | AA11: =IF('1. XL-1E TT'!AJ11="","",'1. XL-1E TT'!AJ11) | AB11: L | AF11: + | AG11: =AG10*10 -> 33.3144 | AH11: =IF('1. XL-1E TT(CA2)'!AB11="","",'1. XL-1E TT(CA2)'!AB11) | AI11: L | AM11: + | AN11: =AN10*10 -> 33.3144 | AO11: =IF('1. XL-1E TT(CA2)'!AF11="","",'1. XL-1E TT(CA2)'!AF11) | AP11: L | AT11: + | AU11: =AU10*10 -> 33.3144 | AV11: =IF('1. XL-1E TT(CA2)'!AJ11="","",'1. XL-1E TT(CA2)'!AJ11) | AW11: L | AX11: ='R.FILE GOC'!W62 -> 22.5 | BA11: + | BB11: 33.3144 | BD11: L | BE11: 23.1
A12: 1E-DG1 | B12: XL-001E | C12: điện giải(1)+電解 | D12: g/L | E12: ='XM.GUI MAIL'!E12 -> 60~80 | F12: ='XM.GUI MAIL'!F12 -> (70±10) | G12: ='XM.GUI MAIL'!G12 -> 70 | H12: =XM.HN!B9 -> 0 | I12: =H12*4 -> 0 | J12: =($G$12-I12)*1156/1000 -> 80.92 | K12: + | L12: =IF(J12<0,0,J12) -> 80.92 | N12: kg | O12: =XM.HN!C9 -> 0 | P12: =O12*4 -> 0 | Q12: =($G$12-P12)*1156/1000 -> 80.92 | R12: + | S12: =IF(Q12<0,0,Q12) -> 80.92 | U12: kg | V12: =XM.HN!D9 -> 0 | W12: =V12*4 -> 0 | X12: =($G$12-W12)*1156/1000 -> 80.92 | Y12: + | Z12: =IF(X12<0,0,X12) -> 80.92 | AB12: kg | AC12: =XM.HN!E9 -> 0 | AD12: =AC12*4 -> 0 | AE12: =($G$12-AD12)*1156/1000 -> 80.92 | AF12: + | AG12: =IF(AE12<0,0,AE12) -> 80.92 | AI12: kg | AJ12: =XM.HN!F9 -> 0 | AK12: =AJ12*4 -> 0 | AL12: =($G$12-AK12)*1156/1000 -> 80.92 | AM12: + | AN12: =IF(AL12<0,0,AL12) -> 80.92 | AP12: kg | AQ12: =XM.HN!G9 -> 0 | AR12: =AQ12*4 -> 0 | AS12: =($G$12-AR12)*1156/1000 -> 80.92 | AT12: + | AU12: =IF(AS12<0,0,AS12) -> 80.92 | AW12: kg | AX12: ='R.FILE GOC'!W63 -> 9 | AY12: 0 | AZ12: 80.92 | BA12: + | BB12: 80.92 | BD12: kg | BE12: 8.6
C13: CleanB 7.5L/NaOH 25kg | E13: 按NaOH添加數據添加 | K13: + | L13: =L12/25*7.5 -> 24.276 | M13: =IF('1. XL-1E TT'!AB13="","",'1. XL-1E TT'!AB13) | N13: L | R13: + | S13: =S12/25*7.5 -> 24.276 | T13: =IF('1. XL-1E TT'!AF13="","",'1. XL-1E TT'!AF13) | U13: L | Y13: + | Z13: =Z12/25*7.5 -> 24.276 | AA13: =IF('1. XL-1E TT'!AJ13="","",'1. XL-1E TT'!AJ13) | AB13: L | AF13: + | AG13: =AG12/25*7.5 -> 24.276 | AH13: =IF('1. XL-1E TT(CA2)'!AB13="","",'1. XL-1E TT(CA2)'!AB13) | AI13: L | AM13: + | AN13: =AN12/25*7.5 -> 24.276 | AO13: =IF('1. XL-1E TT(CA2)'!AF13="","",'1. XL-1E TT(CA2)'!AF13) | AP13: L | AT13: + | AU13: =AU12/25*7.5 -> 24.276 | AV13: =IF('1. XL-1E TT(CA2)'!AJ13="","",'1. XL-1E TT(CA2)'!AJ13) | AW13: L | AX13: ='R.FILE GOC'!W64 -> 7.8 | BA13: + | BB13: 24.276 | BD13: L | BE13: 7.7
A14: 1E-DG2 | B14: XL-001E | C14: điện giải (2)+電解 | D14: g/L | E14: ='XM.GUI MAIL'!E14 -> 60~80 | F14: ='XM.GUI MAIL'!F14 -> (70±10) | G14: ='XM.GUI MAIL'!G14 -> 70 | H14: =XM.HN!B11 -> 0 | I14: =H14*4 -> 0 | J14: =($G$14-I14)*1459/1000 -> 102.13 | K14: + | L14: =IF(J14<0,0,J14) -> 102.13 | N14: kg | O14: =XM.HN!C11 -> 0 | P14: =O14*4 -> 0 | Q14: =($G$14-P14)*1459/1000 -> 102.13 | R14: + | S14: =IF(Q14<0,0,Q14) -> 102.13 | U14: kg | V14: =XM.HN!D11 -> 0 | W14: =V14*4 -> 0 | X14: =($G$14-W14)*1459/1000 -> 102.13 | Y14: + | Z14: =IF(X14<0,0,X14) -> 102.13 | AB14: kg | AC14: =XM.HN!E11 -> 0 | AD14: =AC14*4 -> 0 | AE14: =($G$14-AD14)*1459/1000 -> 102.13 | AF14: + | AG14: =IF(AE14<0,0,AE14) -> 102.13 | AI14: kg | AJ14: =XM.HN!F11 -> 0 | AK14: =AJ14*4 -> 0 | AL14: =($G$14-AK14)*1459/1000 -> 102.13 | AM14: + | AN14: =IF(AL14<0,0,AL14) -> 102.13 | AP14: kg | AQ14: =XM.HN!G11 -> 0 | AR14: =AQ14*4 -> 0 | AS14: =($G$14-AR14)*1459/1000 -> 102.13 | AT14: + | AU14: =IF(AS14<0,0,AS14) -> 102.13 | AW14: kg | AX14: ='R.FILE GOC'!W65 -> 5.5 | AY14: 0 | AZ14: 102.13 | BA14: + | BB14: 102.13 | BD14: kg | BE14: 5.7
C15: CleanB 7.5L/NaOH 25kg | E15: 按NaOH添加數據添加 | K15: + | L15: =L14/25*7.5 -> 30.639 | M15: =IF('1. XL-1E TT'!AB15="","",'1. XL-1E TT'!AB15) | N15: L | R15: + | S15: =S14/25*7.5 -> 30.639 | T15: =IF('1. XL-1E TT'!AF15="","",'1. XL-1E TT'!AF15) | U15: L | Y15: + | Z15: =Z14/25*7.5 -> 30.639 | AA15: =IF('1. XL-1E TT'!AJ15="","",'1. XL-1E TT'!AJ15) | AB15: L | AF15: + | AG15: =AG14/25*7.5 -> 30.639 | AH15: =IF('1. XL-1E TT(CA2)'!AB15="","",'1. XL-1E TT(CA2)'!AB15) | AI15: L | AM15: + | AN15: =AN14/25*7.5 -> 30.639 | AO15: =IF('1. XL-1E TT(CA2)'!AF15="","",'1. XL-1E TT(CA2)'!AF15) | AP15: L | AT15: + | AU15: =AU14/25*7.5 -> 30.639 | AV15: =IF('1. XL-1E TT(CA2)'!AJ15="","",'1. XL-1E TT(CA2)'!AJ15) | AW15: L | AX15: ='R.FILE GOC'!W66 -> 0 | BA15: + | BB15: 30.639 | BD15: L | BE15: 0
A16: 1E-NAOH | B16: XL-001E | C16: Nồng độ NaOH 氫氧化鈉 | D16: g/L | E16: ='XM.GUI MAIL'!E16 -> 130 - 150 | F16: ='XM.GUI MAIL'!F16 -> (140±7) | G16: ='XM.GUI MAIL'!G16 -> 140 | H16: =XM.HN!B13 -> 0 | I16: =H16*8 -> 0 | J16: =($G$16-I16)*19951/1000 -> 2793.14 | K16: + | L16: =IF(J16<0,0,J16) -> 2793.14 | N16: kg | O16: =XM.HN!C13 -> 0 | P16: =O16*8 -> 0 | Q16: =($G$16-P16)*19951/1000 -> 2793.14 | R16: + | S16: =IF(Q16<0,0,Q16) -> 2793.14 | U16: kg | V16: =XM.HN!D13 -> 0 | W16: =V16*8 -> 0 | X16: =($G$16-W16)*19951/1000 -> 2793.14 | Y16: + | Z16: =IF(X16<0,0,X16) -> 2793.14 | AB16: kg | AC16: =XM.HN!E13 -> 0 | AD16: =AC16*8 -> 0 | AE16: =($G$16-AD16)*19951/1000 -> 2793.14 | AF16: + | AG16: =IF(AE16<0,0,AE16) -> 2793.14 | AI16: kg | AJ16: =XM.HN!F13 -> 0 | AK16: =AJ16*8 -> 0 | AL16: =($G$16-AK16)*19951/1000 -> 2793.14 | AM16: + | AN16: =IF(AL16<0,0,AL16) -> 2793.14 | AP16: kg | AQ16: =XM.HN!G13 -> 0 | AR16: =AQ16*8 -> 0 | AS16: =($G$16-AR16)*19951/1000 -> 2793.14 | AT16: + | AU16: =IF(AS16<0,0,AS16) -> 2793.14 | AW16: kg | AX16: ='R.FILE GOC'!W67 -> 15.1 | AY16: 0 | AZ16: 2793.14 | BA16: + | BB16: 2793.14 | BD16: kg | BE16: 15.2
A17: 1E-ZN | B17: XL-001E | C17: Nồng độ Zn 鋅 (1 pcs Zn=25kg) | D17: g/L | E17: ='XM.GUI MAIL'!E17 -> 8~12 | F17: ='XM.GUI MAIL'!F17 -> (10±2) | G17: ='XM.GUI MAIL'!G17 -> 10 | H17: =XM.HN!B14 -> 0 | I17: =H17*1.3 -> 0 | J17: =($G$17-I17)*19951/1000 -> 199.51 | K17: + | L17: =IF(J17<0,0,J17) -> 199.51 | N17: kg | O17: =XM.HN!C14 -> 0 | P17: =O17*1.3 -> 0 | Q17: =($G$17-P17)*19951/1000 -> 199.51 | R17: + | S17: =IF(Q17<0,0,Q17) -> 199.51 | U17: kg | V17: =XM.HN!D14 -> 0 | W17: =V17*1.3 -> 0 | X17: =($G$17-W17)*19951/1000 -> 199.51 | Y17: + | Z17: =IF(X17<0,0,X17) -> 199.51 | AB17: kg | AC17: =XM.HN!E14 -> 0 | AD17: =AC17*1.3 -> 0 | AE17: =($G$17-AD17)*19951/1000 -> 199.51 | AF17: + | AG17: =IF(AE17<0,0,AE17) -> 199.51 | AI17: kg | AJ17: =XM.HN!F14 -> 0 | AK17: =AJ17*1.3 -> 0 | AL17: =($G$17-AK17)*19951/1000 -> 199.51 | AM17: + | AN17: =IF(AL17<0,0,AL17) -> 199.51 | AP17: kg | AQ17: =XM.HN!G14 -> 0 | AR17: =AQ17*1.3 -> 0 | AS17: =($G$17-AR17)*19951/1000 -> 199.51 | AT17: + | AU17: =IF(AS17<0,0,AS17) -> 199.51 | AW17: kg | AX17: ='R.FILE GOC'!W68 -> 11.6 | AY17: 0 | AZ17: 199.51 | BA17: + | BB17: 199.51 | BD17: kg | BE17: 11.7
A18: 1E-CR3I | B18: XL-001E | C18: Nồng độ Cr2O3 三價鉻 | D18: % | E18: ='XM.GUI MAIL'!E18 -> 12~18 | F18: ='XM.GUI MAIL'!F18 -> (14±2) | G18: ='XM.GUI MAIL'!G18 -> 14 | H18: =XM.HN!B15 -> 0 | I18: =H18*100/6.95/10 -> 0 | J18: =($G$18-I18)*575/100 -> 80.5 | K18: + | L18: =IF(J18<0,0,J18) -> 80.5 | N18: L | O18: =XM.HN!C15 -> 0 | P18: =O18*100/6.95/10 -> 0 | Q18: =($G$18-P18)*575/100 -> 80.5 | R18: + | S18: =IF(Q18<0,0,Q18) -> 80.5 | U18: L | V18: =XM.HN!D15 -> 0 | W18: =V18*100/6.95/10 -> 0 | X18: =($G$18-W18)*575/100 -> 80.5 | Y18: + | Z18: =IF(X18<0,0,X18) -> 80.5 | AB18: L | AC18: =XM.HN!E15 -> 0 | AD18: =AC18*100/6.95/10 -> 0 | AE18: =($G$18-AD18)*575/100 -> 80.5 | AF18: + | AG18: =IF(AE18<0,0,AE18) -> 80.5 | AI18: L | AJ18: =XM.HN!F15 -> 0 | AK18: =AJ18*100/6.95/10 -> 0 | AL18: =($G$18-AK18)*575/100 -> 80.5 | AM18: + | AN18: =IF(AL18<0,0,AL18) -> 80.5 | AP18: L | AQ18: =XM.HN!G15 -> 0 | AR18: =AQ18*100/6.95/10 -> 0 | AS18: =($G$18-AR18)*575/100 -> 80.5 | AT18: + | AU18: =IF(AS18<0,0,AS18) -> 80.5 | AW18: L | AX18: ='R.FILE GOC'!W69 | AY18: 0 | AZ18: 80.5 | BA18: + | BB18: 80.5 | BD18: L
A19: 1E-CR3IPH | B19: XL-001E | D19: pH | E19: ='XM.GUI MAIL'!E19 -> 1.6~2.2 | F19: ='XM.GUI MAIL'!F19 -> (2±0.2 ) | G19: ='XM.GUI MAIL'!G19 -> 0 | I19: =XM.HN!B23 -> 0 | P19: =XM.HN!C23 -> 0 | W19: =XM.HN!D23 -> 0 | AD19: =XM.HN!E23 -> 0 | AK19: =XM.HN!F23 -> 0 | AR19: =XM.HN!G23 -> 0 | AX19: ='R.FILE GOC'!W70 | AY19: 0
A20: 1E-HCL1 | B20: XL-001E | C20: Nồng độ acid đặc 鹽酸 濃度 | D20: %V/V | E20: ='XM.GUI MAIL'!E20 -> 40~50 | F20: ='XM.GUI MAIL'!F20 -> (45±5) | G20: ='XM.GUI MAIL'!G20 -> 0.45 | H20: =XM.HN!B17 -> 0 | I20: =(1*H20*36.5)/(1*10)/32%/100 -> 0 | J20: =($G$20-I20)*2122 -> 954.9 | K20: + | L20: =IF(J20<0,0,J20) -> 954.9 | N20: L | O20: =XM.HN!C17 -> 0 | P20: =(1*O20*36.5)/(1*10)/32%/100 -> 0 | Q20: =($G$20-P20)*2122 -> 954.9 | R20: + | S20: =IF(Q20<0,0,Q20) -> 954.9 | U20: L | V20: =XM.HN!D17 -> 0 | W20: =(1*V20*36.5)/(1*10)/32%/100 -> 0 | X20: =($G$20-W20)*2122 -> 954.9 | Y20: + | Z20: =IF(X20<0,0,X20) -> 954.9 | AB20: L | AC20: =XM.HN!E17 -> 0 | AD20: =(1*AC20*36.5)/(1*10)/32%/100 -> 0 | AE20: =($G$20-AD20)*2122 -> 954.9 | AF20: + | AG20: =IF(AE20<0,0,AE20) -> 954.9 | AI20: L | AJ20: =XM.HN!F17 -> 0 | AK20: =(1*AJ20*36.5)/(1*10)/32%/100 -> 0 | AL20: =($G$20-AK20)*2122 -> 954.9 | AM20: + | AN20: =IF(AL20<0,0,AL20) -> 954.9 | AP20: L | AQ20: =XM.HN!G17 -> 0 | AR20: =(1*AQ20*36.5)/(1*10)/32%/100 -> 0 | AS20: =($G$20-AR20)*2122 -> 954.9 | AT20: + | AU20: =IF(AS20<0,0,AS20) -> 954.9 | AW20: L | AX20: ='R.FILE GOC'!W71 -> 2.2 | AY20: 0 | AZ20: 954.9 | BA20: + | BB20: 954.9 | BD20: L | BE20: 2.3
