Workbook
Name _NEW2: [1]吊電B線入出料標準數據!$B$4:$P$4003
Name _XM_XT_THUCTE: 'XM.GUI MAIL'!$A$6:$AP$106
Name AB: #REF!
Name abcd: #REF!
Name abcd: #REF!
Name abcd: #REF!
Name abcd: #REF!
Name abcd: #REF!
Name abcd: #REF!
Name abcd: #REF!
Name abcd: #REF!
Name abcd: #REF!
Name abcd: #REF!
Name CCC: #REF!
Name CXXTA: #REF!
Name CXXTB: [1]吊電B線入出料標準數據!$B$3:$P$428
Name HUANGHAIDONGA: #REF!
Name HUANGHAIDONGB: [1]吊電B線入出料標準數據!$A$3:$P$428
Name PartNo: [2]All!$B$5:$Q$65536
Name RLMLXD: 'R.GUI MAIL'!$A$6:$AQ$114
Name sss: '[3]附表-01'!$A$2:$L$1662
Name WUJIWEI: #REF!
Name XTB123: [4]輸入!#REF!
Name xtl: [1]吊電B線入出料標準數據!$B$3:$P$4002

Sheet PT TAP CHAT
B1: MẪU GỬI NHÀ CUNG ỨNG
B2: =MENU!AC9 -> 2022/12/03
A3: NCC | B3: Type sample | C3: Test Item | D3: Standards | E3: Unit | F3: Result | G3: KQ NCC | H3: ±5%
A4: JASCO | B4: Akaline Zinc (XL-1E) | C4: Zn2+ | D4: ='XM.GUI MAIL'!E11 -> 7-12g/l (9g±1g/l) | E4: g/l | F4: ='XM.GUI MAIL'!H11 -> 10.01 | H4: =IF(G4="","",(F4-G4)/F4)
A5: JASCO | C5: NaOH | D5: ='XM.GUI MAIL'!E10 -> 130 - 150g/L (140±5g/L) | E5: g/l | F5: ='XM.GUI MAIL'!H10 -> 140 | H5: =IF(G5="","",(F5-G5)/F5)
A6: JASCO | C6: Na2CO3 | D6: ＜70g/L | E6: g/l | F6: =XM.HN!E60 -> 0 | H6: =IF(G6="","",(F6-G6)/F6)
A7: JASCO | C7: Fe | D7: <5 | E7: ppm | H7: =IF(G7="","",(F7-G7)/F7)
A8: JASCO | C8: Cu | D8: <5 | E8: ppm | H8: =IF(G8="","",(F8-G8)/F8)
A9: JASCO | C9: Cr | D9: <5 | E9: ppm | H9: =IF(G9="","",(F9-G9)/F9)
A10: JASCO | C10: Pb | D10: <5 | E10: ppm | H10: =IF(G10="","",(F10-G10)/F10)
A11: JASCO | B11: Màu (I) (TR173AH) (XL-1E) | C11: Cr2O3 (TR173AH) | D11: ='XM.GUI MAIL'!E12 -> 12~18 % (14±2%) | E11: % | F11: ='XM.GUI MAIL'!H12 -> 13.669065 | H11: =IF(G11="","",(F11-G11)/F11)
A12: JASCO | C12: pH | D12: ='XM.GUI MAIL'!E13 -> 1.6~2.2(1.8±0.1 ) | E12: / | F12: ='XM.GUI MAIL'!H13 -> 1.76 | H12: =IF(G12="","",(F12-G12)/F12)
A13: JASCO | C13: Fe | D13: <80 | E13: ppm | H13: =IF(G13="","",(F13-G13)/F13)
A14: JASCO | C14: Cu | D14: ＜5 | E14: ppm | H14: =IF(G14="","",(F14-G14)/F14)
A15: JASCO | C15: Zn | D15: ＜7000ppm | E15: ppm | H15: =IF(G15="","",(F15-G15)/F15)
A16: JASCO | B16: Màu K (5U109A) (XL-1E) | C16: Màu K (5U109A) | D16: ='XM.GUI MAIL'!E18 -> 5-10% (7.5±1%) | E16: % | F16: ='XM.GUI MAIL'!H18 -> 7.68 | H16: =IF(G16="","",(F16-G16)/F16)
A17: JASCO | C17: pH | D17: ='XM.GUI MAIL'!E19 -> 1.6~2.0(1.8±0.1) | E17: / | F17: ='XM.GUI MAIL'!H19 -> 2.25 | H17: =IF(G17="","",(F17-G17)/F17)
A18: JASCO | C18: Fe | D18: (2.1±0.1 ) | E18: ppm | H18: =(F18-G18)/F18 -> #DIV/0!
A19: JASCO | C19: Cu | D19: ＜5ppm | E19: ppm | H19: =(F19-G19)/F19 -> #DIV/0!
A20: JASCO | C20: Zn | D20: ＜7000ppm | E20: ppm | H20: =(F20-G20)/F20 -> #DIV/0!
B22: Type sample | C22: Test Item | D22: Standards | E22: Unit | F22: Result
A23: HALO | B23: Akaline Zinc (XL-1F) | C23: Zn2+ | D23: ='XM.GUI MAIL'!E42 -> 8-12g/l (10±1g/l) | E23: g/l | F23: ='XM.GUI MAIL'!H42 -> 8.19 | H23: =IF(G23="","",(F23-G23)/F23)
A24: HALO | C24: NaOH | D24: ='XM.GUI MAIL'!E41 -> 130 - 150g/L (140±10g/L) | E24: g/l | F24: ='XM.GUI MAIL'!H41 -> 140 | H24: =IF(G24="","",(F24-G24)/F24)
A25: HALO | C25: Na2CO3 | D25: ＜70g/L | E25: g/l | F25: =XM.HN!E61 -> 0 | H25: =IF(G25="","",(F25-G25)/F25)
A26: HALO | C26: Fe | D26: <5 | E26: ppm | H26: =IF(G26="","",(F26-G26)/F26)
A27: HALO | C27: Cu | D27: <5 | E27: ppm | H27: =IF(G27="","",(F27-G27)/F27)
A28: HALO | C28: Cr | D28: <5 | E28: ppm | H28: =IF(G28="","",(F28-G28)/F28)
A29: HALO | C29: Pb | D29: <5 | E29: ppm | H29: =IF(G29="","",(F29-G29)/F29)
A30: HALO | B30: Màu (I) (Lanthane 318) (XL-1F) | C30: Lanthane 318 | D30: ='XM.GUI MAIL'!E43 -> 6~10 % (8±0.5%) | E30: % | F30: ='XM.GUI MAIL'!H43 -> 5.81784 | H30: =IF(G30="","",(F30-G30)/F30)
A31: HALO | C31: pH | D31: ='XM.GUI MAIL'!E44 -> 2~2.5(2.3±0.1 ) | E31: / | F31: ='XM.GUI MAIL'!H44 -> 2.35 | H31: =IF(G31="","",(F31-G31)/F31)
A32: HALO | C32: Fe | D32: <80 | E32: ppm | H32: =IF(G32="","",(F32-G32)/F32)
A33: HALO | C33: Cu | D33: ＜5 | E33: ppm | H33: =IF(G33="","",(F33-G33)/F33)
A34: HALO | C34: Zn | D34: ＜7000ppm | E34: ppm | H34: =IF(G34="","",(F34-G34)/F34)
A35: HALO | B35: Màu (K) (Finidip 124) (XL-1F) | C35: Finidip 124 | D35: ='XM.GUI MAIL'!E49 -> 5~8% (6%±0.5) | E35: % | F35: ='XM.GUI MAIL'!H49 -> 5.9 | H35: =IF(G35="","",(F35-G35)/F35)
A36: HALO | C36: pH | D36: ='XM.GUI MAIL'!E50 -> 1.8~2.4 (2.1±0.1 ) | E36: / | F36: ='XM.GUI MAIL'!H50 -> 1.84 | H36: =IF(G36="","",(F36-G36)/F36)
A37: HALO | C37: Fe | D37: (2.1±0.1 ) | E37: ppm | H37: =(F37-G37)/F37 -> #DIV/0!
A38: HALO | C38: Cu | D38: ＜5ppm | E38: ppm | H38: =(F38-G38)/F38 -> #DIV/0!
A39: HALO | C39: Zn | D39: ＜7000ppm | E39: ppm | H39: =(F39-G39)/F39 -> #DIV/0!
B41: Type sample | C41: Test Item | D41: Standards | E41: Unit | F41: Result
A42: HALO | B42: Akaline Zinc (XT-0C) | C42: Zn2+ | D42: ='XM.GUI MAIL'!E73 -> 6~8g/L (7±0.5g/L) | E42: g/l | F42: ='XM.GUI MAIL'!H73 -> 0 | H42: =IF(G42="","",(F42-G42)/F42)
...

Sheet KT DAU
A1: BẢNG KIỂM TRA DẦU NHỚT TRONG BỒN NƯỚC SAU BỒN ACID
A2: Ngày: | B2: =MENU!AC9 -> 2022/12/03
A3: Chuyền | B3: Bồn nước | C3: phán định OK/NG
C4: 0.33333333 | D4: 0.66666667
A5: XL-001E | B5: aicd loãng--> nước
B6: acid hoạt hóa--> nước
B7: HNO3--> nước
A8: XL-001F | B8: aicd loãng--> nước
B9: acid hoạt hóa--> nước
B10: HNO3--> nước
A11: XT-001C | B11: aicd đặc--> nước
B12: HNO3--> nước
A14: ghi chú: | B14: stop: -

Sheet MENU
B3: XI MẠ, XI TREO | J3: RỬA LIỆU, MÀNG LOA, XI ĐEN | R3: KHÁC | V3: IMPORT | AA3: khoảng thời gian Import
B6: XM.HN | F6: XM.GUI MAIL | J6: ED-XI DEN | N6: R.GUI MAIL | R6: IT.NONG DO | V6: 1 | Y6: =AC9+TIME(8,45,0) -> 44898.365 | AA6: 8:15-8:45 | AC6: CA 1 | AD6: L.Yen
AC7: CA 2 | AD7: Trang
B9: XM.FILE GOC | F9: 1. XL-1E TT | J9: R.HN | N9: RL-LINE | R9: IT.NHIET DO | V9: 2 | Y9: =AC9+TIME(10,45,0) -> 44898.448 | AA9: 10:15-10:45 | AC9: 2022/12/03 | AE9: đánh năm/tháng/ngày vào ô bên
B12: 1. XL-1E kh | F12: 2. XL-1F TT | J12: R.FILE GOC | N12: 1.xi den TT | R12: GHI CHU | V12: 3 | Y12: =AC9+TIME(15,30,0) -> 44898.646 | AA12: 15:00-15:30
B15: 2. XL-1F kh | F15: 3.XT-C TT | J15: 1.xi den | N15: 2.RL E tt | R15: PP HÓA NGHIỆM FILE WORD | V15: 4 | Y15: =AC9+TIME(17,0,0) -> 44898.708 | AA15: 16:30-17:00 | AC15: ACID Đ.VAO
B18: 3.XT-C kh | F18: 4.Zn Ni TT | J18: 2.RL E | N18: 3.RL G tt | R18: QC- E | V18: 5 | Y18: =AC9+TIME(20,45,0) -> 44898.865 | AA18: 20:15-20:45
B21: 4.Zn Ni.kh | J21: 3.RL G | N21: 4.RL F tt | R21: QC-1F | V21: 6 | Y21: =AC9+TIME(22,45,0) -> 44898.948 | AA21: 22:15-22:45
B24: XM.BO SUNG kh | F24: XM.BO SUNG tt | J24: 4.RL F | N24: 5.ML tt | R24: QC- XT | V24: 7 | Y24: =AC9+TIME(3,0,0) -> 44898.125 | AA24: 2:30-3:00
J27: 5.ML | R27: QC-RL | V27: 8 | Y27: =AC9+TIME(5,0,0) -> 44898.208 | AA27: 4:30-5:00
B30: XM.chart | F30: XM.chart 1 | J30: RL.chart | N30: RL.chart1 | R30: QC-NI | AA30: tg import
R33: KT DAU
R36: PT TAP CHAT

Sheet 1
A1: "BÁO CÁO KẾT QUẢ HÓA NGHIỆM HÀNG NGÀY 表面處理生產製程管控記錄表"
A2: NGAY | B2: Ma__Hang_muc | C2: Nong_Do_01 | E2: 1 | F2: bs | G2: 2 | H2: bs | I2: 3 | J2: bs | K2: 4 | L2: bs | M2: 5 | N2: bs | O2: 6 | P2: bs | Q2: 1
A3: Date | B3: Code | C3: 濃度 g/L-01
A4: 2022/12/03 8:45:00 AM | B4: 1E-XB1 | C4: 30 | E4: TRUE | F4: FALSE | G4: FALSE | H4: FALSE | I4: FALSE | J4: FALSE | K4: FALSE | L4: FALSE | M4: FALSE | N4: FALSE | O4: FALSE | P4: FALSE
A5: 2022/12/03 8:45:00 AM | B5: 1E-XB2 | C5: 30.8 | E5: TRUE | F5: FALSE | G5: FALSE | H5: FALSE | I5: FALSE | J5: FALSE | K5: FALSE | L5: FALSE | M5: FALSE | N5: FALSE | O5: FALSE | P5: FALSE
A6: 2022/12/03 8:45:00 AM | B6: 1E-DG1 | C6: 65.6 | E6: TRUE | F6: FALSE | G6: FALSE | H6: FALSE | I6: FALSE | J6: FALSE | K6: FALSE | L6: FALSE | M6: FALSE | N6: FALSE | O6: FALSE | P6: FALSE
A7: 2022/12/03 8:45:00 AM | B7: 1E-DG2 | C7: 72.8 | E7: TRUE | F7: FALSE | G7: FALSE | H7: FALSE | I7: FALSE | J7: FALSE | K7: FALSE | L7: FALSE | M7: FALSE | N7: FALSE | O7: FALSE | P7: FALSE
A8: 2022/12/03 8:45:00 AM | B8: 1E-NAOH | C8: 140 | E8: TRUE | F8: FALSE | G8: FALSE | H8: FALSE | I8: FALSE | J8: FALSE | K8: FALSE | L8: FALSE | M8: FALSE | N8: FALSE | O8: FALSE | P8: FALSE
A9: 2022/12/03 8:45:00 AM | B9: 1E-ZN | C9: 10.01 | E9: TRUE | F9: FALSE | G9: FALSE | H9: FALSE | I9: FALSE | J9: FALSE | K9: FALSE | L9: FALSE | M9: FALSE | N9: FALSE | O9: FALSE | P9: FALSE
A10: 2022/12/03 8:45:00 AM | B10: 1E-CR3I | C10: 13.669065 | E10: TRUE | F10: FALSE | G10: FALSE | H10: FALSE | I10: FALSE | J10: FALSE | K10: FALSE | L10: FALSE | M10: FALSE | N10: FALSE | O10: FALSE | P10: FALSE
A11: 2022/12/03 8:45:00 AM | B11: 1E-CR3IPH | C11: 1.76 | E11: TRUE | F11: FALSE | G11: FALSE | H11: FALSE | I11: FALSE | J11: FALSE | K11: FALSE | L11: FALSE | M11: FALSE | N11: FALSE | O11: FALSE | P11: FALSE
A12: 2022/12/03 8:45:00 AM | B12: 1E-HCL1 | C12: 0.49046875 | E12: TRUE | F12: FALSE | G12: FALSE | H12: FALSE | I12: FALSE | J12: FALSE | K12: FALSE | L12: FALSE | M12: FALSE | N12: FALSE | O12: FALSE | P12: FALSE
A13: 2022/12/03 8:45:00 AM | B13: 1E-HCL2 | C13: 0.26234375 | E13: TRUE | F13: FALSE | G13: FALSE | H13: FALSE | I13: FALSE | J13: FALSE | K13: FALSE | L13: FALSE | M13: FALSE | N13: FALSE | O13: FALSE | P13: FALSE
A14: 2022/12/03 8:45:00 AM | B14: 1E-HCL3 | C14: 0.1140625 | E14: TRUE | F14: FALSE | G14: FALSE | H14: FALSE | I14: FALSE | J14: FALSE | K14: FALSE | L14: FALSE | M14: FALSE | N14: FALSE | O14: FALSE | P14: FALSE
A15: 2022/12/03 8:45:00 AM | B15: 1E-HNO3 | C15: 0.0113418 | E15: TRUE | F15: FALSE | G15: FALSE | H15: FALSE | I15: FALSE | J15: FALSE | K15: FALSE | L15: FALSE | M15: FALSE | N15: FALSE | O15: FALSE | P15: FALSE
... A58: 2022/12/03 8:45:00 AM | B58: DC-BLACK08 | C58: 5.62 | E58: TRUE | F58: FALSE | G58: FALSE | H58: FALSE | I58: FALSE | J58: FALSE | K58: FALSE | L58: FALSE | M58: FALSE | N58: FALSE | O58: FALSE | P58: FALSE

Sheet 2
A1: "BÁO CÁO KẾT QUẢ HÓA NGHIỆM HÀNG NGÀY 表面處理生產製程管控記錄表"
A2: NGAY | B2: Ma__Hang_muc | C2: Nong_Do_02 | E2: 1 | F2: bs | G2: 2 | H2: bs | I2: 3 | J2: bs | K2: 4 | L2: bs | M2: 5 | N2: bs | O2: 6 | P2: bs | Q2: 2
A3: Date | B3: Code | C3: 濃度 g/L-02
A4: 2022/12/03 10:45:00 AM | B4: 1E-XB1 | C4: 29.6 | E4: FALSE | F4: FALSE | G4: TRUE | H4: FALSE | I4: FALSE | J4: FALSE | K4: FALSE | L4: FALSE | M4: FALSE | N4: FALSE | O4: FALSE | P4: FALSE
A5: 2022/12/03 10:45:00 AM | B5: 1E-XB2 | C5: 30 | E5: FALSE | F5: FALSE | G5: TRUE | H5: FALSE | I5: FALSE | J5: FALSE | K5: FALSE | L5: FALSE | M5: FALSE | N5: FALSE | O5: FALSE | P5: FALSE
A6: 2022/12/03 10:45:00 AM | B6: 1E-DG1 | C6: 65.2 | E6: FALSE | F6: FALSE | G6: TRUE | H6: FALSE | I6: FALSE | J6: FALSE | K6: FALSE | L6: FALSE | M6: FALSE | N6: FALSE | O6: FALSE | P6: FALSE
A7: 2022/12/03 10:45:00 AM | B7: 1E-DG2 | C7: 71.2 | E7: FALSE | F7: FALSE | G7: TRUE | H7: FALSE | I7: FALSE | J7: FALSE | K7: FALSE | L7: FALSE | M7: FALSE | N7: FALSE | O7: FALSE | P7: FALSE
A8: 2022/12/03 10:45:00 AM | B8: 1E-NAOH | C8: 139.2 | E8: FALSE | F8: FALSE | G8: TRUE | H8: FALSE | I8: FALSE | J8: FALSE | K8: FALSE | L8: FALSE | M8: FALSE | N8: FALSE | O8: FALSE | P8: FALSE
A9: 2022/12/03 10:45:00 AM | B9: 1E-ZN | C9: 10.01 | E9: FALSE | F9: FALSE | G9: TRUE | H9: FALSE | I9: FALSE | J9: FALSE | K9: FALSE | L9: FALSE | M9: FALSE | N9: FALSE | O9: FALSE | P9: FALSE
A10: 2022/12/03 10:45:00 AM | B10: 1E-CR3I | C10: 14.388489 | E10: FALSE | F10: FALSE | G10: TRUE | H10: FALSE | I10: FALSE | J10: FALSE | K10: FALSE | L10: FALSE | M10: FALSE | N10: FALSE | O10: FALSE | P10: FALSE
A11: 2022/12/03 10:45:00 AM | B11: 1E-CR3IPH | C11: 1.75 | E11: FALSE | F11: FALSE | G11: TRUE | H11: FALSE | I11: FALSE | J11: FALSE | K11: FALSE | L11: FALSE | M11: FALSE | N11: FALSE | O11: FALSE | P11: FALSE
A12: 2022/12/03 10:45:00 AM | B12: 1E-HCL1 | C12: 0.45625 | E12: FALSE | F12: FALSE | G12: TRUE | H12: FALSE | I12: FALSE | J12: FALSE | K12: FALSE | L12: FALSE | M12: FALSE | N12: FALSE | O12: FALSE | P12: FALSE
A13: 2022/12/03 10:45:00 AM | B13: 1E-HCL2 | C13: 0.28515625 | E13: FALSE | F13: FALSE | G13: TRUE | H13: FALSE | I13: FALSE | J13: FALSE | K13: FALSE | L13: FALSE | M13: FALSE | N13: FALSE | O13: FALSE | P13: FALSE
A14: 2022/12/03 10:45:00 AM | B14: 1E-HCL3 | C14: 0.1049375 | E14: FALSE | F14: FALSE | G14: TRUE | H14: FALSE | I14: FALSE | J14: FALSE | K14: FALSE | L14: FALSE | M14: FALSE | N14: FALSE | O14: FALSE | P14: FALSE
A15: 2022/12/03 10:45:00 AM | B15: 1E-HNO3 | C15: 0.0100816 | E15: FALSE | F15: FALSE | G15: TRUE | H15: FALSE | I15: FALSE | J15: FALSE | K15: FALSE | L15: FALSE | M15: FALSE | N15: FALSE | O15: FALSE | P15: FALSE
... A31: 2022/12/03 10:45:00 AM | B31: 1F-BONG | C31: 42 | E31: FALSE | F31: FALSE | G31: TRUE | H31: FALSE | I31: FALSE | J31: FALSE | K31: FALSE | L31: FALSE | M31: FALSE | N31: FALSE | O31: FALSE | P31: FALSE

Sheet 3
A1: "BÁO CÁO KẾT QUẢ HÓA NGHIỆM HÀNG NGÀY 表面處理生產製程管控記錄表"
A2: NGAY | B2: Ma__Hang_muc | C2: Nong_Do_03 | E2: 1 | F2: bs | G2: 2 | H2: bs | I2: 3 | J2: bs | K2: 4 | L2: bs | M2: 5 | N2: bs | O2: 6 | P2: bs | Q2: 3
A3: Date | B3: Code | C3: 濃度 g/03
A4: 2022/12/03 3:30:00 PM | B4: 1E-XB1 | C4: 29.6 | E4: FALSE | F4: FALSE | G4: FALSE | H4: FALSE | I4: TRUE | J4: FALSE | K4: FALSE | L4: FALSE | M4: FALSE | N4: FALSE | O4: FALSE | P4: FALSE
A5: 2022/12/03 3:30:00 PM | B5: 1E-XB2 | C5: 30.8 | E5: FALSE | F5: FALSE | G5: FALSE | H5: FALSE | I5: TRUE | J5: FALSE | K5: FALSE | L5: FALSE | M5: FALSE | N5: FALSE | O5: FALSE | P5: FALSE
A6: 2022/12/03 3:30:00 PM | B6: 1E-DG1 | C6: 66.8 | E6: FALSE | F6: FALSE | G6: FALSE | H6: FALSE | I6: TRUE | J6: FALSE | K6: FALSE | L6: FALSE | M6: FALSE | N6: FALSE | O6: FALSE | P6: FALSE
A7: 2022/12/03 3:30:00 PM | B7: 1E-DG2 | C7: 71.6 | E7: FALSE | F7: FALSE | G7: FALSE | H7: FALSE | I7: TRUE | J7: FALSE | K7: FALSE | L7: FALSE | M7: FALSE | N7: FALSE | O7: FALSE | P7: FALSE
A8: 2022/12/03 3:30:00 PM | B8: 1E-NAOH | C8: 140.8 | E8: FALSE | F8: FALSE | G8: FALSE | H8: FALSE | I8: TRUE | J8: FALSE | K8: FALSE | L8: FALSE | M8: FALSE | N8: FALSE | O8: FALSE | P8: FALSE
A9: 2022/12/03 3:30:00 PM | B9: 1E-ZN | C9: 9.75 | E9: FALSE | F9: FALSE | G9: FALSE | H9: FALSE | I9: TRUE | J9: FALSE | K9: FALSE | L9: FALSE | M9: FALSE | N9: FALSE | O9: FALSE | P9: FALSE
A10: 2022/12/03 3:30:00 PM | B10: 1E-CR3I | C10: 15.251799 | E10: FALSE | F10: FALSE | G10: FALSE | H10: FALSE | I10: TRUE | J10: FALSE | K10: FALSE | L10: FALSE | M10: FALSE | N10: FALSE | O10: FALSE | P10: FALSE
A11: 2022/12/03 3:30:00 PM | B11: 1E-CR3IPH | C11: 1.89 | E11: FALSE | F11: FALSE | G11: FALSE | H11: FALSE | I11: TRUE | J11: FALSE | K11: FALSE | L11: FALSE | M11: FALSE | N11: FALSE | O11: FALSE | P11: FALSE
A12: 2022/12/03 3:30:00 PM | B12: 1E-HCL1 | C12: 0.46765625 | E12: FALSE | F12: FALSE | G12: FALSE | H12: FALSE | I12: TRUE | J12: FALSE | K12: FALSE | L12: FALSE | M12: FALSE | N12: FALSE | O12: FALSE | P12: FALSE
A13: 2022/12/03 3:30:00 PM | B13: 1E-HCL2 | C13: 0.2965625 | E13: FALSE | F13: FALSE | G13: FALSE | H13: FALSE | I13: TRUE | J13: FALSE | K13: FALSE | L13: FALSE | M13: FALSE | N13: FALSE | O13: FALSE | P13: FALSE
A14: 2022/12/03 3:30:00 PM | B14: 1E-HCL3 | C14: 0.09353125 | E14: FALSE | F14: FALSE | G14: FALSE | H14: FALSE | I14: TRUE | J14: FALSE | K14: FALSE | L14: FALSE | M14: FALSE | N14: FALSE | O14: FALSE | P14: FALSE
A15: 2022/12/03 3:30:00 PM | B15: 1E-HNO3 | C15: 0.0113418 | E15: FALSE | F15: FALSE | G15: FALSE | H15: FALSE | I15: TRUE | J15: FALSE | K15: FALSE | L15: FALSE | M15: FALSE | N15: FALSE | O15: FALSE | P15: FALSE
... A38: 2022/12/03 3:30:00 PM | B38: RLG-XBPH | C38: 9 | E38: FALSE | F38: FALSE | G38: FALSE | H38: FALSE | I38: TRUE | J38: FALSE | K38: FALSE | L38: FALSE | M38: FALSE | N38: FALSE | O38: FALSE | P38: FALSE

Sheet 4
A1: "BÁO CÁO KẾT QUẢ HÓA NGHIỆM HÀNG NGÀY 表面處理生產製程管控記錄表"
A2: NGAY | B2: Ma__Hang_muc | C2: Nong_Do_03 | E2: 1 | F2: bs | G2: 2 | H2: bs | I2: 3 | J2: bs | K2: 4 | L2: bs | M2: 5 | N2: bs | O2: 6 | P2: bs | Q2: 3
A3: Date | B3: Code | C3: 濃度 g/03
A4: =MENU!Y15 -> 44898.708 | B4: 1E-XB1 | E4: =ISNUMBER(#REF!) -> FALSE | F4: =ISNUMBER(#REF!) -> FALSE | G4: =ISNUMBER(#REF!) -> FALSE | H4: =ISNUMBER(#REF!) -> FALSE | I4: =ISNUMBER(C4) -> FALSE | J4: =ISNUMBER(#REF!) -> FALSE | K4: =ISNUMBER(#REF!) -> FALSE | L4: =ISNUMBER(#REF!) -> FALSE | M4: =ISNUMBER(#REF!) -> FALSE | N4: =ISNUMBER(#REF!) -> FALSE | O4: =ISNUMBER(#REF!) -> FALSE | P4: =ISNUMBER(#REF!) -> FALSE | Q4: =IF(I4=TRUE,"",1) -> 1
A5: =IF(B5="","",$A$4) -> 44898.708 | B5: RLE-HCL1 | C5: =IFERROR(VLOOKUP($B5,RLMLXD,20,0),"") -> 0 | E5: =ISNUMBER(#REF!) -> FALSE | F5: =ISNUMBER(#REF!) -> FALSE | G5: =ISNUMBER(#REF!) -> FALSE | H5: =ISNUMBER(#REF!) -> FALSE | I5: =ISNUMBER(C5) -> TRUE | J5: =ISNUMBER(#REF!) -> FALSE | K5: =ISNUMBER(#REF!) -> FALSE | L5: =ISNUMBER(#REF!) -> FALSE | M5: =ISNUMBER(#REF!) -> FALSE | N5: =ISNUMBER(#REF!) -> FALSE | O5: =ISNUMBER(#REF!) -> FALSE | P5: =ISNUMBER(#REF!) -> FALSE | Q5: =IF(I5=TRUE,"",1)
A6: =IF(B6="","",$A$4) -> 44898.708 | B6: RLE-HCL2 | C6: =IFERROR(VLOOKUP($B6,RLMLXD,20,0),"") -> 0 | E6: =ISNUMBER(#REF!) -> FALSE | F6: =ISNUMBER(#REF!) -> FALSE | G6: =ISNUMBER(#REF!) -> FALSE | H6: =ISNUMBER(#REF!) -> FALSE | I6: =ISNUMBER(C6) -> TRUE | J6: =ISNUMBER(#REF!) -> FALSE | K6: =ISNUMBER(#REF!) -> FALSE | L6: =ISNUMBER(#REF!) -> FALSE | M6: =ISNUMBER(#REF!) -> FALSE | N6: =ISNUMBER(#REF!) -> FALSE | O6: =ISNUMBER(#REF!) -> FALSE | P6: =ISNUMBER(#REF!) -> FALSE | Q6: =IF(I6=TRUE,"",1)
A7: =IF(B7="","",$A$4) -> 44898.708 | B7: RLE-PP1TA | C7: =IFERROR(VLOOKUP($B7,RLMLXD,20,0),"") -> 0 | E7: =ISNUMBER(#REF!) -> FALSE | F7: =ISNUMBER(#REF!) -> FALSE | G7: =ISNUMBER(#REF!) -> FALSE | H7: =ISNUMBER(#REF!) -> FALSE | I7: =ISNUMBER(C7) -> TRUE | J7: =ISNUMBER(#REF!) -> FALSE | K7: =ISNUMBER(#REF!) -> FALSE | L7: =ISNUMBER(#REF!) -> FALSE | M7: =ISNUMBER(#REF!) -> FALSE | N7: =ISNUMBER(#REF!) -> FALSE | O7: =ISNUMBER(#REF!) -> FALSE | P7: =ISNUMBER(#REF!) -> FALSE | Q7: =IF(I7=TRUE,"",1)
A8: =IF(B8="","",$A$4) -> 44898.708 | B8: RLE-PP1AX | C8: =IFERROR(VLOOKUP($B8,RLMLXD,20,0),"") -> 0 | E8: =ISNUMBER(#REF!) -> FALSE | F8: =ISNUMBER(#REF!) -> FALSE | G8: =ISNUMBER(#REF!) -> FALSE | H8: =ISNUMBER(#REF!) -> FALSE | I8: =ISNUMBER(C8) -> TRUE | J8: =ISNUMBER(#REF!) -> FALSE | K8: =ISNUMBER(#REF!) -> FALSE | L8: =ISNUMBER(#REF!) -> FALSE | M8: =ISNUMBER(#REF!) -> FALSE | N8: =ISNUMBER(#REF!) -> FALSE | O8: =ISNUMBER(#REF!) -> FALSE | P8: =ISNUMBER(#REF!) -> FALSE | Q8: =IF(I8=TRUE,"",1)
A9: =IF(B9="","",$A$4) -> 44898.708 | B9: RLE-PP1PL | C9: =IFERROR(VLOOKUP($B9,RLMLXD,20,0),"") -> 0 | E9: =ISNUMBER(#REF!) -> FALSE | F9: =ISNUMBER(#REF!) -> FALSE | G9: =ISNUMBER(#REF!) -> FALSE | H9: =ISNUMBER(#REF!) -> FALSE | I9: =ISNUMBER(C9) -> TRUE | J9: =ISNUMBER(#REF!) -> FALSE | K9: =ISNUMBER(#REF!) -> FALSE | L9: =ISNUMBER(#REF!) -> FALSE | M9: =ISNUMBER(#REF!) -> FALSE | N9: =ISNUMBER(#REF!) -> FALSE | O9: =ISNUMBER(#REF!) -> FALSE | P9: =ISNUMBER(#REF!) -> FALSE | Q9: =IF(I9=TRUE,"",1)
A10: =IF(B10="","",$A$4) -> 44898.708 | B10: RLE-PP2TA | C10: =IFERROR(VLOOKUP($B10,RLMLXD,20,0),"") -> 0 | E10: =ISNUMBER(#REF!) -> FALSE | F10: =ISNUMBER(#REF!) -> FALSE | G10: =ISNUMBER(#REF!) -> FALSE | H10: =ISNUMBER(#REF!) -> FALSE | I10: =ISNUMBER(C10) -> TRUE | J10: =ISNUMBER(#REF!) -> FALSE | K10: =ISNUMBER(#REF!) -> FALSE | L10: =ISNUMBER(#REF!) -> FALSE | M10: =ISNUMBER(#REF!) -> FALSE | N10: =ISNUMBER(#REF!) -> FALSE | O10: =ISNUMBER(#REF!) -> FALSE | P10: =ISNUMBER(#REF!) -> FALSE | Q10: =IF(I10=TRUE,"",1)
A11: =IF(B11="","",$A$4) -> 44898.708 | B11: RLE-PP2AX | C11: =IFERROR(VLOOKUP($B11,RLMLXD,20,0),"") -> 0 | E11: =ISNUMBER(#REF!) -> FALSE | F11: =ISNUMBER(#REF!) -> FALSE | G11: =ISNUMBER(#REF!) -> FALSE | H11: =ISNUMBER(#REF!) -> FALSE | I11: =ISNUMBER(C11) -> TRUE | J11: =ISNUMBER(#REF!) -> FALSE | K11: =ISNUMBER(#REF!) -> FALSE | L11: =ISNUMBER(#REF!) -> FALSE | M11: =ISNUMBER(#REF!) -> FALSE | N11: =ISNUMBER(#REF!) -> FALSE | O11: =ISNUMBER(#REF!) -> FALSE | P11: =ISNUMBER(#REF!) -> FALSE | Q11: =IF(I11=TRUE,"",1)
A12: =IF(B12="","",$A$4) -> 44898.708 | B12: RLE-PP2PL | C12: =IFERROR(VLOOKUP($B12,RLMLXD,20,0),"") -> 0 | E12: =ISNUMBER(#REF!) -> FALSE | F12: =ISNUMBER(#REF!) -> FALSE | G12: =ISNUMBER(#REF!) -> FALSE | H12: =ISNUMBER(#REF!) -> FALSE | I12: =ISNUMBER(C12) -> TRUE | J12: =ISNUMBER(#REF!) -> FALSE | K12: =ISNUMBER(#REF!) -> FALSE | L12: =ISNUMBER(#REF!) -> FALSE | M12: =ISNUMBER(#REF!) -> FALSE | N12: =ISNUMBER(#REF!) -> FALSE | O12: =ISNUMBER(#REF!) -> FALSE | P12: =ISNUMBER(#REF!) -> FALSE | Q12: =IF(I12=TRUE,"",1)
A13: =IF(B13="","",$A$4) -> 44898.708 | B13: RLE-XB | C13: =IFERROR(VLOOKUP($B13,RLMLXD,20,0),"") -> 0 | E13: =ISNUMBER(#REF!) -> FALSE | F13: =ISNUMBER(#REF!) -> FALSE | G13: =ISNUMBER(#REF!) -> FALSE | H13: =ISNUMBER(#REF!) -> FALSE | I13: =ISNUMBER(C13) -> TRUE | J13: =ISNUMBER(#REF!) -> FALSE | K13: =ISNUMBER(#REF!) -> FALSE | L13: =ISNUMBER(#REF!) -> FALSE | M13: =ISNUMBER(#REF!) -> FALSE | N13: =ISNUMBER(#REF!) -> FALSE | O13: =ISNUMBER(#REF!) -> FALSE | P13: =ISNUMBER(#REF!) -> FALSE | Q13: =IF(I13=TRUE,"",1)
A14: =IF(B14="","",$A$4) -> 44898.708 | B14: RLE-XBPH | C14: =IFERROR(VLOOKUP($B14,RLMLXD,20,0),"") -> 0 | E14: =ISNUMBER(#REF!) -> FALSE | F14: =ISNUMBER(#REF!) -> FALSE | G14: =ISNUMBER(#REF!) -> FALSE | H14: =ISNUMBER(#REF!) -> FALSE | I14: =ISNUMBER(C14) -> TRUE | J14: =ISNUMBER(#REF!) -> FALSE | K14: =ISNUMBER(#REF!) -> FALSE | L14: =ISNUMBER(#REF!) -> FALSE | M14: =ISNUMBER(#REF!) -> FALSE | N14: =ISNUMBER(#REF!) -> FALSE | O14: =ISNUMBER(#REF!) -> FALSE | P14: =ISNUMBER(#REF!) -> FALSE | Q14: =IF(I14=TRUE,"",1)
A15: =IF(B15="","",$A$4) -> 44898.708 | B15: RLG-KD | C15: =IFERROR(VLOOKUP($B15,RLMLXD,20,0),"") -> 0 | E15: =ISNUMBER(#REF!) -> FALSE | F15: =ISNUMBER(#REF!) -> FALSE | G15: =ISNUMBER(#REF!) -> FALSE | H15: =ISNUMBER(#REF!) -> FALSE | I15: =ISNUMBER(C15) -> TRUE | J15: =ISNUMBER(#REF!) -> FALSE | K15: =ISNUMBER(#REF!) -> FALSE | L15: =ISNUMBER(#REF!) -> FALSE | M15: =ISNUMBER(#REF!) -> FALSE | N15: =ISNUMBER(#REF!) -> FALSE | O15: =ISNUMBER(#REF!) -> FALSE | P15: =ISNUMBER(#REF!) -> FALSE | Q15: =IF(I15=TRUE,"",1)
A16: =IF(B16="","",$A$4) -> 44898.708 | B16: RLG-HCL1 | C16: =IFERROR(VLOOKUP($B16,RLMLXD,20,0),"") -> 0 | E16: =ISNUMBER(#REF!) -> FALSE | F16: =ISNUMBER(#REF!) -> FALSE | G16: =ISNUMBER(#REF!) -> FALSE | H16: =ISNUMBER(#REF!) -> FALSE | I16: =ISNUMBER(C16) -> TRUE | J16: =ISNUMBER(#REF!) -> FALSE | K16: =ISNUMBER(#REF!) -> FALSE | L16: =ISNUMBER(#REF!) -> FALSE | M16: =ISNUMBER(#REF!) -> FALSE | N16: =ISNUMBER(#REF!) -> FALSE | O16: =ISNUMBER(#REF!) -> FALSE | P16: =ISNUMBER(#REF!) -> FALSE | Q16: =IF(I16=TRUE,"",1)
... A33: =IF(B33="","",$A$4) -> 44898.708 | B33: XD-8 | C33: =IFERROR(VLOOKUP($B33,RLMLXD,20,0),"") -> 0.81368316 | E33: =ISNUMBER(#REF!) -> FALSE | F33: =ISNUMBER(#REF!) -> FALSE | G33: =ISNUMBER(#REF!) -> FALSE | H33: =ISNUMBER(#REF!) -> FALSE | I33: =ISNUMBER(C33) -> TRUE | J33: =ISNUMBER(#REF!) -> FALSE | K33: =ISNUMBER(#REF!) -> FALSE | L33: =ISNUMBER(#REF!) -> FALSE | M33: =ISNUMBER(#REF!) -> FALSE | N33: =ISNUMBER(#REF!) -> FALSE | O33: =ISNUMBER(#REF!) -> FALSE | P33: =ISNUMBER(#REF!) -> FALSE | Q33: =IF(I33=TRUE,"",1)

Sheet 5
A1: "BÁO CÁO KẾT QUẢ HÓA NGHIỆM HÀNG NGÀY 表面處理生產製程管控記錄表"
A2: NGAY | B2: Ma__Hang_muc | C2: Nong_Do_04 | E2: 1 | F2: bs | G2: 2 | H2: bs | I2: 3 | J2: bs | K2: 4 | L2: bs | M2: 5 | N2: bs | O2: 6 | P2: bs | Q2: 4
A3: Date | B3: Code | C3: 濃度 g/L_04
A4: =MENU!Y18 -> 44898.865 | B4: 1E-XB1 | C4: =IFERROR(VLOOKUP($B4,_XM_XT_THUCTE,26,0),"") -> 30 | E4: =ISNUMBER(#REF!) -> FALSE | F4: =ISNUMBER(#REF!) -> FALSE | G4: =ISNUMBER(#REF!) -> FALSE | H4: =ISNUMBER(#REF!) -> FALSE | I4: =ISNUMBER(#REF!) -> FALSE | J4: =ISNUMBER(#REF!) -> FALSE | K4: =ISNUMBER(C4) -> TRUE | L4: =ISNUMBER(#REF!) -> FALSE | M4: =ISNUMBER(#REF!) -> FALSE | N4: =ISNUMBER(#REF!) -> FALSE | O4: =ISNUMBER(#REF!) -> FALSE | P4: =ISNUMBER(#REF!) -> FALSE | Q4: =IF(K4=TRUE,"",1)
A5: =$A$4 -> 44898.865 | B5: 1E-XB2 | C5: =IFERROR(VLOOKUP($B5,_XM_XT_THUCTE,26,0),"") -> 31.6 | E5: =ISNUMBER(#REF!) -> FALSE | F5: =ISNUMBER(#REF!) -> FALSE | G5: =ISNUMBER(#REF!) -> FALSE | H5: =ISNUMBER(#REF!) -> FALSE | I5: =ISNUMBER(#REF!) -> FALSE | J5: =ISNUMBER(#REF!) -> FALSE | K5: =ISNUMBER(C5) -> TRUE | L5: =ISNUMBER(#REF!) -> FALSE | M5: =ISNUMBER(#REF!) -> FALSE | N5: =ISNUMBER(#REF!) -> FALSE | O5: =ISNUMBER(#REF!) -> FALSE | P5: =ISNUMBER(#REF!) -> FALSE | Q5: =IF(K5=TRUE,"",1)
A6: =$A$4 -> 44898.865 | B6: 1E-DG1 | C6: =IFERROR(VLOOKUP($B6,_XM_XT_THUCTE,26,0),"") -> 72.8 | E6: =ISNUMBER(#REF!) -> FALSE | F6: =ISNUMBER(#REF!) -> FALSE | G6: =ISNUMBER(#REF!) -> FALSE | H6: =ISNUMBER(#REF!) -> FALSE | I6: =ISNUMBER(#REF!) -> FALSE | J6: =ISNUMBER(#REF!) -> FALSE | K6: =ISNUMBER(C6) -> TRUE | L6: =ISNUMBER(#REF!) -> FALSE | M6: =ISNUMBER(#REF!) -> FALSE | N6: =ISNUMBER(#REF!) -> FALSE | O6: =ISNUMBER(#REF!) -> FALSE | P6: =ISNUMBER(#REF!) -> FALSE | Q6: =IF(K6=TRUE,"",1)
A7: =$A$4 -> 44898.865 | B7: 1E-DG2 | C7: =IFERROR(VLOOKUP($B7,_XM_XT_THUCTE,26,0),"") -> 70.4 | E7: =ISNUMBER(#REF!) -> FALSE | F7: =ISNUMBER(#REF!) -> FALSE | G7: =ISNUMBER(#REF!) -> FALSE | H7: =ISNUMBER(#REF!) -> FALSE | I7: =ISNUMBER(#REF!) -> FALSE | J7: =ISNUMBER(#REF!) -> FALSE | K7: =ISNUMBER(C7) -> TRUE | L7: =ISNUMBER(#REF!) -> FALSE | M7: =ISNUMBER(#REF!) -> FALSE | N7: =ISNUMBER(#REF!) -> FALSE | O7: =ISNUMBER(#REF!) -> FALSE | P7: =ISNUMBER(#REF!) -> FALSE | Q7: =IF(K7=TRUE,"",1)
A8: =$A$4 -> 44898.865 | B8: 1E-NAOH | C8: =IFERROR(VLOOKUP($B8,_XM_XT_THUCTE,26,0),"") -> 140.8 | E8: =ISNUMBER(#REF!) -> FALSE | F8: =ISNUMBER(#REF!) -> FALSE | G8: =ISNUMBER(#REF!) -> FALSE | H8: =ISNUMBER(#REF!) -> FALSE | I8: =ISNUMBER(#REF!) -> FALSE | J8: =ISNUMBER(#REF!) -> FALSE | K8: =ISNUMBER(C8) -> TRUE | L8: =ISNUMBER(#REF!) -> FALSE | M8: =ISNUMBER(#REF!) -> FALSE | N8: =ISNUMBER(#REF!) -> FALSE | O8: =ISNUMBER(#REF!) -> FALSE | P8: =ISNUMBER(#REF!) -> FALSE | Q8: =IF(K8=TRUE,"",1)
A9: =$A$4 -> 44898.865 | B9: 1E-ZN | C9: =IFERROR(VLOOKUP($B9,_XM_XT_THUCTE,26,0),"") -> 9.88 | E9: =ISNUMBER(#REF!) -> FALSE | F9: =ISNUMBER(#REF!) -> FALSE | G9: =ISNUMBER(#REF!) -> FALSE | H9: =ISNUMBER(#REF!) -> FALSE | I9: =ISNUMBER(#REF!) -> FALSE | J9: =ISNUMBER(#REF!) -> FALSE | K9: =ISNUMBER(C9) -> TRUE | L9: =ISNUMBER(#REF!) -> FALSE | M9: =ISNUMBER(#REF!) -> FALSE | N9: =ISNUMBER(#REF!) -> FALSE | O9: =ISNUMBER(#REF!) -> FALSE | P9: =ISNUMBER(#REF!) -> FALSE | Q9: =IF(K9=TRUE,"",1)
A10: =$A$4 -> 44898.865 | B10: 1E-CR3I | C10: =IFERROR(VLOOKUP($B10,_XM_XT_THUCTE,26,0),"") -> 11.654676 | E10: =ISNUMBER(#REF!) -> FALSE | F10: =ISNUMBER(#REF!) -> FALSE | G10: =ISNUMBER(#REF!) -> FALSE | H10: =ISNUMBER(#REF!) -> FALSE | I10: =ISNUMBER(#REF!) -> FALSE | J10: =ISNUMBER(#REF!) -> FALSE | K10: =ISNUMBER(C10) -> TRUE | L10: =ISNUMBER(#REF!) -> FALSE | M10: =ISNUMBER(#REF!) -> FALSE | N10: =ISNUMBER(#REF!) -> FALSE | O10: =ISNUMBER(#REF!) -> FALSE | P10: =ISNUMBER(#REF!) -> FALSE | Q10: =IF(K10=TRUE,"",1)
A11: =$A$4 -> 44898.865 | B11: 1E-CR3IPH | C11: =IFERROR(VLOOKUP($B11,_XM_XT_THUCTE,26,0),"") -> 1.78 | E11: =ISNUMBER(#REF!) -> FALSE | F11: =ISNUMBER(#REF!) -> FALSE | G11: =ISNUMBER(#REF!) -> FALSE | H11: =ISNUMBER(#REF!) -> FALSE | I11: =ISNUMBER(#REF!) -> FALSE | J11: =ISNUMBER(#REF!) -> FALSE | K11: =ISNUMBER(C11) -> TRUE | L11: =ISNUMBER(#REF!) -> FALSE | M11: =ISNUMBER(#REF!) -> FALSE | N11: =ISNUMBER(#REF!) -> FALSE | O11: =ISNUMBER(#REF!) -> FALSE | P11: =ISNUMBER(#REF!) -> FALSE | Q11: =IF(K11=TRUE,"",1)
A12: =$A$4 -> 44898.865 | B12: 1E-HCL1 | C12: =IFERROR(VLOOKUP($B12,_XM_XT_THUCTE,26,0),"") -> 0.45625 | E12: =ISNUMBER(#REF!) -> FALSE | F12: =ISNUMBER(#REF!) -> FALSE | G12: =ISNUMBER(#REF!) -> FALSE | H12: =ISNUMBER(#REF!) -> FALSE | I12: =ISNUMBER(#REF!) -> FALSE | J12: =ISNUMBER(#REF!) -> FALSE | K12: =ISNUMBER(C12) -> TRUE | L12: =ISNUMBER(#REF!) -> FALSE | M12: =ISNUMBER(#REF!) -> FALSE | N12: =ISNUMBER(#REF!) -> FALSE | O12: =ISNUMBER(#REF!) -> FALSE | P12: =ISNUMBER(#REF!) -> FALSE | Q12: =IF(K12=TRUE,"",1)
A13: =$A$4 -> 44898.865 | B13: 1E-HCL2 | C13: =IFERROR(VLOOKUP($B13,_XM_XT_THUCTE,26,0),"") -> 0.2509375 | E13: =ISNUMBER(#REF!) -> FALSE | F13: =ISNUMBER(#REF!) -> FALSE | G13: =ISNUMBER(#REF!) -> FALSE | H13: =ISNUMBER(#REF!) -> FALSE | I13: =ISNUMBER(#REF!) -> FALSE | J13: =ISNUMBER(#REF!) -> FALSE | K13: =ISNUMBER(C13) -> TRUE | L13: =ISNUMBER(#REF!) -> FALSE | M13: =ISNUMBER(#REF!) -> FALSE | N13: =ISNUMBER(#REF!) -> FALSE | O13: =ISNUMBER(#REF!) -> FALSE | P13: =ISNUMBER(#REF!) -> FALSE | Q13: =IF(K13=TRUE,"",1)
A14: =$A$4 -> 44898.865 | B14: 1E-HCL3 | C14: =IFERROR(VLOOKUP($B14,_XM_XT_THUCTE,26,0),"") -> 0.10265625 | E14: =ISNUMBER(#REF!) -> FALSE | F14: =ISNUMBER(#REF!) -> FALSE | G14: =ISNUMBER(#REF!) -> FALSE | H14: =ISNUMBER(#REF!) -> FALSE | I14: =ISNUMBER(#REF!) -> FALSE | J14: =ISNUMBER(#REF!) -> FALSE | K14: =ISNUMBER(C14) -> TRUE | L14: =ISNUMBER(#REF!) -> FALSE | M14: =ISNUMBER(#REF!) -> FALSE | N14: =ISNUMBER(#REF!) -> FALSE | O14: =ISNUMBER(#REF!) -> FALSE | P14: =ISNUMBER(#REF!) -> FALSE | Q14: =IF(K14=TRUE,"",1)
A15: =$A$4 -> 44898.865 | B15: 1E-HNO3 | C15: =IFERROR(VLOOKUP($B15,_XM_XT_THUCTE,26,0),"") -> 0.012602 | E15: =ISNUMBER(#REF!) -> FALSE | F15: =ISNUMBER(#REF!) -> FALSE | G15: =ISNUMBER(#REF!) -> FALSE | H15: =ISNUMBER(#REF!) -> FALSE | I15: =ISNUMBER(#REF!) -> FALSE | J15: =ISNUMBER(#REF!) -> FALSE | K15: =ISNUMBER(C15) -> TRUE | L15: =ISNUMBER(#REF!) -> FALSE | M15: =ISNUMBER(#REF!) -> FALSE | N15: =ISNUMBER(#REF!) -> FALSE | O15: =ISNUMBER(#REF!) -> FALSE | P15: =ISNUMBER(#REF!) -> FALSE | Q15: =IF(K15=TRUE,"",1)
A16: =$A$4 -> 44898.865 | B16: 1E-MEM | C16: =IFERROR(VLOOKUP($B16,_XM_XT_THUCTE,26,0),"") -> 335 | E16: =ISNUMBER(#REF!) -> FALSE | F16: =ISNUMBER(#REF!) -> FALSE | G16: =ISNUMBER(#REF!) -> FALSE | H16: =ISNUMBER(#REF!) -> FALSE | I16: =ISNUMBER(#REF!) -> FALSE | J16: =ISNUMBER(#REF!) -> FALSE | K16: =ISNUMBER(C16) -> TRUE | L16: =ISNUMBER(#REF!) -> FALSE | M16: =ISNUMBER(#REF!) -> FALSE | N16: =ISNUMBER(#REF!) -> FALSE | O16: =ISNUMBER(#REF!) -> FALSE | P16: =ISNUMBER(#REF!) -> FALSE | Q16: =IF(K16=TRUE,"",1)
... A45: =$A$4 -> 44898.865 | B45: XT-MEM | C45: =IFERROR(VLOOKUP($B45,_XM_XT_THUCTE,26,0),"") -> 0 | E45: =ISNUMBER(#REF!) -> FALSE | F45: =ISNUMBER(#REF!) -> FALSE | G45: =ISNUMBER(#REF!) -> FALSE | H45: =ISNUMBER(#REF!) -> FALSE | I45: =ISNUMBER(#REF!) -> FALSE | J45: =ISNUMBER(#REF!) -> FALSE | K45: =ISNUMBER(C45) -> TRUE | L45: =ISNUMBER(#REF!) -> FALSE | M45: =ISNUMBER(#REF!) -> FALSE | N45: =ISNUMBER(#REF!) -> FALSE | O45: =ISNUMBER(#REF!) -> FALSE | P45: =ISNUMBER(#REF!) -> FALSE | Q45: =IF(K45=TRUE,"",1)
A46: =$A$4 -> 44898.865 | B46: RLE-HCL1 | C46: =IFERROR(VLOOKUP($B46,RLMLXD,26,0),"") -> 0 | E46: =ISNUMBER(#REF!) -> FALSE | F46: =ISNUMBER(#REF!) -> FALSE | G46: =ISNUMBER(#REF!) -> FALSE | H46: =ISNUMBER(#REF!) -> FALSE | I46: =ISNUMBER(#REF!) -> FALSE | J46: =ISNUMBER(#REF!) -> FALSE | K46: =ISNUMBER(C46) -> TRUE | L46: =ISNUMBER(#REF!) -> FALSE | M46: =ISNUMBER(#REF!) -> FALSE | N46: =ISNUMBER(#REF!) -> FALSE | O46: =ISNUMBER(#REF!) -> FALSE | P46: =ISNUMBER(#REF!) -> FALSE | Q46: =IF(K46=TRUE,"",1)
A47: =$A$4 -> 44898.865 | B47: RLE-HCL2 | C47: =IFERROR(VLOOKUP($B47,RLMLXD,26,0),"") -> 0 | E47: =ISNUMBER(#REF!) -> FALSE | F47: =ISNUMBER(#REF!) -> FALSE | G47: =ISNUMBER(#REF!) -> FALSE | H47: =ISNUMBER(#REF!) -> FALSE | I47: =ISNUMBER(#REF!) -> FALSE | J47: =ISNUMBER(#REF!) -> FALSE | K47: =ISNUMBER(C47) -> TRUE | L47: =ISNUMBER(#REF!) -> FALSE | M47: =ISNUMBER(#REF!) -> FALSE | N47: =ISNUMBER(#REF!) -> FALSE | O47: =ISNUMBER(#REF!) -> FALSE | P47: =ISNUMBER(#REF!) -> FALSE | Q47: =IF(K47=TRUE,"",1)
A48: =$A$4 -> 44898.865 | B48: RLE-PP1TA | C48: =IFERROR(VLOOKUP($B48,RLMLXD,26,0),"") -> 0 | E48: =ISNUMBER(#REF!) -> FALSE | F48: =ISNUMBER(#REF!) -> FALSE | G48: =ISNUMBER(#REF!) -> FALSE | H48: =ISNUMBER(#REF!) -> FALSE | I48: =ISNUMBER(#REF!) -> FALSE | J48: =ISNUMBER(#REF!) -> FALSE | K48: =ISNUMBER(C48) -> TRUE | L48: =ISNUMBER(#REF!) -> FALSE | M48: =ISNUMBER(#REF!) -> FALSE | N48: =ISNUMBER(#REF!) -> FALSE | O48: =ISNUMBER(#REF!) -> FALSE | P48: =ISNUMBER(#REF!) -> FALSE | Q48: =IF(K48=TRUE,"",1)
A49: =$A$4 -> 44898.865 | B49: RLE-PP1AX | C49: =IFERROR(VLOOKUP($B49,RLMLXD,26,0),"") -> 0 | E49: =ISNUMBER(#REF!) -> FALSE | F49: =ISNUMBER(#REF!) -> FALSE | G49: =ISNUMBER(#REF!) -> FALSE | H49: =ISNUMBER(#REF!) -> FALSE | I49: =ISNUMBER(#REF!) -> FALSE | J49: =ISNUMBER(#REF!) -> FALSE | K49: =ISNUMBER(C49) -> TRUE | L49: =ISNUMBER(#REF!) -> FALSE | M49: =ISNUMBER(#REF!) -> FALSE | N49: =ISNUMBER(#REF!) -> FALSE | O49: =ISNUMBER(#REF!) -> FALSE | P49: =ISNUMBER(#REF!) -> FALSE | Q49: =IF(K49=TRUE,"",1)
A50: =$A$4 -> 44898.865 | B50: RLE-PP1PL | C50: =IFERROR(VLOOKUP($B50,RLMLXD,26,0),"") -> 0 | E50: =ISNUMBER(#REF!) -> FALSE | F50: =ISNUMBER(#REF!) -> FALSE | G50: =ISNUMBER(#REF!) -> FALSE | H50: =ISNUMBER(#REF!) -> FALSE | I50: =ISNUMBER(#REF!) -> FALSE | J50: =ISNUMBER(#REF!) -> FALSE | K50: =ISNUMBER(C50) -> TRUE | L50: =ISNUMBER(#REF!) -> FALSE | M50: =ISNUMBER(#REF!) -> FALSE | N50: =ISNUMBER(#REF!) -> FALSE | O50: =ISNUMBER(#REF!) -> FALSE | P50: =ISNUMBER(#REF!) -> FALSE | Q50: =IF(K50=TRUE,"",1)
A51: =$A$4 -> 44898.865 | B51: RLE-PP2TA | C51: =IFERROR(VLOOKUP($B51,RLMLXD,26,0),"") -> 0 | E51: =ISNUMBER(#REF!) -> FALSE | F51: =ISNUMBER(#REF!) -> FALSE | G51: =ISNUMBER(#REF!) -> FALSE | H51: =ISNUMBER(#REF!) -> FALSE | I51: =ISNUMBER(#REF!) -> FALSE | J51: =ISNUMBER(#REF!) -> FALSE | K51: =ISNUMBER(C51) -> TRUE | L51: =ISNUMBER(#REF!) -> FALSE | M51: =ISNUMBER(#REF!) -> FALSE | N51: =ISNUMBER(#REF!) -> FALSE | O51: =ISNUMBER(#REF!) -> FALSE | P51: =ISNUMBER(#REF!) -> FALSE | Q51: =IF(K51=TRUE,"",1)
A52: =$A$4 -> 44898.865 | B52: RLE-PP2AX | C52: =IFERROR(VLOOKUP($B52,RLMLXD,26,0),"") -> 0 | E52: =ISNUMBER(#REF!) -> FALSE | F52: =ISNUMBER(#REF!) -> FALSE | G52: =ISNUMBER(#REF!) -> FALSE | H52: =ISNUMBER(#REF!) -> FALSE | I52: =ISNUMBER(#REF!) -> FALSE | J52: =ISNUMBER(#REF!) -> FALSE | K52: =ISNUMBER(C52) -> TRUE | L52: =ISNUMBER(#REF!) -> FALSE | M52: =ISNUMBER(#REF!) -> FALSE | N52: =ISNUMBER(#REF!) -> FALSE | O52: =ISNUMBER(#REF!) -> FALSE | P52: =ISNUMBER(#REF!) -> FALSE | Q52: =IF(K52=TRUE,"",1)
A53: =$A$4 -> 44898.865 | B53: RLE-PP2PL | C53: =IFERROR(VLOOKUP($B53,RLMLXD,26,0),"") -> 0 | E53: =ISNUMBER(#REF!) -> FALSE | F53: =ISNUMBER(#REF!) -> FALSE | G53: =ISNUMBER(#REF!) -> FALSE | H53: =ISNUMBER(#REF!) -> FALSE | I53: =ISNUMBER(#REF!) -> FALSE | J53: =ISNUMBER(#REF!) -> FALSE | K53: =ISNUMBER(C53) -> TRUE | L53: =ISNUMBER(#REF!) -> FALSE | M53: =ISNUMBER(#REF!) -> FALSE | N53: =ISNUMBER(#REF!) -> FALSE | O53: =ISNUMBER(#REF!) -> FALSE | P53: =ISNUMBER(#REF!) -> FALSE | Q53: =IF(K53=TRUE,"",1)
A54: =$A$4 -> 44898.865 | B54: RLE-XB | C54: =IFERROR(VLOOKUP($B54,RLMLXD,26,0),"") -> 0 | E54: =ISNUMBER(#REF!) -> FALSE | F54: =ISNUMBER(#REF!) -> FALSE | G54: =ISNUMBER(#REF!) -> FALSE | H54: =ISNUMBER(#REF!) -> FALSE | I54: =ISNUMBER(#REF!) -> FALSE | J54: =ISNUMBER(#REF!) -> FALSE | K54: =ISNUMBER(C54) -> TRUE | L54: =ISNUMBER(#REF!) -> FALSE | M54: =ISNUMBER(#REF!) -> FALSE | N54: =ISNUMBER(#REF!) -> FALSE | O54: =ISNUMBER(#REF!) -> FALSE | P54: =ISNUMBER(#REF!) -> FALSE | Q54: =IF(K54=TRUE,"",1)
A55: =$A$4 -> 44898.865 | B55: RLE-XBPH | C55: =IFERROR(VLOOKUP($B55,RLMLXD,26,0),"") -> 0 | E55: =ISNUMBER(#REF!) -> FALSE | F55: =ISNUMBER(#REF!) -> FALSE | G55: =ISNUMBER(#REF!) -> FALSE | H55: =ISNUMBER(#REF!) -> FALSE | I55: =ISNUMBER(#REF!) -> FALSE | J55: =ISNUMBER(#REF!) -> FALSE | K55: =ISNUMBER(C55) -> TRUE | L55: =ISNUMBER(#REF!) -> FALSE | M55: =ISNUMBER(#REF!) -> FALSE | N55: =ISNUMBER(#REF!) -> FALSE | O55: =ISNUMBER(#REF!) -> FALSE | P55: =ISNUMBER(#REF!) -> FALSE | Q55: =IF(K55=TRUE,"",1)
A56: =$A$4 -> 44898.865 | B56: RLG-KD | C56: =IFERROR(VLOOKUP($B56,RLMLXD,26,0),"") -> 0 | E56: =ISNUMBER(#REF!) -> FALSE | F56: =ISNUMBER(#REF!) -> FALSE | G56: =ISNUMBER(#REF!) -> FALSE | H56: =ISNUMBER(#REF!) -> FALSE | I56: =ISNUMBER(#REF!) -> FALSE | J56: =ISNUMBER(#REF!) -> FALSE | K56: =ISNUMBER(C56) -> TRUE | L56: =ISNUMBER(#REF!) -> FALSE | M56: =ISNUMBER(#REF!) -> FALSE | N56: =ISNUMBER(#REF!) -> FALSE | O56: =ISNUMBER(#REF!) -> FALSE | P56: =ISNUMBER(#REF!) -> FALSE | Q56: =IF(K56=TRUE,"",1)
A57: =$A$4 -> 44898.865 | B57: RLG-HCL1 | C57: =IFERROR(VLOOKUP($B57,RLMLXD,26,0),"") -> 0 | E57: =ISNUMBER(#REF!) -> FALSE | F57: =ISNUMBER(#REF!) -> FALSE | G57: =ISNUMBER(#REF!) -> FALSE | H57: =ISNUMBER(#REF!) -> FALSE | I57: =ISNUMBER(#REF!) -> FALSE | J57: =ISNUMBER(#REF!) -> FALSE | K57: =ISNUMBER(C57) -> TRUE | L57: =ISNUMBER(#REF!) -> FALSE | M57: =ISNUMBER(#REF!) -> FALSE | N57: =ISNUMBER(#REF!) -> FALSE | O57: =ISNUMBER(#REF!) -> FALSE | P57: =ISNUMBER(#REF!) -> FALSE | Q57: =IF(K57=TRUE,"",1)
... A83: =$A$4 -> 44898.865 | B83: DC-BLACK08 | C83: =IFERROR(VLOOKUP($B83,RLMLXD,26,0),"") -> 0 | E83: =ISNUMBER(#REF!) -> FALSE | F83: =ISNUMBER(#REF!) -> FALSE | G83: =ISNUMBER(#REF!) -> FALSE | H83: =ISNUMBER(#REF!) -> FALSE | I83: =ISNUMBER(#REF!) -> FALSE | J83: =ISNUMBER(#REF!) -> FALSE | K83: =ISNUMBER(C83) -> TRUE | L83: =ISNUMBER(#REF!) -> FALSE | M83: =ISNUMBER(#REF!) -> FALSE | N83: =ISNUMBER(#REF!) -> FALSE | O83: =ISNUMBER(#REF!) -> FALSE | P83: =ISNUMBER(#REF!) -> FALSE | Q83: =IF(K83=TRUE,"",1)

Sheet 6
A1: "BÁO CÁO KẾT QUẢ HÓA NGHIỆM HÀNG NGÀY 表面處理生產製程管控記錄表"
A2: NGAY | B2: Ma__Hang_muc | C2: Nong_Do_05 | E2: 1 | F2: bs | G2: 2 | H2: bs | I2: 3 | J2: bs | K2: 4 | L2: bs | M2: 5 | N2: bs | O2: 6 | P2: bs | Q2: 5
A3: Date | B3: Code | C3: 濃度 g/L_05
A4: =MENU!Y21 -> 44898.948 | B4: 1E-XB1 | C4: =IFERROR(VLOOKUP($B4,_XM_XT_THUCTE,32,0),"") -> 0 | E4: =ISNUMBER(#REF!) -> FALSE | F4: =ISNUMBER(#REF!) -> FALSE | G4: =ISNUMBER(#REF!) -> FALSE | H4: =ISNUMBER(#REF!) -> FALSE | I4: =ISNUMBER(#REF!) -> FALSE | J4: =ISNUMBER(#REF!) -> FALSE | K4: =ISNUMBER(#REF!) -> FALSE | L4: =ISNUMBER(#REF!) -> FALSE | M4: =ISNUMBER(C4) -> TRUE | N4: =ISNUMBER(#REF!) -> FALSE | O4: =ISNUMBER(#REF!) -> FALSE | P4: =ISNUMBER(#REF!) -> FALSE | Q4: =IF(M4=TRUE,"",1)
A5: =IF(B5="","",$A$4) -> 44898.948 | B5: 1E-XB2 | C5: =IFERROR(VLOOKUP($B5,_XM_XT_THUCTE,32,0),"") -> 0 | E5: =ISNUMBER(#REF!) -> FALSE | F5: =ISNUMBER(#REF!) -> FALSE | G5: =ISNUMBER(#REF!) -> FALSE | H5: =ISNUMBER(#REF!) -> FALSE | I5: =ISNUMBER(#REF!) -> FALSE | J5: =ISNUMBER(#REF!) -> FALSE | K5: =ISNUMBER(#REF!) -> FALSE | L5: =ISNUMBER(#REF!) -> FALSE | M5: =ISNUMBER(C5) -> TRUE | N5: =ISNUMBER(#REF!) -> FALSE | O5: =ISNUMBER(#REF!) -> FALSE | P5: =ISNUMBER(#REF!) -> FALSE | Q5: =IF(M5=TRUE,"",1)
A6: =IF(B6="","",$A$4) -> 44898.948 | B6: 1E-DG1 | C6: =IFERROR(VLOOKUP($B6,_XM_XT_THUCTE,32,0),"") -> 0 | E6: =ISNUMBER(#REF!) -> FALSE | F6: =ISNUMBER(#REF!) -> FALSE | G6: =ISNUMBER(#REF!) -> FALSE | H6: =ISNUMBER(#REF!) -> FALSE | I6: =ISNUMBER(#REF!) -> FALSE | J6: =ISNUMBER(#REF!) -> FALSE | K6: =ISNUMBER(#REF!) -> FALSE | L6: =ISNUMBER(#REF!) -> FALSE | M6: =ISNUMBER(C6) -> TRUE | N6: =ISNUMBER(#REF!) -> FALSE | O6: =ISNUMBER(#REF!) -> FALSE | P6: =ISNUMBER(#REF!) -> FALSE | Q6: =IF(M6=TRUE,"",1)
A7: =IF(B7="","",$A$4) -> 44898.948 | B7: 1E-DG2 | C7: =IFERROR(VLOOKUP($B7,_XM_XT_THUCTE,32,0),"") -> 0 | E7: =ISNUMBER(#REF!) -> FALSE | F7: =ISNUMBER(#REF!) -> FALSE | G7: =ISNUMBER(#REF!) -> FALSE | H7: =ISNUMBER(#REF!) -> FALSE | I7: =ISNUMBER(#REF!) -> FALSE | J7: =ISNUMBER(#REF!) -> FALSE | K7: =ISNUMBER(#REF!) -> FALSE | L7: =ISNUMBER(#REF!) -> FALSE | M7: =ISNUMBER(C7) -> TRUE | N7: =ISNUMBER(#REF!) -> FALSE | O7: =ISNUMBER(#REF!) -> FALSE | P7: =ISNUMBER(#REF!) -> FALSE | Q7: =IF(M7=TRUE,"",1)
A8: =IF(B8="","",$A$4) -> 44898.948 | B8: 1E-NAOH | C8: =IFERROR(VLOOKUP($B8,_XM_XT_THUCTE,32,0),"") -> 0 | E8: =ISNUMBER(#REF!) -> FALSE | F8: =ISNUMBER(#REF!) -> FALSE | G8: =ISNUMBER(#REF!) -> FALSE | H8: =ISNUMBER(#REF!) -> FALSE | I8: =ISNUMBER(#REF!) -> FALSE | J8: =ISNUMBER(#REF!) -> FALSE | K8: =ISNUMBER(#REF!) -> FALSE | L8: =ISNUMBER(#REF!) -> FALSE | M8: =ISNUMBER(C8) -> TRUE | N8: =ISNUMBER(#REF!) -> FALSE | O8: =ISNUMBER(#REF!) -> FALSE | P8: =ISNUMBER(#REF!) -> FALSE | Q8: =IF(M8=TRUE,"",1)
A9: =IF(B9="","",$A$4) -> 44898.948 | B9: 1E-ZN | C9: =IFERROR(VLOOKUP($B9,_XM_XT_THUCTE,32,0),"") -> 0 | E9: =ISNUMBER(#REF!) -> FALSE | F9: =ISNUMBER(#REF!) -> FALSE | G9: =ISNUMBER(#REF!) -> FALSE | H9: =ISNUMBER(#REF!) -> FALSE | I9: =ISNUMBER(#REF!) -> FALSE | J9: =ISNUMBER(#REF!) -> FALSE | K9: =ISNUMBER(#REF!) -> FALSE | L9: =ISNUMBER(#REF!) -> FALSE | M9: =ISNUMBER(C9) -> TRUE | N9: =ISNUMBER(#REF!) -> FALSE | O9: =ISNUMBER(#REF!) -> FALSE | P9: =ISNUMBER(#REF!) -> FALSE | Q9: =IF(M9=TRUE,"",1)
A10: =IF(B10="","",$A$4) -> 44898.948 | B10: 1E-CR3I | C10: =IFERROR(VLOOKUP($B10,_XM_XT_THUCTE,32,0),"") -> 0 | E10: =ISNUMBER(#REF!) -> FALSE | F10: =ISNUMBER(#REF!) -> FALSE | G10: =ISNUMBER(#REF!) -> FALSE | H10: =ISNUMBER(#REF!) -> FALSE | I10: =ISNUMBER(#REF!) -> FALSE | J10: =ISNUMBER(#REF!) -> FALSE | K10: =ISNUMBER(#REF!) -> FALSE | L10: =ISNUMBER(#REF!) -> FALSE | M10: =ISNUMBER(C10) -> TRUE | N10: =ISNUMBER(#REF!) -> FALSE | O10: =ISNUMBER(#REF!) -> FALSE | P10: =ISNUMBER(#REF!) -> FALSE | Q10: =IF(M10=TRUE,"",1)
A11: =IF(B11="","",$A$4) -> 44898.948 | B11: 1E-CR3IPH | C11: =IFERROR(VLOOKUP($B11,_XM_XT_THUCTE,32,0),"") -> 0 | E11: =ISNUMBER(#REF!) -> FALSE | F11: =ISNUMBER(#REF!) -> FALSE | G11: =ISNUMBER(#REF!) -> FALSE | H11: =ISNUMBER(#REF!) -> FALSE | I11: =ISNUMBER(#REF!) -> FALSE | J11: =ISNUMBER(#REF!) -> FALSE | K11: =ISNUMBER(#REF!) -> FALSE | L11: =ISNUMBER(#REF!) -> FALSE | M11: =ISNUMBER(C11) -> TRUE | N11: =ISNUMBER(#REF!) -> FALSE | O11: =ISNUMBER(#REF!) -> FALSE | P11: =ISNUMBER(#REF!) -> FALSE | Q11: =IF(M11=TRUE,"",1)
A12: =IF(B12="","",$A$4) -> 44898.948 | B12: 1E-HCL1 | C12: =IFERROR(VLOOKUP($B12,_XM_XT_THUCTE,32,0),"") -> 0 | E12: =ISNUMBER(#REF!) -> FALSE | F12: =ISNUMBER(#REF!) -> FALSE | G12: =ISNUMBER(#REF!) -> FALSE | H12: =ISNUMBER(#REF!) -> FALSE | I12: =ISNUMBER(#REF!) -> FALSE | J12: =ISNUMBER(#REF!) -> FALSE | K12: =ISNUMBER(#REF!) -> FALSE | L12: =ISNUMBER(#REF!) -> FALSE | M12: =ISNUMBER(C12) -> TRUE | N12: =ISNUMBER(#REF!) -> FALSE | O12: =ISNUMBER(#REF!) -> FALSE | P12: =ISNUMBER(#REF!) -> FALSE | Q12: =IF(M12=TRUE,"",1)
A13: =IF(B13="","",$A$4) -> 44898.948 | B13: 1E-HCL2 | C13: =IFERROR(VLOOKUP($B13,_XM_XT_THUCTE,32,0),"") -> 0 | E13: =ISNUMBER(#REF!) -> FALSE | F13: =ISNUMBER(#REF!) -> FALSE | G13: =ISNUMBER(#REF!) -> FALSE | H13: =ISNUMBER(#REF!) -> FALSE | I13: =ISNUMBER(#REF!) -> FALSE | J13: =ISNUMBER(#REF!) -> FALSE | K13: =ISNUMBER(#REF!) -> FALSE | L13: =ISNUMBER(#REF!) -> FALSE | M13: =ISNUMBER(C13) -> TRUE | N13: =ISNUMBER(#REF!) -> FALSE | O13: =ISNUMBER(#REF!) -> FALSE | P13: =ISNUMBER(#REF!) -> FALSE | Q13: =IF(M13=TRUE,"",1)
A14: =IF(B14="","",$A$4) -> 44898.948 | B14: 1E-HCL3 | C14: =IFERROR(VLOOKUP($B14,_XM_XT_THUCTE,32,0),"") -> 0 | E14: =ISNUMBER(#REF!) -> FALSE | F14: =ISNUMBER(#REF!) -> FALSE | G14: =ISNUMBER(#REF!) -> FALSE | H14: =ISNUMBER(#REF!) -> FALSE | I14: =ISNUMBER(#REF!) -> FALSE | J14: =ISNUMBER(#REF!) -> FALSE | K14: =ISNUMBER(#REF!) -> FALSE | L14: =ISNUMBER(#REF!) -> FALSE | M14: =ISNUMBER(C14) -> TRUE | N14: =ISNUMBER(#REF!) -> FALSE | O14: =ISNUMBER(#REF!) -> FALSE | P14: =ISNUMBER(#REF!) -> FALSE | Q14: =IF(M14=TRUE,"",1)
A15: =IF(B15="","",$A$4) -> 44898.948 | B15: 1E-HNO3 | C15: =IFERROR(VLOOKUP($B15,_XM_XT_THUCTE,32,0),"") -> 0 | E15: =ISNUMBER(#REF!) -> FALSE | F15: =ISNUMBER(#REF!) -> FALSE | G15: =ISNUMBER(#REF!) -> FALSE | H15: =ISNUMBER(#REF!) -> FALSE | I15: =ISNUMBER(#REF!) -> FALSE | J15: =ISNUMBER(#REF!) -> FALSE | K15: =ISNUMBER(#REF!) -> FALSE | L15: =ISNUMBER(#REF!) -> FALSE | M15: =ISNUMBER(C15) -> TRUE | N15: =ISNUMBER(#REF!) -> FALSE | O15: =ISNUMBER(#REF!) -> FALSE | P15: =ISNUMBER(#REF!) -> FALSE | Q15: =IF(M15=TRUE,"",1)
A16: =IF(B16="","",$A$4) -> 44898.948 | B16: 1E-MEM | C16: =IFERROR(VLOOKUP($B16,_XM_XT_THUCTE,32,0),"") -> 0 | E16: =ISNUMBER(#REF!) -> FALSE | F16: =ISNUMBER(#REF!) -> FALSE | G16: =ISNUMBER(#REF!) -> FALSE | H16: =ISNUMBER(#REF!) -> FALSE | I16: =ISNUMBER(#REF!) -> FALSE | J16: =ISNUMBER(#REF!) -> FALSE | K16: =ISNUMBER(#REF!) -> FALSE | L16: =ISNUMBER(#REF!) -> FALSE | M16: =ISNUMBER(C16) -> TRUE | N16: =ISNUMBER(#REF!) -> FALSE | O16: =ISNUMBER(#REF!) -> FALSE | P16: =ISNUMBER(#REF!) -> FALSE | Q16: =IF(M16=TRUE,"",1)
... A45: =IF(B45="","",$A$4) -> 44898.948 | B45: XT-MEM | C45: =IFERROR(VLOOKUP($B45,_XM_XT_THUCTE,32,0),"") -> 0 | E45: =ISNUMBER(#REF!) -> FALSE | F45: =ISNUMBER(#REF!) -> FALSE | G45: =ISNUMBER(#REF!) -> FALSE | H45: =ISNUMBER(#REF!) -> FALSE | I45: =ISNUMBER(#REF!) -> FALSE | J45: =ISNUMBER(#REF!) -> FALSE | K45: =ISNUMBER(#REF!) -> FALSE | L45: =ISNUMBER(#REF!) -> FALSE | M45: =ISNUMBER(C45) -> TRUE | N45: =ISNUMBER(#REF!) -> FALSE | O45: =ISNUMBER(#REF!) -> FALSE | P45: =ISNUMBER(#REF!) -> FALSE | Q45: =IF(M45=TRUE,"",1)

Sheet 7
A1: "BÁO CÁO KẾT QUẢ HÓA NGHIỆM HÀNG NGÀY 表面處理生產製程管控記錄表"
A2: NGAY | B2: Ma__Hang_muc | C2: Nong_Do_06 | E2: 1 | F2: bs | G2: 2 | H2: bs | I2: 3 | J2: bs | K2: 4 | L2: bs | M2: 5 | N2: bs | O2: 6 | P2: bs | Q2: 6
A3: Date | B3: Code | C3: 濃度 g/L_06
A4: =MENU!Y24 -> 44898.125 | B4: 1E-XB1 | C4: =IFERROR(VLOOKUP($B4,_XM_XT_THUCTE,38,0),"") -> 29.2 | E4: =ISNUMBER(#REF!) -> FALSE | F4: =ISNUMBER(#REF!) -> FALSE | G4: =ISNUMBER(#REF!) -> FALSE | H4: =ISNUMBER(#REF!) -> FALSE | I4: =ISNUMBER(#REF!) -> FALSE | J4: =ISNUMBER(#REF!) -> FALSE | K4: =ISNUMBER(#REF!) -> FALSE | L4: =ISNUMBER(#REF!) -> FALSE | ... N4: =ISNUMBER(#REF!) -> FALSE | O4: =ISNUMBER(C4) -> TRUE | P4: =ISNUMBER(#REF!) -> FALSE | Q4: =IF(O4=TRUE,"",1)
A5: =IF(B5="","",$A$4) -> 44898.125 | B5: 1E-XB2 | C5: =IFERROR(VLOOKUP($B5,_XM_XT_THUCTE,38,0),"") -> 30.8 | E5: =ISNUMBER(#REF!) -> FALSE | F5: =ISNUMBER(#REF!) -> FALSE | G5: =ISNUMBER(#REF!) -> FALSE | H5: =ISNUMBER(#REF!) -> FALSE | I5: =ISNUMBER(#REF!) -> FALSE | J5: =ISNUMBER(#REF!) -> FALSE | K5: =ISNUMBER(#REF!) -> FALSE | L5: =ISNUMBER(#REF!) -> FALSE | ... N5: =ISNUMBER(#REF!) -> FALSE | O5: =ISNUMBER(C5) -> TRUE | P5: =ISNUMBER(#REF!) -> FALSE | Q5: =IF(O5=TRUE,"",1)
A6: =IF(B6="","",$A$4) -> 44898.125 | B6: 1E-DG1 | C6: =IFERROR(VLOOKUP($B6,_XM_XT_THUCTE,38,0),"") -> 72 | E6: =ISNUMBER(#REF!) -> FALSE | F6: =ISNUMBER(#REF!) -> FALSE | G6: =ISNUMBER(#REF!) -> FALSE | H6: =ISNUMBER(#REF!) -> FALSE | I6: =ISNUMBER(#REF!) -> FALSE | J6: =ISNUMBER(#REF!) -> FALSE | K6: =ISNUMBER(#REF!) -> FALSE | L6: =ISNUMBER(#REF!) -> FALSE | ... N6: =ISNUMBER(#REF!) -> FALSE | O6: =ISNUMBER(C6) -> TRUE | P6: =ISNUMBER(#REF!) -> FALSE | Q6: =IF(O6=TRUE,"",1)
A7: =IF(B7="","",$A$4) -> 44898.125 | B7: 1E-DG2 | C7: =IFERROR(VLOOKUP($B7,_XM_XT_THUCTE,38,0),"") -> 70 | E7: =ISNUMBER(#REF!) -> FALSE | F7: =ISNUMBER(#REF!) -> FALSE | G7: =ISNUMBER(#REF!) -> FALSE | H7: =ISNUMBER(#REF!) -> FALSE | I7: =ISNUMBER(#REF!) -> FALSE | J7: =ISNUMBER(#REF!) -> FALSE | K7: =ISNUMBER(#REF!) -> FALSE | L7: =ISNUMBER(#REF!) -> FALSE | ... N7: =ISNUMBER(#REF!) -> FALSE | O7: =ISNUMBER(C7) -> TRUE | P7: =ISNUMBER(#REF!) -> FALSE | Q7: =IF(O7=TRUE,"",1)
A8: =IF(B8="","",$A$4) -> 44898.125 | B8: 1E-NAOH | C8: =IFERROR(VLOOKUP($B8,_XM_XT_THUCTE,38,0),"") -> 138.4 | E8: =ISNUMBER(#REF!) -> FALSE | F8: =ISNUMBER(#REF!) -> FALSE | G8: =ISNUMBER(#REF!) -> FALSE | H8: =ISNUMBER(#REF!) -> FALSE | I8: =ISNUMBER(#REF!) -> FALSE | J8: =ISNUMBER(#REF!) -> FALSE | K8: =ISNUMBER(#REF!) -> FALSE | L8: =ISNUMBER(#REF!) -> FALSE | ... N8: =ISNUMBER(#REF!) -> FALSE | O8: =ISNUMBER(C8) -> TRUE | P8: =ISNUMBER(#REF!) -> FALSE | Q8: =IF(O8=TRUE,"",1)
A9: =IF(B9="","",$A$4) -> 44898.125 | B9: 1E-ZN | C9: =IFERROR(VLOOKUP($B9,_XM_XT_THUCTE,38,0),"") -> 9.75 | E9: =ISNUMBER(#REF!) -> FALSE | F9: =ISNUMBER(#REF!) -> FALSE | G9: =ISNUMBER(#REF!) -> FALSE | H9: =ISNUMBER(#REF!) -> FALSE | I9: =ISNUMBER(#REF!) -> FALSE | J9: =ISNUMBER(#REF!) -> FALSE | K9: =ISNUMBER(#REF!) -> FALSE | L9: =ISNUMBER(#REF!) -> FALSE | ... N9: =ISNUMBER(#REF!) -> FALSE | O9: =ISNUMBER(C9) -> TRUE | P9: =ISNUMBER(#REF!) -> FALSE | Q9: =IF(O9=TRUE,"",1)
A10: =IF(B10="","",$A$4) -> 44898.125 | B10: 1E-CR3I | C10: =IFERROR(VLOOKUP($B10,_XM_XT_THUCTE,38,0),"") -> 13.381295 | E10: =ISNUMBER(#REF!) -> FALSE | F10: =ISNUMBER(#REF!) -> FALSE | G10: =ISNUMBER(#REF!) -> FALSE | H10: =ISNUMBER(#REF!) -> FALSE | I10: =ISNUMBER(#REF!) -> FALSE | J10: =ISNUMBER(#REF!) -> FALSE | K10: =ISNUMBER(#REF!) -> FALSE | L10: =ISNUMBER(#REF!) -> FALSE | ... N10: =ISNUMBER(#REF!) -> FALSE | O10: =ISNUMBER(C10) -> TRUE | P10: =ISNUMBER(#REF!) -> FALSE | Q10: =IF(O10=TRUE,"",1)
A11: =IF(B11="","",$A$4) -> 44898.125 | B11: 1E-CR3IPH | C11: =IFERROR(VLOOKUP($B11,_XM_XT_THUCTE,38,0),"") -> 1.8 | E11: =ISNUMBER(#REF!) -> FALSE | F11: =ISNUMBER(#REF!) -> FALSE | G11: =ISNUMBER(#REF!) -> FALSE | H11: =ISNUMBER(#REF!) -> FALSE | I11: =ISNUMBER(#REF!) -> FALSE | J11: =ISNUMBER(#REF!) -> FALSE | K11: =ISNUMBER(#REF!) -> FALSE | L11: =ISNUMBER(#REF!) -> FALSE | ... N11: =ISNUMBER(#REF!) -> FALSE | O11: =ISNUMBER(C11) -> TRUE | P11: =ISNUMBER(#REF!) -> FALSE | Q11: =IF(O11=TRUE,"",1)
A12: =IF(B12="","",$A$4) -> 44898.125 | B12: 1E-HCL1 | C12: =IFERROR(VLOOKUP($B12,_XM_XT_THUCTE,38,0),"") -> 0.44484375 | E12: =ISNUMBER(#REF!) -> FALSE | F12: =ISNUMBER(#REF!) -> FALSE | G12: =ISNUMBER(#REF!) -> FALSE | H12: =ISNUMBER(#REF!) -> FALSE | I12: =ISNUMBER(#REF!) -> FALSE | J12: =ISNUMBER(#REF!) -> FALSE | K12: =ISNUMBER(#REF!) -> FALSE | L12: =ISNUMBER(#REF!) -> FALSE | ... N12: =ISNUMBER(#REF!) -> FALSE | O12: =ISNUMBER(C12) -> TRUE | P12: =ISNUMBER(#REF!) -> FALSE | Q12: =IF(O12=TRUE,"",1)
A13: =IF(B13="","",$A$4) -> 44898.125 | B13: 1E-HCL2 | C13: =IFERROR(VLOOKUP($B13,_XM_XT_THUCTE,38,0),"") -> 0.23953125 | E13: =ISNUMBER(#REF!) -> FALSE | F13: =ISNUMBER(#REF!) -> FALSE | G13: =ISNUMBER(#REF!) -> FALSE | H13: =ISNUMBER(#REF!) -> FALSE | I13: =ISNUMBER(#REF!) -> FALSE | J13: =ISNUMBER(#REF!) -> FALSE | K13: =ISNUMBER(#REF!) -> FALSE | L13: =ISNUMBER(#REF!) -> FALSE | ... N13: =ISNUMBER(#REF!) -> FALSE | O13: =ISNUMBER(C13) -> TRUE | P13: =ISNUMBER(#REF!) -> FALSE | Q13: =IF(O13=TRUE,"",1)
A14: =IF(B14="","",$A$4) -> 44898.125 | B14: 1E-HCL3 | C14: =IFERROR(VLOOKUP($B14,_XM_XT_THUCTE,38,0),"") -> 0.0958125 | E14: =ISNUMBER(#REF!) -> FALSE | F14: =ISNUMBER(#REF!) -> FALSE | G14: =ISNUMBER(#REF!) -> FALSE | H14: =ISNUMBER(#REF!) -> FALSE | I14: =ISNUMBER(#REF!) -> FALSE | J14: =ISNUMBER(#REF!) -> FALSE | K14: =ISNUMBER(#REF!) -> FALSE | L14: =ISNUMBER(#REF!) -> FALSE | ... N14: =ISNUMBER(#REF!) -> FALSE | O14: =ISNUMBER(C14) -> TRUE | P14: =ISNUMBER(#REF!) -> FALSE | Q14: =IF(O14=TRUE,"",1)
A15: =IF(B15="","",$A$4) -> 44898.125 | B15: 1E-HNO3 | C15: =IFERROR(VLOOKUP($B15,_XM_XT_THUCTE,38,0),"") -> 0.01234996 | E15: =ISNUMBER(#REF!) -> FALSE | F15: =ISNUMBER(#REF!) -> FALSE | G15: =ISNUMBER(#REF!) -> FALSE | H15: =ISNUMBER(#REF!) -> FALSE | I15: =ISNUMBER(#REF!) -> FALSE | J15: =ISNUMBER(#REF!) -> FALSE | K15: =ISNUMBER(#REF!) -> FALSE | L15: =ISNUMBER(#REF!) -> FALSE | ... N15: =ISNUMBER(#REF!) -> FALSE | O15: =ISNUMBER(C15) -> TRUE | P15: =ISNUMBER(#REF!) -> FALSE | Q15: =IF(O15=TRUE,"",1)
A16: =IF(B16="","",$A$4) -> 44898.125 | B16: 1E-MEM | C16: =IFERROR(VLOOKUP($B16,_XM_XT_THUCTE,38,0),"") -> 340 | E16: =ISNUMBER(#REF!) -> FALSE | F16: =ISNUMBER(#REF!) -> FALSE | G16: =ISNUMBER(#REF!) -> FALSE | H16: =ISNUMBER(#REF!) -> FALSE | I16: =ISNUMBER(#REF!) -> FALSE | J16: =ISNUMBER(#REF!) -> FALSE | K16: =ISNUMBER(#REF!) -> FALSE | L16: =ISNUMBER(#REF!) -> FALSE | ... N16: =ISNUMBER(#REF!) -> FALSE | O16: =ISNUMBER(C16) -> TRUE | P16: =ISNUMBER(#REF!) -> FALSE | Q16: =IF(O16=TRUE,"",1)
... A45: =IF(B45="","",$A$4) -> 44898.125 | B45: XT-MEM | C45: =IFERROR(VLOOKUP($B45,_XM_XT_THUCTE,38,0),"") -> 0 | E45: =ISNUMBER(#REF!) -> FALSE | F45: =ISNUMBER(#REF!) -> FALSE | G45: =ISNUMBER(#REF!) -> FALSE | H45: =ISNUMBER(#REF!) -> FALSE | I45: =ISNUMBER(#REF!) -> FALSE | J45: =ISNUMBER(#REF!) -> FALSE | K45: =ISNUMBER(#REF!) -> FALSE | L45: =ISNUMBER(#REF!) -> FALSE | ... N45: =ISNUMBER(#REF!) -> FALSE | O45: =ISNUMBER(C45) -> TRUE | P45: =ISNUMBER(#REF!) -> FALSE | Q45: =IF(O45=TRUE,"",1)
A46: =IF(B46="","",$A$4) -> 44898.125 | B46: RLE-HCL1 | C46: =IFERROR(VLOOKUP($B46,RLMLXD,32,0),"") -> 0 | E46: =ISNUMBER(#REF!) -> FALSE | F46: =ISNUMBER(#REF!) -> FALSE | G46: =ISNUMBER(#REF!) -> FALSE | H46: =ISNUMBER(#REF!) -> FALSE | I46: =ISNUMBER(#REF!) -> FALSE | J46: =ISNUMBER(#REF!) -> FALSE | K46: =ISNUMBER(#REF!) -> FALSE | L46: =ISNUMBER(#REF!) -> FALSE | ... N46: =ISNUMBER(#REF!) -> FALSE | O46: =ISNUMBER(C46) -> TRUE | P46: =ISNUMBER(#REF!) -> FALSE | Q46: =IF(O46=TRUE,"",1)
A47: =IF(B47="","",$A$4) -> 44898.125 | B47: RLE-HCL2 | C47: =IFERROR(VLOOKUP($B47,RLMLXD,32,0),"") -> 0 | E47: =ISNUMBER(#REF!) -> FALSE | F47: =ISNUMBER(#REF!) -> FALSE | G47: =ISNUMBER(#REF!) -> FALSE | H47: =ISNUMBER(#REF!) -> FALSE | I47: =ISNUMBER(#REF!) -> FALSE | J47: =ISNUMBER(#REF!) -> FALSE | K47: =ISNUMBER(#REF!) -> FALSE | L47: =ISNUMBER(#REF!) -> FALSE | ... N47: =ISNUMBER(#REF!) -> FALSE | O47: =ISNUMBER(C47) -> TRUE | P47: =ISNUMBER(#REF!) -> FALSE | Q47: =IF(O47=TRUE,"",1)
A48: =IF(B48="","",$A$4) -> 44898.125 | B48: RLE-PP1TA | C48: =IFERROR(VLOOKUP($B48,RLMLXD,32,0),"") -> 0 | E48: =ISNUMBER(#REF!) -> FALSE | F48: =ISNUMBER(#REF!) -> FALSE | G48: =ISNUMBER(#REF!) -> FALSE | H48: =ISNUMBER(#REF!) -> FALSE | I48: =ISNUMBER(#REF!) -> FALSE | J48: =ISNUMBER(#REF!) -> FALSE | K48: =ISNUMBER(#REF!) -> FALSE | L48: =ISNUMBER(#REF!) -> FALSE | ... N48: =ISNUMBER(#REF!) -> FALSE | O48: =ISNUMBER(C48) -> TRUE | P48: =ISNUMBER(#REF!) -> FALSE | Q48: =IF(O48=TRUE,"",1)
A49: =IF(B49="","",$A$4) -> 44898.125 | B49: RLE-PP1AX | C49: =IFERROR(VLOOKUP($B49,RLMLXD,32,0),"") -> 0 | E49: =ISNUMBER(#REF!) -> FALSE | F49: =ISNUMBER(#REF!) -> FALSE | G49: =ISNUMBER(#REF!) -> FALSE | H49: =ISNUMBER(#REF!) -> FALSE | I49: =ISNUMBER(#REF!) -> FALSE | J49: =ISNUMBER(#REF!) -> FALSE | K49: =ISNUMBER(#REF!) -> FALSE | L49: =ISNUMBER(#REF!) -> FALSE | ... N49: =ISNUMBER(#REF!) -> FALSE | O49: =ISNUMBER(C49) -> TRUE | P49: =ISNUMBER(#REF!) -> FALSE | Q49: =IF(O49=TRUE,"",1)
A50: =IF(B50="","",$A$4) -> 44898.125 | B50: RLE-PP1PL | C50: =IFERROR(VLOOKUP($B50,RLMLXD,32,0),"") -> 0 | E50: =ISNUMBER(#REF!) -> FALSE | F50: =ISNUMBER(#REF!) -> FALSE | G50: =ISNUMBER(#REF!) -> FALSE | H50: =ISNUMBER(#REF!) -> FALSE | I50: =ISNUMBER(#REF!) -> FALSE | J50: =ISNUMBER(#REF!) -> FALSE | K50: =ISNUMBER(#REF!) -> FALSE | L50: =ISNUMBER(#REF!) -> FALSE | ... N50: =ISNUMBER(#REF!) -> FALSE | O50: =ISNUMBER(C50) -> TRUE | P50: =ISNUMBER(#REF!) -> FALSE | Q50: =IF(O50=TRUE,"",1)
A51: =IF(B51="","",$A$4) -> 44898.125 | B51: RLE-PP2TA | C51: =IFERROR(VLOOKUP($B51,RLMLXD,32,0),"") -> 0 | E51: =ISNUMBER(#REF!) -> FALSE | F51: =ISNUMBER(#REF!) -> FALSE | G51: =ISNUMBER(#REF!) -> FALSE | H51: =ISNUMBER(#REF!) -> FALSE | I51: =ISNUMBER(#REF!) -> FALSE | J51: =ISNUMBER(#REF!) -> FALSE | K51: =ISNUMBER(#REF!) -> FALSE | L51: =ISNUMBER(#REF!) -> FALSE | ... N51: =ISNUMBER(#REF!) -> FALSE | O51: =ISNUMBER(C51) -> TRUE | P51: =ISNUMBER(#REF!) -> FALSE | Q51: =IF(O51=TRUE,"",1)
A52: =IF(B52="","",$A$4) -> 44898.125 | B52: RLE-PP2AX | C52: =IFERROR(VLOOKUP($B52,RLMLXD,32,0),"") -> 0 | E52: =ISNUMBER(#REF!) -> FALSE | F52: =ISNUMBER(#REF!) -> FALSE | G52: =ISNUMBER(#REF!) -> FALSE | H52: =ISNUMBER(#REF!) -> FALSE | I52: =ISNUMBER(#REF!) -> FALSE | J52: =ISNUMBER(#REF!) -> FALSE | K52: =ISNUMBER(#REF!) -> FALSE | L52: =ISNUMBER(#REF!) -> FALSE | ... N52: =ISNUMBER(#REF!) -> FALSE | O52: =ISNUMBER(C52) -> TRUE | P52: =ISNUMBER(#REF!) -> FALSE | Q52: =IF(O52=TRUE,"",1)
A53: =IF(B53="","",$A$4) -> 44898.125 | B53: RLE-PP2PL | C53: =IFERROR(VLOOKUP($B53,RLMLXD,32,0),"") -> 0 | E53: =ISNUMBER(#REF!) -> FALSE | F53: =ISNUMBER(#REF!) -> FALSE | G53: =ISNUMBER(#REF!) -> FALSE | H53: =ISNUMBER(#REF!) -> FALSE | I53: =ISNUMBER(#REF!) -> FALSE | J53: =ISNUMBER(#REF!) -> FALSE | K53: =ISNUMBER(#REF!) -> FALSE | L53: =ISNUMBER(#REF!) -> FALSE | ... N53: =ISNUMBER(#REF!) -> FALSE | O53: =ISNUMBER(C53) -> TRUE | P53: =ISNUMBER(#REF!) -> FALSE | Q53: =IF(O53=TRUE,"",1)
A54: =IF(B54="","",$A$4) -> 44898.125 | B54: RLE-XB | C54: =IFERROR(VLOOKUP($B54,RLMLXD,32,0),"") -> 0 | E54: =ISNUMBER(#REF!) -> FALSE | F54: =ISNUMBER(#REF!) -> FALSE | G54: =ISNUMBER(#REF!) -> FALSE | H54: =ISNUMBER(#REF!) -> FALSE | I54: =ISNUMBER(#REF!) -> FALSE | J54: =ISNUMBER(#REF!) -> FALSE | K54: =ISNUMBER(#REF!) -> FALSE | L54: =ISNUMBER(#REF!) -> FALSE | ... N54: =ISNUMBER(#REF!) -> FALSE | O54: =ISNUMBER(C54) -> TRUE | P54: =ISNUMBER(#REF!) -> FALSE | Q54: =IF(O54=TRUE,"",1)
A55: =IF(B55="","",$A$4) -> 44898.125 | B55: RLE-XBPH | C55: =IFERROR(VLOOKUP($B55,RLMLXD,32,0),"") -> 0 | E55: =ISNUMBER(#REF!) -> FALSE | F55: =ISNUMBER(#REF!) -> FALSE | G55: =ISNUMBER(#REF!) -> FALSE | H55: =ISNUMBER(#REF!) -> FALSE | I55: =ISNUMBER(#REF!) -> FALSE | J55: =ISNUMBER(#REF!) -> FALSE | K55: =ISNUMBER(#REF!) -> FALSE | L55: =ISNUMBER(#REF!) -> FALSE | ... N55: =ISNUMBER(#REF!) -> FALSE | O55: =ISNUMBER(C55) -> TRUE | P55: =ISNUMBER(#REF!) -> FALSE | Q55: =IF(O55=TRUE,"",1)
A56: =IF(B56="","",$A$4) -> 44898.125 | B56: RLG-KD | C56: =IFERROR(VLOOKUP($B56,RLMLXD,32,0),"") -> 0 | E56: =ISNUMBER(#REF!) -> FALSE | F56: =ISNUMBER(#REF!) -> FALSE | G56: =ISNUMBER(#REF!) -> FALSE | H56: =ISNUMBER(#REF!) -> FALSE | I56: =ISNUMBER(#REF!) -> FALSE | J56: =ISNUMBER(#REF!) -> FALSE | K56: =ISNUMBER(#REF!) -> FALSE | L56: =ISNUMBER(#REF!) -> FALSE | ... N56: =ISNUMBER(#REF!) -> FALSE | O56: =ISNUMBER(C56) -> TRUE | P56: =ISNUMBER(#REF!) -> FALSE | Q56: =IF(O56=TRUE,"",1)
A57: =IF(B57="","",$A$4) -> 44898.125 | B57: RLG-HCL1 | C57: =IFERROR(VLOOKUP($B57,RLMLXD,32,0),"") -> 0 | E57: =ISNUMBER(#REF!) -> FALSE | F57: =ISNUMBER(#REF!) -> FALSE | G57: =ISNUMBER(#REF!) -> FALSE | H57: =ISNUMBER(#REF!) -> FALSE | I57: =ISNUMBER(#REF!) -> FALSE | J57: =ISNUMBER(#REF!) -> FALSE | K57: =ISNUMBER(#REF!) -> FALSE | L57: =ISNUMBER(#REF!) -> FALSE | ... N57: =ISNUMBER(#REF!) -> FALSE | O57: =ISNUMBER(C57) -> TRUE | P57: =ISNUMBER(#REF!) -> FALSE | Q57: =IF(O57=TRUE,"",1)
... A69: =IF(B69="","",$A$4) -> 44898.125 | B69: RLF-XBPH | C69: =IFERROR(VLOOKUP($B69,RLMLXD,32,0),"") -> 0 | E69: =ISNUMBER(#REF!) -> FALSE | F69: =ISNUMBER(#REF!) -> FALSE | G69: =ISNUMBER(#REF!) -> FALSE | H69: =ISNUMBER(#REF!) -> FALSE | I69: =ISNUMBER(#REF!) -> FALSE | J69: =ISNUMBER(#REF!) -> FALSE | K69: =ISNUMBER(#REF!) -> FALSE | L69: =ISNUMBER(#REF!) -> FALSE | ... N69: =ISNUMBER(#REF!) -> FALSE | O69: =ISNUMBER(C69) -> TRUE | P69: =ISNUMBER(#REF!) -> FALSE | Q69: =IF(O69=TRUE,"",1)

Sheet 8
A1: "BÁO CÁO KẾT QUẢ HÓA NGHIỆM HÀNG NGÀY 表面處理生產製程管控記錄表"
A2: NGAY | B2: Ma__Hang_muc | C2: Nong_Do_06 | E2: 1 | F2: bs | G2: 2 | H2: bs | I2: 3 | J2: bs | K2: 4 | L2: bs | M2: 5 | N2: bs | O2: 6 | P2: bs | Q2: 6
A3: Date | B3: Code | C3: 濃度 g/L_06
A4: =MENU!Y27 -> 44898.208 | B4: 1E-XB1 | E4: =ISNUMBER(#REF!) -> FALSE | F4: =ISNUMBER(#REF!) -> FALSE | G4: =ISNUMBER(#REF!) -> FALSE | H4: =ISNUMBER(#REF!) -> FALSE | I4: =ISNUMBER(#REF!) -> FALSE | J4: =ISNUMBER(#REF!) -> FALSE | K4: =ISNUMBER(#REF!) -> FALSE | L4: =ISNUMBER(#REF!) -> FALSE | ... N4: =ISNUMBER(#REF!) -> FALSE | O4: =ISNUMBER(C4) -> FALSE | P4: =ISNUMBER(#REF!) -> FALSE | Q4: =IF(O4=TRUE,"",1) -> 1
A5: =IF(B5="","",$A$4) -> 44898.208 | B5: RLE-HCL1 | C5: =IFERROR(VLOOKUP($B5,RLMLXD,38,0),"") -> 0 | E5: =ISNUMBER(#REF!) -> FALSE | F5: =ISNUMBER(#REF!) -> FALSE | G5: =ISNUMBER(#REF!) -> FALSE | H5: =ISNUMBER(#REF!) -> FALSE | I5: =ISNUMBER(#REF!) -> FALSE | J5: =ISNUMBER(#REF!) -> FALSE | K5: =ISNUMBER(#REF!) -> FALSE | L5: =ISNUMBER(#REF!) -> FALSE | ... N5: =ISNUMBER(#REF!) -> FALSE | O5: =ISNUMBER(C5) -> TRUE | P5: =ISNUMBER(#REF!) -> FALSE | Q5: =IF(O5=TRUE,"",1)
A6: =IF(B6="","",$A$4) -> 44898.208 | B6: RLE-HCL2 | C6: =IFERROR(VLOOKUP($B6,RLMLXD,38,0),"") -> 0 | E6: =ISNUMBER(#REF!) -> FALSE | F6: =ISNUMBER(#REF!) -> FALSE | G6: =ISNUMBER(#REF!) -> FALSE | H6: =ISNUMBER(#REF!) -> FALSE | I6: =ISNUMBER(#REF!) -> FALSE | J6: =ISNUMBER(#REF!) -> FALSE | K6: =ISNUMBER(#REF!) -> FALSE | L6: =ISNUMBER(#REF!) -> FALSE | ... N6: =ISNUMBER(#REF!) -> FALSE | O6: =ISNUMBER(C6) -> TRUE | P6: =ISNUMBER(#REF!) -> FALSE | Q6: =IF(O6=TRUE,"",1)
